Workbook
Name EssAliasTable: "Default"
Name EssAliasTable: "Default"
Name EssAliasTable: "JDE"
Name EssAliasTable: "Default"
Name EssAliasTable: "Misc Alias"
Name EssLatest: "Oct"
Name EssLatest: "Oct"
Name EssLatest: "Oct"
Name EssLatest: "Oct"
Name EssLatest: "Beg Bal"
Name EssOptions: "A3100000000110000011001100020_08#missing00"
Name EssOptions: "A1100000000110000011001100020_08#missing00"
Name EssOptions: "A1100000000110000011001100020_08#missing00"
Name EssOptions: "A1100000000110000011001100020_08#missing00"
Name EssOptions: "A1100000000111001000001100020_08#missing00"
Name EssSamplingValue: 100
Name EssSamplingValue: 100
Name EssSamplingValue: 100
Name EssSamplingValue: 100
Name EssSamplingValue: 100

Sheet Pharm Demand
A1: Specialty Generics and Specialty Pharmaceuticals
A2: FY11 APR LE - Outfreight Expense - 7171
C3: PharmDmnd
C4: WF | D4: WF | E4: WF | F4: WF | G4: WF | H4: WF | I4: WF | J4: WF | K4: WF | L4: WF | M4: WF | N4: WF | O4: 12WF | P4: 12WF | Q4: 12WF | R4: 12WF | S4: 12WF | T4: 12WF | U4: 12WF | V4: 12WF | W4: 12WF | X4: 12WF | Y4: 12WF | Z4: 12WF | AA4: 13WF | AB4: 13WF | AC4: 13WF | AD4: 13WF | AE4: 13WF | AF4: 13WF | AG4: 13WF | AH4: 13WF | AI4: 13WF | AJ4: 13WF | AK4: 13WF | AL4: 13WF | AM4: 14WF | AN4: 14WF | AO4: 14WF | AP4: 14WF | AQ4: 14WF | AR4: 14WF | AS4: 14WF | AT4: 14WF | AU4: 14WF | AV4: 14WF | AW4: 14WF | AX4: 14WF
C5: Oct | D5: Nov | E5: Dec | F5: Jan | G5: Feb | H5: Mar | I5: Apr | J5: May | K5: Jun | L5: Jul | M5: Aug | N5: Sep | O5: Oct | P5: Nov | Q5: Dec | R5: Jan | S5: Feb | T5: Mar | U5: Apr | V5: May | W5: Jun | X5: Jul | Y5: Aug | Z5: Sep | AA5: Oct | AB5: Nov | AC5: Dec | AD5: Jan | AE5: Feb | AF5: Mar | AG5: Apr | AH5: May | AI5: Jun | AJ5: Jul | AK5: Aug | AL5: Sep | AM5: Oct | AN5: Nov | AO5: Dec | AP5: Jan | AQ5: Feb | AR5: Mar | AS5: Apr | AT5: May | AU5: Jun | AV5: Jul | AW5: Aug | AX5: Sep
A6: Hydrocodone | B6: Sales Volume | C6: 1235886 | D6: 1804512 | E6: 1149335 | F6: 1051728 | G6: 1426134 | H6: 1317971 | I6: 1417836 | J6: 1775462.3 | K6: 1378399.5 | L6: 1404003.1 | M6: 1847024.6 | N6: 1681835.2 | O6: 1477714.9 | P6: 1847143.6 | Q6: 1477714.9 | R6: 1477714.9 | S6: 1847143.6 | T6: 1477714.9 | U6: 1477714.9 | V6: 1847143.6 | W6: 1477714.9 | X6: 1477714.9 | Y6: 1847143.6 | Z6: 1477714.9 | AA6: 1727549.9 | AB6: 2159437.3 | AC6: 1727549.9 | AD6: 1727549.9 | AE6: 2159437.3 | AF6: 1727549.9 | AG6: 1727549.9 | AH6: 2159437.3 | AI6: 1727549.9 | AJ6: 1727549.9 | AK6: 2159437.3 | AL6: 1727549.9 | AM6: 2010335.1 | AN6: 2512918.9 | AO6: 2010335.1 | AP6: 2010335.1 | AQ6: 2512918.9 | AR6: 2010686.9 | AS6: 2010335.1 | AT6: 2010335.1 | AU6: 0 | AV6: 0 | AW6: 0 | AX6: 0
A7: Oxycodone | B7: Sales Volume | C7: 714228.01 | D7: 896532 | E7: 821460 | F7: 602232 | G7: 683976 | H7: 727140 | I7: 367608 | J7: 648587.33 | K7: 660521.13 | L7: 634880.65 | M7: 430770.92 | N7: 885758 | O7: 917140.76 | P7: 1037817.8 | Q7: 917140.76 | R7: 917140.76 | S7: 1146426 | T7: 917140.76 | U7: 917140.76 | V7: 1146426 | W7: 917140.76 | X7: 917140.76 | Y7: 1146426 | Z7: 917140.76 | AA7: 1066294.5 | AB7: 1332868.2 | AC7: 1066294.5 | AD7: 1066294.5 | AE7: 1332868.2 | AF7: 1066294.5 | AG7: 1066294.5 | AH7: 1332868.2 | AI7: 1066294.5 | AJ7: 1066294.5 | AK7: 1332868.2 | AL7: 1066294.5 | AM7: 1193040.7 | AN7: 1349451 | AO7: 1193040.7 | AP7: 1307909.6 | AQ7: 1491300.9 | AR7: 1307909.6 | AS7: 1193040.7 | AT7: 1491300.9 | AU7: 0 | AV7: 0 | AW7: 0 | AX7: 0
A8: Oxycodone APAP | B8: Sales Volume | C8: 769026.01 | D8: 765528 | E8: 985284 | F8: 388770 | G8: 878178 | H8: 938220 | I8: 715506 | J8: 1037707 | K8: 796129 | L8: 804051 | M8: 1067163 | N8: 975967 | O8: 867760.3 | P8: 1084700.4 | Q8: 867760.3 | R8: 867760.3 | S8: 1084700.4 | T8: 867760.3 | U8: 867760.3 | V8: 1084700.4 | W8: 867760.3 | X8: 867760.3 | Y8: 1084700.4 | Z8: 867760.3 | AA8: 919245.72 | AB8: 1149057.1 | AC8: 919245.72 | AD8: 919245.72 | AE8: 1149057.1 | AF8: 919245.72 | AG8: 919245.72 | AH8: 1149057.1 | AI8: 919245.72 | AJ8: 919245.72 | AK8: 1149057.1 | AL8: 919245.72 | AM8: 972370.82 | AN8: 1215463.5 | AO8: 972370.82 | AP8: 972370.82 | AQ8: 1215463.5 | AR8: 972370.82 | AS8: 972370.82 | AT8: 972938.82 | AU8: 0 | AV8: 0 | AW8: 0 | AX8: 0
A9: ADHD Generic | B9: Sales Volume | C9: 159138.01 | D9: 193788.01 | E9: 242058.01 | F9: 37698 | G9: 76002.006 | H9: 85596.007 | I9: 107310.01 | J9: 146296 | K9: 119026 | L9: 119682.62 | M9: 176711.52 | N9: 181721.02 | O9: 205964.62 | P9: 213520.41 | Q9: 167834.12 | R9: 176031.12 | S9: 225267.41 | T9: 173295.12 | U9: 182739.12 | V9: 225355.41 | W9: 167883.12 | X9: 177426.12 | Y9: 215859.41 | Z9: 177114.12 | AA9: 182921.85 | AB9: 203740.56 | AC9: 177211.85 | AD9: 175999.85 | AE9: 225113.56 | AF9: 172934.85 | AG9: 182750.85 | AH9: 215256.56 | AI9: 177283.85 | AJ9: 175702.85 | AK9: 214293.56 | AL9: 175646.85 | AM9: 180245.82 | AN9: 190050.78 | AO9: 183560.82 | AP9: 153021.82 | AQ9: 159532.78 | AR9: 154251.23 | AS9: 195123.36 | AT9: 195123.36 | AU9: 0 | AV9: 0 | AW9: 0 | AX9: 0
A10: Morphine ER | B10: Sales Volume | C10: 170508 | D10: 231108 | E10: 184188 | F10: 88344 | G10: 212772 | H10: 146740 | I10: 177840 | J10: 244186.09 | K10: 195348.87 | L10: 195348.87 | M10: 244186.09 | N10: 195783.03 | O10: 207682.83 | P10: 259603.54 | Q10: 207682.83 | R10: 207682.83 | S10: 259603.54 | T10: 207682.83 | U10: 207682.83 | V10: 259603.54 | W10: 207682.83 | X10: 207682.83 | Y10: 259603.54 | Z10: 207682.83 | AA10: 213565.8 | AB10: 266957.25 | AC10: 213565.8 | AD10: 213565.8 | AE10: 266957.25 | AF10: 213565.8 | AG10: 213565.8 | AH10: 266957.25 | AI10: 213565.8 | AJ10: 213565.8 | AK10: 266957.25 | AL10: 213565.8 | AM10: 219350.09 | AN10: 274187.61 | AO10: 219350.09 | AP10: 219350.09 | AQ10: 274187.61 | AR10: 219784.24 | AS10: 219350.09 | AT10: 219350.09 | AU10: 0 | AV10: 0 | AW10: 0 | AX10: 0
A11: Hydromorphone | B11: Sales Volume | C11: 149232 | D11: 214428 | E11: 166200 | F11: 123204 | G11: 203892 | H11: 117984 | I11: 147372 | J11: 179281.56 | K11: 138096.48 | L11: 139910.43 | M11: 186439.45 | N11: 179404.76 | O11: 152073.92 | P11: 176110.09 | Q11: 146425.93 | R11: 147130.17 | S11: 192837.64 | T11: 154989.1 | U11: 155708.12 | V11: 195535.45 | W11: 150547.83 | X11: 151230.68 | Y11: 198234.09 | Z11: 152598.11 | AA11: 164791.89 | AB11: 193328.81 | AC11: 159414.57 | AD11: 160098.31 | AE11: 209586.61 | AF11: 168389.53 | AG11: 169109.38 | AH11: 212285.26 | AI11: 163515.97 | AJ11: 164198.83 | AK11: 214983.07 | AL11: 165473.72 | AM11: 178395.42 | AN11: 209453.54 | AO11: 172558.36 | AP11: 173228.23 | AQ11: 206745.76 | AR11: 198170.01 | AS11: 185565.34 | AT11: 185565.34 | AU11: 0 | AV11: 0 | AW11: 0 | AX11: 0
A12: Methadone Generic | B12: Sales Volume | C12: 311748 | D12: 431736 | E12: 332172 | F12: 266268 | G12: 355992 | H12: 319104 | I12: 269784 | J12: 419942.35 | K12: 309204.28 | L12: 303423.28 | M12: 419947.35 | N12: 370820.22 | O12: 300455.13 | P12: 393083.2 | Q12: 314435.01 | R12: 249804.89 | S12: 346034.96 | T12: 320488.41 | U12: 298528.02 | V12: 395465.6 | W12: 291292.29 | X12: 298528.02 | Y12: 396155.6 | Z12: 354087.07 | AA12: 300455.13 | AB12: 393083.2 | AC12: 314435.01 | AD12: 249804.89 | AE12: 346034.96 | AF12: 320488.34 | AG12: 298527.95 | AH12: 395465.51 | AI12: 291292.22 | AJ12: 298527.95 | AK12: 396155.51 | AL12: 354087 | AM12: 300455.06 | AN12: 393083.11 | AO12: 314434.94 | AP12: 249804.82 | AQ12: 346034.88 | AR12: 319754.49 | AS12: 299033.42 | AT12: 299033.42 | AU12: 0 | AV12: 0 | AW12: 0 | AX12: 0
A13: APAP/Codeine | B13: Sales Volume | C13: 66192.002 | D13: 85974 | E13: 71430 | F13: 85038 | G13: 82194 | H13: 61014 | I13: 65010 | J13: 77127.619 | K13: 61702.095 | L13: 61702.095 | M13: 77127.619 | N13: 62021.326 | O13: 61067.395 | P13: 76334.244 | Q13: 61067.395 | R13: 61067.395 | S13: 76334.244 | T13: 61067.395 | U13: 61067.395 | V13: 76334.244 | W13: 61067.395 | X13: 61067.395 | Y13: 76334.244 | Z13: 61067.395 | AA13: 59330.54 | AB13: 74163.175 | AC13: 59330.54 | AD13: 59330.54 | AE13: 74163.175 | AF13: 59330.54 | AG13: 59330.54 | AH13: 74163.175 | AI13: 59330.54 | AJ13: 59330.54 | AK13: 74163.175 | AL13: 59330.54 | AM13: 57651.267 | AN13: 72064.083 | AO13: 57651.267 | AP13: 57651.267 | AQ13: 72064.083 | AR13: 57970.498 | AS13: 57651.267 | AT13: 57651.267 | AU13: 0 | AV13: 0 | AW13: 0 | AX13: 0
A14: Fentanyl Lozenge | B14: Sales Volume | C14: 9466.002 | D14: 13527 | E14: 10252 | F14: 6958 | G14: 13787 | H14: 10803 | I14: 9420 | J14: 12465 | K14: 9384 | L14: 9296 | M14: 12114 | N14: 10910 | O14: 9356.3923 | P14: 11695.49 | Q14: 9871.0519 | R14: 9356.3923 | S14: 11695.49 | T14: 9356.3923 | U14: 9356.3923 | V14: 11695.49 | W14: 9356.3923 | X14: 9356.3923 | Y14: 11695.49 | Z14: 9356.3923 | AA14: 8940.9638 | AB14: 11176.205 | AC14: 8940.9638 | AD14: 8940.9638 | AE14: 11176.205 | AF14: 8940.9638 | AG14: 8940.9638 | AH14: 11176.205 | AI14: 9743.2783 | AJ14: 8940.9638 | AK14: 10091.925 | AL14: 8940.9638 | AM14: 8957.7 | AN14: 10778.622 | AO14: 8622.8977 | AP14: 8622.8977 | AQ14: 10323.869 | AR14: 8622.8977 | AS14: 8622.8977 | AT14: 8622.8977 | AU14: 0 | AV14: 0 | AW14: 0 | AX14: 0
A15: Fentanyl Patch | B15: Sales Volume | C15: 0.006 | D15: 0 | E15: 0 | F15: 0 | G15: 38424 | H15: 92616 | I15: 151224 | J15: 196402 | K15: 157121 | L15: 165539 | M15: 213236 | N15: 213236 | O15: 161533 | P15: 185846 | Q15: 153594 | R15: 153663 | S15: 202279 | T15: 161896 | U15: 161970 | V15: 202552 | W15: 154009 | X15: 154077 | Y15: 202824 | Z15: 154216 | AA15: 162467 | AB15: 186992 | AC15: 154597 | AD15: 154726 | AE15: 203754 | AF15: 163136 | AG15: 163270 | AH15: 204255 | AI15: 155361 | AJ15: 167689.42 | AK15: 223057.62 | AL15: 177703.75 | AM15: 180562.53 | AN15: 217325.73 | AO15: 179150.53 | AP15: 180678.29 | AQ15: 220970.97 | AR15: 188396.29 | AS15: 183826.38 | AT15: 183826.38 | AU15: 0 | AV15: 0 | AW15: 0 | AX15: 0
A16: Temazepam | B16: Sales Volume | C16: 2496.002 | D16: 3672 | E16: 3528 | F16: 2292 | G16: 3360 | H16: 2868 | I16: 3384 | J16: 3444 | K16: 2617 | L16: 2617 | M16: 3444 | N16: 2655 | O16: 2846 | P16: 3130 | Q16: 2805 | R16: 3034 | S16: 3152 | T16: 2843 | U16: 3034 | V16: 3114 | W16: 2805 | X16: 3034 | Y16: 3114 | Z16: 2805 | AA16: 2855 | AB16: 3284 | AC16: 2712 | AD16: 2712 | AE16: 3569 | AF16: 2844 | AG16: 2855 | AH16: 3568 | AI16: 2712 | AJ16: 2632 | AK16: 3569 | AL16: 3569 | AM16: 3046 | AN16: 3360 | AO16: 2941 | AP16: 3569 | AQ16: 3035 | AR16: 3046 | AS16: 3043.8657 | AT16: 3043.8657 | AU16: 0 | AV16: 0 | AW16: 0 | AX16: 0
A17: Imipramine Pamoate | B17: Sales Volume | C17: 1890.002 | D17: 3450 | E17: 2616 | F17: 1134 | G17: 2688 | H17: 2250 | I17: 2046 | J17: 2780.9902 | K17: 2146.1125 | L17: 2146.1125 | M17: 2780.9902 | N17: 2146.1125 | O17: 2186.5921 | P17: 2625.031 | Q17: 2146.1125 | R17: 2146.1125 | S17: 2779.9902 | T17: 2186.5921 | U17: 2186.5921 | V17: 2779.9902 | W17: 2146.1125 | X17: 2146.1125 | Y17: 2779.9902 | Z17: 2146.1125 | AA17: 2202.5921 | AB17: 2601.031 | AC17: 2129.1125 | AD17: 2129.1125 | AE17: 2757.9902 | AF17: 2205.5921 | AG17: 2205.5921 | AH17: 2757.9902 | AI17: 2129.1125 | AJ17: 2143.1125 | AK17: 2751.9902 | AL17: 2143.1125 | AM17: 2196.5921 | AN17: 2631.031 | AO17: 2139.1125 | AP17: 2139.1125 | AQ17: 2745.9902 | AR17: 2194.4 | AS17: 2179.8515 | AT17: 2179.8515 | AU17: 0 | AV17: 0 | AW17: 0 | AX17: 0
... A28: Addiction Treatment (Brand) | B28: Sales Volume | C28: 50710.003 | D28: 68422 | E28: 58612.001 | F28: 48428 | G28: 64926 | H28: 52996.001 | I28: 52892.001 | J28: 70434.711 | K28: 57563.941 | L28: 52808.941 | M28: 70858.711 | N28: 62664.941 | O28: 60508.569 | P28: 65359.455 | Q28: 53555.941 | R28: 55260.941 | S28: 70558.711 | T28: 54541.569 | U28: 59312.569 | V28: 70980.711 | W28: 53301.941 | X28: 59185.941 | Y28: 62686.711 | Z28: 59703.941 | AA28: 65159.569 | AB28: 57209.455 | AC28: 61998.941 | AD28: 56162.941 | AE28: 72248.711 | AF28: 54423.569 | AG28: 62902.569 | AH28: 64028.711 | AI28: 62218.941 | AJ28: 57220.941 | AK28: 62158.711 | AL28: 57894.941 | AM28: 64459.569 | AN28: 57240.455 | AO28: 62745.941 | AP28: 55407.941 | AQ28: 67401.711 | AR28: 54468.711 | AS28: 58510.833 | AT28: 58510.833 | AU28: 0 | AV28: 0 | AW28: 0 | AX28: 0
A31: Freight per bottle, except AT | B31: =0.09 -> 0.09 | C31: (FY10 forecast = 0.09 per E.Young, Logistics 11/17/09) | H31: Cost & Inflation Rate Year-to-Year Change
A32: Freight per bottle for AT | B32: 1.08 | C32: (FY11 MARLE = 1.08 per C. Gidcomb 02/21/11) | H32: F12 | I32: 0.11 | J32: F13 | K32: 0.03 | L32: F14 | M32: 0.03
H33: F12 | I33: =I32/B31*B32 -> 1.32 | J33: F12 per Cathy Gidcomb 03/29/11)
A35: Calculated Forecast | C35: =C5 -> Oct | D35: =D5 -> Nov | E35: =E5 -> Dec | F35: =F5 -> Jan | G35: =G5 -> Feb | H35: =H5 -> Mar | I35: =I5 -> Apr | J35: =J5 -> May | ... AX35: =AX5 -> Sep
A36: 157001150211 Frt Exp-Hydrocodone Products | C36: =C6*$B$31 -> 111229.74 | D36: =D6*$B$31 -> 162406.08 | E36: =E6*$B$31 -> 103440.15 | F36: =F6*$B$31 -> 94655.52 | G36: =G6*$B$31 -> 128352.06 | H36: =H6*$B$31 -> 118617.39 | I36: =I6*$B$31 -> 127605.24 | J36: =J6*$B$31 -> 159791.61 | ... N36: =N6*$B$31 -> 151365.17 | O36: =O6*$I$32 -> 162548.64 | P36: =P6*$I$32 -> 203185.8 | Q36: =Q6*$I$32 -> 162548.64 | R36: =R6*$I$32 -> 162548.64 | S36: =S6*$I$32 -> 203185.8 | T36: =T6*$I$32 -> 162548.64 | U36: =U6*$I$32 -> 162548.64 | V36: =V6*$I$32 -> 203185.8 | ... Z36: =Z6*$I$32 -> 162548.64 | AA36: =AA6*$I$32*(1+$K$32) -> 195731.4 | AB36: =AB6*$I$32*(1+$K$32) -> 244664.25 | AC36: =AC6*$I$32*(1+$K$32) -> 195731.4 | AD36: =AD6*$I$32*(1+$K$32) -> 195731.4 | AE36: =AE6*$I$32*(1+$K$32) -> 244664.25 | AF36: =AF6*$I$32*(1+$K$32) -> 195731.4 | AG36: =AG6*$I$32*(1+$K$32) -> 195731.4 | AH36: =AH6*$I$32*(1+$K$32) -> 244664.25 | ... AL36: =AL6*$I$32*(1+$K$32) -> 195731.4 | AM36: =AM6*$I$32*(1+$K$32)*(1+$M$32) -> 234604.09 | AN36: =AN6*$I$32*(1+$K$32)*(1+$M$32) -> 293255.12 | AO36: =AO6*$I$32*(1+$K$32)*(1+$M$32) -> 234604.09 | AP36: =AP6*$I$32*(1+$K$32)*(1+$M$32) -> 234604.09 | AQ36: =AQ6*$I$32*(1+$K$32)*(1+$M$32) -> 293255.12 | AR36: =AR6*$I$32*(1+$K$32)*(1+$M$32) -> 234645.15 | AS36: =AS6*$I$32*(1+$K$32)*(1+$M$32) -> 234604.09 | AT36: =AT6*$I$32*(1+$K$32)*(1+$M$32) -> 234604.09 | ... AX36: =AX6*$I$32*(1+$K$32)*(1+$M$32) -> 0
A37: 157001150210 Frt Exp-Oxycodone Products | C37: =C7*$B$31 -> 64280.521 | D37: =D7*$B$31 -> 80687.88 | E37: =E7*$B$31 -> 73931.4 | F37: =F7*$B$31 -> 54200.88 | G37: =G7*$B$31 -> 61557.84 | H37: =H7*$B$31 -> 65442.6 | I37: =I7*$B$31 -> 33084.72 | J37: =J7*$B$31 -> 58372.859 | ... N37: =N7*$B$31 -> 79718.22 | O37: =O7*$I$32 -> 100885.48 | P37: =P7*$I$32 -> 114159.96 | Q37: =Q7*$I$32 -> 100885.48 | R37: =R7*$I$32 -> 100885.48 | S37: =S7*$I$32 -> 126106.85 | T37: =T7*$I$32 -> 100885.48 | U37: =U7*$I$32 -> 100885.48 | V37: =V7*$I$32 -> 126106.85 | ... Z37: =Z7*$I$32 -> 100885.48 | AA37: =AA7*$I$32*(1+$K$32) -> 120811.17 | AB37: =AB7*$I$32*(1+$K$32) -> 151013.96 | AC37: =AC7*$I$32*(1+$K$32) -> 120811.17 | AD37: =AD7*$I$32*(1+$K$32) -> 120811.17 | AE37: =AE7*$I$32*(1+$K$32) -> 151013.96 | AF37: =AF7*$I$32*(1+$K$32) -> 120811.17 | AG37: =AG7*$I$32*(1+$K$32) -> 120811.17 | AH37: =AH7*$I$32*(1+$K$32) -> 151013.96 | ... AL37: =AL7*$I$32*(1+$K$32) -> 120811.17 | AM37: =AM7*$I$32*(1+$K$32)*(1+$M$32) -> 139226.66 | AN37: =AN7*$I$32*(1+$K$32)*(1+$M$32) -> 157479.58 | AO37: =AO7*$I$32*(1+$K$32)*(1+$M$32) -> 139226.66 | AP37: =AP7*$I$32*(1+$K$32)*(1+$M$32) -> 152631.74 | AQ37: =AQ7*$I$32*(1+$K$32)*(1+$M$32) -> 174033.33 | AR37: =AR7*$I$32*(1+$K$32)*(1+$M$32) -> 152631.74 | AS37: =AS7*$I$32*(1+$K$32)*(1+$M$32) -> 139226.66 | AT37: =AT7*$I$32*(1+$K$32)*(1+$M$32) -> 174033.33 | ... AX37: =AX7*$I$32*(1+$K$32)*(1+$M$32) -> 0
A38: 157001150244 Oxycodone APAP-Frt Exp | C38: =C8*$B$31 -> 69212.341 | D38: =D8*$B$31 -> 68897.52 | E38: =E8*$B$31 -> 88675.56 | F38: =F8*$B$31 -> 34989.3 | G38: =G8*$B$31 -> 79036.02 | H38: =H8*$B$31 -> 84439.8 | I38: =I8*$B$31 -> 64395.54 | J38: =J8*$B$31 -> 93393.63 | ... N38: =N8*$B$31 -> 87837.03 | O38: =O8*$I$32 -> 95453.633 | P38: =P8*$I$32 -> 119317.04 | Q38: =Q8*$I$32 -> 95453.633 | R38: =R8*$I$32 -> 95453.633 | S38: =S8*$I$32 -> 119317.04 | T38: =T8*$I$32 -> 95453.633 | U38: =U8*$I$32 -> 95453.633 | V38: =V8*$I$32 -> 119317.04 | ... Z38: =Z8*$I$32 -> 95453.633 | AA38: =AA8*$I$32*(1+$K$32) -> 104150.54 | AB38: =AB8*$I$32*(1+$K$32) -> 130188.17 | AC38: =AC8*$I$32*(1+$K$32) -> 104150.54 | AD38: =AD8*$I$32*(1+$K$32) -> 104150.54 | AE38: =AE8*$I$32*(1+$K$32) -> 130188.17 | AF38: =AF8*$I$32*(1+$K$32) -> 104150.54 | AG38: =AG8*$I$32*(1+$K$32) -> 104150.54 | AH38: =AH8*$I$32*(1+$K$32) -> 130188.17 | ... AL38: =AL8*$I$32*(1+$K$32) -> 104150.54 | AM38: =AM8*$I$32*(1+$K$32)*(1+$M$32) -> 113474.7 | AN38: =AN8*$I$32*(1+$K$32)*(1+$M$32) -> 141843.38 | AO38: =AO8*$I$32*(1+$K$32)*(1+$M$32) -> 113474.7 | AP38: =AP8*$I$32*(1+$K$32)*(1+$M$32) -> 113474.7 | AQ38: =AQ8*$I$32*(1+$K$32)*(1+$M$32) -> 141843.38 | AR38: =AR8*$I$32*(1+$K$32)*(1+$M$32) -> 113474.7 | AS38: =AS8*$I$32*(1+$K$32)*(1+$M$32) -> 113474.7 | AT38: =AT8*$I$32*(1+$K$32)*(1+$M$32) -> 113540.99 | ... AX38: =AX8*$I$32*(1+$K$32)*(1+$M$32) -> 0
A39: 157001150222 Frt Exp-ADHD | C39: =C9*$B$31 -> 14322.421 | D39: =D9*$B$31 -> 17440.92 | E39: =E9*$B$31 -> 21785.22 | F39: =F9*$B$31 -> 3392.82 | G39: =G9*$B$31 -> 6840.1805 | H39: =H9*$B$31 -> 7703.6406 | I39: =I9*$B$31 -> 9657.9006 | J39: =J9*$B$31 -> 13166.64 | ... N39: =N9*$B$31 -> 16354.892 | O39: =O9*$I$32 -> 22656.108 | P39: =P9*$I$32 -> 23487.245 | Q39: =Q9*$I$32 -> 18461.754 | R39: =R9*$I$32 -> 19363.424 | S39: =S9*$I$32 -> 24779.415 | T39: =T9*$I$32 -> 19062.464 | U39: =U9*$I$32 -> 20101.304 | V39: =V9*$I$32 -> 24789.095 | ... Z39: =Z9*$I$32 -> 19482.554 | AA39: =AA9*$I$32*(1+$K$32) -> 20725.045 | AB39: =AB9*$I$32*(1+$K$32) -> 23083.805 | AC39: =AC9*$I$32*(1+$K$32) -> 20078.102 | AD39: =AD9*$I$32*(1+$K$32) -> 19940.783 | AE39: =AE9*$I$32*(1+$K$32) -> 25505.366 | AF39: =AF9*$I$32*(1+$K$32) -> 19593.518 | AG39: =AG9*$I$32*(1+$K$32) -> 20705.671 | AH39: =AH9*$I$32*(1+$K$32) -> 24388.568 | ... AL39: =AL9*$I$32*(1+$K$32) -> 19900.788 | AM39: =AM9*$I$32*(1+$K$32)*(1+$M$32) -> 21034.507 | AN39: =AN9*$I$32*(1+$K$32)*(1+$M$32) -> 22178.736 | AO39: =AO9*$I$32*(1+$K$32)*(1+$M$32) -> 21421.364 | AP39: =AP9*$I$32*(1+$K$32)*(1+$M$32) -> 17857.494 | AQ39: =AQ9*$I$32*(1+$K$32)*(1+$M$32) -> 18617.316 | AR39: =AR9*$I$32*(1+$K$32)*(1+$M$32) -> 18000.964 | AS39: =AS9*$I$32*(1+$K$32)*(1+$M$32) -> 22770.7 | AT39: =AT9*$I$32*(1+$K$32)*(1+$M$32) -> 22770.7 | ... AX39: =AX9*$I$32*(1+$K$32)*(1+$M$32) -> 0
A40: 157001150229 Morphine ER-Frt Exp | C40: =C10*$B$31 -> 15345.72 | D40: =D10*$B$31 -> 20799.72 | E40: =E10*$B$31 -> 16576.92 | F40: =F10*$B$31 -> 7950.96 | G40: =G10*$B$31 -> 19149.48 | H40: =H10*$B$31 -> 13206.6 | I40: =I10*$B$31 -> 16005.6 | J40: =J10*$B$31 -> 21976.748 | ... N40: =N10*$B$31 -> 17620.472 | O40: =O10*$I$32 -> 22845.111 | P40: =P10*$I$32 -> 28556.389 | Q40: =Q10*$I$32 -> 22845.111 | R40: =R10*$I$32 -> 22845.111 | S40: =S10*$I$32 -> 28556.389 | T40: =T10*$I$32 -> 22845.111 | U40: =U10*$I$32 -> 22845.111 | V40: =V10*$I$32 -> 28556.389 | ... Z40: =Z10*$I$32 -> 22845.111 | AA40: =AA10*$I$32*(1+$K$32) -> 24197.005 | AB40: =AB10*$I$32*(1+$K$32) -> 30246.257 | AC40: =AC10*$I$32*(1+$K$32) -> 24197.005 | AD40: =AD10*$I$32*(1+$K$32) -> 24197.005 | AE40: =AE10*$I$32*(1+$K$32) -> 30246.257 | AF40: =AF10*$I$32*(1+$K$32) -> 24197.005 | AG40: =AG10*$I$32*(1+$K$32) -> 24197.005 | AH40: =AH10*$I$32*(1+$K$32) -> 30246.257 | ... AL40: =AL10*$I$32*(1+$K$32) -> 24197.005 | AM40: =AM10*$I$32*(1+$K$32)*(1+$M$32) -> 25597.936 | AN40: =AN10*$I$32*(1+$K$32)*(1+$M$32) -> 31997.42 | AO40: =AO10*$I$32*(1+$K$32)*(1+$M$32) -> 25597.936 | AP40: =AP10*$I$32*(1+$K$32)*(1+$M$32) -> 25597.936 | AQ40: =AQ10*$I$32*(1+$K$32)*(1+$M$32) -> 31997.42 | AR40: =AR10*$I$32*(1+$K$32)*(1+$M$32) -> 25648.602 | AS40: =AS10*$I$32*(1+$K$32)*(1+$M$32) -> 25597.936 | AT40: =AT10*$I$32*(1+$K$32)*(1+$M$32) -> 25597.936 | ... AX40: =AX10*$I$32*(1+$K$32)*(1+$M$32) -> 0
A41: 157001150230 Hydromorphone-Frt Exp | C41: =C11*$B$31 -> 13430.88 | D41: =D11*$B$31 -> 19298.52 | E41: =E11*$B$31 -> 14958 | F41: =F11*$B$31 -> 11088.36 | G41: =G11*$B$31 -> 18350.28 | H41: =H11*$B$31 -> 10618.56 | I41: =I11*$B$31 -> 13263.48 | J41: =J11*$B$31 -> 16135.341 | ... N41: =N11*$B$31 -> 16146.429 | O41: =O11*$I$32 -> 16728.131 | P41: =P11*$I$32 -> 19372.109 | Q41: =Q11*$I$32 -> 16106.852 | R41: =R11*$I$32 -> 16184.318 | S41: =S11*$I$32 -> 21212.14 | T41: =T11*$I$32 -> 17048.801 | U41: =U11*$I$32 -> 17127.893 | V41: =V11*$I$32 -> 21508.899 | ... Z41: =Z11*$I$32 -> 16785.792 | AA41: =AA11*$I$32*(1+$K$32) -> 18670.921 | AB41: =AB11*$I$32*(1+$K$32) -> 21904.154 | AC41: =AC11*$I$32*(1+$K$32) -> 18061.671 | AD41: =AD11*$I$32*(1+$K$32) -> 18139.139 | AE41: =AE11*$I$32*(1+$K$32) -> 23746.163 | AF41: =AF11*$I$32*(1+$K$32) -> 19078.534 | AG41: =AG11*$I$32*(1+$K$32) -> 19160.093 | AH41: =AH11*$I$32*(1+$K$32) -> 24051.92 | ... AL41: =AL11*$I$32*(1+$K$32) -> 18748.173 | AM41: =AM11*$I$32*(1+$K$32)*(1+$M$32) -> 20818.567 | AN41: =AN11*$I$32*(1+$K$32)*(1+$M$32) -> 24443.018 | AO41: =AO11*$I$32*(1+$K$32)*(1+$M$32) -> 20137.388 | AP41: =AP11*$I$32*(1+$K$32)*(1+$M$32) -> 20215.562 | AQ41: =AQ11*$I$32*(1+$K$32)*(1+$M$32) -> 24127.023 | AR41: =AR11*$I$32*(1+$K$32)*(1+$M$32) -> 23126.242 | AS41: =AS11*$I$32*(1+$K$32)*(1+$M$32) -> 21655.29 | AT41: =AT11*$I$32*(1+$K$32)*(1+$M$32) -> 21655.29 | ... AX41: =AX11*$I$32*(1+$K$32)*(1+$M$32) -> 0
A42: 157001150231 Methadone Generics-Frt Exp | C42: =C12*$B$31 -> 28057.32 | D42: =D12*$B$31 -> 38856.24 | E42: =E12*$B$31 -> 29895.48 | F42: =F12*$B$31 -> 23964.12 | G42: =G12*$B$31 -> 32039.28 | H42: =H12*$B$31 -> 28719.36 | I42: =I12*$B$31 -> 24280.56 | J42: =J12*$B$31 -> 37794.812 | ... N42: =N12*$B$31 -> 33373.82 | O42: =O12*$I$32 -> 33050.064 | P42: =P12*$I$32 -> 43239.152 | Q42: =Q12*$I$32 -> 34587.851 | R42: =R12*$I$32 -> 27478.538 | S42: =S12*$I$32 -> 38063.846 | T42: =T12*$I$32 -> 35253.725 | U42: =U12*$I$32 -> 32838.082 | V42: =V12*$I$32 -> 43501.216 | ... Z42: =Z12*$I$32 -> 38949.578 | AA42: =AA12*$I$32*(1+$K$32) -> 34041.566 | AB42: =AB12*$I$32*(1+$K$32) -> 44536.326 | AC42: =AC12*$I$32*(1+$K$32) -> 35625.487 | AD42: =AD12*$I$32*(1+$K$32) -> 28302.894 | AE42: =AE12*$I$32*(1+$K$32) -> 39205.761 | AF42: =AF12*$I$32*(1+$K$32) -> 36311.329 | AG42: =AG12*$I$32*(1+$K$32) -> 33823.216 | AH42: =AH12*$I$32*(1+$K$32) -> 44806.242 | ... AL42: =AL12*$I$32*(1+$K$32) -> 40118.057 | AM42: =AM12*$I$32*(1+$K$32)*(1+$M$32) -> 35062.805 | AN42: =AN12*$I$32*(1+$K$32)*(1+$M$32) -> 45872.406 | AO42: =AO12*$I$32*(1+$K$32)*(1+$M$32) -> 36694.243 | AP42: =AP12*$I$32*(1+$K$32)*(1+$M$32) -> 29151.973 | AQ42: =AQ12*$I$32*(1+$K$32)*(1+$M$32) -> 40381.924 | AR42: =AR12*$I$32*(1+$K$32)*(1+$M$32) -> 37315.029 | AS42: =AS12*$I$32*(1+$K$32)*(1+$M$32) -> 34896.901 | AT42: =AT12*$I$32*(1+$K$32)*(1+$M$32) -> 34896.901 | ... AX42: =AX12*$I$32*(1+$K$32)*(1+$M$32) -> 0
A43: 157001150232 APAP Codeine-Frt Exp | C43: =C13*$B$31 -> 5957.2802 | D43: =D13*$B$31 -> 7737.66 | E43: =E13*$B$31 -> 6428.7 | F43: =F13*$B$31 -> 7653.42 | G43: =G13*$B$31 -> 7397.46 | H43: =H13*$B$31 -> 5491.26 | I43: =I13*$B$31 -> 5850.9 | J43: =J13*$B$31 -> 6941.4857 | ... N43: =N13*$B$31 -> 5581.9193 | O43: =O13*$I$32 -> 6717.4134 | P43: =P13*$I$32 -> 8396.7668 | Q43: =Q13*$I$32 -> 6717.4134 | R43: =R13*$I$32 -> 6717.4134 | S43: =S13*$I$32 -> 8396.7668 | T43: =T13*$I$32 -> 6717.4134 | U43: =U13*$I$32 -> 6717.4134 | V43: =V13*$I$32 -> 8396.7668 | ... Z43: =Z13*$I$32 -> 6717.4134 | AA43: =AA13*$I$32*(1+$K$32) -> 6722.1502 | AB43: =AB13*$I$32*(1+$K$32) -> 8402.6877 | AC43: =AC13*$I$32*(1+$K$32) -> 6722.1502 | AD43: =AD13*$I$32*(1+$K$32) -> 6722.1502 | AE43: =AE13*$I$32*(1+$K$32) -> 8402.6877 | AF43: =AF13*$I$32*(1+$K$32) -> 6722.1502 | AG43: =AG13*$I$32*(1+$K$32) -> 6722.1502 | AH43: =AH13*$I$32*(1+$K$32) -> 8402.6877 | ... AL43: =AL13*$I$32*(1+$K$32) -> 6722.1502 | AM43: =AM13*$I$32*(1+$K$32)*(1+$M$32) -> 6727.8452 | AN43: =AN13*$I$32*(1+$K$32)*(1+$M$32) -> 8409.8065 | AO43: =AO13*$I$32*(1+$K$32)*(1+$M$32) -> 6727.8452 | AP43: =AP13*$I$32*(1+$K$32)*(1+$M$32) -> 6727.8452 | AQ43: =AQ13*$I$32*(1+$K$32)*(1+$M$32) -> 8409.8065 | AR43: =AR13*$I$32*(1+$K$32)*(1+$M$32) -> 6765.0991 | AS43: =AS13*$I$32*(1+$K$32)*(1+$M$32) -> 6727.8452 | AT43: =AT13*$I$32*(1+$K$32)*(1+$M$32) -> 6727.8452 | ... AX43: =AX13*$I$32*(1+$K$32)*(1+$M$32) -> 0
A44: 157001150234 Fentanyl Lozenge-Frt Exp | C44: =C14*$B$31 -> 851.94018 | D44: =D14*$B$31 -> 1217.43 | E44: =E14*$B$31 -> 922.68 | F44: =F14*$B$31 -> 626.22 | G44: =G14*$B$31 -> 1240.83 | H44: =H14*$B$31 -> 972.27 | I44: =I14*$B$31 -> 847.8 | J44: =J14*$B$31 -> 1121.85 | ... N44: =N14*$B$31 -> 981.9 | O44: =O14*$I$32 -> 1029.2032 | P44: =P14*$I$32 -> 1286.5039 | Q44: =Q14*$I$32 -> 1085.8157 | R44: =R14*$I$32 -> 1029.2032 | S44: =S14*$I$32 -> 1286.5039 | T44: =T14*$I$32 -> 1029.2032 | U44: =U14*$I$32 -> 1029.2032 | V44: =V14*$I$32 -> 1286.5039 | ... Z44: =Z14*$I$32 -> 1029.2032 | AA44: =AA14*$I$32*(1+$K$32) -> 1013.0112 | AB44: =AB14*$I$32*(1+$K$32) -> 1266.264 | AC44: =AC14*$I$32*(1+$K$32) -> 1013.0112 | AD44: =AD14*$I$32*(1+$K$32) -> 1013.0112 | AE44: =AE14*$I$32*(1+$K$32) -> 1266.264 | AF44: =AF14*$I$32*(1+$K$32) -> 1013.0112 | AG44: =AG14*$I$32*(1+$K$32) -> 1013.0112 | AH44: =AH14*$I$32*(1+$K$32) -> 1266.264 | ... AL44: =AL14*$I$32*(1+$K$32) -> 1013.0112 | AM44: =AM14*$I$32*(1+$K$32)*(1+$M$32) -> 1045.3546 | AN44: =AN14*$I$32*(1+$K$32)*(1+$M$32) -> 1257.8544 | AO44: =AO14*$I$32*(1+$K$32)*(1+$M$32) -> 1006.2835 | AP44: =AP14*$I$32*(1+$K$32)*(1+$M$32) -> 1006.2835 | AQ44: =AQ14*$I$32*(1+$K$32)*(1+$M$32) -> 1204.7852 | AR44: =AR14*$I$32*(1+$K$32)*(1+$M$32) -> 1006.2835 | AS44: =AS14*$I$32*(1+$K$32)*(1+$M$32) -> 1006.2835 | AT44: =AT14*$I$32*(1+$K$32)*(1+$M$32) -> 1006.2835 | ... AX44: =AX14*$I$32*(1+$K$32)*(1+$M$32) -> 0
A45: 157001150236 Fentanyl Patch-Frt Exp | C45: =C15*$B$31 -> 0.00054 | D45: =D15*$B$31 -> 0 | E45: =E15*$B$31 -> 0 | F45: =F15*$B$31 -> 0 | G45: =G15*$B$31 -> 3458.16 | H45: =H15*$B$31 -> 8335.44 | I45: =I15*$B$31 -> 13610.16 | J45: =J15*$B$31 -> 17676.18 | ... N45: =N15*$B$31 -> 19191.24 | O45: =O15*$I$32 -> 17768.63 | P45: =P15*$I$32 -> 20443.06 | Q45: =Q15*$I$32 -> 16895.34 | R45: =R15*$I$32 -> 16902.93 | S45: =S15*$I$32 -> 22250.69 | T45: =T15*$I$32 -> 17808.56 | U45: =U15*$I$32 -> 17816.7 | V45: =V15*$I$32 -> 22280.72 | ... Z45: =Z15*$I$32 -> 16963.76 | AA45: =AA15*$I$32*(1+$K$32) -> 18407.511 | AB45: =AB15*$I$32*(1+$K$32) -> 21186.194 | AC45: =AC15*$I$32*(1+$K$32) -> 17515.84 | AD45: =AD15*$I$32*(1+$K$32) -> 17530.456 | AE45: =AE15*$I$32*(1+$K$32) -> 23085.328 | AF45: =AF15*$I$32*(1+$K$32) -> 18483.309 | AG45: =AG15*$I$32*(1+$K$32) -> 18498.491 | AH45: =AH15*$I$32*(1+$K$32) -> 23142.091 | ... AL45: =AL15*$I$32*(1+$K$32) -> 20133.835 | AM45: =AM15*$I$32*(1+$K$32)*(1+$M$32) -> 21071.467 | AN45: =AN15*$I$32*(1+$K$32)*(1+$M$32) -> 25361.695 | AO45: =AO15*$I$32*(1+$K$32)*(1+$M$32) -> 20906.688 | AP45: =AP15*$I$32*(1+$K$32)*(1+$M$32) -> 21084.976 | AQ45: =AQ15*$I$32*(1+$K$32)*(1+$M$32) -> 25787.091 | AR45: =AR15*$I$32*(1+$K$32)*(1+$M$32) -> 21985.659 | AS45: =AS15*$I$32*(1+$K$32)*(1+$M$32) -> 21452.355 | AT45: =AT15*$I$32*(1+$K$32)*(1+$M$32) -> 21452.355 | ... AX45: =AX15*$I$32*(1+$K$32)*(1+$M$32) -> 0
A46: 157001150253 Temazepam-Frt Exp | C46: =C16*$B$31 -> 224.64018 | D46: =D16*$B$31 -> 330.48 | E46: =E16*$B$31 -> 317.52 | F46: =F16*$B$31 -> 206.28 | G46: =G16*$B$31 -> 302.4 | H46: =H16*$B$31 -> 258.12 | I46: =I16*$B$31 -> 304.56 | J46: =J16*$B$31 -> 309.96 | ... N46: =N16*$B$31 -> 238.95 | O46: =O16*$I$32 -> 313.06 | P46: =P16*$I$32 -> 344.3 | Q46: =Q16*$I$32 -> 308.55 | R46: =R16*$I$32 -> 333.74 | S46: =S16*$I$32 -> 346.72 | T46: =T16*$I$32 -> 312.73 | U46: =U16*$I$32 -> 333.74 | V46: =V16*$I$32 -> 342.54 | ... Z46: =Z16*$I$32 -> 308.55 | AA46: =AA16*$I$32*(1+$K$32) -> 323.4715 | AB46: =AB16*$I$32*(1+$K$32) -> 372.0772 | AC46: =AC16*$I$32*(1+$K$32) -> 307.2696 | AD46: =AD16*$I$32*(1+$K$32) -> 307.2696 | AE46: =AE16*$I$32*(1+$K$32) -> 404.3677 | AF46: =AF16*$I$32*(1+$K$32) -> 322.2252 | AG46: =AG16*$I$32*(1+$K$32) -> 323.4715 | AH46: =AH16*$I$32*(1+$K$32) -> 404.2544 | ... AL46: =AL16*$I$32*(1+$K$32) -> 404.3677 | AM46: =AM16*$I$32*(1+$K$32)*(1+$M$32) -> 355.46515 | AN46: =AN16*$I$32*(1+$K$32)*(1+$M$32) -> 392.10864 | AO46: =AO16*$I$32*(1+$K$32)*(1+$M$32) -> 343.21176 | AP46: =AP16*$I$32*(1+$K$32)*(1+$M$32) -> 416.49873 | AQ46: =AQ16*$I$32*(1+$K$32)*(1+$M$32) -> 354.18147 | AR46: =AR16*$I$32*(1+$K$32)*(1+$M$32) -> 355.46515 | AS46: =AS16*$I$32*(1+$K$32)*(1+$M$32) -> 355.21609 | AT46: =AT16*$I$32*(1+$K$32)*(1+$M$32) -> 355.21609 | ... AX46: =AX16*$I$32*(1+$K$32)*(1+$M$32) -> 0
A47: 157001150254 Imipramine Pamoate-Frt Exp | C47: =C17*$B$31 -> 170.10018 | D47: =D17*$B$31 -> 310.5 | E47: =E17*$B$31 -> 235.44 | F47: =F17*$B$31 -> 102.06 | G47: =G17*$B$31 -> 241.92 | H47: =H17*$B$31 -> 202.5 | I47: =I17*$B$31 -> 184.14 | J47: =J17*$B$31 -> 250.28911 | ... N47: =N17*$B$31 -> 193.15013 | O47: =O17*$I$32 -> 240.52513 | P47: =P17*$I$32 -> 288.7534 | Q47: =Q17*$I$32 -> 236.07238 | R47: =R17*$I$32 -> 236.07238 | S47: =S17*$I$32 -> 305.79892 | T47: =T17*$I$32 -> 240.52513 | U47: =U17*$I$32 -> 240.52513 | V47: =V17*$I$32 -> 305.79892 | ... Z47: =Z17*$I$32 -> 236.07238 | AA47: =AA17*$I$32*(1+$K$32) -> 249.55369 | AB47: =AB17*$I$32*(1+$K$32) -> 294.69681 | AC47: =AC17*$I$32*(1+$K$32) -> 241.22845 | AD47: =AD17*$I$32*(1+$K$32) -> 241.22845 | AE47: =AE17*$I$32*(1+$K$32) -> 312.48029 | AF47: =AF17*$I$32*(1+$K$32) -> 249.89359 | AG47: =AG17*$I$32*(1+$K$32) -> 249.89359 | AH47: =AH17*$I$32*(1+$K$32) -> 312.48029 | ... AL47: =AL17*$I$32*(1+$K$32) -> 242.81465 | AM47: =AM17*$I$32*(1+$K$32)*(1+$M$32) -> 256.34011 | AN47: =AN17*$I$32*(1+$K$32)*(1+$M$32) -> 307.03868 | AO47: =AO17*$I$32*(1+$K$32)*(1+$M$32) -> 249.63229 | AP47: =AP17*$I$32*(1+$K$32)*(1+$M$32) -> 249.63229 | AQ47: =AQ17*$I$32*(1+$K$32)*(1+$M$32) -> 320.45431 | AR47: =AR17*$I$32*(1+$K$32)*(1+$M$32) -> 256.08429 | AS47: =AS17*$I$32*(1+$K$32)*(1+$M$32) -> 254.38649 | AT47: =AT17*$I$32*(1+$K$32)*(1+$M$32) -> 254.38649 | ... AX47: =AX17*$I$32*(1+$K$32)*(1+$M$32) -> 0
... A57: 157001150247 Morphine Sulfate ER (Kadian) | C57: =C27*$B$31 -> 0 | D57: =D27*$B$31 -> 0 | E57: =E27*$B$31 -> 0 | F57: =F27*$B$31 -> 0 | G57: =G27*$B$31 -> 0 | H57: =H27*$B$31 -> 0 | I57: =I27*$B$31 -> 0 | J57: =J27*$B$31 -> 0 | ... N57: =N27*$B$31 -> 0 | O57: =O27*$I$32 -> 0 | P57: =P27*$I$32 -> 0 | Q57: =Q27*$I$32 -> 0 | R57: =R27*$I$32 -> 0 | S57: =S27*$I$32 -> 0 | T57: =T27*$I$32 -> 0 | U57: =U27*$I$32 -> 0 | V57: =V27*$I$32 -> 0 | ... Z57: =Z27*$I$32 -> 0 | AA57: =AA27*$I$32*(1+$K$32) -> 0 | AB57: =AB27*$I$32*(1+$K$32) -> 0 | AC57: =AC27*$I$32*(1+$K$32) -> 0 | AD57: =AD27*$I$32*(1+$K$32) -> 0 | AE57: =AE27*$I$32*(1+$K$32) -> 0 | AF57: =AF27*$I$32*(1+$K$32) -> 0 | AG57: =AG27*$I$32*(1+$K$32) -> 0 | AH57: =AH27*$I$32*(1+$K$32) -> 0 | ... AL57: =AL27*$I$32*(1+$K$32) -> 0 | AM57: =AM27*$I$32*(1+$K$32)*(1+$M$32) -> 0 | AN57: =AN27*$I$32*(1+$K$32)*(1+$M$32) -> 0 | AO57: =AO27*$I$32*(1+$K$32)*(1+$M$32) -> 0 | AP57: =AP27*$I$32*(1+$K$32)*(1+$M$32) -> 0 | AQ57: =AQ27*$I$32*(1+$K$32)*(1+$M$32) -> 0 | AR57: =AR27*$I$32*(1+$K$32)*(1+$M$32) -> 0 | AS57: =AS27*$I$32*(1+$K$32)*(1+$M$32) -> 0 | AT57: =AT27*$I$32*(1+$K$32)*(1+$M$32) -> 0 | ... AX57: =AX27*$I$32*(1+$K$32)*(1+$M$32) -> 0
A58: 157001150221 Frt Exp-ADDICTION TREATMENT | C58: =C28*$B$32 -> 54766.803 | D58: =D28*$B$32 -> 73895.76 | E58: =E28*$B$32 -> 63300.961 | F58: =F28*$B$32 -> 52302.24 | G58: =G28*$B$32 -> 70120.08 | H58: =H28*$B$32 -> 57235.681 | I58: =I28*$B$32 -> 57123.361 | J58: =J28*$B$32 -> 76069.488 | ... N58: =N28*$B$32 -> 67678.136 | O58: =O28*$I$33 -> 79871.311 | P58: =P28*$I$33 -> 86274.48 | Q58: =Q28*$I$33 -> 70693.842 | R58: =R28*$I$33 -> 72944.442 | S58: =S28*$I$33 -> 93137.499 | T58: =T28*$I$33 -> 71994.871 | U58: =U28*$I$33 -> 78292.591 | V58: =V28*$I$33 -> 93694.539 | ... Z58: =Z28*$I$33 -> 78809.202 | AA58: =AA28*$I$33*(1+$K$32) -> 88590.95 | AB58: =AB28*$I$33*(1+$K$32) -> 77781.974 | AC58: =AC28*$I$33*(1+$K$32) -> 84293.76 | AD58: =AD28*$I$33*(1+$K$32) -> 76359.134 | AE58: =AE28*$I$33*(1+$K$32) -> 98229.348 | AF58: =AF28*$I$33*(1+$K$32) -> 73994.285 | AG58: =AG28*$I$33*(1+$K$32) -> 85522.333 | AH58: =AH28*$I$33*(1+$K$32) -> 87053.436 | ... AL58: =AL28*$I$33*(1+$K$32) -> 78713.961 | AM58: =AM28*$I$33*(1+$K$32)*(1+$M$32) -> 90268.407 | AN58: =AN28*$I$33*(1+$K$32)*(1+$M$32) -> 80158.846 | AO58: =AO28*$I$33*(1+$K$32)*(1+$M$32) -> 87868.662 | AP58: =AP28*$I$33*(1+$K$32)*(1+$M$32) -> 77592.615 | AQ58: =AQ28*$I$33*(1+$K$32)*(1+$M$32) -> 94388.548 | AR58: =AR28*$I$33*(1+$K$32)*(1+$M$32) -> 76277.33 | AS58: =AS28*$I$33*(1+$K$32)*(1+$M$32) -> 81937.868 | AT58: =AT28*$I$33*(1+$K$32)*(1+$M$32) -> 81937.868 | ... AX58: =AX28*$I$33*(1+$K$32)*(1+$M$32) -> 0
C59: =SUM(C36:C58) -> 378535.33 | D59: =SUM(D36:D58) -> 492836.76 | E59: =SUM(E36:E58) -> 421160.23 | F59: =SUM(F36:F58) -> 291422.61 | G59: =SUM(G36:G58) -> 429172.11 | H59: =SUM(H36:H58) -> 401996.08 | I59: =SUM(I36:I58) -> 366677.92 | J59: =SUM(J36:J58) -> 503867.54 | ... AX59: =SUM(AX36:AX58) -> 0

Sheet Pharm Demand b4
A1: Outfreight Expense - 7171
C2: FY10 Working Forecast
C3: Oct | D3: Nov | E3: Dec | F3: Jan | G3: Feb | H3: Mar | I3: Apr | J3: May | K3: Jun | L3: Jul | M3: Aug | N3: Sep | O3: Full Year
A4: 157001000211 Hydrocodone Products | B4: Sales Volume | C4: 1345130 | D4: 1471821 | E4: 1346264 | F4: 1200818 | G4: 1728087 | H4: 1336101 | I4: 1408275 | J4: 1720179 | K4: 1431618 | L4: 1436689 | M4: 1701222 | N4: 1472273 | O4: 17598477
A5: 157001000210 Oxycodone Products | B5: Sales Volume | C5: 568180.11 | D5: 724518.11 | E5: 557520.11 | F5: 477505.07 | G5: 697911.07 | H5: 477342.07 | I5: 516738.48 | J5: 690798.48 | K5: 520504.48 | L5: 537789.11 | M5: 689765.11 | N5: 565202.11 | O5: 7023774.3
A6: 157001000244 Oxycodone APAP Products | B6: Sales Volume | C6: 817000 | D6: 903185 | E6: 791936 | F6: 724054 | G6: 1015560 | H6: 783302 | I6: 826298 | J6: 1027937 | K6: 839548 | L6: 842285 | M6: 995584 | N6: 860878 | O6: 10427567
A7: 157001000222 ADHD | B7: Sales Volume | C7: 147710 | D7: 157485 | E7: 139903 | F7: 120838 | G7: 174345 | H7: 135215 | I7: 141377 | J7: 169676 | K7: 141415 | L7: 140762 | M7: 163700 | N7: 141123 | O7: 1773549
A8: 157001000227 Oxycodone ER | B8: Sales Volume | C8: 0 | D8: 0 | E8: 0 | F8: 0 | G8: 0 | H8: 0 | I8: 0 | J8: 0 | K8: 0 | L8: 0 | M8: 0 | N8: 0 | O8: 0
A9: Morphine ER | B9: Sales Volume | C9: 129558 | D9: 171034 | E9: 130265 | F9: 131991 | G9: 180135 | H9: 128773 | I9: 135659 | J9: 177744 | K9: 137777 | L9: 138205 | M9: 176268 | N9: 147382 | O9: 1784791
A10: Hydromorphone | B10: Sales Volume | C10: 66453.709 | D10: 94070.588 | E10: 253332.41 | F10: 152406 | G10: 208176 | H10: 148950 | I10: 157051 | J10: 205966 | K10: 159794 | L10: 160438 | M10: 204801 | N10: 171401 | O10: 1982839.7
A11: Methadone Generic | B11: Sales Volume | C11: 386382 | D11: 503539 | E11: 380155 | F11: 380399 | G11: 514297 | H11: 364256 | I11: 379759 | J11: 491787 | K11: 377625 | L11: 374752 | M11: 472544 | N11: 391042 | O11: 5016537
A12: APAP/Codeine | B12: Sales Volume | C12: 87117 | D12: 93644 | E12: 80868 | F12: 71566 | G12: 100949 | H12: 77147 | I12: 80078 | J12: 95666 | K12: 75598 | L12: 78061 | M12: 91650 | N12: 76961 | O12: 1009305
A13: APAP/Propoxyphene | B13: Sales Volume | C13: 0 | D13: 0 | E13: 0 | F13: 0 | G13: 0 | H13: 0 | I13: 0 | J13: 0 | K13: 0 | L13: 0 | M13: 0 | N13: 0 | O13: 0
A14: Fentanyl Lozenge | B14: Sales Volume | C14: 0 | D14: 31802 | E14: 14095 | F14: 13762 | G14: 19153 | H14: 13618 | I14: 14238 | J14: 18507 | K14: 14238 | L14: 14170 | M14: 17935 | N14: 14878 | O14: 186396
A15: Fentanyl Patch | B15: Sales Volume | C15: 0 | D15: 0 | E15: 0 | F15: 0 | G15: 0 | H15: 0 | I15: 114361 | J15: 148669 | K15: 114361 | L15: 113817 | M15: 144066 | N15: 119508 | O15: 754782
... A26: International | B26: Sales Volume | C26: 19000 | D26: 0 | E26: 0 | F26: 0 | G26: 0 | H26: 26000 | I26: 17200 | J26: 0 | K26: 800 | L26: 0 | M26: 0 | N26: 25400 | O26: 88400
O27: =SUM(O4:O26) -> 50288941
A28: Freight per bottle for INTL | B28: 1.7 | C28: (FY10 forecast estimate)
A29: Freight per bottle, except AT | B29: =0.09*1.07*1.052 -> 0.1013076 | C29: (FY09 forecast = .09 + 7% inflation increase + 5% addl per JC)
A30: Freight per bottle for AT | B30: =3.45*1.07*1.052 -> 3.883458 | C30: (FY09 forecast = 3.45 + 7% inflation increase + 5% addl per JC)
A31: Freight for Fentanyl Lozenge and Patch | B31: 50% of bgt | C31: (estimate) | P31: FYI only
O32: FY10 | P32: FY09
A33: 157001150211 Frt Exp-Hydrocodone Products | B33: Dollars | C33: =C4*$B$29 -> 136271.89 | D33: =D4*$B$29 -> 149106.65 | E33: =E4*$B$29 -> 136386.77 | F33: =F4*$B$29 -> 121651.99 | G33: =G4*$B$29 -> 175068.35 | H33: =H4*$B$29 -> 135357.19 | I33: =I4*$B$29 -> 142668.96 | J33: =J4*$B$29 -> 174267.21 | ... M33: =M4*$B$29 -> 172346.72 | N33: =N4*$B$29-2372 -> 146780.44 | O33: =SUM(C33:N33) -> 1780487.5 | P33: 1604044.2
A34: 157001150210 Frt Exp-Oxycodone Products | B34: Dollars | C34: =C5*$B$29 -> 57560.964 | D34: =D5*$B$29 -> 73399.191 | E34: =E5*$B$29 -> 56481.025 | F34: =F5*$B$29 -> 48374.893 | G34: =G5*$B$29 -> 70703.696 | H34: =H5*$B$29 -> 48358.38 | I34: =I5*$B$29 -> 52349.535 | J34: =J5*$B$29 -> 69983.136 | ... N34: =N5*$B$29 -> 57259.269 | O34: =SUM(C34:N34) -> 711561.72 | P34: 939784.42
A35: 157001150244 Oxycodone APAP-Frt Exp | B35: Dollars | C35: =C6*$B$29 -> 82768.309 | D35: =D6*$B$29 -> 91499.505 | E35: =E6*$B$29 -> 80229.136 | F35: =F6*$B$29 -> 73352.173 | G35: =G6*$B$29 -> 102883.95 | H35: =H6*$B$29 -> 79354.446 | I35: =I6*$B$29 -> 83710.267 | J35: =J6*$B$29 -> 104137.83 | ... N35: =N6*$B$29 -> 87213.484 | O35: =SUM(C35:N35) -> 1056391.8 | P35: 1010573.7
A36: 157001150222 Frt Exp-ADHD | B36: Dollars | C36: =C7*$B$29 -> 14964.146 | D36: =D7*$B$29 -> 15954.427 | E36: =E7*$B$29 -> 14173.237 | F36: =F7*$B$29 -> 12241.808 | G36: =G7*$B$29 -> 17662.474 | H36: =H7*$B$29 -> 13698.307 | I36: =I7*$B$29 -> 14322.565 | J36: =J7*$B$29 -> 17189.468 | ... N36: =N7*$B$29 -> 14296.832 | O36: =SUM(C36:N36) -> 179673.99 | P36: 173266.69
A37: 157001150227 Oxycodone ER Products Freight | B37: Dollars | C37: =C8*$B$29 -> 0 | D37: =D8*$B$29 -> 0 | E37: =E8*$B$29 -> 0 | F37: =F8*$B$29 -> 0 | G37: =G8*$B$29 -> 0 | H37: =H8*$B$29 -> 0 | I37: =I8*$B$29 -> 0 | J37: =J8*$B$29 -> 0 | ... N37: =N8*$B$29 -> 0 | O37: =SUM(C37:N37) -> 0 | P37: 118511
A38: 157001150229 Morphine ER-Frt Exp | B38: Dollars | C38: =C9*$B$29 -> 13125.21 | D38: =D9*$B$29 -> 17327.044 | E38: =E9*$B$29 -> 13196.835 | F38: =F9*$B$29 -> 13371.691 | G38: =G9*$B$29 -> 18249.045 | H38: =H9*$B$29 -> 13045.684 | I38: =I9*$B$29 -> 13743.288 | J38: =J9*$B$29 -> 18006.818 | ... N38: =N9*$B$29 -> 14930.917 | O38: =SUM(C38:N38) -> 180812.89 | P38: 172797.05
A39: 157001150230 Hydromorphone-Frt Exp | B39: Dollars | C39: =C10*$B$29 -> 6732.2658 | D39: =D10*$B$29 -> 9530.0655 | E39: =E10*$B$29 -> 25664.499 | F39: =F10*$B$29 -> 15439.886 | G39: =G10*$B$29 -> 21089.811 | H39: =H10*$B$29 -> 15089.767 | I39: =I10*$B$29 -> 15910.46 | J39: =J10*$B$29 -> 20865.921 | ... N39: =N10*$B$29 -> 17364.224 | O39: =SUM(C39:N39) -> 200876.73 | P39: 191280.17
A40: 157001150231 Methadone Generics-Frt Exp | B40: Dollars | C40: =C11*$B$29 -> 39143.433 | D40: =D11*$B$29 -> 51012.328 | E40: =E11*$B$29 -> 38512.591 | F40: =F11*$B$29 -> 38537.31 | G40: =G11*$B$29 -> 52102.195 | H40: =H11*$B$29 -> 36901.901 | I40: =I11*$B$29 -> 38472.473 | J40: =J11*$B$29 -> 49821.761 | ... N40: =N11*$B$29 -> 39615.527 | O40: =SUM(C40:N40) -> 508213.32 | P40: 510997.11
A41: 157001150232 APAP Codeine-Frt Exp | B41: Dollars | C41: =C12*$B$29 -> 8825.6142 | D41: =D12*$B$29 -> 9486.8489 | E41: =E12*$B$29 -> 8192.543 | F41: =F12*$B$29 -> 7250.1797 | G41: =G12*$B$29 -> 10226.901 | H41: =H12*$B$29 -> 7815.5774 | I41: =I12*$B$29 -> 8112.51 | J41: =J12*$B$29 -> 9691.6929 | ... N41: =N12*$B$29 -> 7796.7342 | O41: =SUM(C41:N41) -> 102250.27 | P41: 103658.43
A42: 157001150233 APAP Propoxyphene-Frt Exp | B42: Dollars | C42: =C13*$B$29 -> 0 | D42: =D13*$B$29 -> 0 | E42: =E13*$B$29 -> 0 | F42: =F13*$B$29 -> 0 | G42: =G13*$B$29 -> 0 | H42: =H13*$B$29 -> 0 | I42: =I13*$B$29 -> 0 | J42: =J13*$B$29 -> 0 | ... N42: =N13*$B$29 -> 0 | O42: =SUM(C42:N42) -> 0 | P42: 51178.92
A43: 157001150234 Fentanyl Lozenge-Frt Exp | B43: Dollars | C43: 0 | D43: =44323*0.5 -> 22161.5 | E43: =31586*0.5 -> 15793 | F43: =32279*0.5 -> 16139.5 | G43: =32092*0.5 -> 16046 | H43: =31905*0.5 -> 15952.5 | I43: =31720*0.5 -> 15860 | J43: =31535*0.5 -> 15767.5 | K43: =31157*0.5 -> 15578.5 | L43: =31024*0.5 -> 15512 | M43: =30891*0.5 -> 15445.5 | N43: =30759*0.5 -> 15379.5 | O43: =SUM(C43:N43) -> 179635.5 | P43: 0
A44: 157001150236 Fentanyl Patch-Frt Exp | B44: Dollars | C44: 0 | D44: 0 | E44: 0 | F44: 0 | G44: 0 | H44: 0 | I44: =36813*0.5 -> 18406.5 | J44: =36813*0.5 -> 18406.5 | K44: =36813*0.5 -> 18406.5 | L44: =36813*0.5 -> 18406.5 | M44: =36813*0.5 -> 18406.5 | N44: =36813*0.5 -> 18406.5 | O44: =SUM(C44:N44) -> 110439 | P44: 0
A45: 157001150209 FREIGHT | B45: Dollars | C45: =C16*$B$29 -> 11874.061 | D45: =D16*$B$29 -> 14066.256 | E45: =E16*$B$29 -> 11486.357 | F45: =F16*$B$29 -> 10742.861 | G45: =G16*$B$29 -> 15063.528 | H45: =H16*$B$29 -> 11199.859 | I45: =I16*$B$29 -> 11765.561 | J45: =J16*$B$29 -> 14754.54 | ... N45: =N16*$B$29 -> 7509.4258 | O45: =SUM(C45:N45) -> 136425.58 | P45: 231446.72
A46: 157001150226 Zydus Freight Expense | B46: Dollars | C46: =C17*$B$29 -> 0 | D46: =D17*$B$29 -> 0 | E46: =E17*$B$29 -> 0 | F46: =F17*$B$29 -> 0 | G46: =G17*$B$29 -> 0 | H46: =H17*$B$29 -> 0 | I46: =I17*$B$29 -> 0 | J46: =J17*$B$29 -> 0 | ... N46: =N17*$B$29 -> 0 | O46: =SUM(C46:N46) -> 0 | P46: 59307.39
A47: 157001150246 Restoril/Temazepam Frt Expense | B47: Dollars | C47: =C18*$B$29 -> 725.76765 | D47: =D18*$B$29 -> 922.91224 | E47: =E18*$B$29 -> 669.64324 | F47: =F18*$B$29 -> 639.65619 | G47: =G18*$B$29 -> 949.55613 | H47: =H18*$B$29 -> 650.19218 | I47: =I18*$B$29 -> 664.27393 | J47: =J18*$B$29 -> 547.16235 | ... N47: =N18*$B$29 -> 404.92648 | O47: =SUM(C47:N47) -> 7435.9778 | P47: 14092.33
A48: 157001150245 Tofranil-PM/ImipraPam Frt Exp | B48: Dollars | C48: =C19*$B$29 -> 1104.8607 | D48: =D19*$B$29 -> 1285.4921 | E48: =E19*$B$29 -> 1046.8114 | F48: =F19*$B$29 -> 1005.174 | G48: =G19*$B$29 -> 1382.1396 | H48: =H19*$B$29 -> 1102.2267 | I48: =I19*$B$29 -> 1104.8607 | J48: =J19*$B$29 -> 1331.7897 | ... N48: =N19*$B$29 -> 1154.4001 | O48: =SUM(C48:N48) -> 14062.001 | P48: 13397.13
A49: 157001150225 Frt Exp-CNS Non-Promoted Prod | B49: Dollars | C49: =C20*$B$29 -> 700.64336 | D49: =D20*$B$29 -> 814.31049 | E49: =E20*$B$29 -> 651.30656 | F49: =F20*$B$29 -> 618.78682 | G49: =G20*$B$29 -> 839.33347 | H49: =H20*$B$29 -> 656.06802 | I49: =I20*$B$29 -> 646.34249 | J49: =J20*$B$29 -> 774.4966 | ... N49: =N20*$B$29 -> 629.1202 | O49: =SUM(C49:N49) -> 8318.1644 | P49: 10716.3
A50: 157001150224 Frt Exp-Other Brand Products | B50: Dollars | C50: =C21*$B$29 -> 85.199692 | D50: =D21*$B$29 -> 79.425158 | E50: =E21*$B$29 -> 54.706104 | F50: =F21*$B$29 -> 47.209342 | G50: =G21*$B$29 -> 61.493713 | H50: =H21*$B$29 -> 47.108034 | I50: =I21*$B$29 -> 46.905419 | J50: =J21*$B$29 -> 56.630948 | ... N50: =N21*$B$29 -> 49.134186 | O50: =SUM(C50:N50) -> 678.25438 | P50: 1534.96
...

Sheet Upload to COV
A1: COV
C4: Working Forecast | D4: Working Forecast | E4: Working Forecast | F4: Working Forecast | G4: Working Forecast | H4: Working Forecast | I4: Working Forecast | J4: Working Forecast | K4: Working Forecast | L4: Working Forecast | M4: Working Forecast | N4: Working Forecast | O4: Working Forecast Y2 | P4: Working Forecast Y2 | Q4: Working Forecast Y2 | R4: Working Forecast Y2 | S4: Working Forecast Y2 | T4: Working Forecast Y2 | U4: Working Forecast Y2 | V4: Working Forecast Y2 | W4: Working Forecast Y2 | X4: Working Forecast Y2 | Y4: Working Forecast Y2 | Z4: Working Forecast Y2 | AA4: Working Forecast Y3 | AB4: Working Forecast Y3 | AC4: Working Forecast Y3 | AD4: Working Forecast Y3 | AE4: Working Forecast Y3 | AF4: Working Forecast Y3 | AG4: Working Forecast Y3 | AH4: Working Forecast Y3 | AI4: Working Forecast Y3 | AJ4: Working Forecast Y3 | AK4: Working Forecast Y3 | AL4: Working Forecast Y3 | AM4: Working Forecast Y4 | AN4: Working Forecast Y4 | AO4: Working Forecast Y4 | AP4: Working Forecast Y4 | AQ4: Working Forecast Y4 | AR4: Working Forecast Y4 | AS4: Working Forecast Y4 | AT4: Working Forecast Y4 | AU4: Working Forecast Y4 | AV4: Working Forecast Y4 | AW4: Working Forecast Y4 | AX4: Working Forecast Y4
C5: Oct | D5: Nov | E5: Dec | F5: Jan | G5: Feb | H5: Mar | I5: Apr | J5: May | K5: Jun | L5: Jul | M5: Aug | N5: Sep | O5: Oct | P5: Nov | Q5: Dec | R5: Jan | S5: Feb | T5: Mar | U5: Apr | V5: May | W5: Jun | X5: Jul | Y5: Aug | Z5: Sep | AA5: Oct | AB5: Nov | AC5: Dec | AD5: Jan | AE5: Feb | AF5: Mar | AG5: Apr | AH5: May | AI5: Jun | AJ5: Jul | AK5: Aug | AL5: Sep | AM5: Oct | AN5: Nov | AO5: Dec | AP5: Jan | AQ5: Feb | AR5: Mar | AS5: Apr | AT5: May | AU5: Jun | AV5: Jul | AW5: Aug | AX5: Sep
A6: ='Pharm Demand'!A36 -> 157001150211 Frt Exp-Hydrocodone Products | B6: 7171i | C6: ='Pharm Demand'!C36 -> 111229.74 | D6: ='Pharm Demand'!D36 -> 162406.08 | E6: ='Pharm Demand'!E36 -> 103440.15 | F6: ='Pharm Demand'!F36 -> 94655.52 | G6: ='Pharm Demand'!G36 -> 128352.06 | H6: ='Pharm Demand'!H36 -> 118617.39 | I6: ='Pharm Demand'!I36 -> 127605.24 | J6: ='Pharm Demand'!J36 -> 159791.61 | ... AX6: ='Pharm Demand'!AX36 -> 0
A7: ='Pharm Demand'!A37 -> 157001150210 Frt Exp-Oxycodone Products | B7: 7171i | C7: ='Pharm Demand'!C37 -> 64280.521 | D7: ='Pharm Demand'!D37 -> 80687.88 | E7: ='Pharm Demand'!E37 -> 73931.4 | F7: ='Pharm Demand'!F37 -> 54200.88 | G7: ='Pharm Demand'!G37 -> 61557.84 | H7: ='Pharm Demand'!H37 -> 65442.6 | I7: ='Pharm Demand'!I37 -> 33084.72 | J7: ='Pharm Demand'!J37 -> 58372.859 | ... AX7: ='Pharm Demand'!AX37 -> 0
A8: ='Pharm Demand'!A38 -> 157001150244 Oxycodone APAP-Frt Exp | B8: 7171i | C8: ='Pharm Demand'!C38 -> 69212.341 | D8: ='Pharm Demand'!D38 -> 68897.52 | E8: ='Pharm Demand'!E38 -> 88675.56 | F8: ='Pharm Demand'!F38 -> 34989.3 | G8: ='Pharm Demand'!G38 -> 79036.02 | H8: ='Pharm Demand'!H38 -> 84439.8 | I8: ='Pharm Demand'!I38 -> 64395.54 | J8: ='Pharm Demand'!J38 -> 93393.63 | ... AX8: ='Pharm Demand'!AX38 -> 0
A9: ='Pharm Demand'!A39 -> 157001150222 Frt Exp-ADHD | B9: 7171i | C9: ='Pharm Demand'!C39 -> 14322.421 | D9: ='Pharm Demand'!D39 -> 17440.92 | E9: ='Pharm Demand'!E39 -> 21785.22 | F9: ='Pharm Demand'!F39 -> 3392.82 | G9: ='Pharm Demand'!G39 -> 6840.1805 | H9: ='Pharm Demand'!H39 -> 7703.6406 | I9: ='Pharm Demand'!I39 -> 9657.9006 | J9: ='Pharm Demand'!J39 -> 13166.64 | ... AX9: ='Pharm Demand'!AX39 -> 0
A10: ='Pharm Demand'!A40 -> 157001150229 Morphine ER-Frt Exp | B10: 7171i | C10: ='Pharm Demand'!C40 -> 15345.72 | D10: ='Pharm Demand'!D40 -> 20799.72 | E10: ='Pharm Demand'!E40 -> 16576.92 | F10: ='Pharm Demand'!F40 -> 7950.96 | G10: ='Pharm Demand'!G40 -> 19149.48 | H10: ='Pharm Demand'!H40 -> 13206.6 | I10: ='Pharm Demand'!I40 -> 16005.6 | J10: ='Pharm Demand'!J40 -> 21976.748 | ... AX10: ='Pharm Demand'!AX40 -> 0
A11: ='Pharm Demand'!A41 -> 157001150230 Hydromorphone-Frt Exp | B11: 7171i | C11: ='Pharm Demand'!C41 -> 13430.88 | D11: ='Pharm Demand'!D41 -> 19298.52 | E11: ='Pharm Demand'!E41 -> 14958 | F11: ='Pharm Demand'!F41 -> 11088.36 | G11: ='Pharm Demand'!G41 -> 18350.28 | H11: ='Pharm Demand'!H41 -> 10618.56 | I11: ='Pharm Demand'!I41 -> 13263.48 | J11: ='Pharm Demand'!J41 -> 16135.341 | ... AX11: ='Pharm Demand'!AX41 -> 0
A12: ='Pharm Demand'!A42 -> 157001150231 Methadone Generics-Frt Exp | B12: 7171i | C12: ='Pharm Demand'!C42 -> 28057.32 | D12: ='Pharm Demand'!D42 -> 38856.24 | E12: ='Pharm Demand'!E42 -> 29895.48 | F12: ='Pharm Demand'!F42 -> 23964.12 | G12: ='Pharm Demand'!G42 -> 32039.28 | H12: ='Pharm Demand'!H42 -> 28719.36 | I12: ='Pharm Demand'!I42 -> 24280.56 | J12: ='Pharm Demand'!J42 -> 37794.812 | ... AX12: ='Pharm Demand'!AX42 -> 0
A13: ='Pharm Demand'!A43 -> 157001150232 APAP Codeine-Frt Exp | B13: 7171i | C13: ='Pharm Demand'!C43 -> 5957.2802 | D13: ='Pharm Demand'!D43 -> 7737.66 | E13: ='Pharm Demand'!E43 -> 6428.7 | F13: ='Pharm Demand'!F43 -> 7653.42 | G13: ='Pharm Demand'!G43 -> 7397.46 | H13: ='Pharm Demand'!H43 -> 5491.26 | I13: ='Pharm Demand'!I43 -> 5850.9 | J13: ='Pharm Demand'!J43 -> 6941.4857 | ... AX13: ='Pharm Demand'!AX43 -> 0
A14: 157001150234 Fentanyl Lozenge-Frt Exp | B14: 7171i | C14: ='Pharm Demand'!C44 -> 851.94018 | D14: ='Pharm Demand'!D44 -> 1217.43 | E14: ='Pharm Demand'!E44 -> 922.68 | F14: ='Pharm Demand'!F44 -> 626.22 | G14: ='Pharm Demand'!G44 -> 1240.83 | H14: ='Pharm Demand'!H44 -> 972.27 | I14: ='Pharm Demand'!I44 -> 847.8 | J14: ='Pharm Demand'!J44 -> 1121.85 | ... AX14: ='Pharm Demand'!AX44 -> 0
A15: 157001150236 Fentanyl Patch-Frt Exp | B15: 7171i | C15: ='Pharm Demand'!C45 -> 0.00054 | D15: ='Pharm Demand'!D45 -> 0 | E15: ='Pharm Demand'!E45 -> 0 | F15: ='Pharm Demand'!F45 -> 0 | G15: ='Pharm Demand'!G45 -> 3458.16 | H15: ='Pharm Demand'!H45 -> 8335.44 | I15: ='Pharm Demand'!I45 -> 13610.16 | J15: ='Pharm Demand'!J45 -> 17676.18 | ... AX15: ='Pharm Demand'!AX45 -> 0
A16: 157001150253 Temazepam-Frt Exp | B16: 7171i | C16: ='Pharm Demand'!C46 -> 224.64018 | D16: ='Pharm Demand'!D46 -> 330.48 | E16: ='Pharm Demand'!E46 -> 317.52 | F16: ='Pharm Demand'!F46 -> 206.28 | G16: ='Pharm Demand'!G46 -> 302.4 | H16: ='Pharm Demand'!H46 -> 258.12 | I16: ='Pharm Demand'!I46 -> 304.56 | J16: ='Pharm Demand'!J46 -> 309.96 | ... AX16: ='Pharm Demand'!AX46 -> 0
A17: 157001150254 Imipramine Pamoate-Frt Exp | B17: 7171i | C17: ='Pharm Demand'!C47 -> 170.10018 | D17: ='Pharm Demand'!D47 -> 310.5 | E17: ='Pharm Demand'!E47 -> 235.44 | F17: ='Pharm Demand'!F47 -> 102.06 | G17: ='Pharm Demand'!G47 -> 241.92 | H17: ='Pharm Demand'!H47 -> 202.5 | I17: ='Pharm Demand'!I47 -> 184.14 | J17: ='Pharm Demand'!J47 -> 250.28911 | ... AX17: ='Pharm Demand'!AX47 -> 0
A18: ='Pharm Demand'!A48 -> 157001150209 FREIGHT | B18: 7171i | C18: ='Pharm Demand'!C48 -> 685.62612 | D18: ='Pharm Demand'!D48 -> 958.05297 | E18: ='Pharm Demand'!E48 -> 692.19315 | F18: ='Pharm Demand'!F48 -> 290.43 | G18: ='Pharm Demand'!G48 -> 1086.1229 | H18: ='Pharm Demand'!H48 -> 752.8527 | I18: ='Pharm Demand'!I48 -> 463.9527 | J18: ='Pharm Demand'!J48 -> 866.64415 | ... AX18: ='Pharm Demand'!AX48 -> 0
A19: 157001150237 Methylphenidate ER(MedadateCD) | B19: 7171i | C19: ='Pharm Demand'!C49 -> 0 | D19: ='Pharm Demand'!D49 -> 0 | E19: ='Pharm Demand'!E49 -> 0 | F19: ='Pharm Demand'!F49 -> 0 | G19: ='Pharm Demand'!G49 -> 0 | H19: ='Pharm Demand'!H49 -> 0 | I19: ='Pharm Demand'!I49 -> 0 | J19: ='Pharm Demand'!J49 -> 0 | ... AX19: ='Pharm Demand'!AX49 -> 0
A20: 157001150238 Methylphenidate ER (Concerta) | B20: 7171i | C20: ='Pharm Demand'!C50 -> 0 | D20: ='Pharm Demand'!D50 -> 0 | E20: ='Pharm Demand'!E50 -> 0 | F20: ='Pharm Demand'!F50 -> 0 | G20: ='Pharm Demand'!G50 -> 0 | H20: ='Pharm Demand'!H50 -> 0 | I20: ='Pharm Demand'!I50 -> 0 | J20: ='Pharm Demand'!J50 -> 0 | ... AX20: ='Pharm Demand'!AX50 -> 0
A21: 157001150241 OxymorphoneER(OpanaER) Frt Exp | B21: 7171i | C21: ='Pharm Demand'!C51 -> 0 | D21: ='Pharm Demand'!D51 -> 0 | E21: ='Pharm Demand'!E51 -> 0 | F21: ='Pharm Demand'!F51 -> 0 | G21: ='Pharm Demand'!G51 -> 0 | H21: ='Pharm Demand'!H51 -> 0 | I21: ='Pharm Demand'!I51 -> 0 | J21: ='Pharm Demand'!J51 -> 0 | ... AX21: ='Pharm Demand'!AX51 -> 0
A22: 157001150248 Oxymorphone IR (Opana IR) | B22: 7171i | C22: ='Pharm Demand'!C52 -> 0 | D22: ='Pharm Demand'!D52 -> 0 | E22: ='Pharm Demand'!E52 -> 0 | F22: ='Pharm Demand'!F52 -> 0 | G22: ='Pharm Demand'!G52 -> 0 | H22: ='Pharm Demand'!H52 -> 0 | I22: ='Pharm Demand'!I52 -> 0 | J22: ='Pharm Demand'!J52 -> 0 | ... AX22: ='Pharm Demand'!AX52 -> 0
A23: 157001150227 Oxycodone ER Products Freight | B23: 7171i | C23: ='Pharm Demand'!C53 -> 0.00054 | D23: ='Pharm Demand'!D53 -> 0.00036 | E23: ='Pharm Demand'!E53 -> 0.00036 | F23: ='Pharm Demand'!F53 -> 0 | G23: ='Pharm Demand'!G53 -> 0.00036 | H23: ='Pharm Demand'!H53 -> 0.00036 | I23: ='Pharm Demand'!I53 -> 0.00036 | J23: ='Pharm Demand'!J53 -> 0 | ... AX23: ='Pharm Demand'!AX53 -> 0
A24: 157001150240 Tussi Suspension-Frt Exp | B24: 7171i | C24: ='Pharm Demand'!C54 -> 0 | D24: ='Pharm Demand'!D54 -> 0 | E24: ='Pharm Demand'!E54 -> 0 | F24: ='Pharm Demand'!F54 -> 0 | G24: ='Pharm Demand'!G54 -> 0 | H24: ='Pharm Demand'!H54 -> 0 | I24: ='Pharm Demand'!I54 -> 0 | J24: ='Pharm Demand'!J54 -> 0 | ... AX24: ='Pharm Demand'!AX54 -> 0
A25: 157001150243 Buprenorphine/Naloxone(Subxne) | B25: 7171i | C25: ='Pharm Demand'!C55 -> 0 | D25: ='Pharm Demand'!D55 -> 0 | E25: ='Pharm Demand'!E55 -> 0 | F25: ='Pharm Demand'!F55 -> 0 | G25: ='Pharm Demand'!G55 -> 0 | H25: ='Pharm Demand'!H55 -> 0 | I25: ='Pharm Demand'!I55 -> 0 | J25: ='Pharm Demand'!J55 -> 0 | ... AX25: ='Pharm Demand'!AX55 -> 0
A26: 157001150260 Buprenorphine(Subutex) | B26: 7171i | C26: ='Pharm Demand'!C56 -> 0 | D26: ='Pharm Demand'!D56 -> 0 | E26: ='Pharm Demand'!E56 -> 0 | F26: ='Pharm Demand'!F56 -> 0 | G26: ='Pharm Demand'!G56 -> 0 | H26: ='Pharm Demand'!H56 -> 0 | I26: ='Pharm Demand'!I56 -> 0 | J26: ='Pharm Demand'!J56 -> 0 | ... AX26: ='Pharm Demand'!AX56 -> 0
A27: 157001150247 Morphine Sulfate ER (Kadian) | B27: 7171i | C27: ='Pharm Demand'!C57 -> 0 | D27: ='Pharm Demand'!D57 -> 0 | E27: ='Pharm Demand'!E57 -> 0 | F27: ='Pharm Demand'!F57 -> 0 | G27: ='Pharm Demand'!G57 -> 0 | H27: ='Pharm Demand'!H57 -> 0 | I27: ='Pharm Demand'!I57 -> 0 | J27: ='Pharm Demand'!J57 -> 0 | ... AX27: ='Pharm Demand'!AX57 -> 0
A28: ='[1]Pharm Demand'!A49 -> 157001150221 Frt Exp-ADDICTION TREATMENT | B28: 7171i | C28: ='Pharm Demand'!C58 -> 54766.803 | D28: ='Pharm Demand'!D58 -> 73895.76 | E28: ='Pharm Demand'!E58 -> 63300.961 | F28: ='Pharm Demand'!F58 -> 52302.24 | G28: ='Pharm Demand'!G58 -> 70120.08 | H28: ='Pharm Demand'!H58 -> 57235.681 | I28: ='Pharm Demand'!I58 -> 57123.361 | J28: ='Pharm Demand'!J58 -> 76069.488 | ... AX28: ='Pharm Demand'!AX58 -> 0
A31: 157001150211 Frt Exp-Hydrocodone Products | B31: 7165i | C31: 3600 | D31: 3600 | E31: 3600 | F31: 3600 | G31: 3600 | H31: 3600 | I31: 3600 | J31: 3600 | K31: 3600 | L31: 3600 | M31: 3600 | N31: 3600 | O31: 3600 | P31: 3600 | Q31: 3600 | R31: 3600 | S31: 3600 | T31: 3600 | U31: 3600 | V31: 3600 | W31: 3600 | X31: 3600 | Y31: 3600 | Z31: 3600 | AA31: 3600 | AB31: 3600 | AC31: 3600 | AD31: 3600 | AE31: 3600 | AF31: 3600 | AG31: 3600 | AH31: 3600 | AI31: 3600 | AJ31: 3600 | AK31: 3600 | AL31: 3600 | AM31: 3600 | AN31: 3600 | AO31: 3600 | AP31: 3600 | AQ31: 3600 | AR31: 3600 | AS31: 3600 | AT31: 3600 | AU31: 3600 | AV31: 3600 | AW31: 3600 | AX31: 3600
A32: 157001150210 Frt Exp-Oxycodone Products | B32: 7165i | C32: 3000 | D32: 3000 | E32: 3000 | F32: 3000 | G32: 3000 | H32: 3000 | I32: 3000 | J32: 3000 | K32: 3000 | L32: 3000 | M32: 3000 | N32: 3000 | O32: 3000 | P32: 3000 | Q32: 3000 | R32: 3000 | S32: 3000 | T32: 3000 | U32: 3000 | V32: 3000 | W32: 3000 | X32: 3000 | Y32: 3000 | Z32: 3000 | AA32: 3000 | AB32: 3000 | AC32: 3000 | AD32: 3000 | AE32: 3000 | AF32: 3000 | AG32: 3000 | AH32: 3000 | AI32: 3000 | AJ32: 3000 | AK32: 3000 | AL32: 3000 | AM32: 3000 | AN32: 3000 | AO32: 3000 | AP32: 3000 | AQ32: 3000 | AR32: 3000 | AS32: 3000 | AT32: 3000 | AU32: 3000 | AV32: 3000 | AW32: 3000 | AX32: 3000
A33: 157001150244 Oxycodone APAP-Frt Exp | B33: 7165i | C33: 3000 | D33: 3000 | E33: 3000 | F33: 3000 | G33: 3000 | H33: 3000 | I33: 3000 | J33: 3000 | K33: 3000 | L33: 3000 | M33: 3000 | N33: 3000 | O33: 3000 | P33: 3000 | Q33: 3000 | R33: 3000 | S33: 3000 | T33: 3000 | U33: 3000 | V33: 3000 | W33: 3000 | X33: 3000 | Y33: 3000 | Z33: 3000 | AA33: 3000 | AB33: 3000 | AC33: 3000 | AD33: 3000 | AE33: 3000 | AF33: 3000 | AG33: 3000 | AH33: 3000 | AI33: 3000 | AJ33: 3000 | AK33: 3000 | AL33: 3000 | AM33: 3000 | AN33: 3000 | AO33: 3000 | AP33: 3000 | AQ33: 3000 | AR33: 3000 | AS33: 3000 | AT33: 3000 | AU33: 3000 | AV33: 3000 | AW33: 3000 | AX33: 3000
A34: 157001150222 Frt Exp-ADHD | B34: 7165i | C34: 600 | D34: 600 | E34: 600 | F34: 600 | G34: 600 | H34: 600 | I34: 600 | J34: 600 | K34: 600 | L34: 600 | M34: 600 | N34: 600 | O34: 600 | P34: 600 | Q34: 600 | R34: 600 | S34: 600 | T34: 600 | U34: 600 | V34: 600 | W34: 600 | X34: 600 | Y34: 600 | Z34: 600 | AA34: 600 | AB34: 600 | AC34: 600 | AD34: 600 | AE34: 600 | AF34: 600 | AG34: 600 | AH34: 600 | AI34: 600 | AJ34: 600 | AK34: 600 | AL34: 600 | AM34: 600 | AN34: 600 | AO34: 600 | AP34: 600 | AQ34: 600 | AR34: 600 | AS34: 600 | AT34: 600 | AU34: 600 | AV34: 600 | AW34: 600 | AX34: 600
A35: 157001150229 Morphine ER-Frt Exp | B35: 7165i | C35: 1000 | D35: 1000 | E35: 1000 | F35: 1000 | G35: 1000 | H35: 1000 | I35: 1000 | J35: 1000 | K35: 1000 | L35: 1000 | M35: 1000 | N35: 1000 | O35: 1000 | P35: 1000 | Q35: 1000 | R35: 1000 | S35: 1000 | T35: 1000 | U35: 1000 | V35: 1000 | W35: 1000 | X35: 1000 | Y35: 1000 | Z35: 1000 | AA35: 1000 | AB35: 1000 | AC35: 1000 | AD35: 1000 | AE35: 1000 | AF35: 1000 | AG35: 1000 | AH35: 1000 | AI35: 1000 | AJ35: 1000 | AK35: 1000 | AL35: 1000 | AM35: 1000 | AN35: 1000 | AO35: 1000 | AP35: 1000 | AQ35: 1000 | AR35: 1000 | AS35: 1000 | AT35: 1000 | AU35: 1000 | AV35: 1000 | AW35: 1000 | AX35: 1000
A36: 157001150230 Hydromorphone-Frt Exp | B36: 7165i | C36: 1200 | D36: 1200 | E36: 1200 | F36: 1200 | G36: 1200 | H36: 1200 | I36: 1200 | J36: 1200 | K36: 1200 | L36: 1200 | M36: 1200 | N36: 1200 | O36: 1200 | P36: 1200 | Q36: 1200 | R36: 1200 | S36: 1200 | T36: 1200 | U36: 1200 | V36: 1200 | W36: 1200 | X36: 1200 | Y36: 1200 | Z36: 1200 | AA36: 1200 | AB36: 1200 | AC36: 1200 | AD36: 1200 | AE36: 1200 | AF36: 1200 | AG36: 1200 | AH36: 1200 | AI36: 1200 | AJ36: 1200 | AK36: 1200 | AL36: 1200 | AM36: 1200 | AN36: 1200 | AO36: 1200 | AP36: 1200 | AQ36: 1200 | AR36: 1200 | AS36: 1200 | AT36: 1200 | AU36: 1200 | AV36: 1200 | AW36: 1200 | AX36: 1200
A37: 157001150231 Methadone Generics-Frt Exp | B37: 7165i | C37: 1000 | D37: 1000 | E37: 1000 | F37: 1000 | G37: 1000 | H37: 1000 | I37: 1000 | J37: 1000 | K37: 1000 | L37: 1000 | M37: 1000 | N37: 1000 | O37: 1000 | P37: 1000 | Q37: 1000 | R37: 1000 | S37: 1000 | T37: 1000 | U37: 1000 | V37: 1000 | W37: 1000 | X37: 1000 | Y37: 1000 | Z37: 1000 | AA37: 1000 | AB37: 1000 | AC37: 1000 | AD37: 1000 | AE37: 1000 | AF37: 1000 | AG37: 1000 | AH37: 1000 | AI37: 1000 | AJ37: 1000 | AK37: 1000 | AL37: 1000 | AM37: 1000 | AN37: 1000 | AO37: 1000 | AP37: 1000 | AQ37: 1000 | AR37: 1000 | AS37: 1000 | AT37: 1000 | AU37: 1000 | AV37: 1000 | AW37: 1000 | AX37: 1000
A38: 157001150232 APAP Codeine-Frt Exp | B38: 7165i | C38: 300 | D38: 300 | E38: 300 | F38: 300 | G38: 300 | H38: 300 | I38: 300 | J38: 300 | K38: 300 | L38: 300 | M38: 300 | N38: 300 | O38: 300 | P38: 300 | Q38: 300 | R38: 300 | S38: 300 | T38: 300 | U38: 300 | V38: 300 | W38: 300 | X38: 300 | Y38: 300 | Z38: 300 | AA38: 300 | AB38: 300 | AC38: 300 | AD38: 300 | AE38: 300 | AF38: 300 | AG38: 300 | AH38: 300 | AI38: 300 | AJ38: 300 | AK38: 300 | AL38: 300 | AM38: 300 | AN38: 300 | AO38: 300 | AP38: 300 | AQ38: 300 | AR38: 300 | AS38: 300 | AT38: 300 | AU38: 300 | AV38: 300 | AW38: 300 | AX38: 300
A39: 157001150234 Fentanyl Lozenge-Frt Exp | B39: 7165i | C39: 100 | D39: 100 | E39: 100 | F39: 100 | G39: 100 | H39: 100 | I39: 100 | J39: 100 | K39: 100 | L39: 100 | M39: 100 | N39: 100 | O39: 100 | P39: 100 | Q39: 100 | R39: 100 | S39: 100 | T39: 100 | U39: 100 | V39: 100 | W39: 100 | X39: 100 | Y39: 100 | Z39: 100 | AA39: 100 | AB39: 100 | AC39: 100 | AD39: 100 | AE39: 100 | AF39: 100 | AG39: 100 | AH39: 100 | AI39: 100 | AJ39: 100 | AK39: 100 | AL39: 100 | AM39: 100 | AN39: 100 | AO39: 100 | AP39: 100 | AQ39: 100 | AR39: 100 | AS39: 100 | AT39: 100 | AU39: 100 | AV39: 100 | AW39: 100 | AX39: 100
