Workbook
Name Account_Details: 'GL '!$A$1:$N$7
Name Katie___Item_Record: 'Item Master'!$A$1:$X$1997
Name Katie___Item_Record_1: 'Item Master'!$A$1:$X$2115

Sheet Cover Sheet
B1: JUUL LABS, INC.
B2: MONTH/YEAR: | C2: 43404
B3: GL#: | C3: 220950
B4: ACCOUNT: | C4: 220950 Accrued Freight/Fulfillment
B5: CURRENCY: | C5: GBP
B6: Prepared by: | C6: Matt Osborn | E6: Account Description
B7: Date: | C7: =TODAY() -> 43436 | E7: Accruals for freight costs - should reverse the following period
B8: Reviewed by: | C8: Phil Foyn
B9: Date:
B11: Description | C11: Amount | D11: Preparer Comment
B12: GL balance | C12: -353895.25
B13: Detailed breakdown | C13: =-Recon!D10 -> -353895.25 | D13: #FQ-220950 | G13: All reversed (see breakdown tab) in September 2018
B14: Difference | C14: =C12-C13 -> -0.0037060335
B16: Reconciling Items:
B18: Total Reconciling Items | C18: =SUM(C17:C17) -> 0
B20: Difference | C20: =C18+C14 -> -0.0037060335
B23: MoM Trending Analysis | D23: Amount | E23: Explanation (If over $100k or 10%)
B24: Prior Month Balance | D24: -173185.65 | E24: June/July and Aug Freight inbound costs plus Arvato WH costs
B25: MoM Difference | D25: =C12-D24 -> -180709.6
B26: MoM % Change | D26: =D25/D24 -> 1.0434444
A31: # | B31: Review Comment / Action Item | D31: Comment Date | E31: Preparer Response | G31: Response Date | H31: Status
A32: 1
A33: 2
A34: 3
A35: 4
A36: 5

Sheet Recon
A4: Description | B4: Type | C4: Ref | D4: Amount
A5: Freight In Expense Accrual OCt 2018 | B5: Accrual | C5: 1 | D5: =-'Trial Balance'!E120 -> 58433.106 | F5: Net Capitalized Balance after Reclass AP Invoices JNL from Inventory/Connor Group
A6: ACCR.ARVATO-Oct18 (75% of £160k Inv 94623882) | B6: Accrual | C6: 2 | D6: 120862.5 | F6: 75% accrual of Inv 94623882 - UK Mgt neogotiating lower fees/Pick Pack Rate
A7: ACCR>Avarto - Aug 18 & Sept 18 | B7: Accrual | C7: 3 | D7: 133500 | F7: Aug & Sept Inv not yet agreed. Pick Pack rate under negotiation
A8: ACCR>>Flexport International LLC USD>>pick up date 14.08.2018 freight charges-Oct 18 | B8: Accrual | C8: 4 | D8: 25803.05
A9: ACCR>>Flexport International LLC USD>>Pickup date Aug 30.2018 freight charges-Oct 18 | B9: Accrual | C9: 5 | D9: 15296.59
D10: =SUM(D5:D9) -> 353895.25
E36: =D8 -> 25803.05 | R36: =D9 -> 15296.59

Sheet GL 
A1: Title: | B1: Account Details
A2: Company: | B2: JuulUK
A3: Date: | B3: 02 Dec 2018 08:52 AM GMT+00:00
A5: Parameters
A6: Company: | B6: <Empty>
A7: Branch (Dynamic): | B7: PLOOM
A8: Ledger (Dynamic): | B8: ACTUAL
A9: From Period: | B9: 102018
A10: To Period: | B10: 102018
A11: Account: | B11: 220950
A12: Subaccount (Dynamic): | B12: <Empty>
A13: From Date (Dynamic): | B13: <Empty>
A14: Period Start Date: | B14: 01/10/2018 00:00:00
A15: To Date (Dynamic): | B15: <Empty>
A16: Period End Date: | B16: 31/10/2018 00:00:00
A17: Show Summary (Dynamic): | B17: FALSE
... A24: Ending Balance: | B24: -353895.25
A26: Selected | B26: Module | C26: Batch Number | D26: Tran. Date | E26: Period | F26: Description | G26: Ref. Number | H26: Account | I26: Subaccount | J26: Beg. Balance | K26: Debit Amount | L26: Credit Amount | M26: Ending Balance | N26: Reclass. Batch Number
B27: GL | C27: GL03-00029508 | D27: 43374 | E27: 10-2018 | F27: Freight In Expense Accrual Sep 2018 | H27: 220950 | I27: INTUK-CRP-6000-JUL | J27: -173185.65 | K27: 84836.85 | L27: 0 | M27: -88348.8
B28: GL | C28: GL03-00029595 | D28: 43374 | E28: 10-2018 | F28: Arvato Invoice Sept 18 - montlhy fixed fee | G28: Accrue Stampli | H28: 220950 | I28: INTUK-CRP-6000-JUL | J28: -88348.8 | K28: 15674.4 | L28: 0 | M28: -72674.4
B29: GL | C29: GL03-00029595 | D29: 43374 | E29: 10-2018 | F29: Re-Accrue Arvato - August 18 as inovice not yet received | G29: Accrue Stampli | H29: 220950 | I29: INTUK-CRP-6000-JUL | J29: -72674.4 | K29: 22000 | L29: 0 | M29: -50674.4
B30: GL | C30: GL03-00029595 | D30: 43374 | E30: 10-2018 | F30: Re-Accrue Arvato - August 18 as inovice not yet received | G30: Accrue Stampli | H30: 220950 | I30: INTUK-CRP-6000-JUL | J30: -50674.4 | K30: 15674.4 | L30: 0 | M30: -35000
B31: GL | C31: GL03-00029595 | D31: 43374 | E31: 10-2018 | F31: Re-Accrue Arvato - August 18 as inovice not yet received | G31: Accrue Stampli | H31: 220950 | I31: INTUK-CRP-6000-JUL | J31: -35000 | K31: 35000 | L31: 0 | M31: 0
B32: GL | C32: GL03-00032748 | D32: 43404 | E32: 10-2018 | F32: Freight In Expense Accrual OCt 2018 | H32: 220950 | I32: INTUK-CRP-6000-JUL | J32: 0 | K32: 0 | L32: 58433.11 | M32: -58433.11
B33: GL | C33: GL03-00032455 | D33: 43404 | E33: 10-2018 | F33: ACCR.ARVATO-Oct18 (75% of £160k Inv 94623882) | G33: ACCR.ARVATO | H33: 220950 | I33: INTUK-CRP-4600-JUL | J33: -58433.11 | K33: 0 | L33: 120862.5 | M33: -179295.61
B34: GL | C34: GL03-00032463 | D34: 43404 | E34: 10-2018 | F34: ACCR>Avarto - Aug 18 & Sept 18 | G34: ACCR.ARVATO | H34: 220950 | I34: INTUK-CRP-4600-JUL | J34: -179295.61 | K34: 0 | L34: 133500 | M34: -312795.61
B35: GL | C35: GL03-00032723 | D35: 43404 | E35: 10-2018 | F35: ACCR>>Flexport International LLC USD>>pick up date 14.08.2018 freight charges-Oct 18 | G35: FLEX-382035-1 | H35: 220950 | I35: INTUK-CRP-6000-JUL | J35: -312795.61 | K35: 0 | L35: 25803.05 | M35: -338598.66
B36: GL | C36: GL03-00032723 | D36: 43404 | E36: 10-2018 | F36: ACCR>>Flexport International LLC USD>>Pickup date Aug 30.2018 freight charges-Oct 18 | G36: FLEX-403093-1 | H36: 220950 | I36: INTUK-CRP-6000-JUL | J36: -338598.66 | K36: 0 | L36: 15296.59 | M36: -353895.25

Sheet JE
A1: Account | B1: Description | C1: Subaccount | D1: Ref. Number | E1: Quantity | F1: UOM | G1: Debit Amount | H1: Credit Amount | I1: Transaction Description | J1: Reclass. Batch Number
A2: 515000 | B2: Freight Inbound | C2: INTUK-CRP-4100-JUL | E2: 0 | G2: =-'Trial Balance'!E120 -> 58433.106 | H2: 0 | I2: Freight In Expense Accrual OCt 2018
A3: 220950 | B3: Accrued Freight/Fulfillment | C3: INTUK-CRP-6000-JUL | E3: 0 | G3: =-H2 -> 0 | H3: =G2 -> 58433.106 | I3: Freight In Expense Accrual OCt 2018

Sheet Trial Balance
A1: Trial Balance Summary | D1: Ledger: | E1: ACTUAL | F1: Page: | G1: 1 of 3 | I1: Original Data
A2: Company: | B2: JuulUK | F2: Date: | G2: 43404.861
A3: User: | B3: Karen.Fu | D3: Fin. Period: | E3: 10-2018
A5: Account | B5: Type | C5: Description | D5: Beginning Balance | E5: Debit | F5: Credit | G5: Ending Balance
A6: 112000 | B6: A | C6: MUFG - GBP | D6: 1279489.1 | E6: 3127446.9 | F6: 3700921.7 | G6: 706014.3
A7: 112001 | B7: A | C7: MUFG - EUR | D7: 1234260.6 | E7: 545373.61 | F7: 671530.21 | G7: 1108104
A8: 119000 | B8: A | C8: Undeposited/Cash in Transit | D8: -80456.98 | E8: 491293.93 | F8: 609808.34 | G8: -198971.39
A9: 121100 | B9: A | C9: Trade Accounts Receivable | D9: 611662.61 | E9: 2673802.8 | F9: 1106470.2 | G9: 2178995.1
A10: 123220 | B10: A | C10: VAT Input | D10: 546725.49 | E10: 165232.74 | F10: 7014.01 | G10: 704944.22
A11: 130100 | B11: A | C11: Prepaid Sales & Marketing | D11: 257335 | E11: 237540 | F11: 19795 | G11: 475080
A12: 130600 | B12: A | C12: Prepaid Other | D12: 390347.72 | E12: 2537807 | F12: 120853.17 | G12: 2807301.5
A13: 130650 | B13: A | C13: Clearing Account - Prepaid | D13: 2475599.8 | E13: 31728.69 | F13: 2507348 | G13: -19.49
A14: 141000 | B14: A | C14: Inventory - Finished Products | D14: 1708008.5 | E14: 1604724.6 | F14: 1099013.1 | G14: 2213720
A15: 150300 | B15: A | C15: Computer HW and Equipment | D15: -4781.77 | E15: 14141.41 | F15: 0.01 | G15: 9359.63
A16: 180100 | B16: A | C16: Intercompany Clearing Account | D16: -45.91 | E16: 12109.15 | F16: 0 | G16: 12063.24
A17: 191000 | B17: A | C17: Deposits - Long Term | D17: 1185798.8 | E17: 0 | F17: 71254.97 | G17: 1114543.8
... A106: 821200 | B106: E | C106: Unrealized (gain) loss - currency conversion | D106: 34852.06 | E106: 0 | F106: 0 | G106: 34852.06
C107: Total: | D107: =SUM(D46) -> 68763.55 | E107: =SUM(E46) -> 91883.09 | F107: =SUM(F46) -> 84836.85 | G107: =SUM(G46) -> 75809.79
C109: Account Integration:
C111: AP Invoices from Oct 2018 Shipments | E111: =E46 -> 91883.09 | F111: =F46 -> 84836.85
C112: Net Activity | E112: =E111-F111 -> 7046.24
C114: Shipments Oct 2018 | E114: ='UK Freight Rate'!D9 -> 65479.346
C116: Delta to be Expensed against Freight Capitalization (due to first month to Accrue) | E116: =E114-E112 -> 58433.106
C117: Sep Capitilized Freight | E117: 0
C118: Net Capitalized Balance after Expense | E118: =E117-E116 -> -58433.106
C119: Plus AP Invoices in Inv FG Adjustments | E119: 0
C120: Net Capitalized Balance after Reclass AP Invoices | E120: =E119+E118 -> -58433.106

Sheet UK Freight Rate
B2: Freight In Rates | C2: Current Month | D2: 43404
B4: Inventory Type | C4: Freight Per Unit | D4: Amount to be Expensed
B5: BK | C5: 0.5982425 | D5: =SUMIFS('Shipments UK'!N:N,'Shipments UK'!M:M,'UK Freight Rate'!B5) -> 4926.9816
B6: SK | C6: 0.60750386 | D6: =SUMIFS('Shipments UK'!N:N,'Shipments UK'!M:M,'UK Freight Rate'!B6) -> 30207.813
B7: RK | C7: 0.10367549 | D7: =SUMIFS('Shipments UK'!N:N,'Shipments UK'!M:M,'UK Freight Rate'!B7) -> 29055.147
B8: ACC | C8: 0.1900678 | D8: =SUMIFS('Shipments UK'!N:N,'Shipments UK'!M:M,'UK Freight Rate'!B8) -> 1289.4048
B9: Total | D9: =SUM(D5:D8) -> 65479.346

Sheet Shipments UK
J1: 1 day shipment est | K1: =SUMIF($M:$M,"BK",$L:$L) -> 8235.76 | L1: =(SUMIF($M$7:$M$100114,M1,$L$7:$L$100017)/25)*1 -> 316.76 | M1: BK | N1: =IF(M1="","",IFERROR(VLOOKUP(M1,'UK Freight Rate'!$B$5:$C$8,2,0)*L1,0)) -> 189.49929
J2: 1 day shipment est | K2: =SUMIF($M:$M,"RK",$L:$L) -> 280250.88 | L2: =(SUMIF($M$7:$M$100114,M2,$L$7:$L$100017)/25)*1 -> 1912.48 | M2: SK | N2: =IF(M2="","",IFERROR(VLOOKUP(M2,'UK Freight Rate'!$B$5:$C$8,2,0)*L2,0)) -> 1161.839
J3: 1 day shipment est | K3: =SUMIF($M:$M,"SK",$L:$L) -> 49724.48 | L3: =(SUMIF($M$7:$M$100114,M3,$L$7:$L$100017)/25)*1 -> 10778.88 | M3: RK | N3: =IF(M3="","",IFERROR(VLOOKUP(M3,'UK Freight Rate'!$B$5:$C$8,2,0)*L3,0)) -> 1117.5056
J4: 1 day shipment est | K4: =SUMIF($M:$M,"Acc",$L:$L) -> 6783.92 | L4: =(SUMIF($M$7:$M$100114,M4,$L$7:$L$100017)/25)*1 -> 260.92 | M4: Acc | N4: =IF(M4="","",IFERROR(VLOOKUP(M4,'UK Freight Rate'!$B$5:$C$8,2,0)*L4,0)) -> 49.592491
A6: Inventory ID | B6: Type | C6: Ref. Nbr. | D6: Operation | E6: Order Status | F6: Order Number | G6: Customer ID | H6: Customer Name | I6: Warehouse | J6: UOM | K6: Order Qty. | L6: Shipped Qty. | M6: Item Master | N6: Amount to Expense Freight Inbound
A7: J1A2255 | B7: BO | C7: SH03-00009325 | D7: Issue | E7: Completed | F7: SO03-00009352 | G7: 03-00000082 | H7: Violet's Vapes Ltd | I7: ARVATO-BI | J7: EA | K7: 8 | L7: 8 | M7: =VLOOKUP(A7,'Item Master'!$A:$D,4,0) -> Acc | N7: =IFERROR((VLOOKUP(M7,'UK Freight Rate'!$B$4:$C$8,2,0)*L7),0) -> 1.5205424
A8: J1A2255 | B8: BO | C8: SH03-00009328 | D8: Issue | E8: Completed | F8: SO03-00009355 | G8: 03-00000096 | H8: Magnum News | I8: ARVATO-BI | J8: EA | K8: 8 | L8: 8 | M8: =VLOOKUP(A8,'Item Master'!$A:$D,4,0) -> Acc | N8: =IFERROR((VLOOKUP(M8,'UK Freight Rate'!$B$4:$C$8,2,0)*L8),0) -> 1.5205424
A9: J1A2255 | B9: BO | C9: SH03-00009330 | D9: Issue | E9: Completed | F9: SO03-00009357 | G9: 03-00000024 | H9: INTERNET EXPRESS UK LTD | I9: ARVATO-BI | J9: EA | K9: 16 | L9: 16 | M9: =VLOOKUP(A9,'Item Master'!$A:$D,4,0) -> Acc | N9: =IFERROR((VLOOKUP(M9,'UK Freight Rate'!$B$4:$C$8,2,0)*L9),0) -> 3.0410848
A10: J1A2255 | B10: BO | C10: SH03-00009336 | D10: Issue | E10: Completed | F10: SO03-00009364 | G10: 03-00000031 | H10: Hyde Vapes Ltd | I10: ARVATO-BI | J10: EA | K10: 8 | L10: 8 | M10: =VLOOKUP(A10,'Item Master'!$A:$D,4,0) -> Acc | N10: =IFERROR((VLOOKUP(M10,'UK Freight Rate'!$B$4:$C$8,2,0)*L10),0) -> 1.5205424
A11: J1A2255 | B11: BO | C11: SH03-00009346 | D11: Issue | E11: Completed | F11: SO03-00009376 | G11: 03-00000033 | H11: Shisha Vibe | I11: ARVATO-BI | J11: EA | K11: 8 | L11: 8 | M11: =VLOOKUP(A11,'Item Master'!$A:$D,4,0) -> Acc | N11: =IFERROR((VLOOKUP(M11,'UK Freight Rate'!$B$4:$C$8,2,0)*L11),0) -> 1.5205424
A12: J1A2255 | B12: BO | C12: SH03-00009348 | D12: Issue | E12: Completed | F12: SO03-00009377 | G12: 03-00000060 | H12: EZ Homeware t/a EZ Cloudz | I12: ARVATO-BI | J12: EA | K12: 8 | L12: 8 | M12: =VLOOKUP(A12,'Item Master'!$A:$D,4,0) -> Acc | N12: =IFERROR((VLOOKUP(M12,'UK Freight Rate'!$B$4:$C$8,2,0)*L12),0) -> 1.5205424
A13: J1A2255 | B13: BO | C13: SH03-00009356 | D13: Issue | E13: Completed | F13: SO03-00009385 | G13: 03-00000036 | H13: primary keys ltd | I13: ARVATO-BI | J13: EA | K13: 8 | L13: 8 | M13: =VLOOKUP(A13,'Item Master'!$A:$D,4,0) -> Acc | N13: =IFERROR((VLOOKUP(M13,'UK Freight Rate'!$B$4:$C$8,2,0)*L13),0) -> 1.5205424
A14: J1A2255 | B14: BO | C14: SH03-00009365 | D14: Issue | E14: Completed | F14: SO03-00009394 | G14: 03-00000112 | H14: Manchestervapeman LTD | I14: ARVATO-BI | J14: EA | K14: 8 | L14: 8 | M14: =VLOOKUP(A14,'Item Master'!$A:$D,4,0) -> Acc | N14: =IFERROR((VLOOKUP(M14,'UK Freight Rate'!$B$4:$C$8,2,0)*L14),0) -> 1.5205424
A15: J1A2255 | B15: BO | C15: SH03-00009369 | D15: Issue | E15: Completed | F15: SO03-00009398 | G15: 03-00000010 | H15: Noble Vaping | I15: ARVATO-BI | J15: EA | K15: 16 | L15: 16 | M15: =VLOOKUP(A15,'Item Master'!$A:$D,4,0) -> Acc | N15: =IFERROR((VLOOKUP(M15,'UK Freight Rate'!$B$4:$C$8,2,0)*L15),0) -> 3.0410848
A16: J1A2255 | B16: BO | C16: SH03-00009379 | D16: Issue | E16: Completed | F16: SO03-00009408 | G16: 03-00000083 | H16: Vapeliqs Ltd (T/A Vape&Bean) | I16: ARVATO-BI | J16: EA | K16: 8 | L16: 8 | M16: =VLOOKUP(A16,'Item Master'!$A:$D,4,0) -> Acc | N16: =IFERROR((VLOOKUP(M16,'UK Freight Rate'!$B$4:$C$8,2,0)*L16),0) -> 1.5205424
A17: J1A2255 | B17: BO | C17: SH03-00009382 | D17: Issue | E17: Completed | F17: SO03-00009411 | G17: 03-00000038 | H17: Vapourcore | I17: ARVATO-BI | J17: EA | K17: 48 | L17: 48 | M17: =VLOOKUP(A17,'Item Master'!$A:$D,4,0) -> Acc | N17: =IFERROR((VLOOKUP(M17,'UK Freight Rate'!$B$4:$C$8,2,0)*L17),0) -> 9.1232545
A18: J1A2255 | B18: BO | C18: SH03-00009383 | D18: Issue | E18: Completed | F18: SO03-00009412 | G18: 03-00000009 | H18: House of Vapes | I18: ARVATO-BI | J18: EA | K18: 48 | L18: 48 | M18: =VLOOKUP(A18,'Item Master'!$A:$D,4,0) -> Acc | N18: =IFERROR((VLOOKUP(M18,'UK Freight Rate'!$B$4:$C$8,2,0)*L18),0) -> 9.1232545
... A3030: MKT2222 | B3030: IO | C3030: SH03-00009925 | D3030: Issue | E3030: Completed | F3030: SO03-00009950 | G3030: 03-00000147 | H3030: the beautifull news | I3030: ARVATO-BI | J3030: EA | K3030: 1 | L3030: 1 | M3030: =VLOOKUP(A3030,'Item Master'!$A:$D,4,0) -> Expense | N3030: =IFERROR((VLOOKUP(M3030,'UK Freight Rate'!$B$4:$C$8,2,0)*L3030),0) -> 0

Sheet ACM Shipments
B1: Shipment Details by Inventory Item | G1: Start Date: | H1: 43374 | K1: Page: | L1: 1 of 70 | N1: Original Data
B2: Company: | C2: JuulUK | G2: End Date: | H2: 43404 | K2: Date: | L2: 43404.871
B3: User: | C3: Karen.Fu
B5: Inventory ID | D5: Item Description | H5: Subitem
A6: =VLOOKUP(B6,B:C,2,FALSE) -> 0 | B6: J1A2255 | D6: JUUL UK USB Charger
A7: Inventory ID | B7: Type | C7: Ref. Nbr. | D7: Operation | E7: Order Status | F7: Order Number | G7: Customer ID | H7: Customer Name | I7: Warehouse | J7: UOM | K7: Order Qty. | L7: Shipped Qty.
A8: =IF(B8="","",IF(B7="Type",B6,A7)) -> J1A2255 | B8: BO | C8: SH03-00009325 | D8: Issue | E8: Completed | F8: SO03-00009352 | G8: 03-00000082 | H8: Violet's Vapes Ltd | I8: ARVATO-BI | J8: EA | K8: 8 | L8: 8
A9: =IF(B9="","",IF(B8="Type",B7,A8)) -> J1A2255 | B9: BO | C9: SH03-00009328 | D9: Issue | E9: Completed | F9: SO03-00009355 | G9: 03-00000096 | H9: Magnum News | I9: ARVATO-BI | J9: EA | K9: 8 | L9: 8
A10: =IF(B10="","",IF(B9="Type",B8,A9)) -> J1A2255 | B10: BO | C10: SH03-00009330 | D10: Issue | E10: Completed | F10: SO03-00009357 | G10: 03-00000024 | H10: INTERNET EXPRESS UK LTD | I10: ARVATO-BI | J10: EA | K10: 16 | L10: 16
A11: =IF(B11="","",IF(B10="Type",B9,A10)) -> J1A2255 | B11: BO | C11: SH03-00009336 | D11: Issue | E11: Completed | F11: SO03-00009364 | G11: 03-00000031 | H11: Hyde Vapes Ltd | I11: ARVATO-BI | J11: EA | K11: 8 | L11: 8
A12: =IF(B12="","",IF(B11="Type",B10,A11)) -> J1A2255 | B12: BO | C12: SH03-00009346 | D12: Issue | E12: Completed | F12: SO03-00009376 | G12: 03-00000033 | H12: Shisha Vibe | I12: ARVATO-BI | J12: EA | K12: 8 | L12: 8
A13: =IF(B13="","",IF(B12="Type",B11,A12)) -> J1A2255 | B13: BO | C13: SH03-00009348 | D13: Issue | E13: Completed | F13: SO03-00009377 | G13: 03-00000060 | H13: EZ Homeware t/a EZ Cloudz | I13: ARVATO-BI | J13: EA | K13: 8 | L13: 8
A14: =IF(B14="","",IF(B13="Type",B12,A13)) -> J1A2255 | B14: BO | C14: SH03-00009356 | D14: Issue | E14: Completed | F14: SO03-00009385 | G14: 03-00000036 | H14: primary keys ltd | I14: ARVATO-BI | J14: EA | K14: 8 | L14: 8
A15: =IF(B15="","",IF(B14="Type",B13,A14)) -> J1A2255 | B15: BO | C15: SH03-00009365 | D15: Issue | E15: Completed | F15: SO03-00009394 | G15: 03-00000112 | H15: Manchestervapeman LTD | I15: ARVATO-BI | J15: EA | K15: 8 | L15: 8
A16: =IF(B16="","",IF(B15="Type",B14,A15)) -> J1A2255 | B16: BO | C16: SH03-00009369 | D16: Issue | E16: Completed | F16: SO03-00009398 | G16: 03-00000010 | H16: Noble Vaping | I16: ARVATO-BI | J16: EA | K16: 16 | L16: 16
A17: =IF(B17="","",IF(B16="Type",B15,A16)) -> J1A2255 | B17: BO | C17: SH03-00009379 | D17: Issue | E17: Completed | F17: SO03-00009408 | G17: 03-00000083 | H17: Vapeliqs Ltd (T/A Vape&Bean) | I17: ARVATO-BI | J17: EA | K17: 8 | L17: 8
A18: =IF(B18="","",IF(B17="Type",B16,A17)) -> J1A2255 | B18: BO | C18: SH03-00009382 | D18: Issue | E18: Completed | F18: SO03-00009411 | G18: 03-00000038 | H18: Vapourcore | I18: ARVATO-BI | J18: EA | K18: 48 | L18: 48
A19: =IF(B19="","",IF(B18="Type",B17,A18)) -> J1A2255 | B19: BO | C19: SH03-00009383 | D19: Issue | E19: Completed | F19: SO03-00009412 | G19: 03-00000009 | H19: House of Vapes | I19: ARVATO-BI | J19: EA | K19: 48 | L19: 48
... A166: =IF(B166="","",IF(B165="Type",B164,A165)) -> J1A2255 | B166: IO | C166: SH03-00009897 | D166: Issue | E166: Completed | F166: SO03-00009921 | G166: 03-00000004 | H166: Juul Labs UK | I166: ARVATO-BI | J166: EA | K166: 3 | L166: 3
A167: =IF(B167="","",IF(B166="Type",B165,A166)) | J167: Total: | K167: 6523 | L167: 6523
A168: =IF(B168="","",IF(B167="Type",B166,A167))
A169: =IF(B169="","",IF(B168="Type",B167,A168)) | B169: J1D2295 | D169: JUUL UK Starter Kit, 1.7%, 4 pods
A170: =IF(B170="","",IF(B169="Type",B168,A169)) | B170: Type | C170: Ref. Nbr. | D170: Operation | E170: Order Status | F170: Order Number | G170: Customer ID | H170: Customer Name | I170: Warehouse | J170: UOM | K170: Order Qty. | L170: Shipped Qty.
A171: =IF(B171="","",IF(B170="Type",B169,A170)) -> J1D2295 | B171: BO | C171: SH03-00009470 | D171: Issue | E171: Completed | F171: SO03-00008944 | G171: 03-00000070 | H171: Juice Sauz Ltd | I171: ARVATO-BI | J171: EA | K171: 100 | L171: 6
A172: =IF(B172="","",IF(B171="Type",B170,A171)) -> J1D2295 | B172: BO | C172: SH03-00009313 | D172: Issue | E172: Completed | F172: SO03-00009344 | G172: 03-00000009 | H172: House of Vapes | I172: ARVATO-BI | J172: EA | K172: 336 | L172: 336
A173: =IF(B173="","",IF(B172="Type",B171,A172)) -> J1D2295 | B173: BO | C173: SH03-00009312 | D173: Issue | E173: Completed | F173: SO03-00009345 | G173: 03-00000095 | H173: Root vapes | I173: ARVATO-BI | J173: EA | K173: 16 | L173: 16
A174: =IF(B174="","",IF(B173="Type",B172,A173)) -> J1D2295 | B174: BO | C174: SH03-00009314 | D174: Issue | E174: Completed | F174: SO03-00009346 | G174: 03-00000110 | H174: Mr Ecig | I174: ARVATO-BI | J174: EA | K174: 4 | L174: 4
A175: =IF(B175="","",IF(B174="Type",B173,A174)) -> J1D2295 | B175: BO | C175: SH03-00009315 | D175: Issue | E175: Completed | F175: SO03-00009347 | G175: 03-00000091 | H175: Gold Vape London | I175: ARVATO-BI | J175: EA | K175: 8 | L175: 8
A176: =IF(B176="","",IF(B175="Type",B174,A175)) -> J1D2295 | B176: BO | C176: SH03-00009316 | D176: Issue | E176: Completed | F176: SO03-00009348 | G176: 03-00000049 | H176: city confectionery ltd | I176: ARVATO-BI | J176: EA | K176: 8 | L176: 8
A177: =IF(B177="","",IF(B176="Type",B175,A176)) -> J1D2295 | B177: BO | C177: SH03-00009317 | D177: Issue | E177: Completed | F177: SO03-00009349 | G177: 03-00000021 | H177: Easy Tek LTD t/a Vape Superstore | I177: ARVATO-BI | J177: EA | K177: 72 | L177: 72
A178: =IF(B178="","",IF(B177="Type",B176,A177)) -> J1D2295 | B178: BO | C178: SH03-00009318 | D178: Issue | E178: Completed | F178: SO03-00009350 | G178: 03-00000021 | H178: Easy Tek LTD t/a Vape Superstore | I178: ARVATO-BI | J178: EA | K178: 24 | L178: 24
A179: =IF(B179="","",IF(B178="Type",B177,A178)) -> J1D2295 | B179: BO | C179: SH03-00009325 | D179: Issue | E179: Completed | F179: SO03-00009352 | G179: 03-00000082 | H179: Violet's Vapes Ltd | I179: ARVATO-BI | J179: EA | K179: 8 | L179: 8
A180: =IF(B180="","",IF(B179="Type",B178,A179)) -> J1D2295 | B180: BO | C180: SH03-00009326 | D180: Issue | E180: Completed | F180: SO03-00009353 | G180: 03-00000029 | H180: Hasumati UK Limited | I180: ARVATO-BI | J180: EA | K180: 8 | L180: 8
A181: =IF(B181="","",IF(B180="Type",B179,A180)) -> J1D2295 | B181: BO | C181: SH03-00009329 | D181: Issue | E181: Completed | F181: SO03-00009356 | G181: 03-00000032 | H181: Warwickshire Vape Ltd | I181: ARVATO-BI | J181: EA | K181: 24 | L181: 24
A182: =IF(B182="","",IF(B181="Type",B180,A181)) -> J1D2295 | B182: BO | C182: SH03-00009330 | D182: Issue | E182: Completed | F182: SO03-00009357 | G182: 03-00000024 | H182: INTERNET EXPRESS UK LTD | I182: ARVATO-BI | J182: EA | K182: 40 | L182: 40
... A671: =IF(B671="","",IF(B670="Type",B669,A670)) -> J1D2295 | B671: IO | C671: SH03-00009950 | D671: Issue | E671: Completed | F671: SO03-00009976 | G671: 03-00000178 | H671: online vapour ltd | I671: ARVATO-BI | J671: EA | K671: 4 | L671: 4
A672: =IF(B672="","",IF(B671="Type",B670,A671)) | J672: Total: | K672: 47906 | L672: 47812
A673: =IF(B673="","",IF(B672="Type",B671,A672))
A674: =IF(B674="","",IF(B673="Type",B672,A673)) | B674: J1D2349 | D674: JUUL UK Device Kit
A675: =IF(B675="","",IF(B674="Type",B673,A674)) | B675: Type | C675: Ref. Nbr. | D675: Operation | E675: Order Status | F675: Order Number | G675: Customer ID | H675: Customer Name | I675: Warehouse | J675: UOM | K675: Order Qty. | L675: Shipped Qty.
...

Sheet Shipments UK_Raw Data
A1: Shipment Details by Inventory Item | F1: Start Date: | G1: 43344 | J1: Page: | K1: 1 of 66
A2: Company: | B2: JuulUK | F2: End Date: | G2: 43371 | J2: Date: | K2: 43371.707 | M2: Original Data
A3: User: | B3: Karen.Fu
A5: Inventory ID | C5: Item Description | G5: Subitem
A6: J1A2255 | C6: JUUL UK USB Charger
A7: Type | B7: Ref. Nbr. | C7: Operation | D7: Order Status | E7: Order Number | F7: Customer ID | G7: Customer Name | H7: Warehouse | I7: UOM | J7: Order Qty. | K7: Shipped Qty.
A8: BO | B8: SH03-00008146 | C8: Issue | D8: Completed | E8: SO03-00008191 | F8: 03-00000009 | G8: House of Vapes | H8: ARVATO-BI | I8: EA | J8: 24 | K8: 24
A9: BO | B9: SH03-00008644 | C9: Issue | D9: Completed | E9: SO03-00008686 | F9: 03-00000038 | G9: Vapourcore | H9: ARVATO-BI | I9: EA | J9: 24 | K9: 24
A10: BO | B10: SH03-00008647 | C10: Issue | D10: Completed | E10: SO03-00008689 | F10: 03-00000011 | G10: The London Vape Co | H10: ARVATO-BI | I10: EA | J10: 48 | K10: 48
A11: BO | B11: SH03-00008901 | C11: Issue | D11: Completed | E11: SO03-00008943 | F11: 03-00000029 | G11: Hasumati UK Limited | H11: ARVATO-BI | I11: EA | J11: 8 | K11: 8
A12: BO | B12: SH03-00008910 | C12: Issue | D12: Completed | E12: SO03-00008952 | F12: 03-00000072 | G12: Partica Kingston LTD trading as Vape Lords | H12: ARVATO-BI | I12: EA | J12: 8 | K12: 8
A13: BO | B13: SH03-00008911 | C13: Issue | D13: Completed | E13: SO03-00008953 | F13: 03-00000010 | G13: Noble Vaping | H13: ARVATO-BI | I13: EA | J13: 8 | K13: 8
A14: BO | B14: SH03-00008915 | C14: Issue | D14: Completed | E14: SO03-00008958 | F14: 03-00000047 | G14: Smk Vapes ltd Trading as Smokium | H14: ARVATO-BI | I14: EA | J14: 8 | K14: 8
A15: BO | B15: SH03-00008916 | C15: Issue | D15: Completed | E15: SO03-00008959 | F15: 03-00000073 | G15: Vape Club Ltd | H15: ARVATO-BI | I15: EA | J15: 80 | K15: 80
A16: BO | B16: SH03-00008923 | C16: Issue | D16: Completed | E16: SO03-00008966 | F16: 03-00000074 | G16: V & M (Teddington) Ltd | H16: ARVATO-BI | I16: EA | J16: 8 | K16: 8
A17: BO | B17: SH03-00008924 | C17: Issue | D17: Completed | E17: SO03-00008967 | F17: 03-00000075 | G17: Mobivape Worcester LTD | H17: ARVATO-BI | I17: EA | J17: 8 | K17: 8
A18: BO | B18: SH03-00008926 | C18: Issue | D18: Completed | E18: SO03-00008969 | F18: 03-00000048 | G18: The Eagle Vape Shop (Saras Fix Ltd) | H18: ARVATO-BI | I18: EA | J18: 8 | K18: 8
A19: BO | B19: SH03-00008928 | C19: Issue | D19: Completed | E19: SO03-00008970 | F19: 03-00000076 | G19: Vape Industries Ltd | H19: ARVATO-BI | I19: EA | J19: 8 | K19: 8
... A125: SO | B125: SH03-00008880 | C125: Issue | D125: Completed | E125: SO03-00008914 | F125: 03-00000016 | G125: JUUL UK B2C | H125: ARVATO-BI | I125: EA | J125: 2 | K125: 2
I126: Total: | J126: 1700 | K126: 1700
A128: J1D2295 | C128: JUUL UK Starter Kit, 1.7%, 4 pods
A129: Type | B129: Ref. Nbr. | C129: Operation | D129: Order Status | E129: Order Number | F129: Customer ID | G129: Customer Name | H129: Warehouse | I129: UOM | J129: Order Qty. | K129: Shipped Qty.
A130: BO | B130: SH03-00008144 | C130: Issue | D130: Completed | E130: SO03-00008189 | F130: 03-00000067 | G130: LUCID JUICES VAPE STORE | H130: ARVATO-BI | I130: EA | J130: 4 | K130: 4
A131: BO | B131: SH03-00008145 | C131: Issue | D131: Completed | E131: SO03-00008190 | F131: 03-00000068 | G131: VAPERS BOX LTD | H131: ARVATO-BI | I131: EA | J131: 24 | K131: 24
A132: BO | B132: SH03-00008146 | C132: Issue | D132: Completed | E132: SO03-00008191 | F132: 03-00000009 | G132: House of Vapes | H132: ARVATO-BI | I132: EA | J132: 48 | K132: 48
A133: BO | B133: SH03-00008147 | C133: Issue | D133: Completed | E133: SO03-00008192 | F133: 03-00000057 | G133: Vape Terrace limited | H133: ARVATO-BI | I133: EA | J133: 4 | K133: 4
A134: BO | B134: SH03-00008643 | C134: Issue | D134: Completed | E134: SO03-00008685 | F134: 03-00000017 | G134: James J Fox | H134: ARVATO-BI | I134: EA | J134: 80 | K134: 80
A135: BO | B135: SH03-00008644 | C135: Issue | D135: Completed | E135: SO03-00008686 | F135: 03-00000038 | G135: Vapourcore | H135: ARVATO-BI | I135: EA | J135: 144 | K135: 144
A136: BO | B136: SH03-00008645 | C136: Issue | D136: Completed | E136: SO03-00008687 | F136: 03-00000013 | G136: Evapo Ltd | H136: ARVATO-BI | I136: EA | J136: 408 | K136: 408
A137: BO | B137: SH03-00008646 | C137: Issue | D137: Completed | E137: SO03-00008688 | F137: 03-00000036 | G137: primary keys ltd | H137: ARVATO-BI | I137: EA | J137: 8 | K137: 8
A138: BO | B138: SH03-00008647 | C138: Issue | D138: Completed | E138: SO03-00008689 | F138: 03-00000011 | G138: The London Vape Co | H138: ARVATO-BI | I138: EA | J138: 48 | K138: 48
A139: BO | B139: SH03-00008906 | C139: Issue | D139: Back Order | E139: SO03-00008944 | F139: 03-00000070 | G139: Juice Sauz Ltd | H139: ARVATO-BI | I139: EA | J139: 100 | K139: 94
A140: BO | B140: SH03-00008907 | C140: Issue | D140: Completed | E140: SO03-00008949 | F140: 03-00000034 | G140: els (bromley) ltd | H140: ARVATO-BI | I140: EA | J140: 20 | K140: 20
A141: BO | B141: SH03-00008908 | C141: Issue | D141: Completed | E141: SO03-00008950 | F141: 03-00000071 | G141: Flamenco Ninja LTD | H141: ARVATO-BI | I141: EA | J141: 4 | K141: 4
... A808: SO | B808: SH03-00008892 | C808: Issue | D808: Completed | E808: SO03-00008926 | F808: 03-00000016 | G808: JUUL UK B2C | H808: ARVATO-BI | I808: EA | J808: 1 | K808: 1
I809: Total: | J809: 11936 | K809: 11930
A811: J1D2349 | C811: JUUL UK Device Kit
A812: Type | B812: Ref. Nbr. | C812: Operation | D812: Order Status | E812: Order Number | F812: Customer ID | G812: Customer Name | H812: Warehouse | I812: UOM | J812: Order Qty. | K812: Shipped Qty.
A813: BO | B813: SH03-00008146 | C813: Issue | D813: Completed | E813: SO03-00008191 | F813: 03-00000009 | G813: House of Vapes | H813: ARVATO-BI | I813: EA | J813: 24 | K813: 24
A814: BO | B814: SH03-00008644 | C814: Issue | D814: Completed | E814: SO03-00008686 | F814: 03-00000038 | G814: Vapourcore | H814: ARVATO-BI | I814: EA | J814: 144 | K814: 144
...

Sheet Item Master
A1: Title: | B1: Katie - Item Record
A2: Company: | B2: Juul
A3: Date: | B3: 18 Oct 2018 10:15 AM GMT-08:00
C4: Manual Imput
A5: Item Code | B5: Status | C5: Clasification | D5: Inv Type | E5: Description | F5: Item Class | G5: Item Type | H5: Kit? | I5: Valuation Method | J5: Tax Category | K5: Post Class ID | L5: Lot / Serial Class | M5: Inventory Account | N5: Inventory Sub | O5: Expense Account | P5: Expense Sub | Q5: Sales Account | R5: Sales Sub ID | S5: PO Accrual Account | T5: PO Accrual Sub | U5: PPV Account | V5: PPV Sub ID | W5: Landed Cost V Account | X5: Landed Cost V Sub
A6: 1883 | B6: Active | C6: FG | D6: RK | E6: JUUL pod Tobacco 0% 2.8ml 4-pack | F6: J1C | G6: Finished Good | H6: False | I6: FIFO | J6: TAXABLE | K6: JUL | L6: LOTCONTROL | M6: 141000 | N6: HCORP-CRP-6000-JUL | O6: 511000 | P6: HCORP-CRP-4100-JUL | Q6: 410000 | R6: HCORP-CRP-4100-JUL | S6: 200100 | T6: HCORP-CRP-4100-JUL | U6: 514000 | V6: HCORP-CRP-4100-JUL | W6: 513000 | X6: HCORP-CRP-4600-CRP
A7: 35411 | B7: Active | C7: RM | D7: Pkg | E7: Bemis Top Lid | F7: INV ITEM | G7: Finished Good | H7: False | I7: FIFO | J7: TAXABLE | K7: CORP | L7: NOTTRACKED | M7: 140100 | N7: HCORP-CRP-6000-CRP | O7: 511000 | P7: HCORP-CRP-4100-CRP | Q7: 410000 | R7: HCORP-CRP-4100-CRP | S7: 200100 | T7: HCORP-CRP-4100-CRP | U7: 514000 | V7: HCORP-CRP-4600-JUL
A8: 175-00014 | B8: Active | C8: RM | D8: PCB | E8: J1 Flex PCB | F8: COMPONENTS | G8: Component Part | H8: False | I8: FIFO | J8: TAXABLE | K8: JUUL COM | L8: NOTTRACKED | M8: 143000 | N8: HCORP-CRP-6000-JUL | O8: 143000 | P8: HCORP-CRP-4100-JUL | Q8: 143000 | R8: HCORP-CRP-6000-JUL | S8: 200100 | T8: HCORP-CRP-6000-JUL | U8: 514000 | V8: HCORP-CRP-6000-JUL | W8: 514000 | X8: HCORP-CRP-6000-JUL
A9: 190-00001 | B9: Active | C9: RM | D9: Sensor | E9: Pressure Sensor_P/N TNM-15XXP-12-R | F9: COMPONENTS | G9: Component Part | H9: False | I9: FIFO | J9: TAXABLE | K9: JUUL COM | L9: NOTTRACKED | M9: 140100 | N9: HCORP-CRP-6000-JUL | O9: 140100 | P9: HCORP-CRP-4100-JUL | Q9: 140100 | R9: HCORP-CRP-6000-JUL | S9: 200100 | T9: HCORP-CRP-6000-JUL | U9: 140100 | V9: HCORP-CRP-6000-JUL | W9: 140100 | X9: HCORP-CRP-6000-JUL
A10: 190-00004 | B10: Active | C10: RM | D10: Sensor | E10: Pressure Sensor_MS583702BA01-50 | F10: COMPONENTS | G10: Component Part | H10: False | I10: FIFO | J10: TAXABLE | K10: JUUL COM | L10: NOTTRACKED | M10: 140100 | N10: HCORP-CRP-6000-JUL | O10: 143000 | P10: HCORP-CRP-4100-JUL | Q10: 143000 | R10: HCORP-CRP-6000-JUL | S10: 200100 | T10: HCORP-CRP-6000-JUL | U10: 514000 | V10: HCORP-CRP-6000-JUL | W10: 514000 | X10: HCORP-CRP-6000-JUL
A11: 310-00010 | B11: Active | C11: RM | D11: Coil | E11: Raw Material - Pod Coil | F11: COMPONENTS | G11: Component Part | H11: False | I11: FIFO | J11: TAXABLE | K11: JUUL COM | L11: NOTTRACKED | M11: 140100 | N11: HCORP-CRP-6000-JUL | O11: 511000 | P11: HCORP-CRP-4100-JUL | Q11: 410000 | R11: HCORP-CRP-4100-JUL | S11: 200100 | T11: HCORP-CRP-6000-JUL | U11: 514000 | V11: HCORP-CRP-6000-JUL
A12: 32901-15 | B12: Active | C12: RM | D12: Sensor | E12: Bemis Bottom Forming Plastic 15 mil | F12: INV ITEM | G12: Finished Good | H12: False | I12: FIFO | J12: TAXABLE | K12: CORP | L12: NOTTRACKED | M12: 140100 | N12: HCORP-CRP-6000-CRP | O12: 511000 | P12: HCORP-CRP-4100-CRP | Q12: 410000 | R12: HCORP-CRP-4100-CRP | S12: 200100 | T12: HCORP-CRP-4100-CRP | U12: 514000 | V12: HCORP-CRP-4600-JUL
A13: 345-00001-001 | B13: Active | C13: RM | D13: Liquid | E13: PL2520267E-5G Cool Mint 5% | F13: INV ITEM | G13: Component Part | H13: False | I13: FIFO | J13: TAXABLE | K13: JUUL COM | L13: NOTTRACKED | M13: 140100 | N13: HCORP-CRP-6000-JUL | O13: 511000 | P13: HCORP-CRP-4100-JUL | Q13: 410000 | R13: HCORP-CRP-4100-JUL | S13: 200100 | T13: HCORP-CRP-4100-JUL | U13: 514000 | V13: HCORP-CRP-4600-JUL
A14: 345-00002-001 | B14: Active | C14: RM | D14: Liquid | E14: PL2520538E-5G Crème Brulee 5% | F14: INV ITEM | G14: Component Part | H14: False | I14: FIFO | J14: TAXABLE | K14: JUUL COM | L14: NOTTRACKED | M14: 140100 | N14: HCORP-CRP-6000-JUL | O14: 511000 | P14: HCORP-CRP-4100-JUL | Q14: 410000 | R14: HCORP-CRP-4100-JUL | S14: 200100 | T14: HCORP-CRP-4100-JUL | U14: 514000 | V14: HCORP-CRP-4600-JUL
A15: 345-00003-001 | B15: Active | C15: RM | D15: Liquid | E15: PL2520543E-5G Fruit Medley 5% | F15: INV ITEM | G15: Finished Good | H15: False | I15: FIFO | J15: TAXABLE | K15: CORP | L15: NOTTRACKED | M15: 140100 | N15: HCORP-CRP-6000-CRP | O15: 511000 | P15: HCORP-CRP-4100-CRP | Q15: 410000 | R15: HCORP-CRP-4100-CRP | S15: 200100 | T15: HCORP-CRP-4100-CRP | U15: 514000 | V15: HCORP-CRP-4600-JUL
A16: 345-00004-001 | B16: Active | C16: RM | D16: Liquid | E16: PL2520542E-5G Virginia Tobacco 5% | F16: INV ITEM | G16: Component Part | H16: False | I16: FIFO | J16: TAXABLE | K16: JUUL COM | L16: NOTTRACKED | M16: 140100 | N16: HCORP-CRP-6000-JUL | O16: 511000 | P16: HCORP-CRP-4100-JUL | Q16: 410000 | R16: HCORP-CRP-4100-JUL | S16: 200100 | T16: HCORP-CRP-4100-JUL | U16: 514000 | V16: HCORP-CRP-4600-JUL
A17: 345-00005-001 | B17: Active | C17: RM | D17: Liquid | E17: PL2520357E-5G Mango 5% | F17: INV ITEM | G17: Component Part | H17: False | I17: FIFO | J17: TAXABLE | K17: JUUL COM | L17: NOTTRACKED | M17: 140100 | N17: HCORP-CRP-6000-JUL | O17: 511000 | P17: HCORP-CRP-4100-JUL | Q17: 410000 | R17: HCORP-CRP-4100-JUL | S17: 200100 | T17: HCORP-CRP-4600-JUL | U17: 514000 | V17: HCORP-CRP-4600-JUL
A18: 345-00006-001 | B18: Active | C18: RM | D18: Liquid | E18: Classic Tobacco 5% | F18: INV ITEM | G18: Finished Good | H18: False | I18: FIFO | J18: EXEMPT | K18: NSK ITEMS | L18: NOTTRACKED | M18: 140100 | N18: HCORP-CRP-6000-JUL | O18: 140100 | P18: HCORP-CRP-6000-JUL | Q18: 140100 | R18: HCORP-CRP-6000-JUL | S18: 200100 | T18: HCORP-CRP-6000-JUL | U18: 140100 | V18: HCORP-CRP-6000-JUL | W18: 513000 | X18: HCORP-CRP-5100-CRP
A19: 345-00007-001 | B19: Active | C19: RM | D19: Liquid | E19: Classic Menthol 5% | F19: INV ITEM | G19: Finished Good | H19: False | I19: FIFO | J19: EXEMPT | K19: NSK ITEMS | L19: NOTTRACKED | M19: 140100 | N19: HCORP-CRP-6000-JUL | O19: 140100 | P19: HCORP-CRP-6000-JUL | Q19: 140100 | R19: HCORP-CRP-6000-JUL | S19: 200100 | T19: HCORP-CRP-6000-JUL | U19: 140100 | V19: HCORP-CRP-6000-JUL | W19: 513000 | X19: HCORP-CRP-5100-CRP
A20: 345-00008-001 | B20: Active | C20: RM | D20: Liquid | E20: Lemon Tart (Poppyseed) 5% | F20: INV ITEM | G20: Finished Good | H20: False | I20: FIFO | J20: EXEMPT | K20: NSK ITEMS | L20: NOTTRACKED | M20: 140100 | N20: HCORP-CRP-6000-JUL | O20: 140100 | P20: HCORP-CRP-6000-JUL | Q20: 140100 | R20: HCORP-CRP-6000-JUL | S20: 200100 | T20: HCORP-CRP-6000-JUL | U20: 140100 | V20: HCORP-CRP-6000-JUL | W20: 513000 | X20: HCORP-CRP-5100-CRP
A21: 345-00009-001 | B21: Active | C21: RM | D21: Liquid | E21: E-LIQUID, MIMOSA, 5.0% | F21: INV ITEM | G21: Component Part | H21: False | I21: FIFO | J21: TAXABLE | K21: CORP | L21: NOTTRACKED | M21: 140100 | N21: HCORP-CRP-6000-JUL | O21: 143000 | P21: HCORP-CRP-6000-JUL | Q21: 143000 | R21: HCORP-CRP-6000-JUL | S21: 200100 | T21: HCORP-CRP-6000-JUL | U21: 514000 | V21: HCORP-CRP-4600-JUL
A22: 345-00010-001 | B22: Active | C22: RM | D22: Liquid | E22: PL2620375E-5G Cool Cucumber 5% | F22: INV ITEM | G22: Finished Good | H22: False | I22: FIFO | J22: TAXABLE | K22: CORP | L22: NOTTRACKED | M22: 140100 | N22: HCORP-CRP-6000-CRP | O22: 511000 | P22: HCORP-CRP-4100-CRP | Q22: 410000 | R22: HCORP-CRP-4100-CRP | S22: 200100 | T22: HCORP-CRP-4100-CRP | U22: 514000 | V22: HCORP-CRP-4600-JUL
A23: 345-00016-001 | B23: Active | C23: RM | D23: Liquid | E23: Creme Brulee 3% E-Liquid PL2521394E | F23: INV ITEM | G23: Finished Good | H23: False | I23: FIFO | J23: EXEMPT | K23: NSK ITEMS | L23: NOTTRACKED | M23: 140100 | N23: HCORP-CRP-6000-JUL | O23: 140100 | P23: HCORP-CRP-6000-JUL | Q23: 140100 | R23: HCORP-CRP-6000-JUL | S23: 200100 | T23: HCORP-CRP-6000-JUL | U23: 140100 | V23: HCORP-CRP-6000-JUL | W23: 513000 | X23: HCORP-CRP-5100-CRP
A24: 345-00017-001 | B24: Active | C24: RM | D24: Liquid | E24: Fruit Medley 3% E-Liquid PL2521391E | F24: INV ITEM | G24: Finished Good | H24: False | I24: FIFO | J24: EXEMPT | K24: NSK ITEMS | L24: NOTTRACKED | M24: 140100 | N24: HCORP-CRP-6000-JUL | O24: 140100 | P24: HCORP-CRP-6000-JUL | Q24: 140100 | R24: HCORP-CRP-6000-JUL | S24: 200100 | T24: HCORP-CRP-6000-JUL | U24: 140100 | V24: HCORP-CRP-6000-JUL | W24: 513000 | X24: HCORP-CRP-5100-CRP
A25: 345-00018-001 | B25: Active | C25: RM | D25: Liquid | E25: E-LIQUID, COOL MINT, 3% | F25: INV ITEM | G25: Finished Good | H25: False | I25: FIFO | J25: TAXABLE | K25: CORP | L25: NOTTRACKED | M25: 140100 | N25: HCORP-CRP-6000-JUL | O25: 143000 | P25: HCORP-CRP-6000-JUL | Q25: 143000 | R25: HCORP-CRP-6000-JUL | S25: 200100 | T25: HCORP-CRP-6000-JUL | U25: 514000 | V25: HCORP-CRP-4600-JUL
A26: 345-00019-001 | B26: Active | C26: RM | D26: Liquid | E26: E-LIQUID, VIRGINIA TOBACCO, 3% | F26: INV ITEM | G26: Finished Good | H26: False | I26: FIFO | J26: TAXABLE | K26: CORP | L26: NOTTRACKED | M26: 140100 | N26: HCORP-CRP-6000-JUL | O26: 143000 | P26: HCORP-CRP-6000-JUL | Q26: 143000 | R26: HCORP-CRP-6000-JUL | S26: 200100 | T26: HCORP-CRP-6000-JUL | U26: 514000 | V26: HCORP-CRP-4600-JUL
A27: 345-00020-001 | B27: Active | C27: RM | D27: Liquid | E27: Mango 3% E-Liquid PL2520358E | F27: INV ITEM | G27: Finished Good | H27: False | I27: FIFO | J27: EXEMPT | K27: NSK ITEMS | L27: NOTTRACKED | M27: 140100 | N27: HCORP-CRP-6000-JUL | O27: 140100 | P27: HCORP-CRP-6000-JUL | Q27: 140100 | R27: HCORP-CRP-6000-JUL | S27: 200100 | T27: HCORP-CRP-6000-JUL | U27: 140100 | V27: HCORP-CRP-6000-JUL | W27: 513000 | X27: HCORP-CRP-5100-CRP
A28: 345-00026 | B28: Active | C28: RM | D28: Liquid | E28: E-LIQUID, Apple Cran, 5.0% | F28: INV ITEM | G28: Component Part | H28: False | I28: FIFO | J28: TAXABLE | K28: CORP | L28: NOTTRACKED | M28: 140100 | N28: HCORP-CRP-6000-JUL | O28: 143000 | P28: HCORP-CRP-6000-JUL | Q28: 143000 | R28: HCORP-CRP-6000-JUL | S28: 200100 | T28: HCORP-CRP-6000-JUL | U28: 514000 | V28: HCORP-CRP-4600-JUL
A29: 345-00027 | B29: Active | C29: RM | D29: Liquid | E29: E-LIQUID, APPLE CRUMBLE, 5.0% | F29: INV ITEM | G29: Component Part | H29: False | I29: FIFO | J29: TAXABLE | K29: CORP | L29: NOTTRACKED | M29: 140100 | N29: HCORP-CRP-6000-JUL | O29: 143000 | P29: HCORP-CRP-6000-JUL | Q29: 143000 | R29: HCORP-CRP-6000-JUL | S29: 200100 | T29: HCORP-CRP-6000-JUL | U29: 514000 | V29: HCORP-CRP-4600-JUL
A30: 345-00028 | B30: Active | C30: RM | D30: Liquid | E30: TOBACCO MINT 5% E-LIQUID | F30: INV ITEM | G30: Component Part | H30: False | I30: FIFO | J30: TAXABLE | K30: CORP | L30: NOTTRACKED | M30: 140100 | N30: HCORP-CRP-6000-JUL | O30: 143000 | P30: HCORP-CRP-6000-JUL | Q30: 143000 | R30: HCORP-CRP-6000-JUL | S30: 200100 | T30: HCORP-CRP-6000-JUL | U30: 514000 | V30: HCORP-CRP-4600-JUL
A31: 345-00029 | B31: Active | C31: RM | D31: Liquid | E31: Tobacco Mango 5% E-LIQUID | F31: INV ITEM | G31: Component Part | H31: False | I31: FIFO | J31: TAXABLE | K31: CORP | L31: NOTTRACKED | M31: 140100 | N31: HCORP-CRP-6000-JUL | O31: 143000 | P31: HCORP-CRP-6000-JUL | Q31: 143000 | R31: HCORP-CRP-6000-JUL | S31: 200100 | T31: HCORP-CRP-6000-JUL | U31: 514000 | V31: HCORP-CRP-4600-JUL
A32: 345-00030 | B32: Active | C32: RM | D32: Liquid | E32: Tobacco COOKIE & CREAM 5% E-LIQUID | F32: INV ITEM | G32: Component Part | H32: False | I32: FIFO | J32: TAXABLE | K32: CORP | L32: NOTTRACKED | M32: 140100 | N32: HCORP-CRP-6000-JUL | O32: 143000 | P32: HCORP-CRP-6000-JUL | Q32: 143000 | R32: HCORP-CRP-6000-JUL | S32: 200100 | T32: HCORP-CRP-6000-JUL | U32: 514000 | V32: HCORP-CRP-4600-JUL
A33: 345-00031 | B33: Active | C33: RM | D33: Liquid | E33: Tobacco GREEN APPLE 5% E-LIQUID | F33: INV ITEM | G33: Component Part | H33: False | I33: FIFO | J33: TAXABLE | K33: CORP | L33: NOTTRACKED | M33: 140100 | N33: HCORP-CRP-6000-JUL | O33: 143000 | P33: HCORP-CRP-6000-JUL | Q33: 143000 | R33: HCORP-CRP-6000-JUL | S33: 200100 | T33: HCORP-CRP-6000-JUL | U33: 514000 | V33: HCORP-CRP-4600-JUL
A34: 345-00032 | B34: Active | C34: RM | D34: Liquid | E34: TOBACCO STRAWBERRY 5% E-LIQUID | F34: INV ITEM | G34: Component Part | H34: False | I34: FIFO | J34: TAXABLE | K34: CORP | L34: NOTTRACKED | M34: 140100 | N34: HCORP-CRP-6000-JUL | O34: 143000 | P34: HCORP-CRP-6000-JUL | Q34: 143000 | R34: HCORP-CRP-6000-JUL | S34: 200100 | T34: HCORP-CRP-6000-JUL | U34: 514000 | V34: HCORP-CRP-4600-JUL
A35: 345-00033 | B35: Active | C35: RM | D35: Liquid | E35: E-LIQUID, GINGER PEACH, 5.0% | F35: INV ITEM | G35: Component Part | H35: False | I35: FIFO | J35: TAXABLE | K35: CORP | L35: NOTTRACKED | M35: 140100 | N35: HCORP-CRP-6000-JUL | O35: 143000 | P35: HCORP-CRP-6000-JUL | Q35: 143000 | R35: HCORP-CRP-6000-JUL | S35: 200100 | T35: HCORP-CRP-6000-JUL | U35: 514000 | V35: HCORP-CRP-4600-JUL
A36: 345-00034 | B36: Active | C36: RM | D36: Liquid | E36: E-LIQUID, LEMON TEA, 5.0% | F36: INV ITEM | G36: Component Part | H36: False | I36: FIFO | J36: TAXABLE | K36: CORP | L36: NOTTRACKED | M36: 140100 | N36: HCORP-CRP-6000-JUL | O36: 143000 | P36: HCORP-CRP-6000-JUL | Q36: 143000 | R36: HCORP-CRP-6000-JUL | S36: 200100 | T36: HCORP-CRP-6000-JUL | U36: 514000 | V36: HCORP-CRP-4600-JUL
A37: 345-00035 | B37: Active | C37: RM | D37: Liquid | E37: E-LIQUID, SPICY WATERMELON, 5.0% | F37: INV ITEM | G37: Component Part | H37: False | I37: FIFO | J37: TAXABLE | K37: CORP | L37: NOTTRACKED | M37: 140100 | N37: HCORP-CRP-6000-JUL | O37: 143000 | P37: HCORP-CRP-6000-JUL | Q37: 143000 | R37: HCORP-CRP-6000-JUL | S37: 200100 | T37: HCORP-CRP-6000-JUL | U37: 514000 | V37: HCORP-CRP-4600-JUL
A38: 345-00036 | B38: Active | C38: RM | D38: Liquid | E38: E-LIQUID, Orange Twist (Old Fashioned), 5.0% | F38: INV ITEM | G38: Component Part | H38: False | I38: FIFO | J38: TAXABLE | K38: CORP | L38: NOTTRACKED | M38: 141000 | N38: HCORP-CRP-6000-CRP | O38: 511000 | P38: HCORP-CRP-4100-CRP | Q38: 410000 | R38: HCORP-CRP-4100-CRP | S38: 200100 | T38: HCORP-CRP-4100-CRP
A39: 345-00037 | B39: Active | C39: RM | D39: Liquid | E39: E-LIQUID, CINNAMON SPICE (CINNAMON SNAP), 5.0% | F39: INV ITEM | G39: Component Part | H39: False | I39: FIFO | J39: TAXABLE | K39: CORP | L39: NOTTRACKED | M39: 140100 | N39: HCORP-CRP-6000-JUL | O39: 143000 | P39: HCORP-CRP-6000-JUL | Q39: 143000 | R39: HCORP-CRP-6000-JUL | S39: 200100 | T39: HCORP-CRP-6000-JUL | U39: 514000 | V39: HCORP-CRP-4600-JUL
A40: 345-00038 | B40: Active | C40: RM | D40: Liquid | E40: E-LIQUID, CHAMOMILE TEA, 5.0% | F40: INV ITEM | G40: Component Part | H40: False | I40: FIFO | J40: TAXABLE | K40: CORP | L40: NOTTRACKED | M40: 140100 | N40: HCORP-CRP-6000-JUL | O40: 143000 | P40: HCORP-CRP-6000-JUL | Q40: 143000 | R40: HCORP-CRP-6000-JUL | S40: 200100 | T40: HCORP-CRP-6000-JUL | U40: 514000 | V40: HCORP-CRP-4600-JUL
...

Sheet JNL UK 1
A1: Account | B1: Description | C1: Subaccount | D1: Ref. Number | E1: Quantity | F1: UOM | G1: Debit Amount | H1: Credit Amount | I1: Transaction Description | J1: Reclass. Batch Number
A2: 531000 | B2: Freight Outbound | C2: INTUK-CRP-4600-JUL | D2: ACCR.ARVATO | G2: =193380/1.2*75% -> 120862.5 | I2: ACCR.ARVATO-Oct18 (75% of £160k Inv 94623882)
A3: 220950 | B3: Accrued Freight | C3: INTUK-CRP-4600-JUL | D3: ACCR.ARVATO | H3: =193380/1.2*75% -> 120862.5 | I3: ACCR.ARVATO-Oct18 (75% of £160k Inv 94623882)

Sheet Backup Jnl 1
A1: backup

Sheet JNL UK 2
A1: Account | B1: Description | C1: Subaccount | D1: Ref. Number | E1: Quantity | F1: UOM | G1: Debit Amount | H1: Credit Amount | I1: Transaction Description | J1: Reclass. Batch Number
A2: 531000 | B2: Freight Outbound | C2: INTUK-CRP-4600-JUL | D2: ACCR.ARVATO | G2: =76500+57000 -> 133500 | I2: ACCR>Avarto - Aug 18 & Sept 18
A3: 220950 | B3: Accrued Freight | C3: INTUK-CRP-4600-JUL | D3: ACCR.ARVATO | H3: =G2 -> 133500 | I3: ACCR>Avarto - Aug 18 & Sept 18

Sheet Backup Jnl2
