Workbook
Name EssAliasTable: "Default"
Name EssAliasTable: "Default"
Name EssAliasTable: "Default"
Name EssAliasTable: "Default"
Name EssAliasTable: "Misc Alias"
Name EssLatest: "Oct"
Name EssLatest: "Oct"
Name EssLatest: "Oct"
Name EssLatest: "Oct"
Name EssLatest: "Oct"
Name EssOptions: "A3100000000111000011001100020_08#missing00"
Name EssOptions: "A1100000000110000011001100020_08#missing00"
Name EssOptions: "A1100000000110000011001100020_08#missing00"
Name EssOptions: "A1100000000110000011001100020_08#missing00"
Name EssOptions: "A1100000000111001000001100020_08#missing00"
Name EssSamplingValue: 100
Name EssSamplingValue: 100
Name EssSamplingValue: 100
Name EssSamplingValue: 100
Name EssSamplingValue: 100

Sheet Pharm Demand
A1: Branded Pharmaceuticals
A2: FY13-16 Working Forecast
A3: Outfreight Expense object 7171
C4: NoCustomer | D4: NoCustomer | E4: NoCustomer | F4: NoCustomer | G4: NoCustomer | H4: NoCustomer | I4: NoCustomer | J4: NoCustomer | K4: NoCustomer | L4: NoCustomer | M4: NoCustomer | N4: NoCustomer | O4: NoCustomer | P4: NoCustomer | Q4: NoCustomer | R4: NoCustomer | S4: NoCustomer | T4: NoCustomer | U4: NoCustomer | V4: NoCustomer | W4: NoCustomer | X4: NoCustomer | Y4: NoCustomer | Z4: NoCustomer | AA4: NoCustomer | AB4: NoCustomer | AC4: NoCustomer | AD4: NoCustomer | AE4: NoCustomer | AF4: NoCustomer | AG4: NoCustomer | AH4: NoCustomer | AI4: NoCustomer | AJ4: NoCustomer | AK4: NoCustomer | AL4: NoCustomer | AM4: NoCustomer | AN4: NoCustomer | AO4: NoCustomer | AP4: NoCustomer | AQ4: NoCustomer | AR4: NoCustomer | AS4: NoCustomer | AT4: NoCustomer | AU4: NoCustomer | AV4: NoCustomer | AW4: NoCustomer | AX4: NoCustomer | AY4: NoCustomer | AZ4: NoCustomer | BA4: NoCustomer | BB4: NoCustomer
C5: FY13 Actuals | D5: FY13 Actuals | E5: FY13 Actuals | F5: FY13 Actuals | G5: Working Forecast | H5: Working Forecast | I5: Working Forecast | J5: Working Forecast | K5: Working Forecast | L5: Working Forecast | M5: Working Forecast | N5: Working Forecast | O5: Working Forecast | P5: Working Forecast Y2 | Q5: Working Forecast Y2 | R5: Working Forecast Y2 | S5: Working Forecast Y2 | T5: Working Forecast Y2 | U5: Working Forecast Y2 | V5: Working Forecast Y2 | W5: Working Forecast Y2 | X5: Working Forecast Y2 | Y5: Working Forecast Y2 | Z5: Working Forecast Y2 | AA5: Working Forecast Y2 | AB5: Working Forecast Y2 | AC5: Working Forecast Y3 | AD5: Working Forecast Y3 | AE5: Working Forecast Y3 | AF5: Working Forecast Y3 | AG5: Working Forecast Y3 | AH5: Working Forecast Y3 | AI5: Working Forecast Y3 | AJ5: Working Forecast Y3 | AK5: Working Forecast Y3 | AL5: Working Forecast Y3 | AM5: Working Forecast Y3 | AN5: Working Forecast Y3 | AO5: Working Forecast Y3 | AP5: Working Forecast Y4 | AQ5: Working Forecast Y4 | AR5: Working Forecast Y4 | AS5: Working Forecast Y4 | AT5: Working Forecast Y4 | AU5: Working Forecast Y4 | AV5: Working Forecast Y4 | AW5: Working Forecast Y4 | AX5: Working Forecast Y4 | AY5: Working Forecast Y4 | AZ5: Working Forecast Y4 | BA5: Working Forecast Y4 | BB5: Working Forecast Y4
C6: Oct | D6: Nov | E6: Dec | F6: Jan | G6: Feb | H6: Mar | I6: Apr | J6: May | K6: Jun | L6: Jul | M6: Aug | N6: Sep | O6: Full Year | P6: Oct | Q6: Nov | R6: Dec | S6: Jan | T6: Feb | U6: Mar | V6: Apr | W6: May | X6: Jun | Y6: Jul | Z6: Aug | AA6: Sep | AB6: Full Year | AC6: Oct | AD6: Nov | AE6: Dec | AF6: Jan | AG6: Feb | AH6: Mar | AI6: Apr | AJ6: May | AK6: Jun | AL6: Jul | AM6: Aug | AN6: Sep | AO6: Full Year | AP6: Oct | AQ6: Nov | AR6: Dec | AS6: Jan | AT6: Feb | AU6: Mar | AV6: Apr | AW6: May | AX6: Jun | AY6: Jul | AZ6: Aug | BA6: Sep | BB6: Full Year
A7: Tofranil PM | B7: Sales Volume | C7: 318.002 | D7: 366 | E7: 534.002 | F7: 240.001 | G7: 550 | H7: 427 | I7: 458 | J7: 519 | K7: 408 | L7: 417 | M7: 494 | N7: 409 | O7: 5140.005 | P7: 397 | Q7: 458 | R7: 369 | S7: 361 | T7: 455 | U7: 371 | V7: 363 | W7: 416 | X7: 372 | Y7: 328 | Z7: 433 | AA7: 338 | AB7: 4661 | AC7: 337 | AD7: 397 | AE7: 315 | AF7: 304 | AG7: 400 | AH7: 344 | AI7: 328 | AJ7: 394 | AK7: 340 | AL7: 306 | AM7: 420 | AN7: 305 | AO7: 4190 | AP7: 366 | AQ7: 288 | AR7: 333 | AS7: 318 | AT7: 319.9 | AU7: 0 | AV7: 0 | AW7: 0 | AX7: 0 | AY7: 0 | AZ7: 0 | BA7: 0 | BB7: 1624.9
A8: 157001000225 CNS Non-Promoted Products | B8: Sales Volume | C8: 4560.001 | D8: 5586 | E8: 7842.007 | F8: 3906.002 | G8: 6854.3664 | H8: 5216.7907 | I8: 5372.0602 | J8: 5657 | K8: 4658 | L8: 4404.9778 | M8: 4726.2286 | N8: 4379.6066 | O8: 63163.04 | P8: 5149.4472 | Q8: 5250 | R8: 4490 | S8: 4883.2164 | T8: 5406 | U8: 4653 | V8: 4929.7048 | W8: 5143 | X8: 4685 | Y8: 4817.455 | Z8: 5354 | AA8: 4703 | AB8: 59463.823 | AC8: 4487.7788 | AD8: 5192 | AE8: 4395 | AF8: 4240.5111 | AG8: 5214 | AH8: 4679 | AI8: 4479.0793 | AJ8: 5135 | AK8: 4615 | AL8: 4263.808 | AM8: 5339 | AN8: 4307 | AO8: 56347.177 | AP8: 4697.026 | AQ8: 4136 | AR8: 4428.6753 | AS8: 4407.6753 | AT8: 4580.542 | AU8: 0 | AV8: 0 | AW8: 0 | AX8: 0 | AY8: 0 | AZ8: 0 | BA8: 0 | BB8: 22249.919
A9: 157001000235 Tussicaps | B9: Sales Volume | C9: 0.003 | D9: 0.003 | E9: 0.004 | F9: 0.003 | G9: 0 | H9: 0 | I9: 0 | J9: 0 | K9: 0 | L9: 0 | M9: 0 | N9: 0 | O9: 0.013 | P9: 0 | Q9: 0 | R9: 0 | S9: 0 | T9: 0 | U9: 0 | V9: 0 | W9: 0 | X9: 0 | Y9: 0 | Z9: 0 | AA9: 0 | AB9: 0 | AC9: 0 | AD9: 0 | AE9: 0 | AF9: 0 | AG9: 0 | AH9: 0 | AI9: 0 | AJ9: 0 | AK9: 0 | AL9: 0 | AM9: 0 | AN9: 0 | AO9: 0 | AP9: 0 | AQ9: 0 | AR9: 0 | AS9: 0 | AT9: 0 | AU9: 0 | AV9: 0 | AW9: 0 | AX9: 0 | AY9: 0 | AZ9: 0 | BA9: 0 | BB9: 0
A10: 157001000251 Pennsaid | B10: Sales Volume | C10: 11375 | D10: 14904 | E10: 20832 | F10: 12336 | G10: 24822.336 | H10: 18185.67 | I10: 28840.783 | J10: 37678.116 | K10: 23860.657 | L10: 23733.018 | M10: 24234.107 | N10: 24178.99 | O10: 264980.68 | P10: 19865.442 | Q10: 13206.049 | R10: 8752.9776 | S10: 5680.648 | T10: 3720.4748 | U10: 2374.1937 | V10: 2378.3199 | W10: 2404.5662 | X10: 2432.8003 | Y10: 2447.6958 | Z10: 2471.9682 | AA10: 2483.7957 | AB10: 68218.931 | AC10: 2501.444 | AD10: 2148.9836 | AE10: 1355.2982 | AF10: 812.23332 | AG10: 461.23795 | AH10: 219.71459 | AI10: 54.786627 | AJ10: 0 | AK10: 0 | AL10: 0 | AM10: 0 | AN10: 0 | AO10: 7553.6983 | AP10: 0 | AQ10: 0 | AR10: 0 | AS10: 0 | AT10: 0 | AU10: 0 | AV10: 0 | AW10: 0 | AX10: 0 | AY10: 0 | AZ10: 0 | BA10: 0 | BB10: 0
A11: Pennsaid 2% Pump | B11: Sales Volume | C11: 0 | D11: 0 | E11: 0 | F11: 0 | G11: 0 | H11: 0 | I11: 0 | J11: 0 | K11: 0 | L11: 0 | M11: 0 | N11: 0 | O11: 0 | P11: 21739 | Q11: 15021.428 | R11: 13201 | S11: 21265 | T11: 24150.479 | U11: 18521 | V11: 22696 | W11: 24869.095 | X11: 19158 | Y11: 22395 | Z11: 26196 | AA11: 24197 | AB11: 253409 | AC11: 22513 | AD11: 22754.429 | AE11: 18905 | AF11: 16021 | AG11: 14294.979 | AH11: 13040 | AI11: 12113 | AJ11: 11582.387 | AK11: 11814 | AL11: 11977 | AM11: 12191.546 | AN11: 12340 | AO11: 179546.34 | AP11: 12360 | AQ11: 12890 | AR11: 12960 | AS11: 13336.667 | AT11: 13636.667 | AU11: 0 | AV11: 0 | AW11: 0 | AX11: 0 | AY11: 0 | AZ11: 0 | BA11: 0 | BB11: 65183.333
A12: Diclofenac 2% Pump | B12: Sales Volume | C12: 0 | D12: 0 | E12: 0 | F12: 0 | G12: 0 | H12: 0 | I12: 0 | J12: 0 | K12: 0 | L12: 0 | M12: 0 | N12: 0 | O12: 0 | P12: 0 | Q12: 0 | R12: 0 | S12: 0 | T12: 0 | U12: 0 | V12: 0 | W12: 0 | X12: 0 | Y12: 0 | Z12: 0 | AA12: 0 | AB12: 0 | AC12: 0 | AD12: 0 | AE12: 0 | AF12: 0 | AG12: 0 | AH12: 0 | AI12: 0 | AJ12: 0 | AK12: 0 | AL12: 0 | AM12: 0 | AN12: 0 | AO12: 0 | AP12: 0 | AQ12: 0 | AR12: 0 | AS12: 0 | AT12: 0 | AU12: 0 | AV12: 0 | AW12: 0 | AX12: 0 | AY12: 0 | AZ12: 0 | BA12: 0 | BB12: 0
A13: 157001000252 Exalgo | B13: Sales Volume | C13: 7524 | D13: 9864 | E13: 9396 | F13: 6120 | G13: 11671.249 | H13: 8920.1263 | I13: 7297 | J13: 9875 | K13: 6544 | L13: 6533.702 | M13: 10546.388 | N13: 8045.32 | O13: 102336.79 | P13: 7876 | Q13: 11616 | R13: 1936 | S13: 581 | T13: 1111 | U13: 466 | V13: 500 | W13: 660 | X13: 415 | Y13: 464 | Z13: 794 | AA13: 475 | AB13: 26894 | AC13: 517 | AD13: 809 | AE13: 516 | AF13: 511 | AG13: 829 | AH13: 555 | AI13: 606 | AJ13: 877 | AK13: 560 | AL13: 586 | AM13: 1021 | AN13: 562 | AO13: 7949 | AP13: 738 | AQ13: 833 | AR13: 710 | AS13: 799 | AT13: 746.66667 | AU13: 0 | AV13: 0 | AW13: 0 | AX13: 0 | AY13: 0 | AZ13: 0 | BA13: 0 | BB13: 3826.6667
A14: Exalgo 32 | B14: Sales Volume | C14: 408 | D14: 816 | E14: 1008 | F14: 660 | G14: 1204 | H14: 939 | I14: 1312 | J14: 2014 | K14: 1987 | L14: 2350 | M14: 3661 | N14: 3315 | O14: 19674 | P14: 3977 | Q14: 5070 | R14: 2018 | S14: 1817 | T14: 3074 | U14: 2173 | V14: 2299 | W14: 3095 | X14: 2289 | Y14: 2185 | Z14: 1555 | AA14: 330 | AB14: 29882 | AC14: 233 | AD14: 164 | AE14: 113 | AF14: 113 | AG14: 175 | AH14: 121 | AI14: 128 | AJ14: 179 | AK14: 119 | AL14: 121 | AM14: 202 | AN14: 116 | AO14: 1784 | AP14: 148 | AQ14: 161 | AR14: 145 | AS14: 157 | AT14: 150.33333 | AU14: 0 | AV14: 0 | AW14: 0 | AX14: 0 | AY14: 0 | AZ14: 0 | BA14: 0 | BB14: 761.33333
A15: Hydromorphone ER | B15: Sales Volume | C15: 0 | D15: 0 | E15: 0 | F15: 0 | G15: 0 | H15: 0 | I15: 0 | J15: 0 | K15: 0 | L15: 0 | M15: 0 | N15: 0 | O15: 0 | P15: 0 | Q15: 0 | R15: 0 | S15: 0 | T15: 0 | U15: 0 | V15: 1093 | W15: 925 | X15: 1280 | Y15: 2144 | Z15: 1957 | AA15: 2544 | AB15: 9943 | AC15: 3164 | AD15: 3919 | AE15: 3213 | AF15: 4192 | AG15: 3598 | AH15: 4390 | AI15: 4996 | AJ15: 3605 | AK15: 4253 | AL15: 5530 | AM15: 3797 | AN15: 3797 | AO15: 48454 | AP15: 3797 | AQ15: 4295.6727 | AR15: 4327.2545 | AS15: 4358.8364 | AT15: 4623.9636 | AU15: 0 | AV15: 0 | AW15: 0 | AX15: 0 | AY15: 0 | AZ15: 0 | BA15: 0 | BB15: 21402.727
A16: Hydromorphone ER 32 | B16: Sales Volume | C16: 0 | D16: 0 | E16: 0 | F16: 0 | G16: 0 | H16: 0 | I16: 0 | J16: 0 | K16: 0 | L16: 0 | M16: 0 | N16: 0 | O16: 0 | P16: 0 | Q16: 0 | R16: 0 | S16: 0 | T16: 0 | U16: 0 | V16: 0 | W16: 0 | X16: 0 | Y16: 439 | Z16: 401 | AA16: 521 | AB16: 1361 | AC16: 648 | AD16: -304 | AE16: 710 | AF16: 883 | AG16: 784 | AH16: 929 | AI16: 1013 | AJ16: 768 | AK16: 882 | AL16: 1085 | AM16: 784 | AN16: 784 | AO16: 8966 | AP16: 784 | AQ16: 863.54545 | AR16: 864.95455 | AS16: 866.36364 | AT16: 906.84091 | AU16: 0 | AV16: 0 | AW16: 0 | AX16: 0 | AY16: 0 | AZ16: 0 | BA16: 0 | BB16: 4285.7045
A17: Roxicodone | B17: Sales Volume | C17: 3660.001 | D17: 3168.002 | E17: 2856.003 | F17: 3360.002 | G17: 4296.3877 | H17: 3440.6208 | I17: 4050 | J17: 3713 | K17: 3183 | L17: 4644.4126 | M17: 3796.2723 | N17: 3504.4051 | O17: 43672.107 | P17: 4673.0539 | Q17: 3384 | R17: 3266 | S17: 4478.0539 | T17: 3602 | U17: 3438 | V17: 4306.0539 | W17: 3602 | X17: 3266 | Y17: 4658.0539 | Z17: 3422 | AA17: 3782 | AB17: 45877.216 | AC17: 3782.0539 | AD17: 3782 | AE17: 3782 | AF17: 3782.0539 | AG17: 3782 | AH17: 3782 | AI17: 3782.0539 | AJ17: 3782 | AK17: 3782 | AL17: 3782.0539 | AM17: 3782 | AN17: 3782 | AO17: 45384.216 | AP17: 3782.0539 | AQ17: 3782 | AR17: 3782 | AS17: 3825 | AT17: 3960.4 | AU17: 0 | AV17: 0 | AW17: 0 | AX17: 0 | AY17: 0 | AZ17: 0 | BA17: 0 | BB17: 19131.454
A18: Intrathecal Products | B18: Sales Volume | C18: 7250 | D18: 10491 | E18: 9054 | F18: 6636 | G18: 17083.557 | H18: 14938.892 | I18: 11629.425 | J18: 15474.276 | K18: 13551.781 | L18: 11930.898 | M18: 15774.678 | N18: 13890.919 | O18: 147705.43 | P18: 7070.4299 | Q18: 8793.7911 | R18: 7108.9912 | S18: 7144.9506 | T18: 8902.3882 | U18: 7268.5969 | V18: 7285.6559 | W18: 9017.4815 | X18: 7262.5929 | Y18: 7307.3013 | Z18: 9032.6988 | AA18: 7303.1218 | AB18: 93498 | AC18: 7288.9913 | AD18: 8594.4716 | AE18: 7288.9913 | AF18: 7552.7213 | AG18: 8891.1679 | AH18: 7617.7761 | AI18: 7974.9675 | AJ18: 9521.3797 | AK18: 8277.0077 | AL18: 8685.1542 | AM18: 10249.174 | AN18: 8945.3734 | AO18: 100887.18 | AP18: 0 | AQ18: 0 | AR18: 0 | AS18: 0 | AT18: 0 | AU18: 0 | AV18: 0 | AW18: 0 | AX18: 0 | AY18: 0 | AZ18: 0 | BA18: 0 | BB18: 0
... A22: Brand Pharmaceuticals | B22: Sales Volume | C22: 35095.008 | D22: 45195.006 | E22: 51522.018 | F22: 33258.009 | G22: 66481.897 | H22: 52068.099 | I22: 58959.269 | J22: 74930.391 | K22: 54192.438 | L22: 54014.008 | M22: 63232.674 | N22: 57723.24 | O22: 646672.06 | P22: 70747.373 | Q22: 62799.267 | R22: 41141.969 | S22: 46210.869 | T22: 50421.342 | U22: 39264.791 | V22: 59006.621 | W22: 76444.917 | X22: 80629.053 | Y22: 93586.224 | Z22: 104950.44 | AA22: 106942.75 | AB22: 832145.62 | AC22: 114352.95 | AD22: 126479.23 | AE22: 129758.3 | AF22: 160726.69 | AG22: 193895.72 | AH22: 224294.99 | AI22: 246701.64 | AJ22: 269681.76 | AK22: 291090.25 | AL22: 321647.22 | AM22: 351960.89 | AN22: 377977.51 | AO22: 2808567.2 | AP22: 378666.73 | AQ22: 395826.16 | AR22: 412767.12 | AS22: 450398.92 | AT22: 474793.84 | AU22: 0 | AV22: 0 | AW22: 0 | AX22: 0 | AY22: 0 | AZ22: 0 | BA22: 0 | BB22: 2112452.8
O23: =SUM(O7:O21) -> 646672.05 | AB23: =SUM(AB7:AB21) -> 832145.62 | AO23: =SUM(AO7:AO21) -> 2808567.2 | BB23: =SUM(BB7:BB21) -> 2112452.8
O24: =O23-O22 -> -0.005 | AB24: =AB23-AB22 -> 0 | AO24: =AO23-AO22 -> 0 | BB24: =BB23-BB22 -> 0
A25: Freight per bottle - use FY12 Actual average | B25: 0.1365
A26: Freight per bottle (from RMeisner/CGidcumb 3/29/11) | B26: 0.11
A30: Calculated Forecast | C30: Oct | D30: Nov | E30: Dec | F30: Jan | G30: Feb | H30: Mar | I30: Apr | J30: May | K30: Jun | L30: Jul | M30: Aug | N30: Sep | O30: FY13 | P30: Oct | Q30: Nov | R30: Dec | S30: Jan | T30: Feb | U30: Mar | V30: Apr | W30: May | X30: Jun | Y30: Jul | Z30: Aug | AA30: Sep | AB30: WF FY14 | AC30: Oct | AD30: Nov | AE30: Dec | AF30: Jan | AG30: Feb | AH30: Mar | AI30: Apr | AJ30: May | AK30: Jun | AL30: Jul | AM30: Aug | AN30: Sep | AO30: WF FY15 | AP30: Oct | AQ30: Nov | AR30: Dec | AS30: Jan | AT30: Feb | AU30: Mar | AV30: Apr | AW30: May | AX30: Jun | AY30: Jul | AZ30: Aug | BA30: Sep | BB30: WF FY16
A31: 157001150245 Tofranil-PM/ImipraPam Frt Exp | C31: ='Download COV'!D7 -> 0 | D31: ='Download COV'!E7 -> 0 | E31: ='Download COV'!F7 -> 42 | F31: ='Download COV'!G7 -> 46 | G31: =G7*$B$25 -> 75.075 | H31: =H7*$B$25 -> 58.2855 | I31: =I7*$B$25 -> 62.517 | J31: =J7*$B$25 -> 70.8435 | K31: =K7*$B$25 -> 55.692 | L31: =L7*$B$25 -> 56.9205 | M31: =M7*$B$25 -> 67.431 | N31: =N7*$B$25 -> 55.8285 | O31: =SUM(C31:N31) -> 590.593 | P31: =P7*$B$25 -> 54.1905 | Q31: =Q7*$B$25 -> 62.517 | R31: =R7*$B$25 -> 50.3685 | S31: =S7*$B$25 -> 49.2765 | T31: =T7*$B$25 -> 62.1075 | U31: =U7*$B$25 -> 50.6415 | V31: =V7*$B$25 -> 49.5495 | W31: =W7*$B$25 -> 56.784 | ... AA31: =AA7*$B$25 -> 46.137 | AB31: =SUM(P31:AA31) -> 636.2265 | AC31: =AC7*$B$25 -> 46.0005 | AD31: =AD7*$B$25 -> 54.1905 | AE31: =AE7*$B$25 -> 42.9975 | AF31: =AF7*$B$25 -> 41.496 | AG31: =AG7*$B$25 -> 54.6 | AH31: =AH7*$B$25 -> 46.956 | AI31: =AI7*$B$25 -> 44.772 | AJ31: =AJ7*$B$25 -> 53.781 | ... AN31: =AN7*$B$25 -> 41.6325 | AO31: =SUM(AC31:AN31) -> 571.935 | AP31: =AP7*$B$25 -> 49.959 | AQ31: =AQ7*$B$25 -> 39.312 | AR31: =AR7*$B$25 -> 45.4545 | AS31: =AS7*$B$25 -> 43.407 | AT31: =AT7*$B$25 -> 43.66635 | AU31: =AU7*$B$25 -> 0 | AV31: =AV7*$B$25 -> 0 | AW31: =AW7*$B$25 -> 0 | ... BA31: =BA7*$B$25 -> 0 | BB31: =SUM(AP31:BA31) -> 221.79885
A32: 157001150225 Frt Exp-CNS Non-Promoted Prod | C32: ='Download COV'!D8 -> 890 | D32: ='Download COV'!E8 -> 1055 | E32: ='Download COV'!F8 -> 605 | F32: ='Download COV'!G8 -> 751 | G32: =G8*$B$25 -> 935.62102 | H32: =H8*$B$25 -> 712.09193 | I32: =I8*$B$25 -> 733.28621 | J32: =J8*$B$25 -> 772.1805 | K32: =K8*$B$25 -> 635.817 | L32: =L8*$B$25 -> 601.27947 | M32: =M8*$B$25 -> 645.1302 | N32: =N8*$B$25 -> 597.8163 | O32: =SUM(C32:N32) -> 8934.2226 | P32: =P8*$B$25 -> 702.89955 | Q32: =Q8*$B$25 -> 716.625 | R32: =R8*$B$25 -> 612.885 | S32: =S8*$B$25 -> 666.55904 | T32: =T8*$B$25 -> 737.919 | U32: =U8*$B$25 -> 635.1345 | V32: =V8*$B$25 -> 672.9047 | W32: =W8*$B$25 -> 702.0195 | ... AA32: =AA8*$B$25 -> 641.9595 | AB32: =SUM(P32:AA32) -> 8116.8119 | AC32: =AC8*$B$25 -> 612.5818 | AD32: =AD8*$B$25 -> 708.708 | AE32: =AE8*$B$25 -> 599.9175 | AF32: =AF8*$B$25 -> 578.82977 | AG32: =AG8*$B$25 -> 711.711 | AH32: =AH8*$B$25 -> 638.6835 | AI32: =AI8*$B$25 -> 611.39432 | AJ32: =AJ8*$B$25 -> 700.9275 | ... AN32: =AN8*$B$25 -> 587.9055 | AO32: =SUM(AC32:AN32) -> 7691.3897 | AP32: =AP8*$B$25 -> 641.14405 | AQ32: =AQ8*$B$25 -> 564.564 | AR32: =AR8*$B$25 -> 604.51418 | AS32: =AS8*$B$25 -> 601.64768 | AT32: =AT8*$B$25 -> 625.24398 | AU32: =AU8*$B$25 -> 0 | AV32: =AV8*$B$25 -> 0 | AW32: =AW8*$B$25 -> 0 | ... BA32: =BA8*$B$25 -> 0 | BB32: =SUM(AP32:BA32) -> 3037.1139
A34: 157001150251 Pennsaid Frt Expense | C34: ='Download COV'!D10 -> 2075 | D34: ='Download COV'!E10 -> 2641 | E34: ='Download COV'!F10 -> 1565 | F34: ='Download COV'!G10 -> 2371 | G34: =G10*$B$25 -> 3388.2488 | H34: =H10*$B$25 -> 2482.3439 | I34: =I10*$B$25 -> 3936.7669 | J34: =J10*$B$25 -> 5143.0628 | K34: =K10*$B$25 -> 3256.9797 | L34: =L10*$B$25 -> 3239.557 | M34: =M10*$B$25 -> 3307.9556 | N34: =N10*$B$25 -> 3300.4321 | O34: =SUM(C34:N34) -> 36707.347 | P34: =P10*$B$25 -> 2711.6328 | Q34: =Q10*$B$25 -> 1802.6256 | R34: =R10*$B$25 -> 1194.7814 | S34: =S10*$B$25 -> 775.40845 | T34: =T10*$B$25 -> 507.84481 | U34: =U10*$B$25 -> 324.07744 | V34: =V10*$B$25 -> 324.64067 | W34: =W10*$B$25 -> 328.22328 | ... AA34: =AA10*$B$25 -> 339.03812 | AB34: =SUM(P34:AA34) -> 9311.8841 | AC34: =AC10*$B$25 -> 341.44711 | AD34: =AD10*$B$25 -> 293.33626 | AE34: =AE10*$B$25 -> 184.9982 | AF34: =AF10*$B$25 -> 110.86985 | AG34: =AG10*$B$25 -> 62.958981 | AH34: =AH10*$B$25 -> 29.991041 | AI34: =AI10*$B$25 -> 7.4783745 | AJ34: =AJ10*$B$25 -> 0 | ... AN34: =AN10*$B$25 -> 0 | AO34: =SUM(AC34:AN34) -> 1031.0798 | AP34: =AP10*$B$25 -> 0 | AQ34: =AQ10*$B$25 -> 0 | AR34: =AR10*$B$25 -> 0 | AS34: =AS10*$B$25 -> 0 | AT34: =AT10*$B$25 -> 0 | AU34: =AU10*$B$25 -> 0 | AV34: =AV10*$B$25 -> 0 | AW34: =AW10*$B$25 -> 0 | ... BA34: =BA10*$B$25 -> 0 | BB34: =SUM(AP34:BA34) -> 0
A35: 157001150255 Pennsaid 2% Pump Frt Expense | C35: ='Download COV'!D11 -> 0 | D35: ='Download COV'!E11 -> 0 | E35: ='Download COV'!F11 -> 0 | F35: ='Download COV'!G11 -> 0 | G35: =G11*$B$25 -> 0 | H35: =H11*$B$25 -> 0 | I35: =I11*$B$25 -> 0 | J35: =J11*$B$25 -> 0 | K35: =K11*$B$25 -> 0 | L35: =L11*$B$25 -> 0 | M35: =M11*$B$25 -> 0 | N35: =N11*$B$25 -> 0 | O35: =SUM(C35:N35) -> 0 | P35: =P11*$B$25 -> 2967.3735 | Q35: =Q11*$B$25 -> 2050.4249 | R35: =R11*$B$25 -> 1801.9365 | S35: =S11*$B$25 -> 2902.6725 | T35: =T11*$B$25 -> 3296.5404 | U35: =U11*$B$25 -> 2528.1165 | V35: =V11*$B$25 -> 3098.004 | W35: =W11*$B$25 -> 3394.6315 | ... AA35: =AA11*$B$25 -> 3302.8905 | AB35: =SUM(P35:AA35) -> 34590.329 | AC35: =AC11*$B$25 -> 3073.0245 | AD35: =AD11*$B$25 -> 3105.9795 | AE35: =AE11*$B$25 -> 2580.5325 | AF35: =AF11*$B$25 -> 2186.8665 | AG35: =AG11*$B$25 -> 1951.2646 | AH35: =AH11*$B$25 -> 1779.96 | AI35: =AI11*$B$25 -> 1653.4245 | AJ35: =AJ11*$B$25 -> 1580.9959 | ... AN35: =AN11*$B$25 -> 1684.41 | AO35: =SUM(AC35:AN35) -> 24508.076 | AP35: =AP11*$B$25 -> 1687.14 | AQ35: =AQ11*$B$25 -> 1759.485 | AR35: =AR11*$B$25 -> 1769.04 | AS35: =AS11*$B$25 -> 1820.455 | AT35: =AT11*$B$25 -> 1861.405 | AU35: =AU11*$B$25 -> 0 | AV35: =AV11*$B$25 -> 0 | AW35: =AW11*$B$25 -> 0 | ... BA35: =BA11*$B$25 -> 0 | BB35: =SUM(AP35:BA35) -> 8897.525
A36: 157001150256 Diclofenac 2% Pump Frt Exp | C36: ='Download COV'!D12 -> 0 | D36: ='Download COV'!E12 -> 0 | E36: ='Download COV'!F12 -> 0 | F36: ='Download COV'!G12 -> 0 | G36: =G12*$B$25 -> 0 | H36: =H12*$B$25 -> 0 | I36: =I12*$B$25 -> 0 | J36: =J12*$B$25 -> 0 | K36: =K12*$B$25 -> 0 | L36: =L12*$B$25 -> 0 | M36: =M12*$B$25 -> 0 | N36: =N12*$B$25 -> 0 | O36: =SUM(C36:N36) -> 0 | P36: =P12*$B$25 -> 0 | Q36: =Q12*$B$25 -> 0 | R36: =R12*$B$25 -> 0 | S36: =S12*$B$25 -> 0 | T36: =T12*$B$25 -> 0 | U36: =U12*$B$25 -> 0 | V36: =V12*$B$25 -> 0 | W36: =W12*$B$25 -> 0 | ... AA36: =AA12*$B$25 -> 0 | AB36: =SUM(P36:AA36) -> 0 | AC36: =AC12*$B$25 -> 0 | AD36: =AD12*$B$25 -> 0 | AE36: =AE12*$B$25 -> 0 | AF36: =AF12*$B$25 -> 0 | AG36: =AG12*$B$25 -> 0 | AH36: =AH12*$B$25 -> 0 | AI36: =AI12*$B$25 -> 0 | AJ36: =AJ12*$B$25 -> 0 | ... AN36: =AN12*$B$25 -> 0 | AO36: =SUM(AC36:AN36) -> 0 | AP36: =AP12*$B$25 -> 0 | AQ36: =AQ12*$B$25 -> 0 | AR36: =AR12*$B$25 -> 0 | AS36: =AS12*$B$25 -> 0 | AT36: =AT12*$B$25 -> 0 | AU36: =AU12*$B$25 -> 0 | AV36: =AV12*$B$25 -> 0 | AW36: =AW12*$B$25 -> 0 | ... BA36: =BA12*$B$25 -> 0 | BB36: =SUM(AP36:BA36) -> 0
A37: 157001150252 Exalgo Freight Exp | C37: ='Download COV'!D13 -> 1447 | D37: ='Download COV'!E13 -> 1893 | E37: ='Download COV'!F13 -> 705 | F37: ='Download COV'!G13 -> 1303 | G37: =SUM(G13:G14)*$B$25 -> 1757.4715 | H37: =SUM(H13:H14)*$B$25 -> 1345.7707 | I37: =SUM(I13:I14)*$B$25 -> 1175.1285 | J37: =SUM(J13:J14)*$B$25 -> 1622.8485 | K37: =SUM(K13:K14)*$B$25 -> 1164.4815 | L37: =SUM(L13:L14)*$B$25 -> 1212.6253 | M37: =SUM(M13:M14)*$B$25 -> 1939.3085 | N37: =SUM(N13:N14)*$B$25 -> 1550.6837 | O37: =SUM(C37:N37) -> 17116.318 | P37: =SUM(P13:P14)*$B$25 -> 1617.9345 | Q37: =SUM(Q13:Q14)*$B$25 -> 2277.639 | R37: =SUM(R13:R14)*$B$25 -> 539.721 | S37: =SUM(S13:S14)*$B$25 -> 327.327 | T37: =SUM(T13:T14)*$B$25 -> 571.2525 | U37: =SUM(U13:U14)*$B$25 -> 360.2235 | V37: =SUM(V13:V14)*$B$25 -> 382.0635 | W37: =SUM(W13:W14)*$B$25 -> 512.5575 | ... AA37: =SUM(AA13:AA14)*$B$25 -> 109.8825 | AB37: =SUM(P37:AA37) -> 7749.924 | AC37: =SUM(AC13:AC14)*$B$25 -> 102.375 | AD37: =SUM(AD13:AD14)*$B$25 -> 132.8145 | AE37: =SUM(AE13:AE14)*$B$25 -> 85.8585 | AF37: =SUM(AF13:AF14)*$B$25 -> 85.176 | AG37: =SUM(AG13:AG14)*$B$25 -> 137.046 | AH37: =SUM(AH13:AH14)*$B$25 -> 92.274 | AI37: =SUM(AI13:AI14)*$B$25 -> 100.191 | AJ37: =SUM(AJ13:AJ14)*$B$25 -> 144.144 | ... AN37: =SUM(AN13:AN14)*$B$25 -> 92.547 | AO37: =SUM(AC37:AN37) -> 1328.5545 | AP37: =SUM(AP13:AP14)*$B$25 -> 120.939 | AQ37: =SUM(AQ13:AQ14)*$B$25 -> 135.681 | AR37: =SUM(AR13:AR14)*$B$25 -> 116.7075 | AS37: =SUM(AS13:AS14)*$B$25 -> 130.494 | AT37: =SUM(AT13:AT14)*$B$25 -> 122.4405 | AU37: =SUM(AU13:AU14)*$B$25 -> 0 | AV37: =SUM(AV13:AV14)*$B$25 -> 0 | AW37: =SUM(AW13:AW14)*$B$25 -> 0 | ... BA37: =SUM(BA13:BA14)*$B$25 -> 0 | BB37: =SUM(AP37:BA37) -> 626.262
A39: 157001150258 Hydromorphone ER Frt Exp | C39: ='Download COV'!D15 -> 0 | D39: ='Download COV'!E15 -> 0 | E39: ='Download COV'!F15 -> 0 | F39: ='Download COV'!G15 -> 0 | G39: =SUM(G15:G16)*$B$25 -> 0 | H39: =SUM(H15:H16)*$B$25 -> 0 | I39: =SUM(I15:I16)*$B$25 -> 0 | J39: =SUM(J15:J16)*$B$25 -> 0 | K39: =SUM(K15:K16)*$B$25 -> 0 | L39: =SUM(L15:L16)*$B$25 -> 0 | M39: =SUM(M15:M16)*$B$25 -> 0 | N39: =SUM(N15:N16)*$B$25 -> 0 | O39: =SUM(C39:N39) -> 0 | P39: =SUM(P15:P16)*$B$25 -> 0 | Q39: =SUM(Q15:Q16)*$B$25 -> 0 | R39: =SUM(R15:R16)*$B$25 -> 0 | S39: =SUM(S15:S16)*$B$25 -> 0 | T39: =SUM(T15:T16)*$B$25 -> 0 | U39: =SUM(U15:U16)*$B$25 -> 0 | V39: =SUM(V15:V16)*$B$25 -> 149.1945 | W39: =SUM(W15:W16)*$B$25 -> 126.2625 | ... AA39: =SUM(AA15:AA16)*$B$25 -> 418.3725 | AB39: =SUM(P39:AA39) -> 1542.996 | AC39: =SUM(AC15:AC16)*$B$25 -> 520.338 | AD39: =SUM(AD15:AD16)*$B$25 -> 493.4475 | AE39: =SUM(AE15:AE16)*$B$25 -> 535.4895 | AF39: =SUM(AF15:AF16)*$B$25 -> 692.7375 | AG39: =SUM(AG15:AG16)*$B$25 -> 598.143 | AH39: =SUM(AH15:AH16)*$B$25 -> 726.0435 | AI39: =SUM(AI15:AI16)*$B$25 -> 820.2285 | AJ39: =SUM(AJ15:AJ16)*$B$25 -> 596.9145 | ... AN39: =SUM(AN15:AN16)*$B$25 -> 625.3065 | AO39: =SUM(AC39:AN39) -> 7837.83 | AP39: =SUM(AP15:AP16)*$B$25 -> 625.3065 | AQ39: =SUM(AQ15:AQ16)*$B$25 -> 704.23328 | AR39: =SUM(AR15:AR16)*$B$25 -> 708.73654 | AS39: =SUM(AS15:AS16)*$B$25 -> 713.2398 | AT39: =SUM(AT15:AT16)*$B$25 -> 754.95482 | AU39: =SUM(AU15:AU16)*$B$25 -> 0 | AV39: =SUM(AV15:AV16)*$B$25 -> 0 | AW39: =SUM(AW15:AW16)*$B$25 -> 0 | ... BA39: =SUM(BA15:BA16)*$B$25 -> 0 | BB39: =SUM(AP39:BA39) -> 3506.4709
A41: 157001150268 Roxicodone-Freight | C41: ='Download COV'!D17 -> 668 | D41: ='Download COV'!E17 -> 561 | E41: ='Download COV'!F17 -> 209 | F41: ='Download COV'!G17 -> 646 | G41: =G17*$B$25 -> 586.45692 | H41: =H17*$B$25 -> 469.64474 | I41: =I17*$B$25 -> 552.825 | J41: =J17*$B$25 -> 506.8245 | K41: =K17*$B$25 -> 434.4795 | L41: =L17*$B$25 -> 633.96232 | M41: =M17*$B$25 -> 518.19117 | N41: =N17*$B$25 -> 478.3513 | O41: =SUM(C41:N41) -> 6264.7354 | P41: =P17*$B$25 -> 637.87186 | Q41: =Q17*$B$25 -> 461.916 | R41: =R17*$B$25 -> 445.809 | S41: =S17*$B$25 -> 611.25436 | T41: =T17*$B$25 -> 491.673 | U41: =U17*$B$25 -> 469.287 | V41: =V17*$B$25 -> 587.77636 | W41: =W17*$B$25 -> 491.673 | ... AA41: =AA17*$B$25 -> 516.243 | AB41: =SUM(P41:AA41) -> 6262.2399 | AC41: =AC17*$B$25 -> 516.25036 | AD41: =AD17*$B$25 -> 516.243 | AE41: =AE17*$B$25 -> 516.243 | AF41: =AF17*$B$25 -> 516.25036 | AG41: =AG17*$B$25 -> 516.243 | AH41: =AH17*$B$25 -> 516.243 | AI41: =AI17*$B$25 -> 516.25036 | AJ41: =AJ17*$B$25 -> 516.243 | ... AN41: =AN17*$B$25 -> 516.243 | AO41: =SUM(AC41:AN41) -> 6194.9454 | AP41: =AP17*$B$25 -> 516.25036 | AQ41: =AQ17*$B$25 -> 516.243 | AR41: =AR17*$B$25 -> 516.243 | AS41: =AS17*$B$25 -> 522.1125 | AT41: =AT17*$B$25 -> 540.5946 | AU41: =AU17*$B$25 -> 0 | AV41: =AV17*$B$25 -> 0 | AW41: =AW17*$B$25 -> 0 | ... BA41: =BA17*$B$25 -> 0 | BB41: =SUM(AP41:BA41) -> 2611.4435
A42: 157210151269 Intrathecal-Freight-General | C42: =SUM('Download COV'!D18:D21) -> 0 | D42: =SUM('Download COV'!E18:E21) -> 0 | E42: =SUM('Download COV'!F18:F21) -> 0 | F42: =SUM('Download COV'!G18:G21) -> 25854.04 | G42: 3300 | H42: 2750 | I42: 2500 | J42: 2500 | K42: 2500 | L42: 2500 | M42: 2500 | N42: 2500 | O42: =SUM(C42:N42) -> 46904.04 | P42: 5000 | Q42: 5000 | R42: 5000 | S42: 5000 | T42: 5000 | U42: 5000 | V42: 5000 | W42: 5000 | X42: 5000 | Y42: 5000 | Z42: 5000 | AA42: 5000 | AB42: =SUM(P42:AA42) -> 60000 | AC42: =AC18*$B$25 -> 994.94731 | AD42: =AD18*$B$25 -> 1173.1454 | AE42: =AE18*$B$25 -> 994.94731 | AF42: =AF18*$B$25 -> 1030.9465 | AG42: =AG18*$B$25 -> 1213.6444 | AH42: =AH18*$B$25 -> 1039.8264 | AI42: =AI18*$B$25 -> 1088.5831 | AJ42: =AJ18*$B$25 -> 1299.6683 | ... AN42: =AN18*$B$25 -> 1221.0435 | AO42: =SUM(AC42:AN42) -> 13771.099 | AP42: =AP18*$B$25 -> 0 | AQ42: =AQ18*$B$25 -> 0 | AR42: =AR18*$B$25 -> 0 | AS42: =AS18*$B$25 -> 0 | AT42: =AT18*$B$25 -> 0 | AU42: =AU18*$B$25 -> 0 | AV42: =AV18*$B$25 -> 0 | AW42: =AW18*$B$25 -> 0 | ... BA42: =BA18*$B$25 -> 0 | BB42: =SUM(AP42:BA42) -> 0
A43: 157001150249 Hydrocodone/APAP GR | C43: ='Download COV'!D22 -> 0 | D43: ='Download COV'!E22 -> 0 | E43: ='Download COV'!F22 -> 0 | F43: ='Download COV'!G22 -> 0 | G43: =G19*$B$25 -> 0 | H43: =H19*$B$25 -> 0 | I43: =I19*$B$25 -> 0 | J43: =J19*$B$25 -> 0 | K43: =K19*$B$25 -> 0 | L43: =L19*$B$25 -> 0 | M43: =M19*$B$25 -> 0 | N43: =N19*$B$25 -> 0 | O43: =SUM(C43:N43) -> 0 | P43: =P19*$B$25 -> 0 | Q43: =Q19*$B$25 -> 0 | R43: =R19*$B$25 -> 0 | S43: =S19*$B$25 -> 0 | T43: =T19*$B$25 -> 0 | U43: =U19*$B$25 -> 0 | V43: =V19*$B$25 -> 0 | W43: =W19*$B$25 -> 0 | ... AA43: =AA19*$B$25 -> 0 | AB43: =SUM(P43:AA43) -> 0 | AC43: =AC19*$B$25 -> 0 | AD43: =AD19*$B$25 -> 0 | AE43: =AE19*$B$25 -> 0 | AF43: =AF19*$B$25 -> 3322.5465 | AG43: =AG19*$B$25 -> 6645.2295 | AH43: =AH19*$B$25 -> 9967.776 | AI43: =AI19*$B$25 -> 11710.608 | AJ43: =AJ19*$B$25 -> 13453.44 | ... AN43: =AN19*$B$25 -> 23043.657 | AO43: =SUM(AC43:AN43) -> 121579.32 | AP43: =AP19*$B$25 -> 24708.684 | AQ43: =AQ19*$B$25 -> 26919.029 | AR43: =AR19*$B$25 -> 29129.373 | AS43: =AS19*$B$25 -> 31381.214 | AT43: =AT19*$B$25 -> 33605.39 | AU43: =AU19*$B$25 -> 0 | AV43: =AV19*$B$25 -> 0 | AW43: =AW19*$B$25 -> 0 | ... BA43: =BA19*$B$25 -> 0 | BB43: =SUM(AP43:BA43) -> 145743.69
A44: 157001150250 Oxyocodone/APAP GR | C44: ='Download COV'!D23 -> 0 | D44: ='Download COV'!E23 -> 0 | E44: ='Download COV'!F23 -> 0 | F44: ='Download COV'!G23 -> 0 | G44: =G20*$B$25 -> 0 | H44: =H20*$B$25 -> 0 | I44: =I20*$B$25 -> 0 | J44: =J20*$B$25 -> 0 | K44: =K20*$B$25 -> 0 | L44: =L20*$B$25 -> 0 | M44: =M20*$B$25 -> 0 | N44: =N20*$B$25 -> 0 | O44: =SUM(C44:N44) -> 0 | P44: =P20*$B$25 -> 0 | Q44: =Q20*$B$25 -> 0 | R44: =R20*$B$25 -> 0 | S44: =S20*$B$25 -> 0 | T44: =T20*$B$25 -> 0 | U44: =U20*$B$25 -> 0 | V44: =V20*$B$25 -> 1795.7785 | W44: =W20*$B$25 -> 3591.6936 | ... AA44: =AA20*$B$25 -> 8226.2861 | AB44: =SUM(P44:AA44) -> 32614.989 | AC44: =AC20*$B$25 -> 9402.2125 | AD44: =AD20*$B$25 -> 10786.55 | AE44: =AE20*$B$25 -> 12171.024 | AF44: =AF20*$B$25 -> 13373.475 | AG44: =AG20*$B$25 -> 14575.926 | AH44: =AH20*$B$25 -> 15778.513 | AI44: =AI20*$B$25 -> 17121.843 | AJ44: =AJ20*$B$25 -> 18465.446 | ... AN44: =AN20*$B$25 -> 23781.185 | AO44: =SUM(AC44:AN44) -> 198855.19 | AP44: =AP20*$B$25 -> 23338.585 | AQ44: =AQ20*$B$25 -> 23391.724 | AR44: =AR20*$B$25 -> 23452.643 | AS44: =AS20*$B$25 -> 26266.883 | AT44: =AT20*$B$25 -> 27255.664 | AU44: =AU20*$B$25 -> 0 | AV44: =AV20*$B$25 -> 0 | AW44: =AW20*$B$25 -> 0 | ... BA44: =BA20*$B$25 -> 0 | BB44: =SUM(AP44:BA44) -> 123705.5
A45: Brands | B45: Total | C45: =SUM(C31:C44) -> 5080 | D45: =SUM(D31:D44) -> 6150 | E45: =SUM(E31:E44) -> 3126 | F45: =SUM(F31:F44) -> 30971.04 | G45: =SUM(G31:G44) -> 10042.873 | H45: =SUM(H31:H44) -> 7818.1368 | I45: =SUM(I31:I44) -> 8960.5236 | J45: =SUM(J31:J44) -> 10615.76 | ... BB45: =SUM(BB31:BB44) -> 288349.8
A48: Calculated Freight per Bottle | C48: Oct | D48: Nov | E48: Dec | F48: Jan | G48: Feb | H48: Mar | I48: Apr | J48: May | K48: =K30 -> Jun | L48: =L30 -> Jul | M48: =M30 -> Aug | N48: =N30 -> Sep | O48: YTD FY13 | P48: Oct | Q48: Nov | R48: Dec | S48: Jan | T48: Feb | U48: Mar | V48: Apr | W48: May | X48: Jun | Y48: Jul | Z48: Aug | AA48: Sep | AB48: =AB30 -> WF FY14 | AC48: Oct | AD48: Nov | AE48: Dec | AF48: Jan | AG48: Feb | AH48: Mar | AI48: Apr | AJ48: May | AK48: Jun | AL48: Jul | AM48: Aug | AN48: Sep | AO48: =AO30 -> WF FY15 | AP48: Oct | AQ48: Nov | AR48: Dec | AS48: Jan | AT48: Feb | AU48: Mar | AV48: Apr | AW48: May | AX48: Jun | AY48: Jul | AZ48: Aug | BA48: Sep | BB48: =BB30 -> WF FY16
A49: 157001150245 Tofranil-PM/ImipraPam Frt Exp | C49: =IF(ISERROR(C31/C7)=TRUE,0,(C31/C7)) -> 0 | D49: =IF(ISERROR(D31/D7)=TRUE,0,(D31/D7)) -> 0 | E49: =IF(ISERROR(E31/E7)=TRUE,0,(E31/E7)) -> 0.078651391 | F49: =IF(ISERROR(F31/F7)=TRUE,0,(F31/F7)) -> 0.19166587 | G49: =IF(ISERROR(G31/G7)=TRUE,0,(G31/G7)) -> 0.1365 | H49: =IF(ISERROR(H31/H7)=TRUE,0,(H31/H7)) -> 0.1365 | I49: =IF(ISERROR(I31/I7)=TRUE,0,(I31/I7)) -> 0.1365 | J49: =IF(ISERROR(J31/J7)=TRUE,0,(J31/J7)) -> 0.1365 | ... N49: =IF(ISERROR(N31/N7)=TRUE,0,(N31/N7)) -> 0.1365 | O49: =IF(ISERROR(SUM(C31:N31)/(SUM(C7:N7)))=TRUE,0,(SUM(C31:N31)/(SUM(C7:N7)))) -> 0.11490125 | P49: =IF(ISERROR(P31/P7)=TRUE,0,(P31/P7)) -> 0.1365 | Q49: =IF(ISERROR(Q31/Q7)=TRUE,0,(Q31/Q7)) -> 0.1365 | R49: =IF(ISERROR(R31/R7)=TRUE,0,(R31/R7)) -> 0.1365 | S49: =IF(ISERROR(S31/S7)=TRUE,0,(S31/S7)) -> 0.1365 | T49: =IF(ISERROR(T31/T7)=TRUE,0,(T31/T7)) -> 0.1365 | U49: =IF(ISERROR(U31/U7)=TRUE,0,(U31/U7)) -> 0.1365 | V49: =IF(ISERROR(V31/V7)=TRUE,0,(V31/V7)) -> 0.1365 | W49: =IF(ISERROR(W31/W7)=TRUE,0,(W31/W7)) -> 0.1365 | ... BB49: =IF(ISERROR(BB31/BB7)=TRUE,0,(BB31/BB7)) -> 0.1365
A50: 157001150225 Frt Exp-CNS Non-Promoted Prod | C50: =IF(ISERROR(C32/C8)=TRUE,0,(C32/C8)) -> 0.1951754 | D50: =IF(ISERROR(D32/D8)=TRUE,0,(D32/D8)) -> 0.18886502 | E50: =IF(ISERROR(E32/E8)=TRUE,0,(E32/E8)) -> 0.077148618 | F50: =IF(ISERROR(F32/F8)=TRUE,0,(F32/F8)) -> 0.19226821 | G50: =IF(ISERROR(G32/G8)=TRUE,0,(G32/G8)) -> 0.1365 | H50: =IF(ISERROR(H32/H8)=TRUE,0,(H32/H8)) -> 0.1365 | I50: =IF(ISERROR(I32/I8)=TRUE,0,(I32/I8)) -> 0.1365 | J50: =IF(ISERROR(J32/J8)=TRUE,0,(J32/J8)) -> 0.1365 | ... N50: =IF(ISERROR(N32/N8)=TRUE,0,(N32/N8)) -> 0.1365 | O50: =IF(ISERROR(SUM(C32:N32)/(SUM(C8:N8)))=TRUE,0,(SUM(C32:N32)/(SUM(C8:N8)))) -> 0.141447 | P50: =IF(ISERROR(P32/P8)=TRUE,0,(P32/P8)) -> 0.1365 | Q50: =IF(ISERROR(Q32/Q8)=TRUE,0,(Q32/Q8)) -> 0.1365 | R50: =IF(ISERROR(R32/R8)=TRUE,0,(R32/R8)) -> 0.1365 | S50: =IF(ISERROR(S32/S8)=TRUE,0,(S32/S8)) -> 0.1365 | T50: =IF(ISERROR(T32/T8)=TRUE,0,(T32/T8)) -> 0.1365 | U50: =IF(ISERROR(U32/U8)=TRUE,0,(U32/U8)) -> 0.1365 | V50: =IF(ISERROR(V32/V8)=TRUE,0,(V32/V8)) -> 0.1365 | W50: =IF(ISERROR(W32/W8)=TRUE,0,(W32/W8)) -> 0.1365 | ... BB50: =IF(ISERROR(BB32/BB8)=TRUE,0,(BB32/BB8)) -> 0.1365
A52: 157001150251 Pennsaid Frt Expense | C52: =IF(ISERROR(C34/C10)=TRUE,0,(C34/C10)) -> 0.18241758 | D52: =IF(ISERROR(D34/D10)=TRUE,0,(D34/D10)) -> 0.17720075 | E52: =IF(ISERROR(E34/E10)=TRUE,0,(E34/E10)) -> 0.075124808 | F52: =IF(ISERROR(F34/F10)=TRUE,0,(F34/F10)) -> 0.19220169 | G52: =IF(ISERROR(G34/G10)=TRUE,0,(G34/G10)) -> 0.1365 | H52: =IF(ISERROR(H34/H10)=TRUE,0,(H34/H10)) -> 0.1365 | I52: =IF(ISERROR(I34/I10)=TRUE,0,(I34/I10)) -> 0.1365 | J52: =IF(ISERROR(J34/J10)=TRUE,0,(J34/J10)) -> 0.1365 | ... N52: =IF(ISERROR(N34/N10)=TRUE,0,(N34/N10)) -> 0.1365 | O52: =IF(ISERROR(SUM(C34:N34)/(SUM(C10:N10)))=TRUE,0,(SUM(C34:N34)/(SUM(C10:N10)))) -> 0.13852839 | P52: =IF(ISERROR(P34/P10)=TRUE,0,(P34/P10)) -> 0.1365 | Q52: =IF(ISERROR(Q34/Q10)=TRUE,0,(Q34/Q10)) -> 0.1365 | R52: =IF(ISERROR(R34/R10)=TRUE,0,(R34/R10)) -> 0.1365 | S52: =IF(ISERROR(S34/S10)=TRUE,0,(S34/S10)) -> 0.1365 | T52: =IF(ISERROR(T34/T10)=TRUE,0,(T34/T10)) -> 0.1365 | U52: =IF(ISERROR(U34/U10)=TRUE,0,(U34/U10)) -> 0.1365 | V52: =IF(ISERROR(V34/V10)=TRUE,0,(V34/V10)) -> 0.1365 | W52: =IF(ISERROR(W34/W10)=TRUE,0,(W34/W10)) -> 0.1365 | ... BB52: =IF(ISERROR(BB34/BB10)=TRUE,0,(BB34/BB10)) -> 0
...

Sheet Pharm Demand b4
A1: Outfreight Expense - 7171
C2: FY10 Working Forecast
C3: Oct | D3: Nov | E3: Dec | F3: Jan | G3: Feb | H3: Mar | I3: Apr | J3: May | K3: Jun | L3: Jul | M3: Aug | N3: Sep | O3: Full Year
A4: 157001000211 Hydrocodone Products | B4: Sales Volume | C4: 1345130 | D4: 1471821 | E4: 1346264 | F4: 1200818 | G4: 1728087 | H4: 1336101 | I4: 1408275 | J4: 1720179 | K4: 1431618 | L4: 1436689 | M4: 1701222 | N4: 1472273 | O4: 17598477
A5: 157001000210 Oxycodone Products | B5: Sales Volume | C5: 568180.11 | D5: 724518.11 | E5: 557520.11 | F5: 477505.07 | G5: 697911.07 | H5: 477342.07 | I5: 516738.48 | J5: 690798.48 | K5: 520504.48 | L5: 537789.11 | M5: 689765.11 | N5: 565202.11 | O5: 7023774.3
A6: 157001000244 Oxycodone APAP Products | B6: Sales Volume | C6: 817000 | D6: 903185 | E6: 791936 | F6: 724054 | G6: 1015560 | H6: 783302 | I6: 826298 | J6: 1027937 | K6: 839548 | L6: 842285 | M6: 995584 | N6: 860878 | O6: 10427567
A7: 157001000222 ADHD | B7: Sales Volume | C7: 147710 | D7: 157485 | E7: 139903 | F7: 120838 | G7: 174345 | H7: 135215 | I7: 141377 | J7: 169676 | K7: 141415 | L7: 140762 | M7: 163700 | N7: 141123 | O7: 1773549
A8: 157001000227 Oxycodone ER | B8: Sales Volume | C8: 0 | D8: 0 | E8: 0 | F8: 0 | G8: 0 | H8: 0 | I8: 0 | J8: 0 | K8: 0 | L8: 0 | M8: 0 | N8: 0 | O8: 0
A9: Morphine ER | B9: Sales Volume | C9: 129558 | D9: 171034 | E9: 130265 | F9: 131991 | G9: 180135 | H9: 128773 | I9: 135659 | J9: 177744 | K9: 137777 | L9: 138205 | M9: 176268 | N9: 147382 | O9: 1784791
A10: Hydromorphone | B10: Sales Volume | C10: 66453.709 | D10: 94070.588 | E10: 253332.41 | F10: 152406 | G10: 208176 | H10: 148950 | I10: 157051 | J10: 205966 | K10: 159794 | L10: 160438 | M10: 204801 | N10: 171401 | O10: 1982839.7
A11: Methadone Generic | B11: Sales Volume | C11: 386382 | D11: 503539 | E11: 380155 | F11: 380399 | G11: 514297 | H11: 364256 | I11: 379759 | J11: 491787 | K11: 377625 | L11: 374752 | M11: 472544 | N11: 391042 | O11: 5016537
A12: APAP/Codeine | B12: Sales Volume | C12: 87117 | D12: 93644 | E12: 80868 | F12: 71566 | G12: 100949 | H12: 77147 | I12: 80078 | J12: 95666 | K12: 75598 | L12: 78061 | M12: 91650 | N12: 76961 | O12: 1009305
A13: APAP/Propoxyphene | B13: Sales Volume | C13: 0 | D13: 0 | E13: 0 | F13: 0 | G13: 0 | H13: 0 | I13: 0 | J13: 0 | K13: 0 | L13: 0 | M13: 0 | N13: 0 | O13: 0
A14: Fentanyl Lozenge | B14: Sales Volume | C14: 0 | D14: 31802 | E14: 14095 | F14: 13762 | G14: 19153 | H14: 13618 | I14: 14238 | J14: 18507 | K14: 14238 | L14: 14170 | M14: 17935 | N14: 14878 | O14: 186396
A15: Fentanyl Patch | B15: Sales Volume | C15: 0 | D15: 0 | E15: 0 | F15: 0 | G15: 0 | H15: 0 | I15: 114361 | J15: 148669 | K15: 114361 | L15: 113817 | M15: 144066 | N15: 119508 | O15: 754782
... A26: International | B26: Sales Volume | C26: 19000 | D26: 0 | E26: 0 | F26: 0 | G26: 0 | H26: 26000 | I26: 17200 | J26: 0 | K26: 800 | L26: 0 | M26: 0 | N26: 25400 | O26: 88400
O27: =SUM(O4:O26) -> 50288941
A28: Freight per bottle for INTL | B28: 1.7 | C28: (FY10 forecast estimate)
A29: Freight per bottle, except AT | B29: =0.09*1.07*1.052 -> 0.1013076 | C29: (FY09 forecast = .09 + 7% inflation increase + 5% addl per JC)
A30: Freight per bottle for AT | B30: =3.45*1.07*1.052 -> 3.883458 | C30: (FY09 forecast = 3.45 + 7% inflation increase + 5% addl per JC)
A31: Freight for Fentanyl Lozenge and Patch | B31: 50% of bgt | C31: (estimate) | P31: FYI only
O32: FY10 | P32: FY09
A33: 157001150211 Frt Exp-Hydrocodone Products | B33: Dollars | C33: =C4*$B$29 -> 136271.89 | D33: =D4*$B$29 -> 149106.65 | E33: =E4*$B$29 -> 136386.77 | F33: =F4*$B$29 -> 121651.99 | G33: =G4*$B$29 -> 175068.35 | H33: =H4*$B$29 -> 135357.19 | I33: =I4*$B$29 -> 142668.96 | J33: =J4*$B$29 -> 174267.21 | ... M33: =M4*$B$29 -> 172346.72 | N33: =N4*$B$29-2372 -> 146780.44 | O33: =SUM(C33:N33) -> 1780487.5 | P33: 1604044.2
A34: 157001150210 Frt Exp-Oxycodone Products | B34: Dollars | C34: =C5*$B$29 -> 57560.964 | D34: =D5*$B$29 -> 73399.191 | E34: =E5*$B$29 -> 56481.025 | F34: =F5*$B$29 -> 48374.893 | G34: =G5*$B$29 -> 70703.696 | H34: =H5*$B$29 -> 48358.38 | I34: =I5*$B$29 -> 52349.535 | J34: =J5*$B$29 -> 69983.136 | ... N34: =N5*$B$29 -> 57259.269 | O34: =SUM(C34:N34) -> 711561.72 | P34: 939784.42
A35: 157001150244 Oxycodone APAP-Frt Exp | B35: Dollars | C35: =C6*$B$29 -> 82768.309 | D35: =D6*$B$29 -> 91499.505 | E35: =E6*$B$29 -> 80229.136 | F35: =F6*$B$29 -> 73352.173 | G35: =G6*$B$29 -> 102883.95 | H35: =H6*$B$29 -> 79354.446 | I35: =I6*$B$29 -> 83710.267 | J35: =J6*$B$29 -> 104137.83 | ... N35: =N6*$B$29 -> 87213.484 | O35: =SUM(C35:N35) -> 1056391.8 | P35: 1010573.7
A36: 157001150222 Frt Exp-ADHD | B36: Dollars | C36: =C7*$B$29 -> 14964.146 | D36: =D7*$B$29 -> 15954.427 | E36: =E7*$B$29 -> 14173.237 | F36: =F7*$B$29 -> 12241.808 | G36: =G7*$B$29 -> 17662.474 | H36: =H7*$B$29 -> 13698.307 | I36: =I7*$B$29 -> 14322.565 | J36: =J7*$B$29 -> 17189.468 | ... N36: =N7*$B$29 -> 14296.832 | O36: =SUM(C36:N36) -> 179673.99 | P36: 173266.69
A37: 157001150227 Oxycodone ER Products Freight | B37: Dollars | C37: =C8*$B$29 -> 0 | D37: =D8*$B$29 -> 0 | E37: =E8*$B$29 -> 0 | F37: =F8*$B$29 -> 0 | G37: =G8*$B$29 -> 0 | H37: =H8*$B$29 -> 0 | I37: =I8*$B$29 -> 0 | J37: =J8*$B$29 -> 0 | ... N37: =N8*$B$29 -> 0 | O37: =SUM(C37:N37) -> 0 | P37: 118511
A38: 157001150229 Morphine ER-Frt Exp | B38: Dollars | C38: =C9*$B$29 -> 13125.21 | D38: =D9*$B$29 -> 17327.044 | E38: =E9*$B$29 -> 13196.835 | F38: =F9*$B$29 -> 13371.691 | G38: =G9*$B$29 -> 18249.045 | H38: =H9*$B$29 -> 13045.684 | I38: =I9*$B$29 -> 13743.288 | J38: =J9*$B$29 -> 18006.818 | ... N38: =N9*$B$29 -> 14930.917 | O38: =SUM(C38:N38) -> 180812.89 | P38: 172797.05
A39: 157001150230 Hydromorphone-Frt Exp | B39: Dollars | C39: =C10*$B$29 -> 6732.2658 | D39: =D10*$B$29 -> 9530.0655 | E39: =E10*$B$29 -> 25664.499 | F39: =F10*$B$29 -> 15439.886 | G39: =G10*$B$29 -> 21089.811 | H39: =H10*$B$29 -> 15089.767 | I39: =I10*$B$29 -> 15910.46 | J39: =J10*$B$29 -> 20865.921 | ... N39: =N10*$B$29 -> 17364.224 | O39: =SUM(C39:N39) -> 200876.73 | P39: 191280.17
A40: 157001150231 Methadone Generics-Frt Exp | B40: Dollars | C40: =C11*$B$29 -> 39143.433 | D40: =D11*$B$29 -> 51012.328 | E40: =E11*$B$29 -> 38512.591 | F40: =F11*$B$29 -> 38537.31 | G40: =G11*$B$29 -> 52102.195 | H40: =H11*$B$29 -> 36901.901 | I40: =I11*$B$29 -> 38472.473 | J40: =J11*$B$29 -> 49821.761 | ... N40: =N11*$B$29 -> 39615.527 | O40: =SUM(C40:N40) -> 508213.32 | P40: 510997.11
A41: 157001150232 APAP Codeine-Frt Exp | B41: Dollars | C41: =C12*$B$29 -> 8825.6142 | D41: =D12*$B$29 -> 9486.8489 | E41: =E12*$B$29 -> 8192.543 | F41: =F12*$B$29 -> 7250.1797 | G41: =G12*$B$29 -> 10226.901 | H41: =H12*$B$29 -> 7815.5774 | I41: =I12*$B$29 -> 8112.51 | J41: =J12*$B$29 -> 9691.6929 | ... N41: =N12*$B$29 -> 7796.7342 | O41: =SUM(C41:N41) -> 102250.27 | P41: 103658.43
A42: 157001150233 APAP Propoxyphene-Frt Exp | B42: Dollars | C42: =C13*$B$29 -> 0 | D42: =D13*$B$29 -> 0 | E42: =E13*$B$29 -> 0 | F42: =F13*$B$29 -> 0 | G42: =G13*$B$29 -> 0 | H42: =H13*$B$29 -> 0 | I42: =I13*$B$29 -> 0 | J42: =J13*$B$29 -> 0 | ... N42: =N13*$B$29 -> 0 | O42: =SUM(C42:N42) -> 0 | P42: 51178.92
A43: 157001150234 Fentanyl Lozenge-Frt Exp | B43: Dollars | C43: 0 | D43: =44323*0.5 -> 22161.5 | E43: =31586*0.5 -> 15793 | F43: =32279*0.5 -> 16139.5 | G43: =32092*0.5 -> 16046 | H43: =31905*0.5 -> 15952.5 | I43: =31720*0.5 -> 15860 | J43: =31535*0.5 -> 15767.5 | K43: =31157*0.5 -> 15578.5 | L43: =31024*0.5 -> 15512 | M43: =30891*0.5 -> 15445.5 | N43: =30759*0.5 -> 15379.5 | O43: =SUM(C43:N43) -> 179635.5 | P43: 0
A44: 157001150236 Fentanyl Patch-Frt Exp | B44: Dollars | C44: 0 | D44: 0 | E44: 0 | F44: 0 | G44: 0 | H44: 0 | I44: =36813*0.5 -> 18406.5 | J44: =36813*0.5 -> 18406.5 | K44: =36813*0.5 -> 18406.5 | L44: =36813*0.5 -> 18406.5 | M44: =36813*0.5 -> 18406.5 | N44: =36813*0.5 -> 18406.5 | O44: =SUM(C44:N44) -> 110439 | P44: 0
A45: 157001150209 FREIGHT | B45: Dollars | C45: =C16*$B$29 -> 11874.061 | D45: =D16*$B$29 -> 14066.256 | E45: =E16*$B$29 -> 11486.357 | F45: =F16*$B$29 -> 10742.861 | G45: =G16*$B$29 -> 15063.528 | H45: =H16*$B$29 -> 11199.859 | I45: =I16*$B$29 -> 11765.561 | J45: =J16*$B$29 -> 14754.54 | ... N45: =N16*$B$29 -> 7509.4258 | O45: =SUM(C45:N45) -> 136425.58 | P45: 231446.72
A46: 157001150226 Zydus Freight Expense | B46: Dollars | C46: =C17*$B$29 -> 0 | D46: =D17*$B$29 -> 0 | E46: =E17*$B$29 -> 0 | F46: =F17*$B$29 -> 0 | G46: =G17*$B$29 -> 0 | H46: =H17*$B$29 -> 0 | I46: =I17*$B$29 -> 0 | J46: =J17*$B$29 -> 0 | ... N46: =N17*$B$29 -> 0 | O46: =SUM(C46:N46) -> 0 | P46: 59307.39
A47: 157001150246 Restoril/Temazepam Frt Expense | B47: Dollars | C47: =C18*$B$29 -> 725.76765 | D47: =D18*$B$29 -> 922.91224 | E47: =E18*$B$29 -> 669.64324 | F47: =F18*$B$29 -> 639.65619 | G47: =G18*$B$29 -> 949.55613 | H47: =H18*$B$29 -> 650.19218 | I47: =I18*$B$29 -> 664.27393 | J47: =J18*$B$29 -> 547.16235 | ... N47: =N18*$B$29 -> 404.92648 | O47: =SUM(C47:N47) -> 7435.9778 | P47: 14092.33
A48: 157001150245 Tofranil-PM/ImipraPam Frt Exp | B48: Dollars | C48: =C19*$B$29 -> 1104.8607 | D48: =D19*$B$29 -> 1285.4921 | E48: =E19*$B$29 -> 1046.8114 | F48: =F19*$B$29 -> 1005.174 | G48: =G19*$B$29 -> 1382.1396 | H48: =H19*$B$29 -> 1102.2267 | I48: =I19*$B$29 -> 1104.8607 | J48: =J19*$B$29 -> 1331.7897 | ... N48: =N19*$B$29 -> 1154.4001 | O48: =SUM(C48:N48) -> 14062.001 | P48: 13397.13
A49: 157001150225 Frt Exp-CNS Non-Promoted Prod | B49: Dollars | C49: =C20*$B$29 -> 700.64336 | D49: =D20*$B$29 -> 814.31049 | E49: =E20*$B$29 -> 651.30656 | F49: =F20*$B$29 -> 618.78682 | G49: =G20*$B$29 -> 839.33347 | H49: =H20*$B$29 -> 656.06802 | I49: =I20*$B$29 -> 646.34249 | J49: =J20*$B$29 -> 774.4966 | ... N49: =N20*$B$29 -> 629.1202 | O49: =SUM(C49:N49) -> 8318.1644 | P49: 10716.3
A50: 157001150224 Frt Exp-Other Brand Products | B50: Dollars | C50: =C21*$B$29 -> 85.199692 | D50: =D21*$B$29 -> 79.425158 | E50: =E21*$B$29 -> 54.706104 | F50: =F21*$B$29 -> 47.209342 | G50: =G21*$B$29 -> 61.493713 | H50: =H21*$B$29 -> 47.108034 | I50: =I21*$B$29 -> 46.905419 | J50: =J21*$B$29 -> 56.630948 | ... N50: =N21*$B$29 -> 49.134186 | O50: =SUM(C50:N50) -> 678.25438 | P50: 1534.96
...

Sheet Upload to COV
C2: LC
C3: Input
C4: FY 2013 | D4: FY 2013 | E4: FY 2013 | F4: FY 2013 | G4: FY 2013 | H4: FY 2013 | I4: FY 2013 | J4: FY 2013 | K4: FY 2013 | L4: FY 2013 | M4: FY 2013 | N4: FY 2013 | O4: FY 2013 | P4: FY 2014 | Q4: FY 2014 | R4: FY 2014 | S4: FY 2014 | T4: FY 2014 | U4: FY 2014 | V4: FY 2014 | W4: FY 2014 | X4: FY 2014 | Y4: FY 2014 | Z4: FY 2014 | AA4: FY 2014 | AB4: FY 2014 | AC4: FY 2015 | AD4: FY 2015 | AE4: FY 2015 | AF4: FY 2015 | AG4: FY 2015 | AH4: FY 2015 | AI4: FY 2015 | AJ4: FY 2015 | AK4: FY 2015 | AL4: FY 2015 | AM4: FY 2015 | AN4: FY 2015 | AO4: FY 2015 | AP4: FY 2016 | AQ4: FY 2016 | AR4: FY 2016 | AS4: FY 2016 | AT4: FY 2016 | AU4: FY 2016 | AV4: FY 2016 | AW4: FY 2016 | AX4: FY 2016 | AY4: FY 2016 | AZ4: FY 2016 | BA4: FY 2016 | BB4: FY 2016
C5: Working Forecast | D5: Working Forecast | E5: Working Forecast | F5: Working Forecast | G5: Working Forecast | H5: Working Forecast | I5: Working Forecast | J5: Working Forecast | K5: Working Forecast | L5: Working Forecast | M5: Working Forecast | N5: Working Forecast | O5: Working Forecast | P5: Working Forecast | Q5: Working Forecast | R5: Working Forecast | S5: Working Forecast | T5: Working Forecast | U5: Working Forecast | V5: Working Forecast | W5: Working Forecast | X5: Working Forecast | Y5: Working Forecast | Z5: Working Forecast | AA5: Working Forecast | AB5: Working Forecast | AC5: Working Forecast | AD5: Working Forecast | AE5: Working Forecast | AF5: Working Forecast | AG5: Working Forecast | AH5: Working Forecast | AI5: Working Forecast | AJ5: Working Forecast | AK5: Working Forecast | AL5: Working Forecast | AM5: Working Forecast | AN5: Working Forecast | AO5: Working Forecast | AP5: Working Forecast | AQ5: Working Forecast | AR5: Working Forecast | AS5: Working Forecast | AT5: Working Forecast | AU5: Working Forecast | AV5: Working Forecast | AW5: Working Forecast | AX5: Working Forecast | AY5: Working Forecast | AZ5: Working Forecast | BA5: Working Forecast | BB5: Working Forecast
C6: Oct | D6: Nov | E6: Dec | F6: Jan | G6: Feb | H6: Mar | I6: Apr | J6: May | K6: Jun | L6: Jul | M6: Aug | N6: Sep | O6: Annual | P6: Oct | Q6: Nov | R6: Dec | S6: Jan | T6: Feb | U6: Mar | V6: Apr | W6: May | X6: Jun | Y6: Jul | Z6: Aug | AA6: Sep | AB6: Annual | AC6: Oct | AD6: Nov | AE6: Dec | AF6: Jan | AG6: Feb | AH6: Mar | AI6: Apr | AJ6: May | AK6: Jun | AL6: Jul | AM6: Aug | AN6: Sep | AO6: Annual | AP6: Oct | AQ6: Nov | AR6: Dec | AS6: Jan | AT6: Feb | AU6: Mar | AV6: Apr | AW6: May | AX6: Jun | AY6: Jul | AZ6: Aug | BA6: Sep | BB6: Annual
A7: ='Pharm Demand'!A31 -> 157001150245 Tofranil-PM/ImipraPam Frt Exp | B7: 7171i | C7: ='Pharm Demand'!C31 -> 0 | D7: ='Pharm Demand'!D31 -> 0 | E7: ='Pharm Demand'!E31 -> 42 | F7: ='Pharm Demand'!F31 -> 46 | G7: ='Pharm Demand'!G31 -> 75.075 | H7: ='Pharm Demand'!H31 -> 58.2855 | I7: ='Pharm Demand'!I31 -> 62.517 | J7: ='Pharm Demand'!J31 -> 70.8435 | ... N7: ='Pharm Demand'!N31 -> 55.8285 | O7: =SUM(C7:N7) -> 590.593 | P7: ='Pharm Demand'!P31 -> 54.1905 | Q7: ='Pharm Demand'!Q31 -> 62.517 | R7: ='Pharm Demand'!R31 -> 50.3685 | S7: ='Pharm Demand'!S31 -> 49.2765 | T7: ='Pharm Demand'!T31 -> 62.1075 | U7: ='Pharm Demand'!U31 -> 50.6415 | V7: ='Pharm Demand'!V31 -> 49.5495 | W7: ='Pharm Demand'!W31 -> 56.784 | ... AA7: ='Pharm Demand'!AA31 -> 46.137 | AB7: =SUM(P7:AA7) -> 636.2265 | AC7: ='Pharm Demand'!AC31 -> 46.0005 | AD7: ='Pharm Demand'!AD31 -> 54.1905 | AE7: ='Pharm Demand'!AE31 -> 42.9975 | AF7: ='Pharm Demand'!AF31 -> 41.496 | AG7: ='Pharm Demand'!AG31 -> 54.6 | AH7: ='Pharm Demand'!AH31 -> 46.956 | AI7: ='Pharm Demand'!AI31 -> 44.772 | AJ7: ='Pharm Demand'!AJ31 -> 53.781 | ... AN7: ='Pharm Demand'!AN31 -> 41.6325 | AO7: =SUM(AC7:AN7) -> 571.935 | AP7: ='Pharm Demand'!AP31 -> 49.959 | AQ7: ='Pharm Demand'!AQ31 -> 39.312 | AR7: ='Pharm Demand'!AR31 -> 45.4545 | AS7: ='Pharm Demand'!AS31 -> 43.407 | AT7: ='Pharm Demand'!AT31 -> 43.66635 | AU7: ='Pharm Demand'!AU31 -> 0 | AV7: ='Pharm Demand'!AV31 -> 0 | AW7: ='Pharm Demand'!AW31 -> 0 | ... BA7: ='Pharm Demand'!BA31 -> 0 | BB7: =SUM(AP7:BA7) -> 221.79885
A8: ='Pharm Demand'!A32 -> 157001150225 Frt Exp-CNS Non-Promoted Prod | B8: 7171i | C8: ='Pharm Demand'!C32 -> 890 | D8: ='Pharm Demand'!D32 -> 1055 | E8: ='Pharm Demand'!E32 -> 605 | F8: ='Pharm Demand'!F32 -> 751 | G8: ='Pharm Demand'!G32 -> 935.62102 | H8: ='Pharm Demand'!H32 -> 712.09193 | I8: ='Pharm Demand'!I32 -> 733.28621 | J8: ='Pharm Demand'!J32 -> 772.1805 | ... N8: ='Pharm Demand'!N32 -> 597.8163 | O8: =SUM(C8:N8) -> 8934.2226 | P8: ='Pharm Demand'!P32 -> 702.89955 | Q8: ='Pharm Demand'!Q32 -> 716.625 | R8: ='Pharm Demand'!R32 -> 612.885 | S8: ='Pharm Demand'!S32 -> 666.55904 | T8: ='Pharm Demand'!T32 -> 737.919 | U8: ='Pharm Demand'!U32 -> 635.1345 | V8: ='Pharm Demand'!V32 -> 672.9047 | W8: ='Pharm Demand'!W32 -> 702.0195 | ... AA8: ='Pharm Demand'!AA32 -> 641.9595 | AB8: =SUM(P8:AA8) -> 8116.8119 | AC8: ='Pharm Demand'!AC32 -> 612.5818 | AD8: ='Pharm Demand'!AD32 -> 708.708 | AE8: ='Pharm Demand'!AE32 -> 599.9175 | AF8: ='Pharm Demand'!AF32 -> 578.82977 | AG8: ='Pharm Demand'!AG32 -> 711.711 | AH8: ='Pharm Demand'!AH32 -> 638.6835 | AI8: ='Pharm Demand'!AI32 -> 611.39432 | AJ8: ='Pharm Demand'!AJ32 -> 700.9275 | ... AN8: ='Pharm Demand'!AN32 -> 587.9055 | AO8: =SUM(AC8:AN8) -> 7691.3897 | AP8: ='Pharm Demand'!AP32 -> 641.14405 | AQ8: ='Pharm Demand'!AQ32 -> 564.564 | AR8: ='Pharm Demand'!AR32 -> 604.51418 | AS8: ='Pharm Demand'!AS32 -> 601.64768 | AT8: ='Pharm Demand'!AT32 -> 625.24398 | AU8: ='Pharm Demand'!AU32 -> 0 | AV8: ='Pharm Demand'!AV32 -> 0 | AW8: ='Pharm Demand'!AW32 -> 0 | ... BA8: ='Pharm Demand'!BA32 -> 0 | BB8: =SUM(AP8:BA8) -> 3037.1139
A10: 157001150251 Pennsaid Frt Expense | B10: 7171i | C10: ='Pharm Demand'!C34 -> 2075 | D10: ='Pharm Demand'!D34 -> 2641 | E10: ='Pharm Demand'!E34 -> 1565 | F10: ='Pharm Demand'!F34 -> 2371 | G10: ='Pharm Demand'!G34 -> 3388.2488 | H10: ='Pharm Demand'!H34 -> 2482.3439 | I10: ='Pharm Demand'!I34 -> 3936.7669 | J10: ='Pharm Demand'!J34 -> 5143.0628 | ... N10: ='Pharm Demand'!N34 -> 3300.4321 | O10: =SUM(C10:N10) -> 36707.347 | P10: ='Pharm Demand'!P34 -> 2711.6328 | Q10: ='Pharm Demand'!Q34 -> 1802.6256 | R10: ='Pharm Demand'!R34 -> 1194.7814 | S10: ='Pharm Demand'!S34 -> 775.40845 | T10: ='Pharm Demand'!T34 -> 507.84481 | U10: ='Pharm Demand'!U34 -> 324.07744 | V10: ='Pharm Demand'!V34 -> 324.64067 | W10: ='Pharm Demand'!W34 -> 328.22328 | ... AA10: ='Pharm Demand'!AA34 -> 339.03812 | AB10: =SUM(P10:AA10) -> 9311.8841 | AC10: ='Pharm Demand'!AC34 -> 341.44711 | AD10: ='Pharm Demand'!AD34 -> 293.33626 | AE10: ='Pharm Demand'!AE34 -> 184.9982 | AF10: ='Pharm Demand'!AF34 -> 110.86985 | AG10: ='Pharm Demand'!AG34 -> 62.958981 | AH10: ='Pharm Demand'!AH34 -> 29.991041 | AI10: ='Pharm Demand'!AI34 -> 7.4783745 | AJ10: ='Pharm Demand'!AJ34 -> 0 | ... AN10: ='Pharm Demand'!AN34 -> 0 | AO10: =SUM(AC10:AN10) -> 1031.0798 | AP10: ='Pharm Demand'!AP34 -> 0 | AQ10: ='Pharm Demand'!AQ34 -> 0 | AR10: ='Pharm Demand'!AR34 -> 0 | AS10: ='Pharm Demand'!AS34 -> 0 | AT10: ='Pharm Demand'!AT34 -> 0 | AU10: ='Pharm Demand'!AU34 -> 0 | AV10: ='Pharm Demand'!AV34 -> 0 | AW10: ='Pharm Demand'!AW34 -> 0 | ... BA10: ='Pharm Demand'!BA34 -> 0 | BB10: =SUM(AP10:BA10) -> 0
A11: 157001150255 Pennsaid 2% Pump Frt Expense | B11: 7171i | C11: ='Pharm Demand'!C35 -> 0 | D11: ='Pharm Demand'!D35 -> 0 | E11: ='Pharm Demand'!E35 -> 0 | F11: ='Pharm Demand'!F35 -> 0 | G11: ='Pharm Demand'!G35 -> 0 | H11: ='Pharm Demand'!H35 -> 0 | I11: ='Pharm Demand'!I35 -> 0 | J11: ='Pharm Demand'!J35 -> 0 | ... N11: ='Pharm Demand'!N35 -> 0 | O11: =SUM(C11:N11) -> 0 | P11: ='Pharm Demand'!P35 -> 2967.3735 | Q11: ='Pharm Demand'!Q35 -> 2050.4249 | R11: ='Pharm Demand'!R35 -> 1801.9365 | S11: ='Pharm Demand'!S35 -> 2902.6725 | T11: ='Pharm Demand'!T35 -> 3296.5404 | U11: ='Pharm Demand'!U35 -> 2528.1165 | V11: ='Pharm Demand'!V35 -> 3098.004 | W11: ='Pharm Demand'!W35 -> 3394.6315 | ... AA11: ='Pharm Demand'!AA35 -> 3302.8905 | AB11: =SUM(P11:AA11) -> 34590.329 | AC11: ='Pharm Demand'!AC35 -> 3073.0245 | AD11: ='Pharm Demand'!AD35 -> 3105.9795 | AE11: ='Pharm Demand'!AE35 -> 2580.5325 | AF11: ='Pharm Demand'!AF35 -> 2186.8665 | AG11: ='Pharm Demand'!AG35 -> 1951.2646 | AH11: ='Pharm Demand'!AH35 -> 1779.96 | AI11: ='Pharm Demand'!AI35 -> 1653.4245 | AJ11: ='Pharm Demand'!AJ35 -> 1580.9959 | ... AN11: ='Pharm Demand'!AN35 -> 1684.41 | AO11: =SUM(AC11:AN11) -> 24508.076 | AP11: ='Pharm Demand'!AP35 -> 1687.14 | AQ11: ='Pharm Demand'!AQ35 -> 1759.485 | AR11: ='Pharm Demand'!AR35 -> 1769.04 | AS11: ='Pharm Demand'!AS35 -> 1820.455 | AT11: ='Pharm Demand'!AT35 -> 1861.405 | AU11: ='Pharm Demand'!AU35 -> 0 | AV11: ='Pharm Demand'!AV35 -> 0 | AW11: ='Pharm Demand'!AW35 -> 0 | ... BA11: ='Pharm Demand'!BA35 -> 0 | BB11: =SUM(AP11:BA11) -> 8897.525
A12: 157001150256 Diclofenac 2% Pump Frt Exp | B12: 7171i | C12: ='Pharm Demand'!C36 -> 0 | D12: ='Pharm Demand'!D36 -> 0 | E12: ='Pharm Demand'!E36 -> 0 | F12: ='Pharm Demand'!F36 -> 0 | G12: ='Pharm Demand'!G36 -> 0 | H12: ='Pharm Demand'!H36 -> 0 | I12: ='Pharm Demand'!I36 -> 0 | J12: ='Pharm Demand'!J36 -> 0 | ... N12: ='Pharm Demand'!N36 -> 0 | O12: =SUM(C12:N12) -> 0 | P12: ='Pharm Demand'!P36 -> 0 | Q12: ='Pharm Demand'!Q36 -> 0 | R12: ='Pharm Demand'!R36 -> 0 | S12: ='Pharm Demand'!S36 -> 0 | T12: ='Pharm Demand'!T36 -> 0 | U12: ='Pharm Demand'!U36 -> 0 | V12: ='Pharm Demand'!V36 -> 0 | W12: ='Pharm Demand'!W36 -> 0 | ... AA12: ='Pharm Demand'!AA36 -> 0 | AB12: =SUM(P12:AA12) -> 0 | AC12: ='Pharm Demand'!AC36 -> 0 | AD12: ='Pharm Demand'!AD36 -> 0 | AE12: ='Pharm Demand'!AE36 -> 0 | AF12: ='Pharm Demand'!AF36 -> 0 | AG12: ='Pharm Demand'!AG36 -> 0 | AH12: ='Pharm Demand'!AH36 -> 0 | AI12: ='Pharm Demand'!AI36 -> 0 | AJ12: ='Pharm Demand'!AJ36 -> 0 | ... AN12: ='Pharm Demand'!AN36 -> 0 | AO12: =SUM(AC12:AN12) -> 0 | AP12: ='Pharm Demand'!AP36 -> 0 | AQ12: ='Pharm Demand'!AQ36 -> 0 | AR12: ='Pharm Demand'!AR36 -> 0 | AS12: ='Pharm Demand'!AS36 -> 0 | AT12: ='Pharm Demand'!AT36 -> 0 | AU12: ='Pharm Demand'!AU36 -> 0 | AV12: ='Pharm Demand'!AV36 -> 0 | AW12: ='Pharm Demand'!AW36 -> 0 | ... BA12: ='Pharm Demand'!BA36 -> 0 | BB12: =SUM(AP12:BA12) -> 0
A13: 157001150252 Exalgo Freight Exp | B13: 7171i | C13: ='Pharm Demand'!C37 -> 1447 | D13: ='Pharm Demand'!D37 -> 1893 | E13: ='Pharm Demand'!E37 -> 705 | F13: ='Pharm Demand'!F37 -> 1303 | G13: ='Pharm Demand'!G37 -> 1757.4715 | H13: ='Pharm Demand'!H37 -> 1345.7707 | I13: ='Pharm Demand'!I37 -> 1175.1285 | J13: ='Pharm Demand'!J37 -> 1622.8485 | ... N13: ='Pharm Demand'!N37 -> 1550.6837 | O13: =SUM(C13:N13) -> 17116.318 | P13: ='Pharm Demand'!P37 -> 1617.9345 | Q13: ='Pharm Demand'!Q37 -> 2277.639 | R13: ='Pharm Demand'!R37 -> 539.721 | S13: ='Pharm Demand'!S37 -> 327.327 | T13: ='Pharm Demand'!T37 -> 571.2525 | U13: ='Pharm Demand'!U37 -> 360.2235 | V13: ='Pharm Demand'!V37 -> 382.0635 | W13: ='Pharm Demand'!W37 -> 512.5575 | ... AA13: ='Pharm Demand'!AA37 -> 109.8825 | AB13: =SUM(P13:AA13) -> 7749.924 | AC13: ='Pharm Demand'!AC37 -> 102.375 | AD13: ='Pharm Demand'!AD37 -> 132.8145 | AE13: ='Pharm Demand'!AE37 -> 85.8585 | AF13: ='Pharm Demand'!AF37 -> 85.176 | AG13: ='Pharm Demand'!AG37 -> 137.046 | AH13: ='Pharm Demand'!AH37 -> 92.274 | AI13: ='Pharm Demand'!AI37 -> 100.191 | AJ13: ='Pharm Demand'!AJ37 -> 144.144 | ... AN13: ='Pharm Demand'!AN37 -> 92.547 | AO13: =SUM(AC13:AN13) -> 1328.5545 | AP13: ='Pharm Demand'!AP37 -> 120.939 | AQ13: ='Pharm Demand'!AQ37 -> 135.681 | AR13: ='Pharm Demand'!AR37 -> 116.7075 | AS13: ='Pharm Demand'!AS37 -> 130.494 | AT13: ='Pharm Demand'!AT37 -> 122.4405 | AU13: ='Pharm Demand'!AU37 -> 0 | AV13: ='Pharm Demand'!AV37 -> 0 | AW13: ='Pharm Demand'!AW37 -> 0 | ... BA13: ='Pharm Demand'!BA37 -> 0 | BB13: =SUM(AP13:BA13) -> 626.262
A15: 157001150258 Hydromorphone ER Frt Exp | B15: 7171i | C15: ='Pharm Demand'!C39 -> 0 | D15: ='Pharm Demand'!D39 -> 0 | E15: ='Pharm Demand'!E39 -> 0 | F15: ='Pharm Demand'!F39 -> 0 | G15: ='Pharm Demand'!G39 -> 0 | H15: ='Pharm Demand'!H39 -> 0 | I15: ='Pharm Demand'!I39 -> 0 | J15: ='Pharm Demand'!J39 -> 0 | ... N15: ='Pharm Demand'!N39 -> 0 | O15: =SUM(C15:N15) -> 0 | P15: ='Pharm Demand'!P39 -> 0 | Q15: ='Pharm Demand'!Q39 -> 0 | R15: ='Pharm Demand'!R39 -> 0 | S15: ='Pharm Demand'!S39 -> 0 | T15: ='Pharm Demand'!T39 -> 0 | U15: ='Pharm Demand'!U39 -> 0 | V15: ='Pharm Demand'!V39 -> 149.1945 | W15: ='Pharm Demand'!W39 -> 126.2625 | ... AA15: ='Pharm Demand'!AA39 -> 418.3725 | AB15: =SUM(P15:AA15) -> 1542.996 | AC15: ='Pharm Demand'!AC39 -> 520.338 | AD15: ='Pharm Demand'!AD39 -> 493.4475 | AE15: ='Pharm Demand'!AE39 -> 535.4895 | AF15: ='Pharm Demand'!AF39 -> 692.7375 | AG15: ='Pharm Demand'!AG39 -> 598.143 | AH15: ='Pharm Demand'!AH39 -> 726.0435 | AI15: ='Pharm Demand'!AI39 -> 820.2285 | AJ15: ='Pharm Demand'!AJ39 -> 596.9145 | ... AN15: ='Pharm Demand'!AN39 -> 625.3065 | AO15: =SUM(AC15:AN15) -> 7837.83 | AP15: ='Pharm Demand'!AP39 -> 625.3065 | AQ15: ='Pharm Demand'!AQ39 -> 704.23328 | AR15: ='Pharm Demand'!AR39 -> 708.73654 | AS15: ='Pharm Demand'!AS39 -> 713.2398 | AT15: ='Pharm Demand'!AT39 -> 754.95482 | AU15: ='Pharm Demand'!AU39 -> 0 | AV15: ='Pharm Demand'!AV39 -> 0 | AW15: ='Pharm Demand'!AW39 -> 0 | ... BA15: ='Pharm Demand'!BA39 -> 0 | BB15: =SUM(AP15:BA15) -> 3506.4709
A17: 157001150268 Roxicodone-Freight | B17: 7171i | C17: ='Pharm Demand'!C41 -> 668 | D17: ='Pharm Demand'!D41 -> 561 | E17: ='Pharm Demand'!E41 -> 209 | F17: ='Pharm Demand'!F41 -> 646 | G17: ='Pharm Demand'!G41 -> 586.45692 | H17: ='Pharm Demand'!H41 -> 469.64474 | I17: ='Pharm Demand'!I41 -> 552.825 | J17: ='Pharm Demand'!J41 -> 506.8245 | ... N17: ='Pharm Demand'!N41 -> 478.3513 | O17: =SUM(C17:N17) -> 6264.7354 | P17: ='Pharm Demand'!P41 -> 637.87186 | Q17: ='Pharm Demand'!Q41 -> 461.916 | R17: ='Pharm Demand'!R41 -> 445.809 | S17: ='Pharm Demand'!S41 -> 611.25436 | T17: ='Pharm Demand'!T41 -> 491.673 | U17: ='Pharm Demand'!U41 -> 469.287 | V17: ='Pharm Demand'!V41 -> 587.77636 | W17: ='Pharm Demand'!W41 -> 491.673 | ... AA17: ='Pharm Demand'!AA41 -> 516.243 | AB17: =SUM(P17:AA17) -> 6262.2399 | AC17: ='Pharm Demand'!AC41 -> 516.25036 | AD17: ='Pharm Demand'!AD41 -> 516.243 | AE17: ='Pharm Demand'!AE41 -> 516.243 | AF17: ='Pharm Demand'!AF41 -> 516.25036 | AG17: ='Pharm Demand'!AG41 -> 516.243 | AH17: ='Pharm Demand'!AH41 -> 516.243 | AI17: ='Pharm Demand'!AI41 -> 516.25036 | AJ17: ='Pharm Demand'!AJ41 -> 516.243 | ... AN17: ='Pharm Demand'!AN41 -> 516.243 | AO17: =SUM(AC17:AN17) -> 6194.9454 | AP17: ='Pharm Demand'!AP41 -> 516.25036 | AQ17: ='Pharm Demand'!AQ41 -> 516.243 | AR17: ='Pharm Demand'!AR41 -> 516.243 | AS17: ='Pharm Demand'!AS41 -> 522.1125 | AT17: ='Pharm Demand'!AT41 -> 540.5946 | AU17: ='Pharm Demand'!AU41 -> 0 | AV17: ='Pharm Demand'!AV41 -> 0 | AW17: ='Pharm Demand'!AW41 -> 0 | ... BA17: ='Pharm Demand'!BA41 -> 0 | BB17: =SUM(AP17:BA17) -> 2611.4435
A18: 157001150269 Intrathecal-Freight | B18: 7171i | C18: 0 | D18: 0 | E18: 0 | F18: 0 | G18: 0 | H18: 0 | I18: 0 | J18: 0 | K18: 0 | L18: 0 | M18: 0 | N18: 0 | O18: 0 | P18: 0 | Q18: 0 | R18: 0 | S18: 0 | T18: 0 | U18: 0 | V18: 0 | W18: 0 | X18: 0 | Y18: 0 | Z18: 0 | AA18: 0 | AB18: 0 | AC18: 0 | AD18: 0 | AE18: 0 | AF18: 0 | AG18: 0 | AH18: 0 | AI18: 0 | AJ18: 0 | AK18: 0 | AL18: 0 | AM18: 0 | AN18: 0 | AO18: 0 | AP18: 0 | AQ18: 0 | AR18: 0 | AS18: 0 | AT18: 0 | AU18: 0 | AV18: 0 | AW18: 0 | AX18: 0 | AY18: 0 | AZ18: 0 | BA18: 0 | BB18: 0
