Workbook

Sheet Summary
A3: Business | C3: FY11 May Plan Dollars | D3: FY11 Oct Forecast Dollars | E3: FY11 Jan Forecast Dollars | F3: FY12 Jan Forecast Dollars | H3: FY10 Actual Dollars | J3: FY12 FCST Increase with $105 WTI
A4: In Freight
A5: Pharma
A6: Hobart | C6: 233981 | D6: =Specialty!D4 -> 43295 | E6: =Specialty!F4 -> 43295 | F6: =Specialty!H4 -> 58784 | H6: =Specialty!J4 -> 179973 | J6: =F6-55826 -> 2958
A7: UK Pharma | C7: 1493522 | D7: =API!F42 -> 1415752 | E7: =API!I44 -> 1403626 | F7: =API!L44 -> 1446026 | H7: =API!N44 -> 1197113 | J7: =F7-1403626 -> 42400
A8: Gateway | C8: 0 | D8: 0
A9: Total Pharma In Freight | C9: =SUM(C6:C8) -> 1727503 | D9: =SUM(D6:D8) -> 1459047 | E9: =SUM(E6:E7) -> 1446921 | F9: =SUM(F6:F7) -> 1504810 | H9: =SUM(H6:H8) -> 1377086 | J9: =SUM(J6:J8) -> 45358
A11: CMDS
A12: Cincinnati | C12: 100 | E12: 0 | F12: 0
A13: Joliet | C13: 1294357 | D13: =D12+D9 -> 1459047 | E13: =CMDS!G6 -> 1320179 | F13: =CMDS!I6 -> 1390148 | H13: 0
A14: Total Contrast In Freight | C14: =SUM(C12:C13) -> 1294457 | D14: =SUM(D13) -> 1459047 | E14: =E13 -> 1320179 | F14: =F13 -> 1390148 | H14: =CMDS!K6 -> 1206013 | J14: =F14-1245143 -> 145005
A16: Total In Freight | C16: =C14+C9 -> 3021960 | D16: =D14+D9 -> 2918094 | E16: =E14+E9 -> 2767100 | F16: =F14+F9 -> 2894958 | H16: =H14+H9 -> 2583099 | J16: =J14+J9 -> 190363
A18: Out Freight
A19: Pharma
A20: Hobart | C20: =7457913+72000 -> 7529913 | D20: =Specialty!D10 -> 5717907.7 | E20: =Specialty!F10 -> 5889860.3 | F20: =Specialty!H10 -> 6374941 | H20: =Specialty!J10 -> 5535218 | J20: =F20-6295260 -> 79681.024
A21: API | C21: =13133263-C20 -> 5603350 | D21: =SUM(API!F6+API!F39) -> 5874237.9 | E21: =API!I49 -> 5913612.7 | F21: =API!L39+API!L6 -> 4999473.5 | H21: =API!N39+API!N6 -> 5097344 | J21: =F21-4831576 -> 167897.45
A22: Total Pharma Out Freight | C22: =SUM(C20:C21) -> 13133263 | D22: =SUM(D20:D21) -> 11592146 | E22: =SUM(E20:E21) -> 11803473 | F22: =SUM(F20:F21) -> 11374414 | H22: =SUM(H20:H21) -> 10632562 | J22: =SUM(J20:J21) -> 247578.48
A24: CMDS
A25: Dublin | C25: 0 | D25: 0 | H25: =CMDS!K25 -> 70883
A26: Cincinnati | C26: 792959 | D26: =CMDS!E24 -> 694013 | E26: =CMDS!G24 -> 694013 | F26: =CMDS!I24 -> 651657 | H26: =CMDS!K24 -> 662956 | J26: =F26-636892 -> 14765
A27: Joliet | C27: 3126903 | D27: =CMDS!E16 -> 2576084 | E27: =CMDS!G16 -> 2576084 | F27: =CMDS!I16 -> 2034400 | H27: =CMDS!K16 -> 2406001 | J27: =F27-1988802 -> 45598
A28: Total Contrast Out Freight | C28: =SUM(C25:C27) -> 3919862 | D28: =SUM(D25:D27) -> 3270097 | E28: =SUM(E25:E27) -> 3270097 | F28: =SUM(F25:F27) -> 2686057 | H28: =SUM(H25:H27) -> 3139840 | J28: =SUM(J26:J27) -> 60363
A30: Nuclear
A31: Maryland Heights | C31: 18000000 | D31: 18000000 | E31: =Nuclear!F2 -> 19250000 | F31: =Nuclear!H2 -> 21619608 | H31: =Nuclear!J2 -> 20172766 | J31: =F31-21200000 -> 419608.21
A32: Pharmacies | C32: 0 | D32: 0 | E32: 0 | F32: 0
A33: Total Nuclear | C33: =SUM(C31:C32) -> 18000000 | D33: =SUM(D31:D32) -> 18000000 | E33: =E31 -> 19250000 | F33: =F31 -> 21619608 | H33: =H31 -> 20172766 | J33: =J31 -> 419608.21
A35: Total Out Freight | C35: =C33+C28+C22 -> 35053125 | D35: =D33+D28+D22 -> 32862243 | E35: =E33+E28+E22 -> 34323570 | F35: =F33+F28+F22 -> 35680080 | H35: =H33+H28+H22 -> 33945168 | J35: =J31+J28+J22 -> 727549.68
A37: Total Freight | C37: =C35+C16 -> 38075085 | D37: =D35+D16 -> 35780337 | E37: =E35+E16 -> 37090670 | F37: =F35+F16 -> 38575038 | H37: =H35+H16 -> 36528267 | J37: =F37-37657125 -> 917912.68

Sheet API
A1: API Transportation Forecast | D1: FY11 Planned (Finance) Dollars | E1: FY11 Planned Volume | F1: FY11 Oct Forecast Dollars | H1: FY11 Jan Revised Vol | I1: FY11 Jan Forecast Dollars | K1: FY12 Jan Volume | L1: FY12 Jan Forecast Dollars | N1: FY10 Actual
A2: Narcotics
B3: US & UK 3rd Party | C3: INTL-AIR | E3: 9386 | F3: 54987.894 | H3: 10813 | I3: 66827.502 | K3: 10403 | L3: 74065
C4: SP-AIR | E4: 27893.353 | F4: 88456 | H4: 25118 | I4: 74424.634 | K4: 20748 | L4: 64681.71
C5: TL | E5: 26410.605 | F5: 35390 | H5: 24411 | I5: 30391.695 | K5: 20395 | L5: 28102.88
B6: Total Narcotics | D6: 152401 | E6: =SUM(E3:E5) -> 63689.958 | F6: =SUM(F3:F5) -> 178833.89 | H6: =SUM(H3:H5) -> 60342 | I6: =SUM(I3:I5) -> 171643.83 | K6: =SUM(K3:K5) -> 51546 | L6: =SUM(L3:L5) -> 166849.59 | N6: 289204
A7: Non-Narcotics
A8: US 3rd Party
C9: AIR-HEAVY | E9: 540.76733 | F9: 9246.4262 | H9: 329 | I9: 5615 | K9: 312 | L9: 5855
C10: INTL-AIR | E10: 195560.56 | F10: 565914.36 | H10: 193075.84 | I10: 562080.7 | K10: 202603.56 | L10: 636511.43
C11: INTL-OCEAN | E11: 2713231.3 | F11: 853217.52 | H11: 2217212 | I11: 596249 | K11: 2217212 | L11: 633684.82
C12: LTL | E12: 2979852 | F12: 361158 | H12: 1347956 | I12: 205654 | K12: 1342458 | L12: 222503
B13: INTL | C13: SP-AIR | E13: 1080.5071 | F13: 26729.682 | H13: 1915.1341 | I13: 49410.902 | K13: 1915.1341 | L13: 52395.616
C14: SP-AIR(<150lbs) | E14: 545.99894 | F14: 17117.342 | H14: 329 | I14: 10297 | K14: 312 | L14: 9976
C15: SP-GROUND | E15: 23679.78 | F15: 18165.01 | H15: 2070 | I15: 1588 | K15: 1952 | L15: 1722
C16: TL | E16: 10706391 | F16: 1220764.9 | H16: 6149311 | I16: 661980 | K16: 6114334 | L16: 731263
C17: Aniline | F17: 0 | I17: 0 | L17: 0
B18: INTL | C18: COLLECT * | F18: 0 | H18: 185507.33 | I18: 0 | K18: 150477.37 | L18: 0
C19: COLLECT * | F19: 0 | H19: 7046311 | I19: 0 | K19: 7017888 | L19: -
B20: Total USA 3rd Party | D20: 3506401 | E20: =SUM(E9:E19) -> 16620882 | F20: =SUM(F9:F19) -> 3072313.2 | H20: =SUM(H9:H19) -> 17144016 | I20: =SUM(I9:I19) -> 2092874.6 | K20: =SUM(K9:K19) -> 17049464 | L20: =SUM(L9:L19) -> 2293910.9 | N20: 2664906
A23: UK 3rd party | B23: Ship from USA
C24: INTL-AIR | E24: 11701.93 | F24: 40567.523 | H24: 20638.738 | I24: 119498.29 | K24: 20638.738 | L24: 141169
C25: INTL-OCEAN | E25: 1357070.1 | F25: 387304.23 | H25: 2388980 | I25: 591370 | K25: 2388980.4 | L25: 654104
C26: Total Direct | E26: =SUM(E24:E25) -> 1368772 | F26: =SUM(F24:F25) -> 427871.76 | H26: =SUM(H24:H25) -> 2409618.7 | I26: =SUM(I24:I25) -> 710868.29 | K26: =SUM(K24:K25) -> 2409619.1 | L26: =SUM(L24:L25) -> 795273
B27: Ship from UK Whse
C28: TL | E28: 7499190.2 | F28: 1401591.3 | H28: 6280635 | I28: 1318933 | K28: 6280634.6 | L28: 1522708
C29: INTL-AIR | E29: 20540.122 | F29: 57968.401 | H29: 19225 | I29: 44025 | K29: 19224.839 | L29: 51069
C30: INTL-OCEAN | E30: 755679.35 | F30: 307787.57 | H30: 651673 | I30: 122515 | K30: 651673.14 | L30: 143629
C31: Total Whse | E31: =SUM(E28:E30) -> 8275409.7 | F31: =SUM(F28:F30) -> 1767347.2 | H31: =SUM(H28:H30) -> 6951533 | I31: =SUM(I28:I30) -> 1485473 | K31: =SUM(K28:K30) -> 6951532.6 | L31: =SUM(L28:L30) -> 1717406
B33: Chesterfield | C33: PAP | H33: 448180 | I33: 49127 | K33: =SUM('[1]Intl 2012'!$K$29) -> 107380 | L33: 26034
C34: Aniline | H34: 793560 | I34: 0 | K34: 793560 | L34: 0
B36: Total UK | D36: 1826221 | E36: =SUM(E24:E30) -> 11012954 | F36: =SUM(F24:F30) -> 2623090.8 | H36: =H34+H33+H31+H26 -> 10602892 | I36: =I34+I33+I31+I26 -> 2245468.3 | K36: =K34+K33+K31+K26 -> 10262092 | L36: =L34+L33+L31+L26 -> 2538713 | N36: 2143234
B39: Total Non Narcotics Out Freight | D39: =D36+D20 -> 5332622 | E39: =E36+E20 -> 27633835 | F39: =F36+F20 -> 5695404 | H39: =H36+H20 -> 27746908 | I39: =I36+I20 -> 4338342.9 | K39: =K36+K20 -> 27311556 | L39: =L36+L20 -> 4832623.9 | N39: =N36+N20 -> 4808140
A41: In Freight Costs
C42: UK - Leigh Whse | E42: 8170181 | F42: 1415752 | H42: 7349235 | I42: 1403626 | K42: 7349235 | L42: 1446026
B44: Total In Freight | D44: 1421534 | E44: =SUM(E42:E43) -> 8170181 | F44: =SUM(F42:F43) -> 1415752 | H44: =H42 -> 7349235 | I44: =I42 -> 1403626 | K44: =K42 -> 7349235 | L44: =L42 -> 1446026 | N44: 1197113
B47: Total Non- Narcotics | D47: =D44+D39 -> 6754156 | E47: =E44+E39 -> 35804016 | F47: =F44+F39 -> 7111156 | H47: =H44+H39 -> 35096143 | I47: =I44+I39 -> 5741968.9 | K47: =K44+K39 -> 34660791 | L47: =L44+L39 -> 6278649.9 | N47: =N44+N39 -> 6005253
A49: Total API Transportation Costs and Volumes | D49: =D47+D6 -> 6906557 | E49: =E44+E39+E6 -> 35867706 | F49: =F44+F39+F6 -> 7289989.9 | H49: =H47+H6 -> 35156485 | I49: =I47+I6 -> 5913612.7 | J49: =J47+J6 -> 0 | K49: =K47+K6 -> 34712337 | L49: =L47+L6 -> 6445499.5 | N49: =N47+N6 -> 6294457
A52: * Collect Shipment volumes with no freight costs
A54: Business Assumptions:
...

Sheet CMDS
A1: Imaging Transportation Forecast | D1: FY11 Planned (Finance) Dollars | E1: FY11 Oct Forecast Dollars | G1: FY11 Jan Forecast Dollars | I1: FY12 Jan Forecast | K1: FY10 Actual
A2: CMDS
A4: In Freight
C5: JOLIET
C6: TL | D6: 1100000 | E6: 1320179 | G6: 1320179 | I6: 1390148 | K6: 1206013
C9: CINCINNATI | D9: 100 | E9: 0
C10: Total In Freight | D10: =SUM(D6:D9) -> 1100100 | E10: =SUM(E6:E9) -> 1320179 | G10: =SUM(G6:G9) -> 1320179 | I10: =SUM(I6:I9) -> 1390148 | K10: 0
A12: Out Freight | C12: JOLIET
A13: Contrast Media / Disposables | C13: LTL | E13: 2277987.8 | G13: 2277988 | I13: 1775917
C14: SP - Air | E14: 127937.18 | G14: 127937 | I14: 109769
C15: SP - Ground | E15: 170159 | G15: 170159 | I15: 148714
C16: Total Joliet | D16: 3126903 | E16: =SUM(E13:E15) -> 2576084 | G16: =SUM(G13:G15) -> 2576084 | I16: =SUM(I13:I15) -> 2034400 | K16: 2406001
C18: CINCINNATI
A19: Devices / Urology Suites | C19: Special Services | E19: 173719 | G19: 173719 | I19: 168603
C20: LTL | E20: 30672 | G20: 30672 | I20: 28957
C21: SP Air | E21: 270732 | G21: 270732 | I21: 245949
C22: SP Ground | E22: 128898 | G22: 128898 | I22: 119279
C23: Heavy Air | E23: 89992 | G23: 89992 | I23: 88869
C24: Total | D24: 792959 | E24: =SUM(E19:E23) -> 694013 | G24: =SUM(G19:G23) -> 694013 | I24: =SUM(I19:I23) -> 651657 | K24: 662956
K25: 70883 | L25: Dublin*
A26: Total Out Freight
K27: =SUM(K24:K25) -> 733839
A28: Total CMDS | D28: =D16+D10 -> 4227003 | E28: =E16+E6+E24 -> 4590276 | G28: =G16+G6+G24 -> 4590276 | I28: =I16+I6+I24 -> 4076205 | K28: =K27+K16+K6 -> 4345853
A31: Business Assumptions:
A32: Jan FY11 FCST Update
A33: No change in distribution strategy
A34: No change in customers with all Out Freight base cost to remain same as Oct FY11 FCST
A35: No change in Volumes for FY11 (CM = 94% FY10 volumes and Devices Flat)
A36: Temperature Control for months of November - March only
A38: FY12 Forecast
A39: Volumes based on last 6 months of FY10 with following modifications:
A40: CM = 85% of FY11 Volumes with minimum order QTY of 24 cases
A41: Devices = 90% of FY11 Volumes
A43: *Dublin freight = $4500 cross-charge?? Finance trying to determine reason
A45: All applicable transportation assumptions applied

Sheet Specialty
A1: Specialty Pharma Transportation Forecast | C1: FY11 Planned (Finance) Dollars | D1: FY11 Oct Forecast Dollars | F1: FY11 Jan Forecast Dollars | H1: FY12 Jan Forecast | J1: FY10 Actual
A3: Hobart
A4: In Freight | C4: 233981 | D4: 43295 | F4: 43295 | H4: 58784 | J4: 179973
A6: Out Freight
A7: TL | D7: 792433.95 | F7: 816207 | H7: 859898
A8: SP Air | D8: 4639121.1 | F8: 4778295 | H8: 5121297
A9: International | D9: 286352.68 | F9: 295358.27 | H9: 334962.02
A10: Total Specialty | C10: =7128591+72000 -> 7200591 | D10: =SUM(D7:D9) -> 5717907.7 | F10: =SUM(F7:F9) -> 5889860.3 | H10: =SUM(H4:H9) -> 6374941 | J10: =5467244+67974 -> 5535218
A12: Business Assumptions
A13: FY11 Jan FCST Update | H13: =H8+H7 -> 5981195 | J13: w/o Intl & Inbound
A14: Switch to Temp Control transportation for Out Freight Hobart June - Sept except Addiction Treatment
A15: In Freight to Hobart includes : Pennsaid, Exalgo, Fentanyl Patch, FTOC
A16: No change in shipping modes or customer locations
A17: FY10 Actual Infreight was miss coded to include WIP STL to Hobart. Coding has been corrected for FY11
A19: Volumes | C19: FY11 Plan | D19: FY11 Jan LE | F19: FY12 Forecast
A20: Number of Bottles | C20: 46854709 | D20: 48328257 | F20: 50640530
F22: 55000000 | H22: Revised Forecast
A23: All applicable transportation assumptions applied
F24: =H13/F22 -> 0.108749 | H24: Cost per Bottle

Sheet Nuclear
A1: Nuclear Medicine Transportation Forecast | C1: FY11 Planned (Finance) Dollars | D1: FY11 Oct Forecast Dollars | F1: FY11 Jan Forecast Dollars | H1: FY12 Jan Forecast Dollars | J1: FY10 Actual Dollars
A2: Maryland Heights | C2: 18000000 | D2: 18000000 | F2: 19250000 | H2: =SUM(Q12:Q13) -> 21619608 | J2: 20172766
A3: Pharmacies | C3: 0 | D3: 0
A4: Total Nuclear | C4: =SUM(C2:C3) -> 18000000 | D4: =SUM(D2:D3) -> 18000000 | F4: =F2 -> 19250000 | H4: =SUM(H2:H3) -> 21619608 | J4: =J2 -> 20172766
H6: 1835768.2 | J6: FSC
A8: Business Assumptions:
A9: FY 11 increase due to delay in cost savings projects: | O9: FY 11 YTD avg | Q9: FY12 Spend w/ FSC | S9: FSC FY11 | T9: FY11 YTD Spend
A10: CLE-DTW ($700K) | O10: $81 cpb | Q10: 21200000 | S10: 586352.08 | T10: 8775774.5
A11: CLE-DTW retainer fee of $10k per week | O11: =(105-81)/81 -> 0.2962963 | Q11: 1416160 | T11: =S10/T10 -> 0.066814852
A12: 2X daily shipment termination ($1M) | Q12: =Q10-Q11 -> 19783840
A13: Gov account migration delayed until Jan, 2011 | Q13: =Q11*1.2963 -> 1835768.2
A15: FY12 Forecast Increases
A16: 4% rate increase for deliveries
A17: $1M Fuel sur charge

Sheet Transport Assumptions
A3: US Originating Freight
A4: Mode | B4: FY11 Rate Incr | C4: FY11 Fuel Base | D4: Dec 2010 Fuel Charge | E4: FY12 Rate Incr | F4: FY12 Fuel Base
A5: Truckload | B5: 0.05 | C5: 3.20/gal | D5: .39/mile | E5: 0.05 | F5: 4.11/gal
A6: Less than TL | B6: 0.04 | C6: 3.20/gal | D6: 14% LH | E6: 0.015 | F6: 4.11/gal
A7: Sm Pk GRN | B7: 0.05 | C7: 3.20/gal | D7: 4.8% LH | E7: 0 | F7: 4.11/gal
A8: Sm Pk Air | B8: 0.05 | C8: 3.20/gal | D8: 3% LH | E8: 0 | F8: 4.11/gal
A9: Ocean | B9: 0.175 | C9: 80 BAF | D9: 80 BAF | E9: 0 | F9: 100 BAF
A10: Int'l Air | B10: 0.066 | C10: .85/kg | D10: .90/kg | E10: 0.1 | F10: 1.05/kg
A11: Heavy Air | B11: 0.015 | C11: 13% INCR | D11: 21.5% LH | E11: 0.05 | F11: 9% INCR
A12: Dray | B12: 0 | C12: 3.20/gal | D12: 14% LH | E12: 0.1 | F12: 4.11/gal
A13: TL Special | B13: 0 | C13: 3.20/gal | D13: .39/mile | E13: 0.05 | F13: 4.11/gal
A17: UK Freight
C18: FY11 | D18: FY12 | E18: Comments
A19: Fuel Surcharge | B19: Leigh In | C19: 0 | D19: 0 | E19: FY11 already included in rate?
A20: Fuel Surcharge | B20: Leigh Out | C20: 0 | D20: 0.09 | E20: FY11 already included in OCT LE? Assume rate of 9%.
A21: Fuel Surcharge | B21: Drop Ship | C21: 0 | D21: 0 | E21: FY11 increase already included in OCT LE
A22: Fuel Surcharge | B22: Narcotics | C22: 0 | D22: 0 | E22: included in 10% projected rate rise?
A23: Freight rate increase | B23: Leigh In | C23: 0 | D23: 0 | E23: no rate increases expected
A24: Freight rate increase | B24: Leigh Out | C24: 0 | D24: 0.05 | E24: FY11 already included in OCT LE?
A25: Freight rate increase | B25: Drop Ship | C25: 0 | D25: 0 | E25: Increase already included for FY11 - no increase projected for FY12
A26: Freight rate increase | B26: Narcotics | C26: 0 | D26: 0.1 | E26: 6.6% for FY11 already included in OCT LE
A27: Rate contingency | B27: Drop ship listed valid lanes | C27: 0.05 | D27: 0.05 | E27: incidental charges such as demurrage, surcharges etc.

Sheet Mode Impacts
B1: FY12 Transportation Impacts: | C1: Fuel Cost Impact:
A3: Truckload: | C3: Truckload: | D3: FY12 Update on Fuel - $105/ Gal
A4: FY12 Plus 5% | B4: 5% Rate increase on several major lates at end of FY10 Balance of FY11 remain stable until end of current contracts with expected 5% increase starting in September 2011 | C4: Projecting average price of $3.50 per gallon of FSC of $.47 per loaded mile for FY12 which is a 14% in additional fuel cost over projected FY11 average of $.41/ mile | D4: Projection of Diesel at $4.12 / gal resulting in TL FSC of $52.5 per mile
B5: Driver shortage due to increasing demand and fewer qualified drivers. May have significan impact on security shipments requiring team drivers.
B6: CSA legislation will further educe eligilble drivers as records will now belong to hiring company
B7: HOS legislation to expected to be passed in FY11 and will reduce working hours
B8: Economic downturn 2008-2009 resulted in consolidation and fewer players left
B9: TL RFQ with mansfiled scheduled for late summer FY11
A10: Less than Truckload | C10: LTL:
A11: FY12 Plus 1.5% | B11: Incremental rate increase over 4% increase for FY11 | C11: Projecting average price of $3.50 per gallon resulting in charge of 17% of the LH rate or an additional cost of 3% over FY11 | D11: Projection of Diesel at $4.12 / gal resulting in LTL FSC of 24% of the Line Haul
B12: This segment of the industry remains at over capacity but will also feel the effect of new legislation and HOS legislation
B13: Potential impact would be the fall or purchase of Yellow / Roadway by another carrier who might pull out capacity to drive up rates
B14: Fed Ex Freight/National my also become a larger player as they have won their suit with the union regarding their drivrs being designated as independent contractors. This division has also restructured it's offerings. Covidien does not have a contract with Fed Ex Freight/National
B15: May offset increase by move to Cincinnati
A17: Small PKG Ground and Air
A18: Flat FY12 | B18: Expecting 5% rate increas across th board for Fed Ex within the nest month with no additional increase for FY12 No increase for over 3 years
A20: Ocean | C20: Ocean:
A21: Flat FY12 | B21: FY11 impact has been approx 17.5% increase over early FY10 rates. Rate increase were experience starting in August of FY10 with some lanes increasing as much as 30%. Greates impact of increases in lanes out of EMEA and out of the US into LATAM. | C21: Projecting average WTI at $80-$90/ barrel for BAF index of 80 which is the FY11 projection. The BAF is added as a separate charged per box depending on the lane and ranges from $180 to $670 per container
B22: FY12 should bring little rate increases as the SteamShip lines are expected to be receiving new vessels throughout FY11 and 12 resulting in a glut of available capacity. Continues uneven growth in demand versusu capacity in Brazil,India and China
B23: Steam Ship Lines will protect their current rates thru the continuation of slow and very slow steaming which reduces fuel consumption. Reduced fuel consumption over a years period has been shown to be more cost effective even if it results in adding an additional vessel to a loop
A25: International Air
A26: FY12 Plus 10% | B26: Up 6.6 % for Fy11
B27: Heavy demand and reduced capacity with no good outlook for additonal capcaity | D27: FSC at $1.05 per KG
B28: Capacity being further reduced on passenger planes . Ab380's less cargo space and more long range 737's in use for better fuel economy replacing 747's
B29: So American capacity at critical shortage -only Centurian and LAN provide cargo. Main issue with rates is the lack of North Bound Freight. Other areas for capacity / demand issues are China and India
A31: Heavy Air
A32: FY12 Plus 5% | B32: Expected Fed Ex/Ceva increase
A34: Ocean container dray service
A35: FY12 Plus 10% | B35: No increase in this area for some time. Expect that Old Dominion will increase rates sometime in FY11 as their business increases for international service. This only impacts freight out of Raleigh | D35: Dray will be impacted by FSC of 24% on $4.12/gal diesel
A37: TL Special
A38: FY12 Plus 5% | B38: This category is for the special services supplied by CEVA and Unigroup for the transport of Urology Suites out of Cincinnati. Contract to be renewed in FY11
