Workbook

Sheet Worksheet 2009
A1: UPS | F1: LTL | J1: FED-EX
A3: January
A4: Week Ending | B4: Packages | C4: Dollars | F4: Number of Orders | G4: Weight | H4: Dollars
A5: 39816 | B5: 199 | C5: 10114.14 | F5: 1 | G5: 390 | H5: 70
A6: 39823 | B6: 299 | C6: 11197.57 | F6: 52 | G6: 78067 | H6: 32454.7
A7: 39830 | B7: 378 | C7: 15941.13 | F7: 56 | G7: 69537 | H7: 23401.77
A8: 39837 | B8: 386 | C8: 14807.9 | F8: 53 | G8: 179891 | H8: 33633.22
A9: 39844 | B9: 402 | C9: 15301.26 | F9: 58 | G9: 143618 | H9: 23792.16
F10: 13 | G10: 11863 | H10: 2508.34
F11: 5 | G11: 4337 | H11: 934.75
F12: 57 | G12: 27265 | H12: 15575.55
F13: 1 | G13: 2 | H13: 133.82
F14: 4 | G14: 11413 | H14: 1306.38
F15: 2 | G15: 4 | H15: 109.71
F16: 4 | G16: 8 | H16: 914.49
A18: Jan total | B18: =SUM(B5:B13) -> 1664 | C18: =SUM(C5:C13) -> 67362 | F18: =SUM(F5:F17) -> 306 | G18: =SUM(G5:G17) -> 526395 | H18: =SUM(H5:H17) -> 134834.89
A20: February
A21: Week Ending | B21: Packages | C21: Dollars | F21: Number of Orders | G21: Weight | H21: Dollars
A22: 39851 | B22: 426 | C22: 15968.13 | F22: =[1]Sheet1!$E$65 -> 4 | G22: =[1]Sheet1!$H$65 -> 93842 | H22: =[1]Sheet1!$D$65 -> 8030
A23: 39858 | B23: 431 | C23: 16708.24 | F23: =[2]Sheet1!$E$63 -> 47 | G23: =[2]Sheet1!$H$63 -> 239908 | H23: =[2]Sheet1!$D$63 -> 26102.34
A24: 39865 | B24: 331 | C24: 12332.01 | F24: 65 | G24: 282514 | H24: 40794.06
A25: 39872 | B25: 441 | C25: 18541.46 | F25: 101 | G25: 212610 | H25: 38207.78
F26: 80 | G26: 136752 | H26: 28914.06
F27: 17 | G27: 8459 | H27: 2949.25
F28: 28 | G28: 12105 | H28: 5831.89
F29: 6 | G29: 4370 | H29: 856.56
F30: 6 | G30: 8926 | H30: 3880.91
F31: 2 | G31: 4 | H31: 860.42
F32: 2 | G32: 4 | H32: 193.37
F33: 2 | G33: 4 | H33: 96.77
F34: 1 | G34: 2 | H34: 25.42
F35: 4 | G35: 8 | H35: 1206.63
A36: Feb Total | B36: =SUM(B22:B29) -> 1629 | C36: =SUM(C22:C29) -> 63549.84 | F36: =SUM(F22:F35) -> 365 | G36: =SUM(G22:G35) -> 999508 | H36: =SUM(H22:H35) -> 157949.46
A38: March
A39: Week Ending | B39: Packages | C39: Dollars | F39: Number of Orders | G39: Weight | H39: Dollars | K39: 1 | L39: 46.9
A40: 39879 | B40: 359 | C40: 14661.11 | F40: 1 | G40: 33205 | H40: 1175 | K40: 1 | L40: 46.9
A41: 39886 | B41: 327 | C41: 6827.29 | F41: 78 | G41: 240434 | H41: 35185.8
A42: 39893 | B42: 376 | C42: 16849.46 | F42: 66 | G42: 267489 | H42: 33444.01
A43: 39900 | B43: 425 | C43: 18591.95 | F43: 100 | G43: 211441 | H43: 93101.23
F44: =[3]Sheet1!$E$161 -> 152 | G44: =[3]Sheet1!$H$161 -> 192327 | H44: =[3]Sheet1!$D$161 -> 116115.53
...

Sheet Worksheet 2010
A1: UPS | F1: LTL | J1: FED-EX
A3: January
A4: Week Ending | B4: Packages | C4: Dollars | F4: Number of Orders | G4: Weight | H4: Dollars
A5: 40180 | C5: 29226.23 | F5: 33 | G5: 56303 | H5: 5285.66
A6: 40187 | C6: 31531.75 | F6: 53 | G6: 65558 | H6: 14757.38 | J6: 1 | K6: 25.01
A7: 40194 | C7: 25234 | F7: 41 | G7: 42384 | H7: 36237.18
A8: 40201 | C8: 25234 | F8: 51 | G8: 39386 | H8: 26577.94
A9: 40208 | C9: 25746.72 | F9: 129 | G9: 157209 | H9: 50564.66
F10: 8 | G10: 4626 | H10: 5416.62
F11: 9 | G11: 3485 | H11: 1552.96
F12: 1 | G12: 2 | H12: 52.41
F13: 3 | G13: 2029 | H13: 401.3
A18: Jan total | B18: =SUM(B5:B13) -> 0 | C18: =SUM(C5:C13) -> 136972.7 | F18: =SUM(F5:F17) -> 328 | G18: =SUM(G5:G17) -> 370982 | H18: =SUM(H5:H17) -> 140846.11 | J18: =SUM(J6:J17) -> 1 | K18: =SUM(K6:K17) -> 25.01
A20: February
A21: Week Ending | B21: Packages | C21: Dollars | F21: Number of Orders | G21: Weight | H21: Dollars
A22: 40215 | C22: 25154.72 | F22: 29 | G22: 39896 | H22: 4033.68 | J22: 1 | K22: 25.04
A23: 40222 | C23: 24991 | F23: 52 | G23: 65207 | H23: 20720.38
A24: 40229 | C24: 22977.74 | F24: 105 | G24: 106497 | H24: 63493.23 | J24: 1 | K24: 26.17
A25: 40236 | F25: 101 | G25: 103115 | H25: 43553.41
F26: 15 | G26: 5676 | H26: 4326.52
F27: 1 | G27: 618 | H27: 74.03
F28: 1 | G28: 2 | H28: 559.16
F29: 1 | G29: 2 | H29: 11.01
F30: 1 | G30: 2 | H30: 12.24
F31: 2 | G31: 2378 | H31: 297.15
A36: Feb Total | B36: =SUM(B22:B29) -> 0 | C36: =SUM(C22:C29) -> 73123.46 | F36: =SUM(F22:F35) -> 308 | G36: =SUM(G22:G35) -> 323393 | H36: =SUM(H22:H35) -> 137080.81 | J36: =SUM(J22:J35) -> 2 | K36: =SUM(K22:K35) -> 51.21
A38: March
A39: Week Ending | B39: Packages | C39: Dollars | F39: Number of Orders | G39: Weight | H39: Dollars
A40: 40243 | C40: 29225.98 | F40: 60 | G40: 84121 | H40: 28688.33
A41: 40250 | C41: 25504.8 | F41: 79 | G41: 79190 | H41: 34309.19 | J41: 1 | K41: 26.17
A42: 40257 | C42: 27131.52 | F42: 85 | G42: 80742 | H42: 34566.73
A43: 40264 | C43: 38796.01 | F43: 39 | G43: 57115 | H43: 14740.16
F44: 73 | G44: 76182 | H44: 69746.73
F45: 35 | G45: 24865 | H45: 20527.15
A62: Mar Total | B62: =SUM(B40:B49) -> 0 | C62: =SUM(C40:C49) -> 120658.31 | F62: =SUM(F40:F61) -> 371 | G62: =SUM(G40:G61) -> 402215 | H62: =SUM(H40:H61) -> 202578.29 | J62: 1 | K62: =SUM(K39:K61) -> 26.17
A64: April
A65: Week Ending | B65: Packages | C65: Dollars | F65: Number of Orders | G65: Weight | H65: Dollars
A66: 40271 | C66: 27056.09 | F66: 3 | G66: 7652 | H66: 741.79
A67: 40278 | C67: 27847.62 | F67: 82 | G67: 86964 | H67: 38467.16
A68: 40285 | C68: 24855.74 | F68: 63 | G68: 45061 | H68: 35884.87
...

Sheet Freight 2009-2010
B1: Net Sales | C1: Grand Total $ (Freight) | D1: % of Net Sales | E1: Total Units | F1: Grand Total Shipments** | G1: UPS Boxes | I1: UPS $ | J1: Cost per Box (UPS) | K1: UPS Weight | M1: Fedex Boxes | O1: Fedex$ | P1: Cost per Box ( FEDEX) | Q1: Fedex Weight | R1: UPS/Fedex Weight | T1: UPS/FEDEX $ | V1: Difference $ (ADC VS MDC) | X1: UPS/FED Units *** | Z1: Difference Units (ADC VS MDC) | AB1: LTL Orders | AC1: LTL Weight | AE1: LTL$ | AF1: Cost per Shipment ( LTL)
A3: 39814 | B3: 1.000168e+08 | C3: 202196.89 | D3: 0.0020216292 | E3: 1169614 | F3: 1970 | G3: 1664 | I3: 67362 | J3: 40.481971 | T3: 67362 | X3: 1664 | AB3: 306 | AC3: 526395 | AE3: 134834.89 | AF3: 440.6369
A4: 40179 | B4: 1.3133529e+08 | C4: =SUM(I4,O4,T4) -> 273995.42 | D4: =C4/B4 -> 0.0020862285 | E4: 1305602 | F4: =SUM(G4,M4,AB4) -> 329 | G4: ='Worksheet 2010'!B18 -> 0 | I4: ='Worksheet 2010'!C18 -> 136972.7 | J4: =I4/G4 -> #DIV/0! | M4: ='Worksheet 2010'!J18 -> 1 | O4: ='Worksheet 2010'!K18 -> 25.01 | T4: =SUM(I4,O4) -> 136997.71 | X4: =SUM(G4,M4) -> 1 | AB4: ='Worksheet 2010'!F18 -> 328 | AC4: ='Worksheet 2010'!G18 -> 370982 | AE4: ='Worksheet 2010'!H18 -> 140846.11 | AF4: =AE4/AB4 -> 429.40887
A6: 39845 | B6: 1.0512049e+08 | C6: 221499.3 | D6: 0.0021070991 | E6: 1394613 | F6: 1994 | G6: 1629 | I6: 63549.84 | J6: 39.011565 | T6: 63549.84 | X6: 1629 | AB6: 365 | AC6: 999508 | AE6: 157949.46 | AF6: 432.73825
A7: 40219 | B7: 1.0841425e+08 | C7: =SUM(I7,O7,T7) -> 146349.34 | D7: =C7/B7 -> 0.0013499087 | E7: 984652 | F7: =SUM(G7,M7,AB7) -> 310 | G7: ='Worksheet 2010'!B36 -> 0 | I7: ='Worksheet 2010'!C36 -> 73123.46 | J7: =I7/G7 -> #DIV/0! | M7: ='Worksheet 2010'!J36 -> 2 | O7: ='Worksheet 2010'!K36 -> 51.21 | T7: =SUM(I7,O7) -> 73174.67 | X7: =SUM(G7,M7) -> 2 | AB7: ='Worksheet 2010'!F36 -> 308 | AC7: ='Worksheet 2010'!G36 -> 323393 | AE7: ='Worksheet 2010'!H36 -> 137080.81 | AF7: =AE7/AB7 -> 445.06756
A9: 39873 | B9: 1.4300737e+08 | C9: 409448.6 | D9: 0.0028631294 | E9: 1747620 | F9: 1969 | G9: 1487 | I9: 56929.81 | J9: 38.28501 | M9: 2 | O9: 93.8 | T9: 57023.61 | X9: 1489 | AB9: 480 | AC9: 1067286 | AE9: 352424.99 | AF9: 734.21873
A10: 40238 | B10: 1.3529734e+08 | C10: =SUM(I10,O10,T10) -> 241368.96 | D10: =C10/B10 -> 0.001783989 | E10: 1253261 | F10: =SUM(G10,M10,AB10) -> 372 | G10: ='Worksheet 2010'!B62 -> 0 | I10: ='Worksheet 2010'!C62 -> 120658.31 | J10: =I10/G10 -> #DIV/0! | M10: ='Worksheet 2010'!J62 -> 1 | O10: ='Worksheet 2010'!K62 -> 26.17 | T10: =SUM(I10,O10) -> 120684.48 | X10: =SUM(G10,M10) -> 1 | AB10: ='Worksheet 2010'!F62 -> 371 | AC10: ='Worksheet 2010'!G62 -> 402215 | AE10: ='Worksheet 2010'!H62 -> 202578.29 | AF10: =AE10/AB10 -> 546.03313
A12: 39904 | B12: 1.3063995e+08 | C12: 237106.21 | D12: 0.0018149595 | E12: 1370883 | F12: 3337 | G12: 2293 | I12: 74108.06 | J12: 32.319259 | M12: 1 | O12: 47.25 | T12: 74155.31 | X12: 2294 | AB12: 1043 | AC12: 747618 | AE12: 162950.9 | AF12: 156.23289
A13: 40269 | B13: 1.3582922e+08 | C13: =SUM(I13,O13,T13) -> 203792.06 | D13: =C13/B13 -> 0.001500355 | E13: 1233908 | F13: =SUM(G13,M13,AB13) -> 788 | G13: ='Worksheet 2010'!B85 -> 0 | I13: ='Worksheet 2010'!C85 -> 101896.03 | J13: =I13/G13 -> #DIV/0! | M13: ='Worksheet 2010'!J85 -> 0 | O13: ='Worksheet 2010'!K85 -> 0 | T13: =SUM(I13,O13) -> 101896.03 | X13: =SUM(G13,M13) -> 0 | AB13: ='Worksheet 2010'!F85 -> 788 | AC13: ='Worksheet 2010'!G85 -> 340935 | AE13: ='Worksheet 2010'!H85 -> 139264.44 | AF13: =AE13/AB13 -> 176.73152
A15: 39934 | B15: 1.0941589e+08 | C15: 221719.26 | D15: 0.0020263899 | E15: 1079187 | F15: 2456 | G15: 2186 | I15: 89113.57 | J15: 40.765586 | T15: 89113.57 | X15: 2186 | AB15: 270 | AC15: 500843 | AE15: 132605.69 | AF15: 491.13219
A16: 40299 | B16: 1.2845684e+08 | C16: =SUM(I16,O16,T16) -> 189646.84 | D16: =C16/B16 -> 0.0014763468 | E16: 1184712 | F16: =SUM(G16,M16,AB16) -> 633 | G16: ='Worksheet 2010'!B103 -> 557 | I16: ='Worksheet 2010'!C103 -> 94770.47 | J16: =I16/G16 -> 170.14447 | M16: ='Worksheet 2010'!J103 -> 2 | O16: ='Worksheet 2010'!K103 -> 52.95 | T16: =SUM(I16,O16) -> 94823.42 | X16: =SUM(G16,M16) -> 559 | AB16: ='Worksheet 2010'!F103 -> 74 | AC16: ='Worksheet 2010'!G103 -> 88265 | AE16: ='Worksheet 2010'!H103 -> 28957.13 | AF16: =AE16/AB16 -> 391.31257
A18: 39965 | B18: 1.1507381e+08 | C18: 236702.89 | D18: 0.0020569658 | E18: 1155004 | F18: 2092 | G18: 1724 | I18: 71509.78 | J18: 41.478991 | T18: 71509.78 | X18: 1724 | AB18: 368 | AC18: 578624 | AE18: 165193.11 | AF18: 448.89432
A19: 40330 | C19: =SUM(I19,O19,T19) -> 0 | D19: =C19/B19 -> #DIV/0! | F19: =SUM(G19,M19,AB19) -> 0 | G19: ='Worksheet 2010'!B124 -> 0 | T19: =SUM(I19,O19) -> 0 | X19: =SUM(G19,M19) -> 0 | AF19: =AE19/AB19 -> #DIV/0!
A21: 39995 | B21: 1.2635173e+08 | C21: 197375.15 | D21: 0.0015621088 | E21: 1202463 | F21: 1687 | G21: 1393 | I21: 67153.79 | J21: 48.208033 | T21: 67153.79 | X21: 1393 | AB21: 294 | AC21: 546142 | AE21: 130221.36 | AF21: 442.9298
A23: 40026 | B23: 1.0680306e+08 | C23: 211200.55 | D23: 0.0019774767 | E23: 1089383 | F23: 2390 | G23: 2034 | I23: 81012.14 | J23: 39.828977 | T23: 81012.14 | X23: 2034 | AB23: 356 | AC23: 451722 | AE23: 130188.41 | AF23: 365.69778
A25: 40057 | B25: 1.2009225e+08 | C25: 302857.13 | D25: 0.0025218707 | E25: 1221043 | F25: 1988 | G25: 1602 | I25: 68867.61 | J25: 42.988521 | M25: 2 | O25: 46.76 | T25: 68914.37 | X25: 1604 | AB25: 384 | AC25: 596976 | AE25: 233942.76 | AF25: 609.22594
A27: 40087 | B27: 1.4388218e+08 | C27: 180342.99 | D27: 0.0012534074 | E27: 1352901 | F27: 2250 | G27: 1957 | I27: 85331.27 | J27: 43.603102 | M27: 2 | O27: 46.76 | T27: 85378.03 | X27: 1959 | AB27: 291 | AC27: 358067 | AE27: 94964.959 | AF27: 326.34007
A29: 40118 | B29: 1.2568699e+08 | C29: 292644.17 | D29: 0.0023283569 | E29: 1174335 | F29: 2244 | G29: 1900 | I29: 96356.21 | J29: 50.713795 | M29: 1 | O29: 24.78 | T29: 96380.99 | X29: 1901 | AB29: 343 | AC29: 497238 | AE29: 196263.18 | AF29: 572.19586
A31: 40148 | B31: 1.3209954e+08 | C31: 136616.22 | D31: 0.0010341915 | E31: 1258399 | F31: 2921 | G31: 2850 | I31: 116502.79 | J31: 40.878172 | T31: 116502.79 | X31: 2850 | AB31: 71 | AC31: 89742 | AE31: 20113.43 | AF31: 283.28775
A34: * Shipments
A35: UPS: Packages
A36: LTL: Pallets
A43: UPS MDC ( only) 2000 | I43: 674466.34

Sheet Freight - total 
B1: Net Sales | C1: Grand Total $ (Freight) | D1: % of Net Sales | E1: Total Units | F1: Grand Total Shipments** | G1: UPS Boxes | I1: UPS $ | J1: Cost per Box (UPS) | K1: UPS Weight | M1: Fedex Boxes | O1: Fedex$ | P1: Cost per Box (FEDEX) | Q1: Fedex Weight | R1: UPS/Fedex Weight | T1: UPS/FEDEX $ | V1: Difference $ (ADC VS MDC) | X1: UPS/FED Units *** | Z1: Difference Units (ADC VS MDC) | AB1: LTL Orders | AC1: LTL Weight | AE1: LTL$ | AF1: Cost per Shipment ( LTL) | AH1: Difference $ (ADC vs MDC Grand Total) | AI1: Difference Units (ADC vs MDC Grand Total) | AJ1: B/O Product | AK1: # orders ( x 2) | AL1: Average Cost /Shipment | AM1: O/N Shipment | AN1: Total Average | AO1: Total O/N
A3: ADC Jan 1999 | B3: 7400000 | C3: 87671.01 | D3: 0.011847434 | F3: 4669 | G3: 1606 | I3: 8516.81 | J3: 5.3031196 | K3: 8516.81 | M3: 2812 | O3: 48768.89 | P3: 17.343133 | Q3: 48802 | R3: 57318.81 | T3: 57285.7 | V3: 0 | X3: 4418 | Z3: -2482 | AB3: 251 | AC3: 59451 | AE3: 30385.31 | AF3: 121.05701
A4: ADC Jan 2000 | B4: 7826992.6 | C4: 137398.77 | D4: 0.017554478 | E4: 909758 | F4: 7298 | G4: 3924 | I4: 15127.84 | J4: 3.855209 | K4: 47545.38 | M4: 2976 | O4: 57560.41 | P4: 19.341536 | Q4: 58079 | R4: 105624.38 | T4: 72688.25 | X4: 6900 | AB4: 398 | AC4: 133480.37 | AE4: 64710.52 | AF4: 162.58925
A5: MDC Jan 2001 | B5: 13641310 | C5: 73365.85 | D5: 0.0053782115 | E5: 466018 | F5: 2057 | G5: 1905 | I5: 38953.85 | J5: 20.448215 | T5: 38953.85 | X5: 1905 | AB5: 152 | AC5: 64991 | AE5: 34412 | AF5: 226.39474
A6: MDC Jan 2002 | B6: 34731081 | C6: 136306.97 | D6: 0.0039246394 | E6: 805305 | F6: 7975 | G6: 7753 | I6: 79111.56 | J6: 10.203993 | M6: 16 | O6: 675.1 | P6: 42.19375 | T6: 79786.66 | X6: 7769 | AB6: 206 | AC6: 58753 | AE6: 56520.31 | AF6: 274.37044
A7: MDC Jan 2003 | B7: 64075075 | C7: 254354.97 | D7: 0.0039696399 | E7: 1004762 | F7: 7590 | G7: 6983 | I7: 89992.76 | J7: 12.887407 | T7: 89992.76 | X7: 6983 | AB7: 607 | AC7: 358240 | AE7: 164362.21 | AF7: 270.77794
A8: MDC Jan 2004 | B8: 83549000 | C8: 341593.53 | D8: 0.0040885412 | E8: 1397122 | F8: 7921 | G8: 7355 | I8: 147372.5 | J8: 20.03705 | T8: 147372.5 | X8: 7355 | AB8: 566 | AC8: 413229 | AE8: 194221.03 | AF8: 343.1467
A9: MDC Jan 2005 | B9: 55669433 | C9: 157015.23 | D9: 0.0028204927 | E9: 807575 | F9: 4216 | G9: 4059 | I9: 80599.53 | J9: 19.856992 | T9: 80599.53 | X9: 4059 | AB9: 157 | AC9: 242465 | AE9: 76415.7 | AF9: 486.7242
A10: MDC Jan 2006 | B10: 65062458 | C10: 310711.39 | D10: 0.0047755864 | E10: 974900 | F10: 4037 | G10: 3571 | I10: 60334.97 | J10: 16.895819 | M10: 0 | O10: 0 | T10: 60334.97 | X10: 3571 | AB10: 466 | AC10: 541835 | AE10: 250376.42 | AF10: 537.28845
A11: MDC Jan 2007 | B11: 75469565 | C11: 183877.04 | D11: 0.0024364397 | E11: 867354 | F11: 2233 | G11: 1833 | I11: 34341.23 | J11: 18.734986 | M11: 0 | O11: 0 | T11: 34341.23 | X11: 1833 | AB11: 400 | AC11: 479034 | AE11: 149535.81 | AF11: 373.83952
A12: MDC Jan 2008 | B12: 96198920 | C12: 170894.66 | D12: 0.0017764717 | E12: 885123 | F12: 1800 | G12: 1485 | I12: 28774.05 | J12: 19.376465 | T12: 28774.05 | X12: 1485 | AB12: 315 | AC12: 495654 | AE12: 142120.61 | AF12: 451.17654
A13: MDC Jan 2009 | B13: 1.000168e+08 | C13: 202196.89 | D13: 0.0020216292 | E13: 1169614 | F13: 1970 | G13: 1664 | H13: 0 | I13: 67362 | J13: 40.481971 | K13: 0 | L13: 0 | M13: 0 | N13: 0 | O13: 0 | P13: 0 | Q13: 0 | R13: 0 | S13: 0 | T13: 67362 | U13: 0 | V13: 0 | W13: 0 | X13: 1664 | Y13: 0 | Z13: 0 | AA13: 0 | AB13: 306 | AC13: 526395 | AD13: 0 | AE13: 134834.89 | AF13: 440.6369
A14: 40179 | B14: ='Freight 2009-2010'!B4 -> 1.3133529e+08 | C14: ='Freight 2009-2010'!C4 -> 273995.42 | D14: ='Freight 2009-2010'!D4 -> 0.0020862285 | E14: ='Freight 2009-2010'!E4 -> 1305602 | F14: ='Freight 2009-2010'!F4 -> 329 | G14: ='Freight 2009-2010'!G4 -> 0 | I14: ='Freight 2009-2010'!I4 -> 136972.7 | J14: ='Freight 2009-2010'!J4 -> #DIV/0! | K14: ='Freight 2009-2010'!K4 -> 0 | L14: ='Freight 2009-2010'!L4 -> 0 | M14: ='Freight 2009-2010'!M4 -> 1 | N14: ='Freight 2009-2010'!N4 -> 0 | O14: ='Freight 2009-2010'!O4 -> 25.01 | P14: ='Freight 2009-2010'!P4 -> 0 | ... AF14: ='Freight 2009-2010'!AF4 -> 429.40887
A16: ADC Feb 1999 | B16: 10487000 | C16: 37863.35 | D16: 0.0036105035 | F16: 3408 | G16: 2833 | I16: 12155.1 | J16: 4.2905401 | K16: 31967.3 | M16: 356 | O16: 6774.25 | P16: 19.028792 | Q16: 6464 | R16: 38431.3 | T16: 18929.35 | V16: 0 | X16: 3189 | Z16: -4457 | AB16: 219 | AC16: 48725 | AE16: 18934 | AF16: 86.456621
A17: ADC Feb 2000 | B17: 8131359.8 | C17: 74472.46 | D17: 0.0091586723 | E17: 970965 | F17: 7944 | G17: 5691 | I17: 11802.86 | J17: 2.0739519 | K17: 32547.19 | M17: 1955 | O17: 37365.6 | P17: 19.112839 | Q17: 34971 | R17: 67518.19 | T17: 49168.46 | X17: 7646 | AB17: 298 | AC17: 163911 | AE17: 25304 | AF17: 84.912752
A18: MDC Feb 2001 | B18: 9544805 | C18: 69678.99 | D18: 0.0073002005 | E18: 389763 | F18: 4363 | G18: 4290 | I18: 47056.57 | J18: 10.968897 | O18: 291.78 | T18: 47348.35 | X18: 4290 | AB18: 73 | AC18: 34808 | AE18: 22330.64 | AF18: 305.89918
A19: MDC Feb 2002 | B19: 26001715 | C19: 85313.19 | D19: 0.0032810601 | E19: 427195 | F19: 4227 | G19: 4085 | I19: 45303.87 | J19: 11.090299 | M19: 6 | P19: 215.57 | T19: 45303.87 | X19: 4091 | AB19: 136 | AC19: 56649 | AE19: 40009.32 | AF19: 294.18618
A20: MDC Feb 2003 | B20: 49389005 | C20: 195541.58 | D20: 0.0039592128 | E20: 789649 | F20: 5152 | G20: 4713 | I20: 97265.59 | J20: 20.637723 | T20: 97265.59 | X20: 4713 | AB20: 439 | AC20: 207093 | AE20: 98275.99 | AF20: 223.8633
A21: MDC Feb 2004 | B21: 53403528 | C21: 192709.75 | D21: 0.0036085584 | E21: 793259 | F21: 5002 | G21: 4570 | I21: 58406.39 | J21: 12.780392 | M21: 2 | O21: 19.38 | T21: 58425.77 | X21: 4572 | AB21: 430 | AC21: 427269 | AE21: 134283.98 | AF21: 312.28833
A22: MDC Feb 2005 | B22: 32347055 | C22: 180922.97 | D22: 0.0055931822 | E22: 640148 | F22: 5113 | G22: 4758 | I22: 64437.28 | J22: 13.542934 | T22: 64437.28 | X22: 4758 | AB22: 355 | AC22: 337913 | AE22: 116485.69 | AF22: 328.1287
A23: MDC Feb 2006 | B23: 64339939 | C23: 252806.24 | D23: 0.0039292272 | E23: 893205 | F23: 4159 | G23: 3706 | I23: 57676.68 | J23: 15.563055 | T23: 57676.68 | X23: 3706 | AB23: 453 | AC23: 534947 | AE23: 195129.56 | AF23: 430.74958
A24: MDC Feb 2007 | B24: 75547676 | C24: 120775.66 | D24: 0.0015986681 | E24: 819664 | F24: 1982 | G24: 1735 | I24: 30727.03 | J24: 17.710104 | T24: 30727.03 | X24: 1735 | AB24: 247 | AC24: 261660 | AE24: 90048.63 | AF24: 364.56935
A25: MDC Feb 2008 | B25: 86737515 | C25: 144724.78 | D25: 0.0016685373 | E25: 870275 | F25: 2008 | G25: 1692 | I25: 30171.95 | J25: 17.832122 | T25: 30171.95 | X25: 1692 | AB25: 316 | AC25: 455121 | AE25: 114552.83 | AF25: 362.50896
A26: MDC Feb 2009 | B26: 1.0512049e+08 | C26: 221499.3 | D26: 0.0021070991 | E26: 1394613 | F26: 1994 | G26: 1629 | H26: 0 | I26: 63549.84 | J26: 39.011565 | K26: 0 | L26: 0 | M26: 0 | N26: 0 | O26: 0 | P26: 0 | Q26: 0 | R26: 0 | S26: 0 | T26: 63549.84 | U26: 0 | V26: 0 | W26: 0 | X26: 1629 | Y26: 0 | Z26: 0 | AA26: 0 | AB26: 365 | AC26: 999508 | AD26: 0 | AE26: 157949.46 | AF26: 432.73825
A27: 40210 | B27: ='Freight 2009-2010'!B7 -> 1.0841425e+08 | C27: ='Freight 2009-2010'!C7 -> 146349.34 | D27: ='Freight 2009-2010'!D7 -> 0.0013499087 | E27: ='Freight 2009-2010'!E7 -> 984652 | F27: ='Freight 2009-2010'!F7 -> 310 | G27: ='Freight 2009-2010'!G7 -> 0 | H27: ='Freight 2009-2010'!H7 -> 0 | I27: ='Freight 2009-2010'!I7 -> 73123.46 | ... AF27: ='Freight 2009-2010'!AF7 -> 445.06756
A29: ADC March 1999 | B29: 10200000 | C29: 128393.25 | D29: 0.012587574 | E29: 464105 | F29: 7141 | G29: 2539 | I29: 11330.21 | J29: 4.4624695 | K29: 26052.35 | M29: 4326 | O29: 81674.65 | P29: 18.879947 | Q29: 80147 | R29: 106199.35 | T29: 93004.86 | V29: 0 | X29: 6865 | Z29: 3962 | AB29: 276 | AC29: 79292.05 | AE29: 35388.39 | AF29: 128.2188
A30: ADC March 2000 | B30: 8100261 | C30: 43895.35 | D30: 0.0054190044 | E30: 719507 | F30: 2958 | G30: 1502 | I30: 5886.3 | J30: 3.9189747 | K30: 16389.21 | M30: 1401 | O30: 30457.08 | P30: 21.739529 | Q30: 27723 | R30: 44112.21 | T30: 36343.38 | V30: 15610.13 | X30: 2903 | Z30: 830 | AB30: 55 | AC30: 13404 | AE30: 7551.97 | AF30: 137.30855 | AH30: 21432.69 | AI30: 878
A31: MDC March 2000 | B31: 2860931 | C31: 22462.66 | D31: 0.0078515211 | E31: 464105 | F31: 2080 | G31: 2073 | I31: 20733.25 | J31: 10.001568 | T31: 20733.25 | X31: 2073 | AB31: 7 | AC31: 3588 | AE31: 1729.41 | AF31: 247.05857
A32: MDC March 2001 | B32: 16445897 | C32: 82428.85 | D32: 0.0050121225 | E32: 464105 | F32: 3282 | G32: 3145 | I32: 50786.19 | J32: 16.148232 | O32: 364.78 | T32: 51150.97 | X32: 3145 | AB32: 137 | AC32: 51295 | AE32: 31277.88 | AF32: 228.30569
A33: MDC March 2002 | B33: 26222268 | C33: 47632.28 | D33: 0.0018164821 | E33: 383406 | F33: 10990 | G33: 10784 | I33: 43048.67 | J33: 3.9919019 | O33: 55.56 | T33: 43104.23 | X33: 10784 | AB33: 206 | AC33: 38633 | AE33: 4528.05 | AF33: 21.980825
A34: MDC March 2003 | B34: 46282727 | C34: 213091.23 | D34: 0.00460412 | E34: 857054 | F34: 4618 | G34: 4110 | I34: 71330.69 | J34: 17.355399 | T34: 71330.69 | X34: 4110 | AB34: 508 | AC34: 274920 | AE34: 141760.54 | AF34: 279.05618
A35: MDC March 2004 | B35: 33154203 | C35: 113620.32 | D35: 0.0034270261 | E35: 611930 | F35: 3924 | G35: 3683 | I35: 43775.81 | J35: 11.885911 | M35: 2 | O35: 19.7 | T35: 43795.51 | X35: 3685 | AB35: 239 | AC35: 126002 | AE35: 69824.81 | AF35: 292.15402
A36: MDC March 2005 | B36: 45238681 | C36: 220374.8 | D36: 0.0048713799 | E36: 707379 | F36: 5223 | G36: 4843 | I36: 64027 | J36: 13.220524 | T36: 64027 | X36: 4843 | AB36: 380 | AC36: 434353 | AE36: 156347.8 | AF36: 411.44158
A37: MDC March 2006 | B37: 84503070 | C37: 326433.61 | D37: 0.0038629793 | E37: 1172205 | F37: 4071 | G37: 3582 | I37: 55620.6 | J37: 15.527806 | T37: 55620.6 | X37: 3582 | AB37: 489 | AC37: 585985 | AE37: 270813.01 | AF37: 553.80984
A38: MDC March 2007 | B38: 90619680 | C38: 238475.09 | D38: 0.0026316037 | E38: 998516 | F38: 2683 | G38: 2332 | I38: 48835.89 | J38: 20.941634 | T38: 48835.89 | X38: 2332 | AB38: 351 | AC38: 408330 | AE38: 189639.2 | AF38: 540.28262
A39: MDC March 2008 | B39: 1.1266421e+08 | C39: 252902.65 | D39: 0.002244747 | E39: 1249899 | F39: 2678 | G39: 2317 | I39: 50864.24 | J39: 21.952628 | T39: 50864.24 | X39: 2317 | AB39: 361 | AC39: 517632 | AE39: 202038.41 | AF39: 559.66319
A40: MDC March 2009 | B40: 1.4300737e+08 | C40: 409448.6 | D40: 0.0028631294 | E40: 1747620 | F40: 1969 | G40: 1487 | H40: 0 | I40: 56929.81 | J40: 38.28501 | K40: 0 | L40: 0 | M40: 2 | N40: 0 | O40: 93.8 | P40: 0 | Q40: 0 | R40: 0 | S40: 0 | T40: 57023.61 | U40: 0 | V40: 0 | W40: 0 | X40: 1489 | Y40: 0 | Z40: 0 | AA40: 0 | AB40: 480 | AC40: 1067286 | AD40: 0 | AE40: 352424.99 | AF40: 734.21873
A41: 40238 | B41: ='Freight 2009-2010'!B10 -> 1.3529734e+08 | C41: ='Freight 2009-2010'!C10 -> 241368.96 | D41: ='Freight 2009-2010'!D10 -> 0.001783989 | E41: ='Freight 2009-2010'!E10 -> 1253261 | F41: ='Freight 2009-2010'!F10 -> 372 | G41: ='Freight 2009-2010'!G10 -> 0 | H41: ='Freight 2009-2010'!H10 -> 0 | I41: ='Freight 2009-2010'!I10 -> 120658.31 | ... AF41: ='Freight 2009-2010'!AF10 -> 546.03313
A43: ADC April 1999 | B43: 3757200 | C43: 72319.66 | D43: 0.019248286 | E43: 415564 | F43: 4888 | G43: 2384 | I43: 11478.37 | J43: 4.8147525 | K43: 21176.36 | M43: 2349 | O43: 43605.07 | P43: 18.563248 | Q43: 39821 | R43: 60997.36 | T43: 55083.44 | V43: 12624.65 | X43: 4733 | Z43: 2051 | AB43: 155 | AC43: 24832 | AE43: 17236.22 | AF43: 111.20142 | AH43: 15368.89 | AI43: 2133
A44: MDC April 2000 | B44: 12563556 | C44: 56950.77 | D44: 0.0045330136 | E44: 731336 | F44: 2755 | G44: 2682 | I44: 42458.79 | J44: 15.831018 | T44: 42458.79 | X44: 2682 | AB44: 73 | AC44: 24251 | AE44: 14491.98 | AF44: 198.52027
...
