Workbook
Name Account_Details: 'July Contra Actuals'!$A$1:$P$11

Sheet Freight Out
E3: Contra Revenue Accruals | O3: June Forecast | W3: SGD
E4: Gross Revenue | F4: 43586 | G4: 43617 | H4: 43647 | I4: 43678 | J4: 43709 | K4: 43739 | L4: 43770 | M4: 43800 | N4: YTD July | O4: 43617 | V4: Freight out amount | W4: 44223.53 | X4: Sub Account
E5: Korea Duty free | F5: ='APAC 28.6.2019'!C14 -> 2561909.3 | G5: ='7.9.2019'!M12 -> 1215975.6 | H5: =-'JULY Actuals'!C16 -> 1080986.1 | N5: =SUM(F5:H5) -> 4858871 | W5: =(H5/$H$10)*$W$4 -> 22192.741 | X5: KR001-DUT-4140-JUL
E6: Guam Duty Free | F6: 0 | G6: ='7.9.2019'!M18 -> 103675.56 | H6: =-'JULY Actuals'!C15 -> 34384.079 | N6: =SUM(F6:H6) -> 138059.64 | W6: =(H6/$H$10)*$W$4 -> 705.90818 | X6: GU001-DUT-4140-JUL
E7: Philippines | F7: ='APAC 28.6.2019'!C34 -> 1291859 | G7: ='June Actuals'!C3 -> 0 | H7: =-'JULY Actuals'!C13 -> 1038713.6 | N7: =SUM(F7:H7) -> 2330572.6 | W7: =(H7/$H$10)*$W$4 -> 21324.881 | X7: PH001-STR-4100-JUL
E8: Indonesia | F8: ='APAC 28.6.2019'!C44 -> 898765.7 | G8: ='7.9.2019'!M20 -> 730618.05 | N8: =SUM(F8:H8) -> 1629383.8
E9: Korea Domestic | F9: ='APAC 28.6.2019'!C4 -> 13091092 | G9: ='7.9.2019'!M10+'7.9.2019'!M11 -> 19351813 | N9: =SUM(F9:H9) -> 32442906 | P9: 20649512
E10: APAC TOTAL | F10: =SUM(F5:F9) -> 17843626 | G10: =SUM(G5:G9) -> 21402083 | H10: =SUM(H5:H9) -> 2154083.8 | N10: =SUM(F10:H10) -> 41399793 | O10: ='APAC 28.6.2019'!D76 -> 22720756 | P10: =P9-G9 -> 1297698.5
D12: GL Account | E12: Contra Revenue | F12: 43586 | G12: 43617 | H12: 43647 | N12: YTD July | O12: 1.35
D13: 497100 | E13: Korea Duty free | F13: ='APAC 28.6.2019'!C16 -> -386369.46 | G13: ='7.9.2019'!M15 -> -171668.31 | H13: =-H5*0.15 -> -162147.92 | N13: =SUM(F13:H13) -> -720185.69 | O13: =N13*$O$12 -> -972250.68
D14: 497100 | E14: Guam Duty Free | F14: 0 | G14: ='7.9.2019'!M19 -> -15348.761 | H14: =-H6*0.15 -> -5157.6119 | N14: =SUM(F14:H14) -> -20506.373 | O14: =N14*$O$12 -> -27683.603 | S14: -2087169
D15: 497100 | E15: Philippines | F15: 0 | G15: -900000 | H15: =-H7*0.7 -> -727099.49 | N15: =SUM(F15:H15) -> -1627099.5 | O15: =N15*$O$12 -> -2196584.3 | S15: =F7*10% -> 129185.9 | U15: =G18-S15 -> -2094569.2
D16: 497100 | E16: Indonesia | F16: 0 | G16: ='7.9.2019'!M21 -> -108165.16 | H16: =H8*0% -> 0 | N16: =SUM(F16:H16) -> -108165.16 | O16: =N16*$O$12 -> -146022.97 | S16: =S14+S15 -> -1957983.1
E17: Korea Domestic | F17: ='APAC 28.6.2019'!C6 -> -584510.12 | G17: ='7.9.2019'!M13 -> -770201.04 | N17: =SUM(F17:H17) -> -1354711.2
E18: APAC TOTAL | F18: =SUM(F13:F17) -> -970879.58 | G18: =SUM(G13:G17) -> -1965383.3 | H18: =SUM(H13:H17) -> -894405.02 | N18: =SUM(F18:H18) -> -3830667.9 | S18: 21402083
E20: Net Revenue (Expected) | F20: 43586 | G20: 43617 | H20: 43647 | N20: YTD July
E21: Korea Duty free | F21: =F5+F13 -> 2175539.8 | G21: =G5+G13 -> 1044307.3 | H21: =H5+H13 -> 918838.21 | N21: =SUM(F21:H21) -> 4138685.3
E22: Guam Duty Free | F22: =F6+F14 -> 0 | G22: =G6+G14 -> 88326.8 | H22: =H6+H14 -> 29226.467 | N22: =SUM(F22:H22) -> 117553.27
E23: Philippines | F23: =F7+F15 -> 1291859 | G23: =G7+G15 -> -900000 | H23: =H7+H15 -> 311614.07 | N23: =SUM(F23:H23) -> 703473.06
E24: Indonesia | F24: =F8+F16 -> 898765.7 | G24: =G8+G16 -> 622452.89 | H24: =H8+H16 -> 0 | N24: =SUM(F24:H24) -> 1521218.6
E25: Korea Domestic | F25: =F9+F17 -> 12506582 | G25: =G9+G17 -> 18581612 | H25: =H9+H17 -> 0 | N25: =SUM(F25:H25) -> 31088195
E26: APAC TOTAL | F26: =SUM(F21:F25) -> 16872747 | G26: =SUM(G21:G25) -> 19436699 | H26: =SUM(H21:H25) -> 1259678.7 | N26: =SUM(F26:H26) -> 37569125 | O26: ='APAC 28.6.2019'!D78 -> 21619342 | P26: =G26-O26 -> -2182643
E29: ** JV will be on reversal mode, accruals to be based upon YTD numbers

Sheet JULY Actuals
A3: Row Labels | B3: Sum of Credit Amount
A4: Better For You Corporation | B4: -1427504.1
A5: HDC Shilla Duty Free LTD. | B5: -139226.84
A6: Hotel Lotte Co., Ltd. (Duty Free) | B6: -1346372.4
A7: Lotte Duty Free Guam | B7: -47254.04
A8: PT JAGAD UTAMA LESTARI | B8: 82190.17
A9: Grand Total | B9: -2878167.2
A12: Gross Revenue | C12: 1.3743 | D12: From MY exchange rate file.
A13: BFY | B13: =B4 -> -1427504.1 | C13: =B13/$C$12 -> -1038713.6
A14: PT JUUL | B14: =B8 -> 82190.17 | C14: =B14/$C$12 -> 59805.115
A15: Dutyfree Guam, | B15: =B7 -> -47254.04 | C15: =B15/$C$12 -> -34384.079
A16: Dutyfree Korea | B16: =B5+B6 -> -1485599.2 | C16: =B16/$C$12 -> -1080986.1

Sheet July Contra Actuals
A1: Selected | B1: Module | C1: Batch Number | D1: Tran. Date | E1: Period | F1: Description | G1: Business Account | H1: Ref. Number | I1: Account | J1: Subaccount | K1: Beg. Balance | L1: Debit Amount | M1: Reclass. Batch Number | N1: Credit Amount | O1: Ending Balance | P1: Business Account Name
B2: GL | C2: GL08-00001545 | D2: 43647 | E2: 07-2019 | F2: Payment to Philippines Master Distributor | H2: BFY | I2: 497100 | J2: PH001-STR-4100-JUL | K2: 2149317.8 | L2: 0 | N2: 1217522.6 | O2: 931795.25
B3: GL | C3: GL08-00001432 | D3: 43647 | E3: 07-2019 | F3: Contra Revenue Accruals - YTD June 2019 | H3: Contra Accrl Ju | I3: 497100 | J3: KR001-DUT-4140-JRK | K3: 931795.25 | L3: 0 | N3: 767977.59 | O3: 163817.66
B4: GL | C4: GL08-00001432 | D4: 43647 | E4: 07-2019 | F4: Contra Revenue Accruals - YTD June 2019 | H4: Contra Accrl Ju | I4: 497100 | J4: GU001-DUT-4140-JRK | K4: 163817.66 | L4: 0 | N4: 20914.22 | O4: 142903.44
B5: GL | C5: GL08-00001432 | D5: 43647 | E5: 07-2019 | F5: Contra Revenue Accruals - YTD June 2019 | H5: Contra Accrl Ju | I5: 497100 | J5: PH001-STR-4100-JRK | K5: 142903.44 | L5: 0 | N5: 174763.06 | O5: -31859.62
B6: GL | C6: GL08-00001432 | D6: 43647 | E6: 07-2019 | F6: Contra Revenue Accruals - YTD June 2019 | H6: Contra Accrl Ju | I6: 497100 | J6: ID001-STR-4100-JRK | K6: -31859.62 | L6: 0 | N6: 147385.84 | O6: -179245.46
B7: GL | C7: GL08-00001604 | D7: 43647 | E7: 07-2019 | F7: Reversal of Contra Revenue Accruals - YTD June 2019 | H7: Contra Accrl Ju | I7: 497100 | J7: PH001-STR-4100-JUL | K7: -179245.46 | L7: 174763.06 | N7: 0 | O7: -4482.4
B8: AP | C8: GL08-00001975 | D8: 43627 | E8: 07-2019 | F8: Q2_Others (BFY headcount) | G8: 08-0000097 | H8: AP08-00001007 | I8: 497100 | J8: PH001-CRP-4100-JUL | K8: -4482.4 | L8: 461148.83 | N8: 0 | O8: 456666.43 | P8: Better For You Corporation
B9: AP | C9: GL08-00001975 | D9: 43627 | E9: 07-2019 | F9: Q2_Others (BFY headcount) 12% VAT | G9: 08-0000097 | H9: AP08-00001007 | I9: 497100 | J9: PH001-CRP-4100-JUL | K9: 456666.43 | L9: 55337.86 | N9: 0 | O9: 512004.29 | P9: Better For You Corporation
B10: AP | C10: GL08-00001498 | D10: 43644 | E10: 07-2019 | F10: Minimart - Listing & branding fee payment | G10: 08-0000140 | H10: AP08-00000713 | I10: 497100 | J10: ID001-CRP-4100-JUL | K10: 512004.29 | L10: 157906.43 | N10: 0 | O10: 669910.72 | P10: PT Jagad Utama Lestari
B11: AP | C11: GL08-00001498 | D11: 43644 | E11: 07-2019 | F11: Minimart - Listing & branding fee payment_10% VAT | G11: 08-0000140 | H11: AP08-00000713 | I11: 497100 | J11: ID001-CRP-4100-JUL | K11: 669910.72 | L11: 15790.64 | N11: 0 | O11: 685701.36 | P11: PT Jagad Utama Lestari
M13: 1.3743
K14: BFY | L14: =L8+L9 -> 516486.69 | M14: =L14/$M$13 -> 375818.01
K15: PT JUL | L15: =L10+L11 -> 173697.07 | M15: =L15/$M$13 -> 126389.49

Sheet APAC 28.6.2019
C1: AVG May Rate | D1: AOP/FC Rates | E1: AOP/FC Rates | F1: AOP/FC Rates | G1: AOP/FC Rates | H1: AOP/FC Rates | I1: AOP/FC Rates | J1: AOP/FC Rates | M1: AVG May Rate | N1: AOP Rates | O1: AOP Rates | P1: AOP Rates | Q1: AOP Rates | R1: AOP Rates | S1: AOP Rates | T1: AOP Rates | V1: With Korea Rate at 1125 | W1: ='[1]Currency Exchange Rate'!E126 -> 0.00091 | X1: =1/W1 -> 1098.9011 | Y1: Due on 6/28 | AD1: Due on 6/17 | AI1: Due on 6/10 | AN1: May FC | AS1: June Flash on 6/10 | AT1: June Flash on 6/17 | AU1: June Flash on 6/28 | AV1: May Forecast | AW1: Variance | AX1: Variance | AY1: Variance | BA1: 6/17 Vs. 6/10 | BF1: Contra Revenue % over Gross Revenue
B2: USD | C2: Actual | D2: June FC | E2: June FC | F2: June FC | G2: June FC | H2: June FC | I2: June FC | J2: June FC | K2: FY 2019 | L2: FC Rates | M2: Actual (LC) | N2: FC (LC) | O2: FC (LC) | P2: FC (LC) | Q2: FC (LC) | R2: FC (LC) | S2: FC (LC) | T2: FC (LC) | U2: FY 2019 | V2: FY2019 | W2: 0.000889 | X2: =1/W2 -> 1124.8594 | Y2: June FC | Z2: June FC | AA2: June FC | AB2: June FC | AC2: June FC | AD2: June FC | AE2: June FC | AF2: June FC | AG2: June FC | AH2: June FC | AI2: June FC | AJ2: June FC | AK2: June FC | AL2: June FC | AM2: June FC | AN2: May FC | AO2: May FC | AP2: May FC | AQ2: May FC | AR2: May FC | AS2: FY 2019 | AT2: FY 2019 | AU2: FY 2019 | AV2: FY 2019 | AW2: 6/17 Vs 6/28 | AX2: 6/10 Vs 6/17 | AY2: 6/17 Vs May FC | BF2: Q2 | BH2: Q3 | BJ2: Q4 | BL2: FY
C3: May | D3: June | E3: July | F3: August | G3: September | H3: October | I3: November | J3: December | K3: Total | L3: ='[1]Currency Exchange Rate'!H126 -> 0.00091 | M3: May | N3: June | O3: July | P3: August | Q3: September | R3: October | S3: November | T3: December | U3: Total | V3: Total | Y3: Q1 | Z3: Q2 | AA3: Q3 | AB3: Q4 | AC3: FY 2019 | AD3: Q1 | AE3: Q2 | AF3: Q3 | AG3: Q4 | AH3: FY 2019 | AI3: Q1 | AJ3: Q2 | AK3: Q3 | AL3: Q4 | AM3: FY 2019 | AN3: Q1 | AO3: Q2 | AP3: Q3 | AQ3: Q4 | AR3: FY 2019 | AS3: Total | AT3: Total | AU3: Total | AV3: Total | BA3: Q2 | BB3: Q3 | BC3: Q4 | BD3: FY | BF3: 6/17 | BG3: 6/10 | BH3: 6/17 | BI3: 6/10 | BJ3: 6/17 | BK3: 6/10 | BL3: 6/17 | BM3: 6/10
A4: Korea Domestic | B4: Gross Revenue | C4: ='[1]6.28 (PH Edit)'!L21+'[1]6.28 (PH Edit)'!L28 -> 13091092 | D4: ='[1]6.28 (PH Edit)'!M21+'[1]6.28 (PH Edit)'!M28 -> 20761003 | E4: ='[1]6.28 (PH Edit)'!N21+'[1]6.28 (PH Edit)'!N28 -> 28670871 | F4: ='[1]6.28 (PH Edit)'!O21+'[1]6.28 (PH Edit)'!O28 -> 15732135 | G4: ='[1]6.28 (PH Edit)'!P21+'[1]6.28 (PH Edit)'!P28 -> 16738996 | H4: ='[1]6.28 (PH Edit)'!Q21+'[1]6.28 (PH Edit)'!Q28 -> 16244102 | I4: ='[1]6.28 (PH Edit)'!R21+'[1]6.28 (PH Edit)'!R28 -> 17309508 | J4: ='[1]6.28 (PH Edit)'!S21+'[1]6.28 (PH Edit)'!S28 -> 18426614 | K4: =SUM(C4:J4) -> 1.4697432e+08 | M4: =C4/$L$3 -> 1.4385816e+10 | N4: =D4/$L$3 -> 22814289110 | O4: =E4/$L$3 -> 31506451209 | P4: =F4/$L$3 -> 17288060759 | Q4: =G4/$L$3 -> 18394501514 | R4: =H4/$L$3 -> 17850661627 | S4: =I4/$L$3 -> 19021436909 | T4: =J4/$L$3 -> 20249026234 | U4: =K4/$L$3 -> 1.6151024e+11 | V4: =K4*$X$1/$X$2 -> 1.4358261e+08 | Y4: 0 | Z4: =C4+D4 -> 33852095 | AA4: =E4+F4+G4 -> 61142002 | AB4: =H4+I4+J4 -> 51980224 | AC4: =SUM(Y4:AB4) -> 1.4697432e+08 | AD4: ='[1]APAC 17.6.2019'!Y4 -> 0 | AE4: ='[1]APAC 17.6.2019'!Z4 -> 41451186 | AF4: ='[1]APAC 17.6.2019'!AA4 -> 49661195 | AG4: ='[1]APAC 17.6.2019'!AB4 -> 34112921 | AH4: ='[1]APAC 17.6.2019'!AC4 -> 1.252253e+08 | AJ4: ='[1]6.10'!X4 -> 41450548 | AK4: ='[1]6.10'!Y4 -> 29875408 | AL4: ='[1]6.10'!Z4 -> 43635981 | AM4: =SUM(AI4:AL4) -> 1.1496194e+08 | AN4: 0 | AO4: ='[1]May Forecast'!AC37 -> 12988452 | AP4: ='[1]May Forecast'!AD37 -> 29893494 | AQ4: ='[1]May Forecast'!AE37 -> 43660458 | AR4: =SUM(AN4:AQ4) -> 86542404 | AS4: 1.1496194e+08 | AT4: =AH4 -> 1.252253e+08 | AU4: =AC4 -> 1.4697432e+08 | AV4: =AV24-AV14 -> 86542404 | AW4: =AU4-AT4 -> 21749019 | AX4: =AT4-AS4 -> 10263365 | AY4: =AC4-AV4 -> 60431917 | BA4: =Z4-AJ4 -> -7598452.2 | BB4: =AA4-AK4 -> 31266594 | BC4: =AB4-AL4 -> 8344242.2 | BD4: =AC4-AM4 -> 32012384
A5: Korea Domestic | B5: Other Income | C5: 0 | D5: 0 | E5: 0 | F5: 0 | G5: 0 | H5: 0 | I5: 0 | J5: 0 | K5: =SUM(C5:J5) -> 0 | M5: =C5/$L$3 -> 0 | N5: =D5/$L$3 -> 0 | O5: =E5/$L$3 -> 0 | P5: =F5/$L$3 -> 0 | Q5: =G5/$L$3 -> 0 | R5: =H5/$L$3 -> 0 | S5: =I5/$L$3 -> 0 | T5: =J5/$L$3 -> 0 | U5: =K5/$L$3 -> 0 | V5: =K5*$X$1/$X$2 -> 0 | Y5: 0 | Z5: =C5+D5 -> 0 | AA5: =E5+F5+G5 -> 0 | AB5: =H5+I5+J5 -> 0 | AC5: =SUM(Y5:AB5) -> 0 | AD5: ='[1]APAC 17.6.2019'!Y5 -> 0 | AE5: ='[1]APAC 17.6.2019'!Z5 -> 0 | AF5: ='[1]APAC 17.6.2019'!AA5 -> 0 | AG5: ='[1]APAC 17.6.2019'!AB5 -> 0 | AH5: ='[1]APAC 17.6.2019'!AC5 -> 0 | AJ5: ='[1]6.10'!X5 -> 0 | AK5: ='[1]6.10'!Y5 -> 0 | AL5: ='[1]6.10'!Z5 -> 0 | AM5: =SUM(AI5:AL5) -> 0 | AN5: 0 | AR5: =SUM(AN5:AQ5) -> 0 | AS5: 0 | AT5: =AH5 -> 0 | AU5: =AC5 -> 0 | AV5: 0 | AW5: =AU5-AT5 -> 0 | AX5: =AC5-AS5 -> 0 | AY5: =AC5-AV5 -> 0 | BA5: =Z5-AJ5 -> 0 | BB5: =AA5-AK5 -> 0 | BC5: =AB5-AL5 -> 0 | BD5: =AC5-AM5 -> 0
A6: Korea Domestic | B6: Returns and Allowances | C6: ='[1]6.28 (PH Edit)'!L22+'[1]6.28 (PH Edit)'!L29 -> -584510.12 | D6: ='[1]6.28 (PH Edit)'!M22+'[1]6.28 (PH Edit)'!M29 -> -807450.63 | E6: ='[1]6.28 (PH Edit)'!N22+'[1]6.28 (PH Edit)'!N29 -> -2963888.1 | F6: ='[1]6.28 (PH Edit)'!O22+'[1]6.28 (PH Edit)'!O29 -> -2128278.1 | G6: ='[1]6.28 (PH Edit)'!P22+'[1]6.28 (PH Edit)'!P29 -> -2338479.2 | H6: ='[1]6.28 (PH Edit)'!Q22+'[1]6.28 (PH Edit)'!Q29 -> -2377235.4 | I6: ='[1]6.28 (PH Edit)'!R22+'[1]6.28 (PH Edit)'!R29 -> -2492897 | J6: ='[1]6.28 (PH Edit)'!S22+'[1]6.28 (PH Edit)'!S29 -> -2634340.6 | K6: =SUM(C6:J6) -> -16327079 | M6: =C6/$L$3 -> -6.4231881e+08 | N6: =D6/$L$3 -> -887308387 | O6: =E6/$L$3 -> -3257019927 | P6: =F6/$L$3 -> -2338767156 | Q6: =G6/$L$3 -> -2569757373 | R6: =H6/$L$3 -> -2612346599 | S6: =I6/$L$3 -> -2.7394472e+09 | T6: =J6/$L$3 -> -2.8948798e+09 | U6: =K6/$L$3 -> -1.7941845e+10 | V6: =K6*$X$1/$X$2 -> -15950300 | Y6: 0 | Z6: =C6+D6 -> -1391960.7 | AA6: =E6+F6+G6 -> -7430645.5 | AB6: =H6+I6+J6 -> -7504473 | AC6: =SUM(Y6:AB6) -> -16327079 | AD6: ='[1]APAC 17.6.2019'!Y6 -> 0 | AE6: ='[1]APAC 17.6.2019'!Z6 -> -2883821.2 | AF6: ='[1]APAC 17.6.2019'!AA6 -> -6941053.8 | AG6: ='[1]APAC 17.6.2019'!AB6 -> -6968448.4 | AH6: ='[1]APAC 17.6.2019'!AC6 -> -16793323 | AJ6: ='[1]6.10'!X6 -> -4354014.1 | AK6: ='[1]6.10'!Y6 -> -4343981.5 | AL6: ='[1]6.10'!Z6 -> -6379984.7 | AM6: =SUM(AI6:AL6) -> -15077980 | AN6: 0 | AO6: ='[1]May Forecast'!AC39 -> -1912215.7 | AP6: ='[1]May Forecast'!AD39 -> -4345053.6 | AQ6: ='[1]May Forecast'!AE39 -> -6381150 | AR6: =SUM(AN6:AQ6) -> -12638419 | AS6: -15077980 | AT6: =AH6 -> -16793323 | AU6: =AC6 -> -16327079 | AV6: =AV26-AV16 -> -12638419 | AW6: =AU6-AT6 -> 466244.09 | AX6: =AC6-AS6 -> -1249098.9 | AY6: =AC6-AV6 -> -3688659.9 | BA6: =Z6-AJ6 -> 2962053.4 | BB6: =AA6-AK6 -> -3086664 | BC6: =AB6-AL6 -> -1124488.3 | BD6: =AC6-AM6 -> -1249098.9 | BF6: =-Z6/Z4 -> 0.041118895 | BG6: =-AJ6/AJ4 -> 0.10504117 | BH6: =-AA6/AA4 -> 0.12153095 | BI6: =-AK6/AK4 -> 0.14540325 | BJ6: =-AB6/AB4 -> 0.1443717 | BK6: =-AL6/AL4 -> 0.14620926 | BL6: =-AC6/AC4 -> 0.11108797 | BM6: =-AM6/AM4 -> 0.13115628
A7: Korea Domestic | B7: Net Revenue w/o Promotions | C7: =SUM(C4:C6) -> 12506582 | D7: =SUM(D4:D6) -> 19953552 | E7: =SUM(E4:E6) -> 25706982 | F7: =SUM(F4:F6) -> 13603857 | G7: =SUM(G4:G6) -> 14400517 | H7: =SUM(H4:H6) -> 13866867 | I7: =SUM(I4:I6) -> 14816611 | J7: =SUM(J4:J6) -> 15792273 | K7: =SUM(C7:J7) -> 1.3064724e+08 | M7: =C7/$L$3 -> 1.3743497e+10 | N7: =D7/$L$3 -> 2.1926981e+10 | O7: =E7/$L$3 -> 2.8249431e+10 | P7: =F7/$L$3 -> 1.4949294e+10 | Q7: =G7/$L$3 -> 15824744141 | R7: =H7/$L$3 -> 1.5238315e+10 | S7: =I7/$L$3 -> 1.628199e+10 | T7: =J7/$L$3 -> 17354146417 | U7: =K7/$L$3 -> 1.435684e+11 | V7: =K7*$X$1/$X$2 -> 1.2763231e+08 | Y7: 0 | Z7: =C7+D7 -> 32460135 | AA7: =E7+F7+G7 -> 53711357 | AB7: =H7+I7+J7 -> 44475751 | AC7: =SUM(Y7:AB7) -> 1.3064724e+08 | AD7: ='[1]APAC 17.6.2019'!Y7 -> 0 | AE7: ='[1]APAC 17.6.2019'!Z7 -> 38567365 | AF7: ='[1]APAC 17.6.2019'!AA7 -> 42720142 | AG7: ='[1]APAC 17.6.2019'!AB7 -> 27144472 | AH7: ='[1]APAC 17.6.2019'!AC7 -> 1.0843198e+08 | AJ7: =SUM(AJ4:AJ6) -> 37096533 | AK7: =SUM(AK4:AK6) -> 25531427 | AL7: =SUM(AL4:AL6) -> 37255997 | AM7: =SUM(AI7:AL7) -> 99883957 | AN7: 0 | AO7: =SUM(AO4:AO6) -> 11076236 | AP7: =SUM(AP4:AP6) -> 25548441 | AQ7: =SUM(AQ4:AQ6) -> 37279308 | AR7: =SUM(AN7:AQ7) -> 73903985 | AS7: 99883957 | AT7: =AH7 -> 1.0843198e+08 | AU7: =AC7 -> 1.3064724e+08 | AV7: =AV27-AV17 -> 73904325 | AW7: =AU7-AT7 -> 22215263 | AX7: =AC7-AS7 -> 30763285 | AY7: =AC7-AV7 -> 56742917 | BA7: =Z7-AJ7 -> -4636398.8 | BB7: =AA7-AK7 -> 28179930 | BC7: =AB7-AL7 -> 7219753.8 | BD7: =AC7-AM7 -> 30763285
A8: Korea Domestic | B8: Promotions | C8: ='[1]6.28'!L23+'[1]6.28'!L30 -> 0 | D8: ='[1]6.28'!M23+'[1]6.28'!M30 -> 0 | E8: ='[1]6.28'!N23+'[1]6.28'!N30 -> 0 | F8: ='[1]6.28'!O23+'[1]6.28'!O30 -> 0 | G8: ='[1]6.28'!P23+'[1]6.28'!P30 -> 0 | H8: ='[1]6.28'!Q23+'[1]6.28'!Q30 -> -893366.48 | I8: ='[1]6.28'!R23+'[1]6.28'!R30 -> 0 | J8: ='[1]6.28'!S23+'[1]6.28'!S30 -> -999323.18 | K8: =SUM(C8:J8) -> -1892689.7 | M8: =C8/$L$3 -> 0 | N8: =D8/$L$3 -> 0 | O8: =E8/$L$3 -> 0 | P8: =F8/$L$3 -> 0 | Q8: =G8/$L$3 -> 0 | R8: =H8/$L$3 -> -9.817214e+08 | S8: =I8/$L$3 -> 0 | T8: =J8/$L$3 -> -1098157341 | U8: =K8/$L$3 -> -2079878743 | V8: =K8*$X$1/$X$2 -> -1849012.2 | Y8: 0 | Z8: =C8+D8 -> 0 | AA8: =E8+F8+G8 -> 0 | AB8: =H8+I8+J8 -> -1892689.7 | AC8: =SUM(Y8:AB8) -> -1892689.7 | AD8: ='[1]APAC 17.6.2019'!Y8 -> 0 | AE8: ='[1]APAC 17.6.2019'!Z8 -> 0 | AF8: ='[1]APAC 17.6.2019'!AA8 -> 0 | AG8: ='[1]APAC 17.6.2019'!AB8 -> -3036285.6 | AH8: ='[1]APAC 17.6.2019'!AC8 -> -3036285.6 | AJ8: ='[1]6.10'!X8 -> -583907.43 | AK8: ='[1]6.10'!Y8 -> 0 | AL8: ='[1]6.10'!Z8 -> -2107210.2 | AM8: =SUM(AI8:AL8) -> -2691117.6 | AN8: 0 | AO8: ='[1]May Forecast'!AC40 -> 0 | AP8: ='[1]May Forecast'!AD40 -> 0 | AQ8: ='[1]May Forecast'!AE40 -> -2107210.2 | AR8: =SUM(AN8:AQ8) -> -2107210.2 | AS8: -2691117.6 | AT8: =AH8 -> -3036285.6 | AU8: =AC8 -> -1892689.7 | AV8: =AV28-AV18 -> -2107210.2 | AW8: =AU8-AT8 -> 1143596 | AX8: =AC8-AS8 -> 798427.96 | AY8: =AC8-AV8 -> 214520.53 | BA8: =Z8-AJ8 -> 583907.43 | BB8: =AA8-AK8 -> 0 | BC8: =AB8-AL8 -> 214520.53 | BD8: =AC8-AM8 -> 798427.96
A9: Korea Domestic | B9: Net Revenue w/ Promotions | C9: =SUM(C7:C8) -> 12506582 | D9: =SUM(D7:D8) -> 19953552 | E9: =SUM(E7:E8) -> 25706982 | F9: =SUM(F7:F8) -> 13603857 | G9: =SUM(G7:G8) -> 14400517 | H9: =SUM(H7:H8) -> 12973500 | I9: =SUM(I7:I8) -> 14816611 | J9: =SUM(J7:J8) -> 14792950 | K9: =SUM(C9:J9) -> 1.2875455e+08 | M9: =C9/$L$3 -> 1.3743497e+10 | N9: =D9/$L$3 -> 2.1926981e+10 | O9: =E9/$L$3 -> 2.8249431e+10 | P9: =F9/$L$3 -> 1.4949294e+10 | Q9: =G9/$L$3 -> 15824744141 | R9: =H9/$L$3 -> 14256593626 | S9: =I9/$L$3 -> 1.628199e+10 | T9: =J9/$L$3 -> 1.6255989e+10 | U9: =K9/$L$3 -> 1.4148852e+11 | V9: =K9*$X$1/$X$2 -> 1.2578329e+08 | Y9: 0 | Z9: =C9+D9 -> 32460135 | AA9: =E9+F9+G9 -> 53711357 | AB9: =H9+I9+J9 -> 42583061 | AC9: =SUM(Y9:AB9) -> 1.2875455e+08 | AD9: ='[1]APAC 17.6.2019'!Y9 -> 0 | AE9: ='[1]APAC 17.6.2019'!Z9 -> 38567365 | AF9: ='[1]APAC 17.6.2019'!AA9 -> 42720142 | AG9: ='[1]APAC 17.6.2019'!AB9 -> 24108187 | AH9: ='[1]APAC 17.6.2019'!AC9 -> 1.0539569e+08 | AJ9: =SUM(AJ7:AJ8) -> 36512626 | AK9: =SUM(AK7:AK8) -> 25531427 | AL9: =SUM(AL7:AL8) -> 35148786 | AM9: =SUM(AI9:AL9) -> 97192839 | AN9: 0 | AO9: =SUM(AO7:AO8) -> 11076236 | AP9: =SUM(AP7:AP8) -> 25548441 | AQ9: =SUM(AQ7:AQ8) -> 35172097 | AR9: =SUM(AN9:AQ9) -> 71796774 | AS9: 97192839 | AT9: =AH9 -> 1.0539569e+08 | AU9: =AC9 -> 1.2875455e+08 | AV9: =SUM(AV7:AV8) -> 71797115 | AW9: =AU9-AT9 -> 23358859 | AX9: =AC9-AS9 -> 31561713 | AY9: =AC9-AV9 -> 56957437 | BA9: =Z9-AJ9 -> -4052491.4 | BB9: =AA9-AK9 -> 28179930 | BC9: =AB9-AL9 -> 7434274.4 | BD9: =AC9-AM9 -> 31561713
A10: Korea Domestic | B10: COGS | C10: ='[1]May KR TB'!J43 -> 6669050.8 | D10: ='[1]6.28 (PH Edit)'!M24+'[1]6.28 (PH Edit)'!M31 -> 11647341 | E10: ='[1]6.28 (PH Edit)'!N24+'[1]6.28 (PH Edit)'!N31 -> 15758577 | F10: ='[1]6.28 (PH Edit)'!O24+'[1]6.28 (PH Edit)'!O31 -> 8363361.4 | G10: ='[1]6.28 (PH Edit)'!P24+'[1]6.28 (PH Edit)'!P31 -> 8792301.3 | H10: ='[1]6.28 (PH Edit)'!Q24+'[1]6.28 (PH Edit)'!Q31 -> 8416011.8 | I10: ='[1]6.28 (PH Edit)'!R24+'[1]6.28 (PH Edit)'!R31 -> 8856130.4 | J10: ='[1]6.28 (PH Edit)'!S24+'[1]6.28 (PH Edit)'!S31 -> 9291798.9 | K10: =SUM(C10:J10) -> 77794573 | M10: =C10/$L$3 -> 7.3286272e+09 | N10: =D10/$L$3 -> 12799276022 | O10: =E10/$L$3 -> 17317117483 | P10: =F10/$L$3 -> 9190507072 | Q10: =G10/$L$3 -> 9661869550 | R10: =H10/$L$3 -> 9248364630 | S10: =I10/$L$3 -> 9732011449 | T10: =J10/$L$3 -> 1.0210768e+10 | U10: =K10/$L$3 -> 8.5488542e+10 | V10: =K10*$X$1/$X$2 -> 75999313 | Y10: 0 | Z10: =C10+D10 -> 18316392 | AA10: =E10+F10+G10 -> 32914240 | AB10: =H10+I10+J10 -> 26563941 | AC10: =SUM(Y10:AB10) -> 77794573 | AD10: ='[1]APAC 17.6.2019'!Y10 -> 0 | AE10: ='[1]APAC 17.6.2019'!Z10 -> 22477846 | AF10: ='[1]APAC 17.6.2019'!AA10 -> 26867106 | AG10: ='[1]APAC 17.6.2019'!AB10 -> 17476012 | AH10: ='[1]APAC 17.6.2019'!AC10 -> 66820963 | AJ10: ='[1]6.10'!X10 -> 22240256 | AK10: ='[1]6.10'!Y10 -> 14881775 | AL10: ='[1]6.10'!Z10 -> 20697245 | AM10: =SUM(AI10:AL10) -> 57819277 | AN10: 0 | AO10: ='[1]May Forecast'!AC41 -> 7422443.5 | AP10: ='[1]May Forecast'!AD41 -> 15836295 | AQ10: ='[1]May Forecast'!AE41 -> 22205876 | AR10: =SUM(AN10:AQ10) -> 45464615 | AS10: 63492107 | AT10: =AH10 -> 66820963 | AU10: =AC10 -> 77794573 | AV10: =AV30-AV20 -> 45464615 | AW10: =AU10-AT10 -> 10973610 | AX10: =AC10-AS10 -> 14302466 | AY10: =AC10-AV10 -> 32329958 | BA10: =Z10-AJ10 -> -3923864.5 | BB10: =AA10-AK10 -> 18032465 | BC10: =AB10-AL10 -> 5866695.7 | BD10: =AC10-AM10 -> 19975296
A11: Korea Domestic | B11: Gross Margin | C11: =C9-C10 -> 5837531.3 | D11: =D9-D10 -> 8306211.3 | E11: =E9-E10 -> 9948405.6 | F11: =F9-F10 -> 5240495.7 | G11: =G9-G10 -> 5608215.9 | H11: =H9-H10 -> 4557488.4 | I11: =I9-I10 -> 5960480.2 | J11: =J9-J10 -> 5501151.1 | K11: =SUM(C11:J11) -> 50959979 | M11: =C11/$L$3 -> 6.4148696e+09 | N11: =D11/$L$3 -> 9.1277047e+09 | O11: =E11/$L$3 -> 10932313799 | P11: =F11/$L$3 -> 5.7587865e+09 | Q11: =G11/$L$3 -> 6.1628746e+09 | R11: =H11/$L$3 -> 5.008229e+09 | S11: =I11/$L$3 -> 6.5499782e+09 | T11: =J11/$L$3 -> 6.045221e+09 | U11: =K11/$L$3 -> 5.5999977e+10 | V11: =K11*$X$1/$X$2 -> 49783980 | Y11: 0 | Z11: =C11+D11 -> 14143743 | AA11: =E11+F11+G11 -> 20797117 | AB11: =H11+I11+J11 -> 16019120 | AC11: =SUM(Y11:AB11) -> 50959979 | AD11: ='[1]APAC 17.6.2019'!Y11 -> 0 | AE11: ='[1]APAC 17.6.2019'!Z11 -> 16089519 | AF11: ='[1]APAC 17.6.2019'!AA11 -> 15853036 | AG11: ='[1]APAC 17.6.2019'!AB11 -> 6632175.1 | AH11: ='[1]APAC 17.6.2019'!AC11 -> 38574730 | AJ11: =AJ9-AJ10 -> 14272370 | AK11: =AK9-AK10 -> 10649652 | AL11: =AL9-AL10 -> 14451541 | AM11: =SUM(AI11:AL11) -> 39373563 | AN11: 0 | AO11: =AO9-AO10 -> 3653792.8 | AP11: =AP9-AP10 -> 9712145.3 | AQ11: =AQ9-AQ10 -> 12966221 | AR11: =SUM(AN11:AQ11) -> 26332159 | AS11: 33700732 | AT11: =AH11 -> 38574730 | AU11: =AC11 -> 50959979 | AV11: =AV9-AV10 -> 26332500 | AW11: =AU11-AT11 -> 12385249 | AX11: =AC11-AS11 -> 17259247 | AY11: =AC11-AV11 -> 24627480 | BA11: =Z11-AJ11 -> -128626.94 | BB11: =AA11-AK11 -> 10147465 | BC11: =AB11-AL11 -> 1567578.7 | BD11: =AC11-AM11 -> 11586417
B12: GM% | C12: =C11/C9 -> 0.46675673 | D12: =D11/D9 -> 0.41627732 | E12: =E11/E9 -> 0.38699235 | F12: =F11/F9 -> 0.38522131 | G12: =G11/G9 -> 0.38944545 | H12: =H11/H9 -> 0.35129212 | I12: =I11/I9 -> 0.40228365 | J12: =J11/J9 -> 0.37187654 | K12: =K11/K9 -> 0.39579167 | AD12: ='[1]APAC 17.6.2019'!Y12 -> 0 | AE12: ='[1]APAC 17.6.2019'!Z12 -> 0 | AF12: ='[1]APAC 17.6.2019'!AA12 -> 0 | AG12: ='[1]APAC 17.6.2019'!AB12 -> 0 | AH12: ='[1]APAC 17.6.2019'!AC12 -> 0 | AT12: =AH12 -> 0 | AU12: =AC12 -> 0 | AW12: =AU12-AT12 -> 0
M13: =M6+M8 -> -6.4231881e+08 | N13: =N6+N8 -> -887308387 | O13: =O6+O8 -> -3257019927 | P13: =P6+P8 -> -2338767156 | Q13: =Q6+Q8 -> -2569757373 | R13: =R6+R8 -> -3594068001 | S13: =S6+S8 -> -2.7394472e+09 | T13: =T6+T8 -> -3.9930372e+09 | AC13: =SUM(Y13:AB13) -> 0 | AD13: ='[1]APAC 17.6.2019'!Y13 -> 0 | AE13: ='[1]APAC 17.6.2019'!Z13 -> 0 | AF13: ='[1]APAC 17.6.2019'!AA13 -> 0 | AG13: ='[1]APAC 17.6.2019'!AB13 -> 0 | AH13: ='[1]APAC 17.6.2019'!AC13 -> 0 | AM13: =SUM(AI13:AL13) -> 0 | AR13: =SUM(AN13:AQ13) -> 0 | AT13: =AH13 -> 0 | AU13: =AC13 -> 0 | AW13: =AU13-AT13 -> 0 | BA13: =Z13-AJ13 -> 0 | BB13: =AA13-AK13 -> 0 | BC13: =AB13-AL13 -> 0 | BD13: =AC13-AM13 -> 0
A14: Korea DF | B14: Gross Revenue | C14: ='[1]6.28'!L25 -> 2561909.3 | D14: ='[1]6.28'!M25 -> 1243286.4 | E14: ='[1]6.28'!N25 -> 852583.68 | F14: ='[1]6.28'!O25 -> 2294450.2 | G14: ='[1]6.28'!P25 -> 1345255.8 | H14: ='[1]6.28'!Q25 -> 1384499.1 | I14: ='[1]6.28'!R25 -> 1404364.2 | J14: ='[1]6.28'!S25 -> 1415599.2 | K14: =SUM(C14:J14) -> 12501948 | L14: =L3 -> 0.00091 | M14: =C14/$L$14 -> 2.8152849e+09 | N14: =D14/$L$14 -> 1366248791 | O14: =E14/$L$14 -> 936905143 | P14: =F14/$L$14 -> 2521373890 | Q14: =G14/$L$14 -> 1478303097 | R14: =H14/$L$14 -> 1521427542 | S14: =I14/$L$14 -> 1543257368 | T14: =J14/$L$14 -> 1555603479 | U14: =K14/$L$14 -> 1.3738404e+10 | V14: =K14*$X$1/$X$2 -> 12213441 | Y14: 0 | Z14: =C14+D14 -> 3805195.7 | AA14: =E14+F14+G14 -> 4492289.7 | AB14: =H14+I14+J14 -> 4204462.4 | AC14: =SUM(Y14:AB14) -> 12501948 | AD14: ='[1]APAC 17.6.2019'!Y14 -> 0 | AE14: ='[1]APAC 17.6.2019'!Z14 -> 3805195.7 | AF14: ='[1]APAC 17.6.2019'!AA14 -> 4492289.7 | AG14: ='[1]APAC 17.6.2019'!AB14 -> 4204462.4 | AH14: ='[1]APAC 17.6.2019'!AC14 -> 12501948 | AJ14: ='[1]6.10'!X13 -> 3925578.7 | AK14: ='[1]6.10'!Y13 -> 3689604.7 | AL14: ='[1]6.10'!Z13 -> 4993092.6 | AM14: =SUM(AI14:AL14) -> 12608276 | AN14: 0 | AO14: ='[1]May Forecast'!AC43 -> 5186119.9 | AP14: ='[1]May Forecast'!AD43 -> 3671518.4 | AQ14: ='[1]May Forecast'!AE43 -> 4968616.7 | AR14: =SUM(AN14:AQ14) -> 13826255 | AS14: 12608276 | AT14: =AH14 -> 12501948 | AU14: =AC14 -> 12501948 | AV14: ='[1]MFC Duty Free - Total'!P23 -> 13826255 | AW14: =AU14-AT14 -> 0 | AX14: =AC14-AS14 -> -106328.18 | AY14: =AC14-AV14 -> -1324307.1 | BA14: =Z14-AJ14 -> -120383.01 | BB14: =AA14-AK14 -> 802685.01 | BC14: =AB14-AL14 -> -788630.18 | BD14: =AC14-AM14 -> -106328.18
A15: Korea DF | B15: Other Income | C15: 0 | D15: 0 | E15: 0 | F15: 0 | G15: 0 | H15: 0 | I15: 0 | J15: 0 | K15: =SUM(C15:J15) -> 0 | M15: =C15/$L$14 -> 0 | N15: =D15/$L$14 -> 0 | O15: =E15/$L$14 -> 0 | P15: =F15/$L$14 -> 0 | Q15: =G15/$L$14 -> 0 | R15: =H15/$L$14 -> 0 | S15: =I15/$L$14 -> 0 | T15: =J15/$L$14 -> 0 | U15: =K15/$L$14 -> 0 | V15: =K15*$X$1/$X$2 -> 0 | AC15: =SUM(Y15:AB15) -> 0 | AD15: ='[1]APAC 17.6.2019'!Y15 -> 0 | AE15: ='[1]APAC 17.6.2019'!Z15 -> 0 | AF15: ='[1]APAC 17.6.2019'!AA15 -> 0 | AG15: ='[1]APAC 17.6.2019'!AB15 -> 0 | AH15: ='[1]APAC 17.6.2019'!AC15 -> 0 | AJ15: ='[1]6.10'!X14 -> 0 | AK15: ='[1]6.10'!Y14 -> 0 | AL15: ='[1]6.10'!Z14 -> 0 | AM15: =SUM(AI15:AL15) -> 0 | AO15: ='[1]May Forecast'!AC44 -> 25930.599 | AP15: ='[1]May Forecast'!AD44 -> 18357.592 | AQ15: ='[1]May Forecast'!AE44 -> 24843.083 | AR15: =SUM(AN15:AQ15) -> 69131.275 | AS15: 0 | AT15: =AH15 -> 0 | AU15: =AC15 -> 0 | AV15: ='[1]MFC Duty Free - Total'!P31 -> 69131.275 | AW15: =AU15-AT15 -> 0 | AX15: =AC15-AS15 -> 0 | AY15: =AC15-AV15 -> -69131.275 | BA15: =Z15-AJ15 -> 0 | BB15: =AA15-AK15 -> 0 | BC15: =AB15-AL15 -> 0 | BD15: =AC15-AM15 -> 0
A16: Korea DF | B16: Returns and Allowances | C16: ='[1]6.28'!L26 -> -386369.46 | D16: ='[1]6.28'!M26 -> -186492.96 | E16: ='[1]6.28'!N26 -> -127887.55 | F16: ='[1]6.28'!O26 -> -344167.54 | G16: ='[1]6.28'!P26 -> -201788.37 | H16: ='[1]6.28'!Q26 -> -207674.86 | I16: ='[1]6.28'!R26 -> -210654.63 | J16: ='[1]6.28'!S26 -> -212339.87 | K16: =SUM(C16:J16) -> -1877375.2 | M16: =C16/$L$14 -> -4.2458183e+08 | N16: =D16/$L$14 -> -204937319 | O16: =E16/$L$14 -> -140535772 | P16: =F16/$L$14 -> -378206083 | Q16: =G16/$L$14 -> -221745465 | R16: =H16/$L$14 -> -228214131 | S16: =I16/$L$14 -> -231488605 | T16: =J16/$L$14 -> -233340521 | U16: =K16/$L$14 -> -2.0630497e+09 | V16: =K16*$X$1/$X$2 -> -1834051.2 | Y16: 0 | Z16: =C16+D16 -> -572862.42 | AA16: =E16+F16+G16 -> -673843.46 | AB16: =H16+I16+J16 -> -630669.36 | AC16: =SUM(Y16:AB16) -> -1877375.2 | AD16: ='[1]APAC 17.6.2019'!Y16 -> 0 | AE16: ='[1]APAC 17.6.2019'!Z16 -> -572862.42 | AF16: ='[1]APAC 17.6.2019'!AA16 -> -673843.46 | AG16: ='[1]APAC 17.6.2019'!AB16 -> -630669.36 | AH16: ='[1]APAC 17.6.2019'!AC16 -> -1877375.2 | AJ16: ='[1]6.10'!X15 -> -680932.09 | AK16: ='[1]6.10'!Y15 -> -218717.7 | AL16: ='[1]6.10'!Z15 -> -237723.81 | AM16: =SUM(AI16:AL16) -> -1137373.6 | AN16: 0 | AO16: ='[1]May Forecast'!AC45 -> -180583.6 | AP16: ='[1]May Forecast'!AD45 -> -217645.55 | AQ16: ='[1]May Forecast'!AE45 -> -236558.5 | AR16: =SUM(AN16:AQ16) -> -634787.65 | AS16: -1137373.6 | AT16: =AH16 -> -1877375.2 | AU16: =AC16 -> -1877375.2 | AV16: ='[1]MFC Duty Free - Total'!P56 -> -634787.65 | AW16: =AU16-AT16 -> 0 | AX16: =AC16-AS16 -> -740001.64 | AY16: =AC16-AV16 -> -1242587.6 | BA16: =Z16-AJ16 -> 108069.67 | BB16: =AA16-AK16 -> -455125.76 | BC16: =AB16-AL16 -> -392945.55 | BD16: =AC16-AM16 -> -740001.64 | BF16: =-Z16/Z14 -> 0.15054743 | BG16: =-AJ16/AJ14 -> 0.17346031 | BH16: =-AA16/AA14 -> 0.15 | BI16: =-AK16/AK14 -> 0.059279439 | BJ16: =-AB16/AB14 -> 0.15 | BK16: =-AL16/AL14 -> 0.047610536 | BL16: =-AC16/AC14 -> 0.15016662 | BM16: =-AM16/AM14 -> 0.090208495
A17: Korea DF | B17: Net Revenue w/o Promotions | C17: =SUM(C14:C16) -> 2175539.8 | D17: =SUM(D14:D16) -> 1056793.4 | E17: =SUM(E14:E16) -> 724696.13 | F17: =SUM(F14:F16) -> 1950282.7 | G17: =SUM(G14:G16) -> 1143467.4 | H17: =SUM(H14:H16) -> 1176824.2 | I17: =SUM(I14:I16) -> 1193709.6 | J17: =SUM(J14:J16) -> 1203259.3 | K17: =SUM(C17:J17) -> 10624573 | M17: =C17/$L$14 -> 2.3907031e+09 | N17: =D17/$L$14 -> 1161311472 | O17: =E17/$L$14 -> 796369371 | P17: =F17/$L$14 -> 2143167807 | Q17: =G17/$L$14 -> 1.2565576e+09 | R17: =H17/$L$14 -> 1293213411 | S17: =I17/$L$14 -> 1.3117688e+09 | T17: =J17/$L$14 -> 1322262958 | U17: =K17/$L$14 -> 1.1675354e+10 | V17: =K17*$X$1/$X$2 -> 10379390 | Y17: 0 | Z17: =C17+D17 -> 3232333.2 | AA17: =E17+F17+G17 -> 3818446.3 | AB17: =H17+I17+J17 -> 3573793.1 | AC17: =SUM(Y17:AB17) -> 10624573 | AD17: ='[1]APAC 17.6.2019'!Y17 -> 0 | AE17: ='[1]APAC 17.6.2019'!Z17 -> 3232333.2 | AF17: ='[1]APAC 17.6.2019'!AA17 -> 3818446.3 | AG17: ='[1]APAC 17.6.2019'!AB17 -> 3573793.1 | AH17: ='[1]APAC 17.6.2019'!AC17 -> 10624573 | AJ17: =SUM(AJ14:AJ16) -> 3244646.6 | AK17: =SUM(AK14:AK16) -> 3470887 | AL17: =SUM(AL14:AL16) -> 4755368.8 | AM17: =SUM(AI17:AL17) -> 11470902 | AN17: 0 | AO17: =SUM(AO14:AO16) -> 5031466.9 | AP17: =SUM(AP14:AP16) -> 3472230.5 | AQ17: =SUM(AQ14:AQ16) -> 4756901.3 | AR17: =SUM(AN17:AQ17) -> 13260599 | AS17: 11470902 | AT17: =AH17 -> 10624573 | AU17: =AC17 -> 10624573 | AV17: =SUM(AV14:AV16) -> 13260599 | AW17: =AU17-AT17 -> 0 | AX17: =AC17-AS17 -> -846329.82 | AY17: =AC17-AV17 -> -2636026 | BA17: =Z17-AJ17 -> -12313.337 | BB17: =AA17-AK17 -> 347559.25 | BC17: =AB17-AL17 -> -1181575.7 | BD17: =AC17-AM17 -> -846329.82
A18: Korea DF | B18: Promotions | C18: 0 | D18: ='[1]Host Loaded1'!M70 -> 0 | E18: ='[1]Host Loaded1'!N70 -> 0 | F18: ='[1]Host Loaded1'!O70 -> 0 | G18: ='[1]Host Loaded1'!P70 -> 0 | H18: ='[1]Host Loaded1'!Q70 -> 0 | I18: ='[1]Host Loaded1'!R70 -> 0 | J18: ='[1]Host Loaded1'!S70 -> 0 | K18: =SUM(C18:J18) -> 0 | M18: =C18/$L$14 -> 0 | N18: =D18/$L$14 -> 0 | O18: =E18/$L$14 -> 0 | P18: =F18/$L$14 -> 0 | Q18: =G18/$L$14 -> 0 | R18: =H18/$L$14 -> 0 | S18: =I18/$L$14 -> 0 | T18: =J18/$L$14 -> 0 | U18: =K18/$L$14 -> 0 | V18: =K18*$X$1/$X$2 -> 0 | Y18: 0 | Z18: =C18+D18 -> 0 | AA18: =E18+F18+G18 -> 0 | AB18: =H18+I18+J18 -> 0 | AC18: =SUM(Y18:AB18) -> 0 | AD18: ='[1]APAC 17.6.2019'!Y18 -> 0 | AE18: ='[1]APAC 17.6.2019'!Z18 -> 0 | AF18: ='[1]APAC 17.6.2019'!AA18 -> 0 | AG18: ='[1]APAC 17.6.2019'!AB18 -> 0 | AH18: ='[1]APAC 17.6.2019'!AC18 -> 0 | AJ18: ='[1]6.10'!X17 -> 0 | AK18: ='[1]6.10'!Y17 -> 0 | AL18: ='[1]6.10'!Z17 -> 0 | AM18: =SUM(AI18:AL18) -> 0 | AN18: 0 | AO18: ='[1]May Forecast'!AC46 -> 0 | AP18: ='[1]May Forecast'!AD46 -> 0 | AQ18: ='[1]May Forecast'!AE46 -> 0 | AR18: =SUM(AN18:AQ18) -> 0 | AS18: 0 | AT18: =AH18 -> 0 | AU18: =AC18 -> 0 | AV18: ='[1]MFC Duty Free - Total'!P65 -> 0 | AW18: =AU18-AT18 -> 0 | AX18: =AC18-AS18 -> 0 | AY18: =AC18-AV18 -> 0 | BA18: =Z18-AJ18 -> 0 | BB18: =AA18-AK18 -> 0 | BC18: =AB18-AL18 -> 0 | BD18: =AC18-AM18 -> 0
A19: Korea DF | B19: Net Revenue w/ Promotions | C19: =SUM(C17:C18) -> 2175539.8 | D19: =SUM(D17:D18) -> 1056793.4 | E19: =SUM(E17:E18) -> 724696.13 | F19: =SUM(F17:F18) -> 1950282.7 | G19: =SUM(G17:G18) -> 1143467.4 | H19: =SUM(H17:H18) -> 1176824.2 | I19: =SUM(I17:I18) -> 1193709.6 | J19: =SUM(J17:J18) -> 1203259.3 | K19: =SUM(C19:J19) -> 10624573 | M19: =C19/$L$14 -> 2.3907031e+09 | N19: =D19/$L$14 -> 1161311472 | O19: =E19/$L$14 -> 796369371 | P19: =F19/$L$14 -> 2143167807 | Q19: =G19/$L$14 -> 1.2565576e+09 | R19: =H19/$L$14 -> 1293213411 | S19: =I19/$L$14 -> 1.3117688e+09 | T19: =J19/$L$14 -> 1322262958 | U19: =K19/$L$14 -> 1.1675354e+10 | V19: =K19*$X$1/$X$2 -> 10379390 | Y19: 0 | Z19: =C19+D19 -> 3232333.2 | AA19: =E19+F19+G19 -> 3818446.3 | AB19: =H19+I19+J19 -> 3573793.1 | AC19: =SUM(Y19:AB19) -> 10624573 | AD19: ='[1]APAC 17.6.2019'!Y19 -> 0 | AE19: ='[1]APAC 17.6.2019'!Z19 -> 3232333.2 | AF19: ='[1]APAC 17.6.2019'!AA19 -> 3818446.3 | AG19: ='[1]APAC 17.6.2019'!AB19 -> 3573793.1 | AH19: ='[1]APAC 17.6.2019'!AC19 -> 10624573 | AJ19: =SUM(AJ17:AJ18) -> 3244646.6 | AK19: =SUM(AK17:AK18) -> 3470887 | AL19: =SUM(AL17:AL18) -> 4755368.8 | AM19: =SUM(AI19:AL19) -> 11470902 | AN19: 0 | AO19: =SUM(AO17:AO18) -> 5031466.9 | AP19: =SUM(AP17:AP18) -> 3472230.5 | AQ19: =SUM(AQ17:AQ18) -> 4756901.3 | AR19: =SUM(AN19:AQ19) -> 13260599 | AS19: 11470902 | AT19: =AH19 -> 10624573 | AU19: =AC19 -> 10624573 | AV19: =SUM(AV17:AV18) -> 13260599 | AW19: =AU19-AT19 -> 0 | AX19: =AC19-AS19 -> -846329.82 | AY19: =AC19-AV19 -> -2636026 | BA19: =Z19-AJ19 -> -12313.337 | BB19: =AA19-AK19 -> 347559.25 | BC19: =AB19-AL19 -> -1181575.7 | BD19: =AC19-AM19 -> -846329.82
A20: Korea DF | B20: COGS | C20: ='[1]6.28'!L27 -> 818832.46 | D20: ='[1]6.28'!M27 -> 652686.32 | E20: ='[1]6.28'!N27 -> 422482.01 | F20: ='[1]6.28'!O27 -> 1056269.9 | G20: ='[1]6.28'!P27 -> 553905.97 | H20: ='[1]6.28'!Q27 -> 530642.76 | I20: ='[1]6.28'!R27 -> 516361.45 | J20: ='[1]6.28'!S27 -> 528297.21 | K20: =(SUM(C20:J20))*-1 -> -5079478.1 | M20: =C20/$L$14 -> 8.9981589e+08 | N20: =D20/$L$14 -> 7.1723771e+08 | O20: =E20/$L$14 -> 464265949 | P20: =F20/$L$14 -> 1.1607362e+09 | Q20: =G20/$L$14 -> 6.0868788e+08 | R20: =H20/$L$14 -> 583123912 | S20: =I20/$L$14 -> 567430160 | T20: =J20/$L$14 -> 580546386 | U20: =K20/$L$14 -> -5.5818441e+09 | V20: =K20*$X$1/$X$2 -> -4962259.4 | Y20: 0 | Z20: =C20+D20 -> 1471518.8 | AA20: =E20+F20+G20 -> 2032657.9 | AB20: =H20+I20+J20 -> 1575301.4 | AC20: =SUM(Y20:AB20) -> 5079478.1 | AD20: ='[1]APAC 17.6.2019'!Y20 -> 0 | AE20: ='[1]APAC 17.6.2019'!Z20 -> 1471518.8 | AF20: ='[1]APAC 17.6.2019'!AA20 -> 2032657.9 | AG20: ='[1]APAC 17.6.2019'!AB20 -> 1575301.4 | AH20: ='[1]APAC 17.6.2019'!AC20 -> 5079478.1 | AJ20: ='[1]6.10'!X19 -> 1585003.7 | AK20: ='[1]6.10'!Y19 -> 2473558.8 | AL20: ='[1]6.10'!Z19 -> 3341510.5 | AM20: =SUM(AI20:AL20) -> 7400072.9 | AN20: 0 | AO20: ='[1]May Forecast'!AC47 -> 2082070.4 | AP20: ='[1]May Forecast'!AD47 -> 1519038.1 | AQ20: ='[1]May Forecast'!AE47 -> 1832879.8 | AR20: =SUM(AN20:AQ20) -> 5433988.2 | AS20: 7400072.9 | AT20: =AH20 -> 5079478.1 | AU20: =AC20 -> 5079478.1 | AV20: =-'[1]MFC Duty Free - Total'!P97 -> 5433988.2 | AW20: =AU20-AT20 -> 0 | AX20: =AC20-AS20 -> -2320594.8 | AY20: =AC20-AV20 -> -354510.09 | BA20: =Z20-AJ20 -> -113484.9 | BB20: =AA20-AK20 -> -440900.88 | BC20: =AB20-AL20 -> -1766209 | BD20: =AC20-AM20 -> -2320594.8
A21: Korea DF | B21: Gross Margin | C21: =C19-C20 -> 1356707.3 | D21: =D19-D20 -> 404107.12 | E21: =E19-E20 -> 302214.11 | F21: =F19-F20 -> 894012.76 | G21: =G19-G20 -> 589561.48 | H21: =H19-H20 -> 646181.44 | I21: =I19-I20 -> 677348.13 | J21: =J19-J20 -> 674962.08 | K21: =SUM(C21:J21) -> 5545094.5 | M21: =C21/$L$14 -> 1.4908872e+09 | N21: =D21/$L$14 -> 4.4407376e+08 | O21: =E21/$L$14 -> 332103422 | P21: =F21/$L$14 -> 9.824316e+08 | Q21: =G21/$L$14 -> 6.4786976e+08 | R21: =H21/$L$14 -> 710089499 | S21: =I21/$L$14 -> 7.443386e+08 | T21: =J21/$L$14 -> 7.4171657e+08 | U21: =K21/$L$14 -> 6.0935104e+09 | V21: =K21*$X$1/$X$2 -> 5417130.7 | Y21: 0 | Z21: =C21+D21 -> 1760814.5 | AA21: =E21+F21+G21 -> 1785788.3 | AB21: =H21+I21+J21 -> 1998491.7 | AC21: =SUM(Y21:AB21) -> 5545094.5 | AD21: ='[1]APAC 17.6.2019'!Y21 -> 0 | AE21: ='[1]APAC 17.6.2019'!Z21 -> 1760814.5 | AF21: ='[1]APAC 17.6.2019'!AA21 -> 1785788.3 | AG21: ='[1]APAC 17.6.2019'!AB21 -> 1998491.7 | AH21: ='[1]APAC 17.6.2019'!AC21 -> 5545094.5 | AJ21: =AJ19-AJ20 -> 1659642.9 | AK21: =AK19-AK20 -> 997328.22 | AL21: =AL19-AL20 -> 1413858.3 | AM21: =SUM(AI21:AL21) -> 4070829.5 | AN21: 0 | AO21: =AO19-AO20 -> 2949396.5 | AP21: =AP19-AP20 -> 1953192.4 | AQ21: =AQ19-AQ20 -> 2924021.5 | AR21: =SUM(AN21:AQ21) -> 7826610.4 | AS21: 4070829.5 | AT21: =AH21 -> 5545094.5 | AU21: =AC21 -> 5545094.5 | AV21: =AV19-AV20 -> 7826610.4 | AW21: =AU21-AT21 -> 0 | AX21: =AC21-AS21 -> 1474265 | AY21: =AC21-AV21 -> -2281515.9 | BA21: =Z21-AJ21 -> 101171.56 | BB21: =AA21-AK21 -> 788460.13 | BC21: =AB21-AL21 -> 584633.31 | BD21: =AC21-AM21 -> 1474265
B22: GM% | C22: =C21/C19 -> 0.62361872 | D22: =D21/D19 -> 0.38238988 | E22: =E21/E19 -> 0.41702184 | F22: =F21/F19 -> 0.45840162 | G22: =G21/G19 -> 0.51559096 | H22: =H21/H19 -> 0.54908919 | I22: =I21/I19 -> 0.56743126 | J22: =J21/J19 -> 0.56094483 | K22: =K21/K19 -> 0.52191224 | AD22: ='[1]APAC 17.6.2019'!Y22 -> 0 | AE22: ='[1]APAC 17.6.2019'!Z22 -> 0 | AF22: ='[1]APAC 17.6.2019'!AA22 -> 0 | AG22: ='[1]APAC 17.6.2019'!AB22 -> 0 | AH22: ='[1]APAC 17.6.2019'!AC22 -> 0 | AT22: =AH22 -> 0 | AU22: =AC22 -> 0 | AW22: =AU22-AT22 -> 0
AC23: =SUM(Y23:AB23) -> 0 | AD23: ='[1]APAC 17.6.2019'!Y23 -> 0 | AE23: ='[1]APAC 17.6.2019'!Z23 -> 0 | AF23: ='[1]APAC 17.6.2019'!AA23 -> 0 | AG23: ='[1]APAC 17.6.2019'!AB23 -> 0 | AH23: ='[1]APAC 17.6.2019'!AC23 -> 0 | AM23: =SUM(AI23:AL23) -> 0 | AR23: =SUM(AN23:AQ23) -> 0 | AT23: =AH23 -> 0 | AU23: =AC23 -> 0 | AW23: =AU23-AT23 -> 0 | BA23: =Z23-AJ23 -> 0 | BB23: =AA23-AK23 -> 0 | BC23: =AB23-AL23 -> 0 | BD23: =AC23-AM23 -> 0
A24: Korea Total | B24: Gross Revenue | C24: =C14+C4 -> 15653002 | D24: =D14+D4 -> 22004289 | E24: =E14+E4 -> 29523454 | F24: =F14+F4 -> 18026586 | G24: =G14+G4 -> 18084252 | H24: =H14+H4 -> 17628601 | I24: =I14+I4 -> 18713872 | J24: =J14+J4 -> 19842213 | K24: =SUM(C24:J24) -> 1.5947627e+08 | V24: =K24*$X$1/$X$2 -> 1.5579605e+08 | Y24: 0 | Z24: =C24+D24 -> 37657291 | AA24: =E24+F24+G24 -> 65634292 | AB24: =H24+I24+J24 -> 56184686 | AC24: =SUM(Y24:AB24) -> 1.5947627e+08 | AD24: ='[1]APAC 17.6.2019'!Y24 -> 0 | AE24: ='[1]APAC 17.6.2019'!Z24 -> 45256382 | AF24: ='[1]APAC 17.6.2019'!AA24 -> 54153485 | AG24: ='[1]APAC 17.6.2019'!AB24 -> 38317383 | AH24: ='[1]APAC 17.6.2019'!AC24 -> 1.3772725e+08 | AJ24: ='[1]6.10'!X22 -> 45376126 | AK24: ='[1]6.10'!Y22 -> 33565013 | AL24: ='[1]6.10'!Z22 -> 48629074 | AM24: =SUM(AI24:AL24) -> 1.2757021e+08 | AN24: 0 | AO24: =AO4+AO14 -> 18174572 | AP24: =AP4+AP14 -> 33565013 | AQ24: =AQ4+AQ14 -> 48629074 | AR24: =SUM(AN24:AQ24) -> 1.0036866e+08 | AS24: 1.2757021e+08 | AT24: =AH24 -> 1.3772725e+08 | AU24: =AC24 -> 1.5947627e+08 | AV24: ='[1]May Forecast'!AA15 -> 1.0036866e+08 | AW24: =AU24-AT24 -> 21749019 | AX24: =AC24-AS24 -> 31906056 | AY24: =AC24-AV24 -> 59107610 | BA24: =Z24-AJ24 -> -7718835.2 | BB24: =AA24-AK24 -> 32069279 | BC24: =AB24-AL24 -> 7555612 | BD24: =AC24-AM24 -> 31906056
A25: Korea Total | B25: Other Income | C25: =C15+C5 -> 0 | D25: =D15+D5 -> 0 | E25: =E15+E5 -> 0 | F25: =F15+F5 -> 0 | G25: =G15+G5 -> 0 | H25: =H15+H5 -> 0 | I25: =I15+I5 -> 0 | J25: =J15+J5 -> 0 | K25: =SUM(C25:J25) -> 0 | V25: =K25*$X$1/$X$2 -> 0 | Y25: 0 | Z25: =C25+D25 -> 0 | AA25: =E25+F25+G25 -> 0 | AB25: =H25+I25+J25 -> 0 | AC25: =SUM(Y25:AB25) -> 0 | AD25: ='[1]APAC 17.6.2019'!Y25 -> 0 | AE25: ='[1]APAC 17.6.2019'!Z25 -> 0 | AF25: ='[1]APAC 17.6.2019'!AA25 -> 0 | AG25: ='[1]APAC 17.6.2019'!AB25 -> 0 | AH25: ='[1]APAC 17.6.2019'!AC25 -> 0 | AJ25: ='[1]6.10'!X23 -> 0 | AK25: ='[1]6.10'!Y23 -> 0 | AL25: ='[1]6.10'!Z23 -> 0 | AM25: =SUM(AI25:AL25) -> 0 | AN25: 0 | AO25: =AO5+AO15 -> 25930.599 | AP25: =AP5+AP15 -> 18357.592 | AQ25: =AQ5+AQ15 -> 24843.083 | AR25: =SUM(AN25:AQ25) -> 69131.275 | AS25: 0 | AT25: =AH25 -> 0 | AU25: =AC25 -> 0 | AV25: ='[1]May Forecast'!AA16 -> 69471.823 | AW25: =AU25-AT25 -> 0 | AX25: =AC25-AS25 -> 0 | AY25: =AC25-AV25 -> -69471.823 | BA25: =Z25-AJ25 -> 0 | BB25: =AA25-AK25 -> 0 | BC25: =AB25-AL25 -> 0 | BD25: =AC25-AM25 -> 0
A26: Korea Total | B26: Returns and Allowances | C26: =C16+C6 -> -970879.58 | D26: =D16+D6 -> -993943.59 | E26: =E16+E6 -> -3091775.7 | F26: =F16+F6 -> -2472445.6 | G26: =G16+G6 -> -2540267.6 | H26: =H16+H6 -> -2584910.3 | I26: =I16+I6 -> -2703551.6 | J26: =J16+J6 -> -2846680.5 | K26: =SUM(C26:J26) -> -18204454 | V26: =K26*$X$1/$X$2 -> -17784352 | Y26: 0 | Z26: =C26+D26 -> -1964823.2 | AA26: =E26+F26+G26 -> -8104488.9 | AB26: =H26+I26+J26 -> -8135142.4 | AC26: =SUM(Y26:AB26) -> -18204454 | AD26: ='[1]APAC 17.6.2019'!Y26 -> 0 | AE26: ='[1]APAC 17.6.2019'!Z26 -> -3456683.6 | AF26: ='[1]APAC 17.6.2019'!AA26 -> -7614897.2 | AG26: ='[1]APAC 17.6.2019'!AB26 -> -7599117.7 | AH26: ='[1]APAC 17.6.2019'!AC26 -> -18670699 | AJ26: ='[1]6.10'!X24 -> -5034946.2 | AK26: ='[1]6.10'!Y24 -> -4562699.2 | AL26: ='[1]6.10'!Z24 -> -6617708.5 | AM26: =SUM(AI26:AL26) -> -16215354 | AN26: 0 | AO26: =AO6+AO16 -> -2092799.3 | AP26: =AP6+AP16 -> -4562699.2 | AQ26: =AQ6+AQ16 -> -6617708.5 | AR26: =SUM(AN26:AQ26) -> -13273207 | AS26: -16215354 | AT26: =AH26 -> -18670699 | AU26: =AC26 -> -18204454 | AV26: ='[1]May Forecast'!AA17 -> -13273207 | AW26: =AU26-AT26 -> 466244.09 | AX26: =AC26-AS26 -> -1989100.6 | AY26: =AC26-AV26 -> -4931247.5 | BA26: =Z26-AJ26 -> 3070123 | BB26: =AA26-AK26 -> -3541789.8 | BC26: =AB26-AL26 -> -1517433.9 | BD26: =AC26-AM26 -> -1989100.6 | BF26: =-Z26/Z24 -> 0.052176434 | BG26: =-AJ26/AJ24 -> 0.11096025 | BH26: =-AA26/AA24 -> 0.12347949 | BI26: =-AK26/AK24 -> 0.13593617 | BJ26: =-AB26/AB24 -> 0.14479288 | BK26: =-AL26/AL24 -> 0.13608543 | BL26: =-AC26/AC24 -> 0.11415149 | BM26: =-AM26/AM24 -> 0.12710925
A27: Korea Total | B27: Net Revenue w/o Promotions | C27: =SUM(C24:C26) -> 14682122 | D27: =SUM(D24:D26) -> 21010346 | E27: =SUM(E24:E26) -> 26431679 | F27: =SUM(F24:F26) -> 15554140 | G27: =SUM(G24:G26) -> 15543985 | H27: =SUM(H24:H26) -> 15043691 | I27: =SUM(I24:I26) -> 16010320 | J27: =SUM(J24:J26) -> 16995533 | K27: =SUM(C27:J27) -> 1.4127181e+08 | V27: =K27*$X$1/$X$2 -> 1.380117e+08 | Y27: 0 | Z27: =C27+D27 -> 35692468 | AA27: =E27+F27+G27 -> 57529803 | AB27: =H27+I27+J27 -> 48049544 | AC27: =SUM(Y27:AB27) -> 1.4127181e+08 | AD27: ='[1]APAC 17.6.2019'!Y27 -> 0 | AE27: ='[1]APAC 17.6.2019'!Z27 -> 41799698 | AF27: ='[1]APAC 17.6.2019'!AA27 -> 46538588 | AG27: ='[1]APAC 17.6.2019'!AB27 -> 30718265 | AH27: ='[1]APAC 17.6.2019'!AC27 -> 1.1905655e+08 | AJ27: =SUM(AJ24:AJ26) -> 40341180 | AK27: =SUM(AK24:AK26) -> 29002314 | AL27: =SUM(AL24:AL26) -> 42011365 | AM27: =SUM(AI27:AL27) -> 1.1135486e+08 | AN27: 0 | AO27: =SUM(AO24:AO26) -> 16107703 | AP27: =SUM(AP24:AP26) -> 29020671 | AQ27: =SUM(AQ24:AQ26) -> 42036209 | AR27: =SUM(AN27:AQ27) -> 87164583 | AS27: 1.1135486e+08 | AT27: =AH27 -> 1.1905655e+08 | AU27: =AC27 -> 1.4127181e+08 | AV27: =SUM(AV24:AV26) -> 87164924 | AW27: =AU27-AT27 -> 22215263 | AX27: =AC27-AS27 -> 29916955 | AY27: =AC27-AV27 -> 54106891 | BA27: =Z27-AJ27 -> -4648712.2 | BB27: =AA27-AK27 -> 28527489 | BC27: =AB27-AL27 -> 6038178.1 | BD27: =AC27-AM27 -> 29916955
A28: Korea Total | B28: Promotions | C28: =C18+C8 -> 0 | D28: =D18+D8 -> 0 | E28: =E18+E8 -> 0 | F28: =F18+F8 -> 0 | G28: =G18+G8 -> 0 | H28: =H18+H8 -> -893366.48 | I28: =I18+I8 -> 0 | J28: =J18+J8 -> -999323.18 | K28: =SUM(C28:J28) -> -1892689.7 | V28: =K28*$X$1/$X$2 -> -1849012.2 | Y28: 0 | Z28: =C28+D28 -> 0 | AA28: =E28+F28+G28 -> 0 | AB28: =H28+I28+J28 -> -1892689.7 | AC28: =SUM(Y28:AB28) -> -1892689.7 | AD28: ='[1]APAC 17.6.2019'!Y28 -> 0 | AE28: ='[1]APAC 17.6.2019'!Z28 -> 0 | AF28: ='[1]APAC 17.6.2019'!AA28 -> 0 | AG28: ='[1]APAC 17.6.2019'!AB28 -> -3036285.6 | AH28: ='[1]APAC 17.6.2019'!AC28 -> -3036285.6 | AJ28: ='[1]6.10'!X26 -> -583907.43 | AK28: ='[1]6.10'!Y26 -> 0 | AL28: ='[1]6.10'!Z26 -> -2107210.2 | AM28: =SUM(AI28:AL28) -> -2691117.6 | AN28: 0 | AO28: =AO8+AO18 -> 0 | AP28: =AP8+AP18 -> 0 | AQ28: =AQ8+AQ18 -> -2107210.2 | AR28: =SUM(AN28:AQ28) -> -2107210.2 | AS28: -2691117.6 | AT28: =AH28 -> -3036285.6 | AU28: =AC28 -> -1892689.7 | AV28: ='[1]May Forecast'!AA18 -> -2107210.2 | AW28: =AU28-AT28 -> 1143596 | AX28: =AC28-AS28 -> 798427.96 | AY28: =AC28-AV28 -> 214520.53 | BA28: =Z28-AJ28 -> 583907.43 | BB28: =AA28-AK28 -> 0 | BC28: =AB28-AL28 -> 214520.53 | BD28: =AC28-AM28 -> 798427.96
A29: Korea Total | B29: Net Revenue w/ Promotions | C29: =SUM(C27:C28) -> 14682122 | D29: =SUM(D27:D28) -> 21010346 | E29: =SUM(E27:E28) -> 26431679 | F29: =SUM(F27:F28) -> 15554140 | G29: =SUM(G27:G28) -> 15543985 | H29: =SUM(H27:H28) -> 14150324 | I29: =SUM(I27:I28) -> 16010320 | J29: =SUM(J27:J28) -> 15996209 | K29: =SUM(C29:J29) -> 1.3937912e+08 | V29: =K29*$X$1/$X$2 -> 1.3616268e+08 | Y29: 0 | Z29: =C29+D29 -> 35692468 | AA29: =E29+F29+G29 -> 57529803 | AB29: =H29+I29+J29 -> 46156854 | AC29: =SUM(Y29:AB29) -> 1.3937912e+08 | AD29: ='[1]APAC 17.6.2019'!Y29 -> 0 | AE29: ='[1]APAC 17.6.2019'!Z29 -> 41799698 | AF29: ='[1]APAC 17.6.2019'!AA29 -> 46538588 | AG29: ='[1]APAC 17.6.2019'!AB29 -> 27681980 | AH29: ='[1]APAC 17.6.2019'!AC29 -> 1.1602027e+08 | AJ29: =SUM(AJ27:AJ28) -> 39757273 | AK29: =SUM(AK27:AK28) -> 29002314 | AL29: =SUM(AL27:AL28) -> 39904155 | AM29: =SUM(AI29:AL29) -> 1.0866374e+08 | AN29: 0 | AO29: =SUM(AO27:AO28) -> 16107703 | AP29: =SUM(AP27:AP28) -> 29020671 | AQ29: =SUM(AQ27:AQ28) -> 39928999 | AR29: =SUM(AN29:AQ29) -> 85057373 | AS29: 1.0866374e+08 | AT29: =AH29 -> 1.1602027e+08 | AU29: =AC29 -> 1.3937912e+08 | AV29: =SUM(AV27:AV28) -> 85057714 | AW29: =AU29-AT29 -> 23358859 | AX29: =AC29-AS29 -> 30715383 | AY29: =AC29-AV29 -> 54321411 | BA29: =Z29-AJ29 -> -4064804.7 | BB29: =AA29-AK29 -> 28527489 | BC29: =AB29-AL29 -> 6252698.6 | BD29: =AC29-AM29 -> 30715383
A30: Korea Total | B30: COGS | C30: =C10+C20 -> 7487883.3 | D30: =D10+D20 -> 12300027 | E30: =E10+E20 -> 16181059 | F30: =F10+F20 -> 9419631.4 | G30: =G10+G20 -> 9346207.3 | H30: =H10+H20 -> 8946654.6 | I30: =I10+I20 -> 9372491.9 | J30: =J10+J20 -> 9820096.1 | K30: =SUM(C30:J30) -> 82874051 | V30: =K30*$X$1/$X$2 -> 80961573 | Y30: 0 | Z30: =C30+D30 -> 19787911 | AA30: =E30+F30+G30 -> 34946898 | AB30: =H30+I30+J30 -> 28139243 | AC30: =SUM(Y30:AB30) -> 82874051 | AD30: ='[1]APAC 17.6.2019'!Y30 -> 0 | AE30: ='[1]APAC 17.6.2019'!Z30 -> 23949365 | AF30: ='[1]APAC 17.6.2019'!AA30 -> 28899764 | AG30: ='[1]APAC 17.6.2019'!AB30 -> 19051313 | AH30: ='[1]APAC 17.6.2019'!AC30 -> 71900441 | AJ30: ='[1]6.10'!X28 -> 23825260 | AK30: ='[1]6.10'!Y28 -> 17355333 | AL30: ='[1]6.10'!Z28 -> 24038756 | AM30: =SUM(AI30:AL30) -> 65219350 | AN30: 0 | AO30: =AO10+AO20 -> 9504513.8 | AP30: =AP10+AP20 -> 17355333 | AQ30: =AQ10+AQ20 -> 24038756 | AR30: =SUM(AN30:AQ30) -> 50898603 | AS30: 70892180 | AT30: =AH30 -> 71900441 | AU30: =AC30 -> 82874051 | AV30: ='[1]May Forecast'!AA19 -> 50898603 | AW30: =AU30-AT30 -> 10973610 | AX30: =AC30-AS30 -> 11981871 | AY30: =AC30-AV30 -> 31975448 | BA30: =Z30-AJ30 -> -4037349.4 | BB30: =AA30-AK30 -> 17591564 | BC30: =AB30-AL30 -> 4100486.7 | BD30: =AC30-AM30 -> 17654701
A31: Korea Total | B31: Gross Margin | C31: =C29-C30 -> 7194238.7 | D31: =D29-D30 -> 8710318.4 | E31: =E29-E30 -> 10250620 | F31: =F29-F30 -> 6134508.5 | G31: =G29-G30 -> 6197777.4 | H31: =H29-H30 -> 5203669.8 | I31: =I29-I30 -> 6637828.3 | J31: =J29-J30 -> 6176113.2 | K31: =SUM(C31:J31) -> 56505074 | V31: =K31*$X$1/$X$2 -> 55201111 | Y31: 0 | Z31: =C31+D31 -> 15904557 | AA31: =E31+F31+G31 -> 22582906 | AB31: =H31+I31+J31 -> 18017611 | AC31: =SUM(Y31:AB31) -> 56505074 | AD31: ='[1]APAC 17.6.2019'!Y31 -> 0 | AE31: ='[1]APAC 17.6.2019'!Z31 -> 17850334 | AF31: ='[1]APAC 17.6.2019'!AA31 -> 17638824 | AG31: ='[1]APAC 17.6.2019'!AB31 -> 8630666.7 | AH31: ='[1]APAC 17.6.2019'!AC31 -> 44119825 | AJ31: =AJ29-AJ30 -> 15932012 | AK31: =AK29-AK30 -> 11646980 | AL31: =AL29-AL30 -> 15865399 | AM31: =SUM(AI31:AL31) -> 43444392 | AN31: 0 | AO31: =AO29-AO30 -> 6603189.4 | AP31: =AP29-AP30 -> 11665338 | AQ31: =AQ29-AQ30 -> 15890243 | AR31: =SUM(AN31:AQ31) -> 34158770 | AS31: 37771562 | AT31: =AH31 -> 44119825 | AU31: =AC31 -> 56505074 | AV31: =AV29-AV30 -> 34159110 | AW31: =AU31-AT31 -> 12385249 | AX31: =AC31-AS31 -> 18733512 | AY31: =AC31-AV31 -> 22345964 | BA31: =Z31-AJ31 -> -27455.377 | BB31: =AA31-AK31 -> 10935925 | BC31: =AB31-AL31 -> 2152212 | BD31: =AC31-AM31 -> 13060682
B32: GM% | C32: =C31/C29 -> 0.48999993 | D32: =D31/D29 -> 0.41457282 | E32: =E31/E29 -> 0.38781569 | F32: =F31/F29 -> 0.39439715 | G32: =G31/G29 -> 0.39872513 | H32: =H31/H29 -> 0.36774209 | I32: =I31/I29 -> 0.41459685 | J32: =J31/J29 -> 0.38609855 | K32: =K31/K29 -> 0.40540557 | AD32: ='[1]APAC 17.6.2019'!Y32 -> 0 | AE32: ='[1]APAC 17.6.2019'!Z32 -> 0 | AF32: ='[1]APAC 17.6.2019'!AA32 -> 0 | AG32: ='[1]APAC 17.6.2019'!AB32 -> 0 | AH32: ='[1]APAC 17.6.2019'!AC32 -> 0 | AT32: =AH32 -> 0 | AU32: =AC32 -> 0 | AW32: =AU32-AT32 -> 0
K33: =SUM(C33:J33) -> 0 | AC33: =SUM(Y33:AB33) -> 0 | AD33: ='[1]APAC 17.6.2019'!Y33 -> 0 | AE33: ='[1]APAC 17.6.2019'!Z33 -> 0 | AF33: ='[1]APAC 17.6.2019'!AA33 -> 0 | AG33: ='[1]APAC 17.6.2019'!AB33 -> 0 | AH33: ='[1]APAC 17.6.2019'!AC33 -> 0 | AM33: =SUM(AI33:AL33) -> 0 | AR33: =SUM(AN33:AQ33) -> 0 | AS33: 0 | AT33: =AH33 -> 0 | AU33: =AC33 -> 0 | AW33: =AU33-AT33 -> 0 | BA33: =Z33-AJ33 -> 0 | BB33: =AA33-AK33 -> 0 | BC33: =AB33-AL33 -> 0 | BD33: =AC33-AM33 -> 0
A34: Philippines | B34: Gross Revenue | C34: ='[1]6.28'!L42 -> 1291859 | D34: ='[1]6.28'!M42 -> 0 | E34: ='[1]6.28'!N42 -> 495958.62 | F34: ='[1]6.28'!O42 -> 520793.17 | G34: ='[1]6.28'!P42 -> 623556.75 | H34: ='[1]6.28'!Q42 -> 722834.8 | I34: ='[1]6.28'!R42 -> 783132.49 | J34: ='[1]6.28'!S42 -> 847514.09 | K34: =SUM(C34:J34) -> 5285648.9 | L34: ='[1]Currency Exchange Rate'!H156 -> 0.01937 | M34: =C34/$L$34 -> 66693804 | N34: =D34/$L$34 -> 0 | O34: =E34/$L$34 -> 25604472 | P34: =F34/$L$34 -> 26886586 | Q34: =G34/$L$34 -> 32191882 | R34: =H34/$L$34 -> 37317233 | S34: =I34/$L$34 -> 40430175 | T34: =J34/$L$34 -> 43753954 | U34: =K34/$L$34 -> 2.7287811e+08 | V34: 5771025.7 | Y34: 0 | Z34: =C34+D34 -> 1291859 | AA34: =E34+F34+G34 -> 1640308.5 | AB34: =H34+I34+J34 -> 2353481.4 | AC34: =SUM(Y34:AB34) -> 5285648.9 | AD34: ='[1]APAC 17.6.2019'!Y34 -> 0 | AE34: ='[1]APAC 17.6.2019'!Z34 -> 1291859 | AF34: ='[1]APAC 17.6.2019'!AA34 -> 1640308.5 | AG34: ='[1]APAC 17.6.2019'!AB34 -> 2353481.4 | AH34: ='[1]APAC 17.6.2019'!AC34 -> 5285648.9 | AJ34: ='[1]6.10'!X31 -> 1798146.1 | AK34: ='[1]6.10'!Y31 -> 1306679 | AL34: ='[1]6.10'!Z31 -> 1715445 | AM34: =SUM(AI34:AL34) -> 4820270.1 | AN34: 0 | AO34: ='[1]May Forecast'!AC29 -> 1577851 | AP34: ='[1]May Forecast'!AD29 -> 1306679.1 | AQ34: ='[1]May Forecast'!AE29 -> 1715445.3 | AR34: =SUM(AN34:AQ34) -> 4599975.3 | AS34: 4820270.1 | AT34: =AH34 -> 5285648.9 | AU34: =AC34 -> 5285648.9 | AV34: ='[1]May Forecast'!AA29 -> 4599975.3 | AW34: =AU34-AT34 -> 0 | AX34: =AC34-AS34 -> 465378.78 | AY34: =AC34-AV34 -> 685673.6 | BA34: =Z34-AJ34 -> -506287.15 | BB34: =AA34-AK34 -> 333629.55 | BC34: =AB34-AL34 -> 638036.38 | BD34: =AC34-AM34 -> 465378.78
A35: Philippines | B35: Other Income | C35: 0 | D35: 0 | E35: 0 | F35: 0 | G35: 0 | H35: 0 | I35: 0 | J35: 0 | K35: =SUM(C35:J35) -> 0 | M35: =C35/$L$34 -> 0 | N35: =D35/$L$34 -> 0 | O35: =E35/$L$34 -> 0 | P35: =F35/$L$34 -> 0 | Q35: =G35/$L$34 -> 0 | R35: =H35/$L$34 -> 0 | S35: =I35/$L$34 -> 0 | T35: =J35/$L$34 -> 0 | U35: =K35/$L$34 -> 0 | V35: 0 | Y35: 0 | Z35: =C35+D35 -> 0 | AA35: =E35+F35+G35 -> 0 | AB35: =H35+I35+J35 -> 0 | AC35: =SUM(Y35:AB35) -> 0 | AD35: ='[1]APAC 17.6.2019'!Y35 -> 0 | AE35: ='[1]APAC 17.6.2019'!Z35 -> 0 | AF35: ='[1]APAC 17.6.2019'!AA35 -> 0 | AG35: ='[1]APAC 17.6.2019'!AB35 -> 0 | AH35: ='[1]APAC 17.6.2019'!AC35 -> 0 | AJ35: ='[1]6.10'!X32 -> 0 | AK35: ='[1]6.10'!Y32 -> 0 | AL35: ='[1]6.10'!Z32 -> 0 | AM35: =SUM(AI35:AL35) -> 0 | AN35: 0 | AO35: ='[1]May Forecast'!AC30 -> 7889.246 | AP35: ='[1]May Forecast'!AD30 -> 6533.3848 | AQ35: ='[1]May Forecast'!AE30 -> 8577.2297 | AR35: =SUM(AN35:AQ35) -> 22999.861 | AS35: 0 | AT35: =AH35 -> 0 | AU35: =AC35 -> 0 | AV35: ='[1]May Forecast'!AA30 -> 22999.861 | AW35: =AU35-AT35 -> 0 | AX35: =AC35-AS35 -> 0 | AY35: =AC35-AV35 -> -22999.861 | BA35: =Z35-AJ35 -> 0 | BB35: =AA35-AK35 -> 0 | BC35: =AB35-AL35 -> 0 | BD35: =AC35-AM35 -> 0
A36: Philippines | B36: Returns and Allowances | C36: ='[1]6.28 (PH Edit)'!L43 -> 0 | D36: ='[1]6.28 (PH Edit)'!M43 -> 0 | E36: ='[1]6.28 (PH Edit)'!N43 -> -347171.04 | F36: ='[1]6.28 (PH Edit)'!O43 -> -364555.22 | G36: ='[1]6.28 (PH Edit)'!P43 -> -436489.73 | H36: ='[1]6.28 (PH Edit)'!Q43 -> -505984.36 | I36: ='[1]6.28 (PH Edit)'!R43 -> -548192.74 | J36: ='[1]6.28 (PH Edit)'!S43 -> -593259.86 | K36: =SUM(C36:J36) -> -2795653 | M36: =C36/$L$34 -> 0 | N36: =D36/$L$34 -> 0 | O36: =E36/$L$34 -> -17923130 | P36: =F36/$L$34 -> -18820610 | Q36: =G36/$L$34 -> -22534317 | R36: =H36/$L$34 -> -26122063 | S36: =I36/$L$34 -> -28301122 | T36: =J36/$L$34 -> -30627768 | U36: =K36/$L$34 -> -1.4432901e+08 | V36: -546232.7 | Y36: 0 | Z36: =C36+D36 -> 0 | AA36: =E36+F36+G36 -> -1148216 | AB36: =H36+I36+J36 -> -1647437 | AC36: =SUM(Y36:AB36) -> -2795653 | AD36: ='[1]APAC 17.6.2019'!Y36 -> 0 | AE36: ='[1]APAC 17.6.2019'!Z36 -> 0 | AF36: ='[1]APAC 17.6.2019'!AA36 -> -328061.71 | AG36: ='[1]APAC 17.6.2019'!AB36 -> -470696.29 | AH36: ='[1]APAC 17.6.2019'!AC36 -> -798758 | AJ36: ='[1]6.10'!X33 -> -78920 | AK36: ='[1]6.10'!Y33 -> -159619 | AL36: ='[1]6.10'!Z33 -> -209552 | AM36: =SUM(AI36:AL36) -> -448091 | AN36: 0 | AO36: ='[1]May Forecast'!AC31 -> -192744.4 | AP36: ='[1]May Forecast'!AD31 -> -159619.12 | AQ36: ='[1]May Forecast'!AE31 -> -209552.47 | AR36: =SUM(AN36:AQ36) -> -561915.99 | AS36: -448091 | AT36: =AH36 -> -798758 | AU36: =AC36 -> -2795653 | AV36: ='[1]May Forecast'!AA31 -> -561915.99 | AW36: =AU36-AT36 -> -1996895 | AX36: =AC36-AS36 -> -2347562 | AY36: =AC36-AV36 -> -2233737 | BA36: =Z36-AJ36 -> 78920 | BB36: =AA36-AK36 -> -988596.98 | BC36: =AB36-AL36 -> -1437885 | BD36: =AC36-AM36 -> -2347562 | BF36: =-Z36/Z34 -> 0 | BG36: =-AJ36/AJ34 -> 0.043889647 | BH36: =-AA36/AA34 -> 0.7 | BI36: =-AK36/AK34 -> 0.12215624 | BJ36: =-AB36/AB34 -> 0.7 | BK36: =-AL36/AL34 -> 0.12215606 | BL36: =-AC36/AC34 -> 0.52891386 | BM36: =-AM36/AM34 -> 0.092959728
A37: Philippines | B37: Net Revenue w/o Promotions | C37: =SUM(C34:C36) -> 1291859 | D37: =SUM(D34:D36) -> 0 | E37: =SUM(E34:E36) -> 148787.59 | F37: =SUM(F34:F36) -> 156237.95 | G37: =SUM(G34:G36) -> 187067.03 | H37: =SUM(H34:H36) -> 216850.44 | I37: =SUM(I34:I36) -> 234939.75 | J37: =SUM(J34:J36) -> 254254.23 | K37: =SUM(C37:J37) -> 2489996 | M37: =C37/$L$34 -> 66693804 | N37: =D37/$L$34 -> 0 | O37: =E37/$L$34 -> 7681341.6 | P37: =F37/$L$34 -> 8065975.8 | Q37: =G37/$L$34 -> 9657564.6 | R37: =H37/$L$34 -> 11195170 | S37: =I37/$L$34 -> 12129052 | T37: =J37/$L$34 -> 13126186 | U37: =K37/$L$34 -> 1.285491e+08 | V37: 5224793 | Y37: 0 | Z37: =C37+D37 -> 1291859 | AA37: =E37+F37+G37 -> 492092.56 | AB37: =H37+I37+J37 -> 706044.41 | AC37: =SUM(Y37:AB37) -> 2489996 | AD37: ='[1]APAC 17.6.2019'!Y37 -> 0 | AE37: ='[1]APAC 17.6.2019'!Z37 -> 1291859 | AF37: ='[1]APAC 17.6.2019'!AA37 -> 1312246.8 | AG37: ='[1]APAC 17.6.2019'!AB37 -> 1882785.1 | AH37: ='[1]APAC 17.6.2019'!AC37 -> 4486890.9 | AJ37: =SUM(AJ34:AJ36) -> 1719226.1 | AK37: =SUM(AK34:AK36) -> 1147060 | AL37: =SUM(AL34:AL36) -> 1505893 | AM37: =SUM(AI37:AL37) -> 4372179.1 | AN37: 0 | AO37: =SUM(AO34:AO36) -> 1392995.8 | AP37: =SUM(AP34:AP36) -> 1153593.3 | AQ37: =SUM(AQ34:AQ36) -> 1514470.1 | AR37: =SUM(AN37:AQ37) -> 4061059.2 | AS37: 4372179.1 | AT37: =AH37 -> 4486890.9 | AU37: =AC37 -> 2489996 | AV37: =SUM(AV34:AV36) -> 4061059.2 | AW37: =AU37-AT37 -> -1996895 | AX37: =AC37-AS37 -> -1882183.2 | AY37: =AC37-AV37 -> -1571063.2 | BA37: =Z37-AJ37 -> -427367.15 | BB37: =AA37-AK37 -> -654967.44 | BC37: =AB37-AL37 -> -799848.59 | BD37: =AC37-AM37 -> -1882183.2
A38: Philippines | B38: Promotions | K38: =SUM(C38:J38) -> 0 | M38: =C38/$L$34 -> 0 | N38: =D38/$L$34 -> 0 | O38: =E38/$L$34 -> 0 | P38: =F38/$L$34 -> 0 | Q38: =G38/$L$34 -> 0 | R38: =H38/$L$34 -> 0 | S38: =I38/$L$34 -> 0 | T38: =J38/$L$34 -> 0 | U38: =K38/$L$34 -> 0 | V38: 0 | Y38: 0 | Z38: =C38+D38 -> 0 | AA38: =E38+F38+G38 -> 0 | AB38: =H38+I38+J38 -> 0 | AC38: =SUM(Y38:AB38) -> 0 | AD38: ='[1]APAC 17.6.2019'!Y38 -> 0 | AE38: ='[1]APAC 17.6.2019'!Z38 -> 0 | AF38: ='[1]APAC 17.6.2019'!AA38 -> 0 | AG38: ='[1]APAC 17.6.2019'!AB38 -> 0 | AH38: ='[1]APAC 17.6.2019'!AC38 -> 0 | AJ38: ='[1]6.10'!X35 -> 0 | AK38: ='[1]6.10'!Y35 -> 0 | AL38: ='[1]6.10'!Z35 -> 0 | AM38: =SUM(AI38:AL38) -> 0 | AN38: 0 | AR38: =SUM(AN38:AQ38) -> 0 | AS38: 0 | AT38: =AH38 -> 0 | AU38: =AC38 -> 0 | AV38: 0 | AW38: =AU38-AT38 -> 0 | AX38: =AC38-AS38 -> 0 | AY38: =AC38-AV38 -> 0 | BA38: =Z38-AJ38 -> 0 | BB38: =AA38-AK38 -> 0 | BC38: =AB38-AL38 -> 0 | BD38: =AC38-AM38 -> 0
A39: Philippines | B39: Net Revenue w/ Promotions | C39: =SUM(C37:C38) -> 1291859 | D39: =SUM(D37:D38) -> 0 | E39: =SUM(E37:E38) -> 148787.59 | F39: =SUM(F37:F38) -> 156237.95 | G39: =SUM(G37:G38) -> 187067.03 | H39: =SUM(H37:H38) -> 216850.44 | I39: =SUM(I37:I38) -> 234939.75 | J39: =SUM(J37:J38) -> 254254.23 | K39: =SUM(C39:J39) -> 2489996 | M39: =C39/$L$34 -> 66693804 | N39: =D39/$L$34 -> 0 | O39: =E39/$L$34 -> 7681341.6 | P39: =F39/$L$34 -> 8065975.8 | Q39: =G39/$L$34 -> 9657564.6 | R39: =H39/$L$34 -> 11195170 | S39: =I39/$L$34 -> 12129052 | T39: =J39/$L$34 -> 13126186 | U39: =K39/$L$34 -> 1.285491e+08 | V39: 5224793 | Y39: 0 | Z39: =C39+D39 -> 1291859 | AA39: =E39+F39+G39 -> 492092.56 | AB39: =H39+I39+J39 -> 706044.41 | AC39: =SUM(Y39:AB39) -> 2489996 | AD39: ='[1]APAC 17.6.2019'!Y39 -> 0 | AE39: ='[1]APAC 17.6.2019'!Z39 -> 1291859 | AF39: ='[1]APAC 17.6.2019'!AA39 -> 1312246.8 | AG39: ='[1]APAC 17.6.2019'!AB39 -> 1882785.1 | AH39: ='[1]APAC 17.6.2019'!AC39 -> 4486890.9 | AJ39: =SUM(AJ37:AJ38) -> 1719226.1 | AK39: =SUM(AK37:AK38) -> 1147060 | AL39: =SUM(AL37:AL38) -> 1505893 | AM39: =SUM(AI39:AL39) -> 4372179.1 | AN39: 0 | AO39: =SUM(AO37:AO38) -> 1392995.8 | AP39: =SUM(AP37:AP38) -> 1153593.3 | AQ39: =SUM(AQ37:AQ38) -> 1514470.1 | AR39: =SUM(AN39:AQ39) -> 4061059.2 | AS39: 4372179.1 | AT39: =AH39 -> 4486890.9 | AU39: =AC39 -> 2489996 | AV39: =SUM(AV37:AV38) -> 4061059.2 | AW39: =AU39-AT39 -> -1996895 | AX39: =AC39-AS39 -> -1882183.2 | AY39: =AC39-AV39 -> -1571063.2 | BA39: =Z39-AJ39 -> -427367.15 | BB39: =AA39-AK39 -> -654967.44 | BC39: =AB39-AL39 -> -799848.59 | BD39: =AC39-AM39 -> -1882183.2
