Workbook

Sheet Summary
L1: Invoiced | M1: Freight Coding | N1: February | O1: March | P1: April | Q1: May | R1: June | S1: July | T1: August | U1: September | V1: October | W1: November | X1: December | Y1: Total Expense May to Jul 2018 | AB1: Trial Balance Summary | AE1: Ledger: | AF1: ACTUAL | AG1: Page: | AH1: 1 of 1
M2: Total by Month | N2: =SUM(N3:N250) -> 72 | O2: =SUM(O3:O250) -> 181575.68 | P2: =SUM(P3:P250) -> 1309884.9 | Q2: =SUM(Q3:Q250) -> 1023340 | R2: =SUM(R3:R250) -> 1038270 | S2: =SUM(S3:S250) -> 920939.59 | T2: =SUM(T3:T250) -> 110601.42 | U2: =SUM(U3:U250) -> 0 | ... X2: =SUM(X3:X250) -> 0 | Y2: =SUM(N2:X2) -> 4584683.5 | AB2: Company: | AC2: Juul | AE2: Branch: | AF2: PLOOM | AG2: Date: | AH2: 43322.44
A3: =$L3&N$1&$M3 -> MarchFebruaryAFG NC - DCL KY | B3: =$L3&O$1&$M3 -> MarchMarchAFG NC - DCL KY | C3: =$L3&P$1&$M3 -> MarchAprilAFG NC - DCL KY | D3: =$L3&Q$1&$M3 -> MarchMayAFG NC - DCL KY | E3: =$L3&R$1&$M3 -> MarchJuneAFG NC - DCL KY | F3: =$L3&S$1&$M3 -> MarchJulyAFG NC - DCL KY | G3: =$L3&T$1&$M3 -> MarchAugustAFG NC - DCL KY | H3: =$L3&U$1&$M3 -> MarchSeptemberAFG NC - DCL KY | ... K3: =$L3&X$1&$M3 -> MarchDecemberAFG NC - DCL KY | L3: March | M3: AFG NC - DCL KY | N3: =SUMIF(Data!$A:$A,Summary!A3,Data!$M:$M) -> 0 | O3: =SUMIF(Data!$A:$A,Summary!B3,Data!$M:$M) -> 1725 | P3: =SUMIF(Data!$A:$A,Summary!C3,Data!$M:$M) -> 0 | Q3: =SUMIF(Data!$A:$A,Summary!D3,Data!$M:$M) -> 0 | R3: =SUMIF(Data!$A:$A,Summary!E3,Data!$M:$M) -> 0 | S3: =SUMIF(Data!$A:$A,Summary!F3,Data!$M:$M) -> 0 | T3: =SUMIF(Data!$A:$A,Summary!G3,Data!$M:$M) -> 0 | U3: =SUMIF(Data!$A:$A,Summary!H3,Data!$M:$M) -> 0 | ... X3: =SUMIF(Data!$A:$A,Summary!K3,Data!$M:$M) -> 0 | AB3: User: | AC3: alejandro | AE3: Fin. Period: | AF3: 05-2018
A4: =$L4&N$1&$M4 -> MarchFebruaryAFG NC - Canada | B4: =$L4&O$1&$M4 -> MarchMarchAFG NC - Canada | C4: =$L4&P$1&$M4 -> MarchAprilAFG NC - Canada | D4: =$L4&Q$1&$M4 -> MarchMayAFG NC - Canada | E4: =$L4&R$1&$M4 -> MarchJuneAFG NC - Canada | F4: =$L4&S$1&$M4 -> MarchJulyAFG NC - Canada | G4: =$L4&T$1&$M4 -> MarchAugustAFG NC - Canada | H4: =$L4&U$1&$M4 -> MarchSeptemberAFG NC - Canada | ... K4: =$L4&X$1&$M4 -> MarchDecemberAFG NC - Canada | L4: March | M4: AFG NC - Canada | N4: =SUMIF(Data!$A:$A,Summary!A4,Data!$M:$M) -> 0 | O4: =SUMIF(Data!$A:$A,Summary!B4,Data!$M:$M) -> 0 | P4: =SUMIF(Data!$A:$A,Summary!C4,Data!$M:$M) -> 0 | Q4: =SUMIF(Data!$A:$A,Summary!D4,Data!$M:$M) -> 0 | R4: =SUMIF(Data!$A:$A,Summary!E4,Data!$M:$M) -> 0 | S4: =SUMIF(Data!$A:$A,Summary!F4,Data!$M:$M) -> 0 | T4: =SUMIF(Data!$A:$A,Summary!G4,Data!$M:$M) -> 0 | U4: =SUMIF(Data!$A:$A,Summary!H4,Data!$M:$M) -> 0 | ... X4: =SUMIF(Data!$A:$A,Summary!K4,Data!$M:$M) -> 0 | AB4: Account | AC4: Type | AD4: Description | AE4: Beginning Balance | AF4: Debit | AG4: Credit | AH4: Ending Balance
A5: =$L5&N$1&$M5 -> MarchFebruaryAFG NC - Phillips WI | B5: =$L5&O$1&$M5 -> MarchMarchAFG NC - Phillips WI | C5: =$L5&P$1&$M5 -> MarchAprilAFG NC - Phillips WI | D5: =$L5&Q$1&$M5 -> MarchMayAFG NC - Phillips WI | E5: =$L5&R$1&$M5 -> MarchJuneAFG NC - Phillips WI | F5: =$L5&S$1&$M5 -> MarchJulyAFG NC - Phillips WI | G5: =$L5&T$1&$M5 -> MarchAugustAFG NC - Phillips WI | H5: =$L5&U$1&$M5 -> MarchSeptemberAFG NC - Phillips WI | ... K5: =$L5&X$1&$M5 -> MarchDecemberAFG NC - Phillips WI | L5: March | M5: AFG NC - Phillips WI | N5: =SUMIF(Data!$A:$A,Summary!A5,Data!$M:$M) -> 0 | O5: =SUMIF(Data!$A:$A,Summary!B5,Data!$M:$M) -> 0 | P5: =SUMIF(Data!$A:$A,Summary!C5,Data!$M:$M) -> 0 | Q5: =SUMIF(Data!$A:$A,Summary!D5,Data!$M:$M) -> 0 | R5: =SUMIF(Data!$A:$A,Summary!E5,Data!$M:$M) -> 0 | S5: =SUMIF(Data!$A:$A,Summary!F5,Data!$M:$M) -> 0 | T5: =SUMIF(Data!$A:$A,Summary!G5,Data!$M:$M) -> 0 | U5: =SUMIF(Data!$A:$A,Summary!H5,Data!$M:$M) -> 0 | ... X5: =SUMIF(Data!$A:$A,Summary!K5,Data!$M:$M) -> 0 | AB5: 513000 | AC5: E | AD5: Cost of Goods - Landed Cost Variance | AE5: 2421092.3 | AF5: 749631.24 | AG5: 0 | AH5: 3170723.5
A6: =$L6&N$1&$M6 -> MarchFebruaryAFG Suzho - DCL KY | B6: =$L6&O$1&$M6 -> MarchMarchAFG Suzho - DCL KY | C6: =$L6&P$1&$M6 -> MarchAprilAFG Suzho - DCL KY | D6: =$L6&Q$1&$M6 -> MarchMayAFG Suzho - DCL KY | E6: =$L6&R$1&$M6 -> MarchJuneAFG Suzho - DCL KY | F6: =$L6&S$1&$M6 -> MarchJulyAFG Suzho - DCL KY | G6: =$L6&T$1&$M6 -> MarchAugustAFG Suzho - DCL KY | H6: =$L6&U$1&$M6 -> MarchSeptemberAFG Suzho - DCL KY | ... K6: =$L6&X$1&$M6 -> MarchDecemberAFG Suzho - DCL KY | L6: March | M6: AFG Suzho - DCL KY | N6: =SUMIF(Data!$A:$A,Summary!A6,Data!$M:$M) -> 0 | O6: =SUMIF(Data!$A:$A,Summary!B6,Data!$M:$M) -> 0 | P6: =SUMIF(Data!$A:$A,Summary!C6,Data!$M:$M) -> 0 | Q6: =SUMIF(Data!$A:$A,Summary!D6,Data!$M:$M) -> 0 | R6: =SUMIF(Data!$A:$A,Summary!E6,Data!$M:$M) -> 0 | S6: =SUMIF(Data!$A:$A,Summary!F6,Data!$M:$M) -> 0 | T6: =SUMIF(Data!$A:$A,Summary!G6,Data!$M:$M) -> 0 | U6: =SUMIF(Data!$A:$A,Summary!H6,Data!$M:$M) -> 0 | ... X6: =SUMIF(Data!$A:$A,Summary!K6,Data!$M:$M) -> 0 | AB6: 515000 | AC6: E | AD6: Freight Inbound | AE6: 403113.61 | AF6: 986440.3 | AG6: 534470.8 | AH6: 855083.11
A7: =$L7&N$1&$M7 -> MarchFebruaryAFG Suzho - DECI NC | B7: =$L7&O$1&$M7 -> MarchMarchAFG Suzho - DECI NC | C7: =$L7&P$1&$M7 -> MarchAprilAFG Suzho - DECI NC | D7: =$L7&Q$1&$M7 -> MarchMayAFG Suzho - DECI NC | E7: =$L7&R$1&$M7 -> MarchJuneAFG Suzho - DECI NC | F7: =$L7&S$1&$M7 -> MarchJulyAFG Suzho - DECI NC | G7: =$L7&T$1&$M7 -> MarchAugustAFG Suzho - DECI NC | H7: =$L7&U$1&$M7 -> MarchSeptemberAFG Suzho - DECI NC | ... K7: =$L7&X$1&$M7 -> MarchDecemberAFG Suzho - DECI NC | L7: March | M7: AFG Suzho - DECI NC | N7: =SUMIF(Data!$A:$A,Summary!A7,Data!$M:$M) -> 0 | O7: =SUMIF(Data!$A:$A,Summary!B7,Data!$M:$M) -> 0 | P7: =SUMIF(Data!$A:$A,Summary!C7,Data!$M:$M) -> 0 | Q7: =SUMIF(Data!$A:$A,Summary!D7,Data!$M:$M) -> 0 | R7: =SUMIF(Data!$A:$A,Summary!E7,Data!$M:$M) -> 0 | S7: =SUMIF(Data!$A:$A,Summary!F7,Data!$M:$M) -> 0 | T7: =SUMIF(Data!$A:$A,Summary!G7,Data!$M:$M) -> 0 | U7: =SUMIF(Data!$A:$A,Summary!H7,Data!$M:$M) -> 0 | ... X7: =SUMIF(Data!$A:$A,Summary!K7,Data!$M:$M) -> 0 | AD7: Total: | AE7: =SUM(AE5:AE6) -> 2824205.9 | AF7: =SUM(AF5:AF6) -> 1736071.5 | AG7: =SUM(AG5:AG6) -> 534470.8 | AH7: =SUM(AH5:AH6) -> 4025806.7
A8: =$L8&N$1&$M8 -> MarchFebruaryAFG Suzho - Flex IL | B8: =$L8&O$1&$M8 -> MarchMarchAFG Suzho - Flex IL | C8: =$L8&P$1&$M8 -> MarchAprilAFG Suzho - Flex IL | D8: =$L8&Q$1&$M8 -> MarchMayAFG Suzho - Flex IL | E8: =$L8&R$1&$M8 -> MarchJuneAFG Suzho - Flex IL | F8: =$L8&S$1&$M8 -> MarchJulyAFG Suzho - Flex IL | G8: =$L8&T$1&$M8 -> MarchAugustAFG Suzho - Flex IL | H8: =$L8&U$1&$M8 -> MarchSeptemberAFG Suzho - Flex IL | ... K8: =$L8&X$1&$M8 -> MarchDecemberAFG Suzho - Flex IL | L8: March | M8: AFG Suzho - Flex IL | N8: =SUMIF(Data!$A:$A,Summary!A8,Data!$M:$M) -> 0 | O8: =SUMIF(Data!$A:$A,Summary!B8,Data!$M:$M) -> 0 | P8: =SUMIF(Data!$A:$A,Summary!C8,Data!$M:$M) -> 0 | Q8: =SUMIF(Data!$A:$A,Summary!D8,Data!$M:$M) -> 0 | R8: =SUMIF(Data!$A:$A,Summary!E8,Data!$M:$M) -> 0 | S8: =SUMIF(Data!$A:$A,Summary!F8,Data!$M:$M) -> 0 | T8: =SUMIF(Data!$A:$A,Summary!G8,Data!$M:$M) -> 0 | U8: =SUMIF(Data!$A:$A,Summary!H8,Data!$M:$M) -> 0 | ... X8: =SUMIF(Data!$A:$A,Summary!K8,Data!$M:$M) -> 0 | AF8: =AF7-AG7 -> 1201600.7
A9: =$L9&N$1&$M9 -> MarchFebruaryChicago IL - Phillips WI | B9: =$L9&O$1&$M9 -> MarchMarchChicago IL - Phillips WI | C9: =$L9&P$1&$M9 -> MarchAprilChicago IL - Phillips WI | D9: =$L9&Q$1&$M9 -> MarchMayChicago IL - Phillips WI | E9: =$L9&R$1&$M9 -> MarchJuneChicago IL - Phillips WI | F9: =$L9&S$1&$M9 -> MarchJulyChicago IL - Phillips WI | G9: =$L9&T$1&$M9 -> MarchAugustChicago IL - Phillips WI | H9: =$L9&U$1&$M9 -> MarchSeptemberChicago IL - Phillips WI | ... K9: =$L9&X$1&$M9 -> MarchDecemberChicago IL - Phillips WI | L9: March | M9: Chicago IL - Phillips WI | N9: =SUMIF(Data!$A:$A,Summary!A9,Data!$M:$M) -> 0 | O9: =SUMIF(Data!$A:$A,Summary!B9,Data!$M:$M) -> 0 | P9: =SUMIF(Data!$A:$A,Summary!C9,Data!$M:$M) -> 0 | Q9: =SUMIF(Data!$A:$A,Summary!D9,Data!$M:$M) -> 0 | R9: =SUMIF(Data!$A:$A,Summary!E9,Data!$M:$M) -> 0 | S9: =SUMIF(Data!$A:$A,Summary!F9,Data!$M:$M) -> 0 | T9: =SUMIF(Data!$A:$A,Summary!G9,Data!$M:$M) -> 0 | U9: =SUMIF(Data!$A:$A,Summary!H9,Data!$M:$M) -> 0 | ... X9: =SUMIF(Data!$A:$A,Summary!K9,Data!$M:$M) -> 0 | AB9: Trial Balance Summary | AE9: Ledger: | AF9: ACTUAL | AG9: Page: | AH9: 1 of 1
A10: =$L10&N$1&$M10 -> MarchFebruaryChina - DCL KY | B10: =$L10&O$1&$M10 -> MarchMarchChina - DCL KY | C10: =$L10&P$1&$M10 -> MarchAprilChina - DCL KY | D10: =$L10&Q$1&$M10 -> MarchMayChina - DCL KY | E10: =$L10&R$1&$M10 -> MarchJuneChina - DCL KY | F10: =$L10&S$1&$M10 -> MarchJulyChina - DCL KY | G10: =$L10&T$1&$M10 -> MarchAugustChina - DCL KY | H10: =$L10&U$1&$M10 -> MarchSeptemberChina - DCL KY | ... K10: =$L10&X$1&$M10 -> MarchDecemberChina - DCL KY | L10: March | M10: China - DCL KY | N10: =SUMIF(Data!$A:$A,Summary!A10,Data!$M:$M) -> 0 | O10: =SUMIF(Data!$A:$A,Summary!B10,Data!$M:$M) -> 62064.18 | P10: =SUMIF(Data!$A:$A,Summary!C10,Data!$M:$M) -> 0 | Q10: =SUMIF(Data!$A:$A,Summary!D10,Data!$M:$M) -> 0 | R10: =SUMIF(Data!$A:$A,Summary!E10,Data!$M:$M) -> 0 | S10: =SUMIF(Data!$A:$A,Summary!F10,Data!$M:$M) -> 0 | T10: =SUMIF(Data!$A:$A,Summary!G10,Data!$M:$M) -> 0 | U10: =SUMIF(Data!$A:$A,Summary!H10,Data!$M:$M) -> 0 | ... X10: =SUMIF(Data!$A:$A,Summary!K10,Data!$M:$M) -> 0 | AB10: Company: | AC10: Juul | AE10: Branch: | AF10: PLOOM | AG10: Date: | AH10: 43322.501
A11: =$L11&N$1&$M11 -> MarchFebruaryChina - DECI NC | B11: =$L11&O$1&$M11 -> MarchMarchChina - DECI NC | C11: =$L11&P$1&$M11 -> MarchAprilChina - DECI NC | D11: =$L11&Q$1&$M11 -> MarchMayChina - DECI NC | E11: =$L11&R$1&$M11 -> MarchJuneChina - DECI NC | F11: =$L11&S$1&$M11 -> MarchJulyChina - DECI NC | G11: =$L11&T$1&$M11 -> MarchAugustChina - DECI NC | H11: =$L11&U$1&$M11 -> MarchSeptemberChina - DECI NC | ... K11: =$L11&X$1&$M11 -> MarchDecemberChina - DECI NC | L11: March | M11: China - DECI NC | N11: =SUMIF(Data!$A:$A,Summary!A11,Data!$M:$M) -> 0 | O11: =SUMIF(Data!$A:$A,Summary!B11,Data!$M:$M) -> 0 | P11: =SUMIF(Data!$A:$A,Summary!C11,Data!$M:$M) -> 0 | Q11: =SUMIF(Data!$A:$A,Summary!D11,Data!$M:$M) -> 0 | R11: =SUMIF(Data!$A:$A,Summary!E11,Data!$M:$M) -> 0 | S11: =SUMIF(Data!$A:$A,Summary!F11,Data!$M:$M) -> 0 | T11: =SUMIF(Data!$A:$A,Summary!G11,Data!$M:$M) -> 0 | U11: =SUMIF(Data!$A:$A,Summary!H11,Data!$M:$M) -> 0 | ... X11: =SUMIF(Data!$A:$A,Summary!K11,Data!$M:$M) -> 0 | AB11: User: | AC11: alejandro | AE11: Fin. Period: | AF11: 06-2018
A12: =$L12&N$1&$M12 -> MarchFebruaryChina - Flex IL | B12: =$L12&O$1&$M12 -> MarchMarchChina - Flex IL | C12: =$L12&P$1&$M12 -> MarchAprilChina - Flex IL | D12: =$L12&Q$1&$M12 -> MarchMayChina - Flex IL | E12: =$L12&R$1&$M12 -> MarchJuneChina - Flex IL | F12: =$L12&S$1&$M12 -> MarchJulyChina - Flex IL | G12: =$L12&T$1&$M12 -> MarchAugustChina - Flex IL | H12: =$L12&U$1&$M12 -> MarchSeptemberChina - Flex IL | ... K12: =$L12&X$1&$M12 -> MarchDecemberChina - Flex IL | L12: March | M12: China - Flex IL | N12: =SUMIF(Data!$A:$A,Summary!A12,Data!$M:$M) -> 0 | O12: =SUMIF(Data!$A:$A,Summary!B12,Data!$M:$M) -> 0 | P12: =SUMIF(Data!$A:$A,Summary!C12,Data!$M:$M) -> 0 | Q12: =SUMIF(Data!$A:$A,Summary!D12,Data!$M:$M) -> 0 | R12: =SUMIF(Data!$A:$A,Summary!E12,Data!$M:$M) -> 0 | S12: =SUMIF(Data!$A:$A,Summary!F12,Data!$M:$M) -> 0 | T12: =SUMIF(Data!$A:$A,Summary!G12,Data!$M:$M) -> 0 | U12: =SUMIF(Data!$A:$A,Summary!H12,Data!$M:$M) -> 0 | ... X12: =SUMIF(Data!$A:$A,Summary!K12,Data!$M:$M) -> 0 | AB12: Account | AC12: Type | AD12: Description | AE12: Beginning Balance | AF12: Debit | AG12: Credit | AH12: Ending Balance
A13: =$L13&N$1&$M13 -> MarchFebruaryChina - Phillips WI | B13: =$L13&O$1&$M13 -> MarchMarchChina - Phillips WI | C13: =$L13&P$1&$M13 -> MarchAprilChina - Phillips WI | D13: =$L13&Q$1&$M13 -> MarchMayChina - Phillips WI | E13: =$L13&R$1&$M13 -> MarchJuneChina - Phillips WI | F13: =$L13&S$1&$M13 -> MarchJulyChina - Phillips WI | G13: =$L13&T$1&$M13 -> MarchAugustChina - Phillips WI | H13: =$L13&U$1&$M13 -> MarchSeptemberChina - Phillips WI | ... K13: =$L13&X$1&$M13 -> MarchDecemberChina - Phillips WI | L13: March | M13: China - Phillips WI | N13: =SUMIF(Data!$A:$A,Summary!A13,Data!$M:$M) -> 0 | O13: =SUMIF(Data!$A:$A,Summary!B13,Data!$M:$M) -> 0 | P13: =SUMIF(Data!$A:$A,Summary!C13,Data!$M:$M) -> 0 | Q13: =SUMIF(Data!$A:$A,Summary!D13,Data!$M:$M) -> 0 | R13: =SUMIF(Data!$A:$A,Summary!E13,Data!$M:$M) -> 0 | S13: =SUMIF(Data!$A:$A,Summary!F13,Data!$M:$M) -> 0 | T13: =SUMIF(Data!$A:$A,Summary!G13,Data!$M:$M) -> 0 | U13: =SUMIF(Data!$A:$A,Summary!H13,Data!$M:$M) -> 0 | ... X13: =SUMIF(Data!$A:$A,Summary!K13,Data!$M:$M) -> 0 | AB13: 513000 | AC13: E | AD13: Cost of Goods - Landed Cost Variance | AE13: 3170723.5 | AF13: 491441.76 | AG13: 0 | AH13: 3662165.3
A14: =$L14&N$1&$M14 -> MarchFebruaryChina - San Francisco | B14: =$L14&O$1&$M14 -> MarchMarchChina - San Francisco | C14: =$L14&P$1&$M14 -> MarchAprilChina - San Francisco | D14: =$L14&Q$1&$M14 -> MarchMayChina - San Francisco | E14: =$L14&R$1&$M14 -> MarchJuneChina - San Francisco | F14: =$L14&S$1&$M14 -> MarchJulyChina - San Francisco | G14: =$L14&T$1&$M14 -> MarchAugustChina - San Francisco | H14: =$L14&U$1&$M14 -> MarchSeptemberChina - San Francisco | ... K14: =$L14&X$1&$M14 -> MarchDecemberChina - San Francisco | L14: March | M14: China - San Francisco | N14: =SUMIF(Data!$A:$A,Summary!A14,Data!$M:$M) -> 0 | O14: =SUMIF(Data!$A:$A,Summary!B14,Data!$M:$M) -> 0 | P14: =SUMIF(Data!$A:$A,Summary!C14,Data!$M:$M) -> 0 | Q14: =SUMIF(Data!$A:$A,Summary!D14,Data!$M:$M) -> 0 | R14: =SUMIF(Data!$A:$A,Summary!E14,Data!$M:$M) -> 0 | S14: =SUMIF(Data!$A:$A,Summary!F14,Data!$M:$M) -> 0 | T14: =SUMIF(Data!$A:$A,Summary!G14,Data!$M:$M) -> 0 | U14: =SUMIF(Data!$A:$A,Summary!H14,Data!$M:$M) -> 0 | ... X14: =SUMIF(Data!$A:$A,Summary!K14,Data!$M:$M) -> 0 | AB14: 515000 | AC14: E | AD14: Freight Inbound | AE14: 855083.11 | AF14: 730453.14 | AG14: 87693.64 | AH14: 1497842.6
A15: =$L15&N$1&$M15 -> MarchFebruaryDCL KY - Canada | B15: =$L15&O$1&$M15 -> MarchMarchDCL KY - Canada | C15: =$L15&P$1&$M15 -> MarchAprilDCL KY - Canada | D15: =$L15&Q$1&$M15 -> MarchMayDCL KY - Canada | E15: =$L15&R$1&$M15 -> MarchJuneDCL KY - Canada | F15: =$L15&S$1&$M15 -> MarchJulyDCL KY - Canada | G15: =$L15&T$1&$M15 -> MarchAugustDCL KY - Canada | H15: =$L15&U$1&$M15 -> MarchSeptemberDCL KY - Canada | ... K15: =$L15&X$1&$M15 -> MarchDecemberDCL KY - Canada | L15: March | M15: DCL KY - Canada | N15: =SUMIF(Data!$A:$A,Summary!A15,Data!$M:$M) -> 0 | O15: =SUMIF(Data!$A:$A,Summary!B15,Data!$M:$M) -> 0 | P15: =SUMIF(Data!$A:$A,Summary!C15,Data!$M:$M) -> 0 | Q15: =SUMIF(Data!$A:$A,Summary!D15,Data!$M:$M) -> 0 | R15: =SUMIF(Data!$A:$A,Summary!E15,Data!$M:$M) -> 0 | S15: =SUMIF(Data!$A:$A,Summary!F15,Data!$M:$M) -> 0 | T15: =SUMIF(Data!$A:$A,Summary!G15,Data!$M:$M) -> 0 | U15: =SUMIF(Data!$A:$A,Summary!H15,Data!$M:$M) -> 0 | ... X15: =SUMIF(Data!$A:$A,Summary!K15,Data!$M:$M) -> 0 | AD15: Total: | AE15: =SUM(AE13:AE14) -> 4025806.7 | AF15: =SUM(AF13:AF14) -> 1221894.9 | AG15: =SUM(AG13:AG14) -> 87693.64 | AH15: =SUM(AH13:AH14) -> 5160007.9
A16: =$L16&N$1&$M16 -> MarchFebruaryDECI NC - DCL KY | B16: =$L16&O$1&$M16 -> MarchMarchDECI NC - DCL KY | C16: =$L16&P$1&$M16 -> MarchAprilDECI NC - DCL KY | D16: =$L16&Q$1&$M16 -> MarchMayDECI NC - DCL KY | E16: =$L16&R$1&$M16 -> MarchJuneDECI NC - DCL KY | F16: =$L16&S$1&$M16 -> MarchJulyDECI NC - DCL KY | G16: =$L16&T$1&$M16 -> MarchAugustDECI NC - DCL KY | H16: =$L16&U$1&$M16 -> MarchSeptemberDECI NC - DCL KY | ... K16: =$L16&X$1&$M16 -> MarchDecemberDECI NC - DCL KY | L16: March | M16: DECI NC - DCL KY | N16: =SUMIF(Data!$A:$A,Summary!A16,Data!$M:$M) -> 0 | O16: =SUMIF(Data!$A:$A,Summary!B16,Data!$M:$M) -> 0 | P16: =SUMIF(Data!$A:$A,Summary!C16,Data!$M:$M) -> 0 | Q16: =SUMIF(Data!$A:$A,Summary!D16,Data!$M:$M) -> 0 | R16: =SUMIF(Data!$A:$A,Summary!E16,Data!$M:$M) -> 0 | S16: =SUMIF(Data!$A:$A,Summary!F16,Data!$M:$M) -> 0 | T16: =SUMIF(Data!$A:$A,Summary!G16,Data!$M:$M) -> 0 | U16: =SUMIF(Data!$A:$A,Summary!H16,Data!$M:$M) -> 0 | ... X16: =SUMIF(Data!$A:$A,Summary!K16,Data!$M:$M) -> 0 | AF16: =AF15-AG15 -> 1134201.3
A17: =$L17&N$1&$M17 -> MarchFebruaryGreensboro NC - Phillips WI | B17: =$L17&O$1&$M17 -> MarchMarchGreensboro NC - Phillips WI | C17: =$L17&P$1&$M17 -> MarchAprilGreensboro NC - Phillips WI | D17: =$L17&Q$1&$M17 -> MarchMayGreensboro NC - Phillips WI | E17: =$L17&R$1&$M17 -> MarchJuneGreensboro NC - Phillips WI | F17: =$L17&S$1&$M17 -> MarchJulyGreensboro NC - Phillips WI | G17: =$L17&T$1&$M17 -> MarchAugustGreensboro NC - Phillips WI | H17: =$L17&U$1&$M17 -> MarchSeptemberGreensboro NC - Phillips WI | ... K17: =$L17&X$1&$M17 -> MarchDecemberGreensboro NC - Phillips WI | L17: March | M17: Greensboro NC - Phillips WI | N17: =SUMIF(Data!$A:$A,Summary!A17,Data!$M:$M) -> 0 | O17: =SUMIF(Data!$A:$A,Summary!B17,Data!$M:$M) -> 3122.8 | P17: =SUMIF(Data!$A:$A,Summary!C17,Data!$M:$M) -> 0 | Q17: =SUMIF(Data!$A:$A,Summary!D17,Data!$M:$M) -> 0 | R17: =SUMIF(Data!$A:$A,Summary!E17,Data!$M:$M) -> 0 | S17: =SUMIF(Data!$A:$A,Summary!F17,Data!$M:$M) -> 0 | T17: =SUMIF(Data!$A:$A,Summary!G17,Data!$M:$M) -> 0 | U17: =SUMIF(Data!$A:$A,Summary!H17,Data!$M:$M) -> 0 | ... X17: =SUMIF(Data!$A:$A,Summary!K17,Data!$M:$M) -> 0 | AB17: Trial Balance Summary | AE17: Ledger: | AF17: ACTUAL | AG17: Page: | AH17: 1 of 1
A18: =$L18&N$1&$M18 -> MarchFebruaryFlex IL - UK | B18: =$L18&O$1&$M18 -> MarchMarchFlex IL - UK | C18: =$L18&P$1&$M18 -> MarchAprilFlex IL - UK | D18: =$L18&Q$1&$M18 -> MarchMayFlex IL - UK | E18: =$L18&R$1&$M18 -> MarchJuneFlex IL - UK | F18: =$L18&S$1&$M18 -> MarchJulyFlex IL - UK | G18: =$L18&T$1&$M18 -> MarchAugustFlex IL - UK | H18: =$L18&U$1&$M18 -> MarchSeptemberFlex IL - UK | ... K18: =$L18&X$1&$M18 -> MarchDecemberFlex IL - UK | L18: March | M18: Flex IL - UK | N18: =SUMIF(Data!$A:$A,Summary!A18,Data!$M:$M) -> 0 | O18: =SUMIF(Data!$A:$A,Summary!B18,Data!$M:$M) -> 0 | P18: =SUMIF(Data!$A:$A,Summary!C18,Data!$M:$M) -> 0 | Q18: =SUMIF(Data!$A:$A,Summary!D18,Data!$M:$M) -> 0 | R18: =SUMIF(Data!$A:$A,Summary!E18,Data!$M:$M) -> 0 | S18: =SUMIF(Data!$A:$A,Summary!F18,Data!$M:$M) -> 0 | T18: =SUMIF(Data!$A:$A,Summary!G18,Data!$M:$M) -> 0 | U18: =SUMIF(Data!$A:$A,Summary!H18,Data!$M:$M) -> 0 | ... X18: =SUMIF(Data!$A:$A,Summary!K18,Data!$M:$M) -> 0 | AB18: Company: | AC18: Juul | AE18: Branch: | AF18: PLOOM | AG18: Date: | AH18: 43322.44
A19: =$L19&N$1&$M19 -> MarchFebruaryFlorida - Phillips WI | B19: =$L19&O$1&$M19 -> MarchMarchFlorida - Phillips WI | C19: =$L19&P$1&$M19 -> MarchAprilFlorida - Phillips WI | D19: =$L19&Q$1&$M19 -> MarchMayFlorida - Phillips WI | E19: =$L19&R$1&$M19 -> MarchJuneFlorida - Phillips WI | F19: =$L19&S$1&$M19 -> MarchJulyFlorida - Phillips WI | G19: =$L19&T$1&$M19 -> MarchAugustFlorida - Phillips WI | H19: =$L19&U$1&$M19 -> MarchSeptemberFlorida - Phillips WI | ... K19: =$L19&X$1&$M19 -> MarchDecemberFlorida - Phillips WI | L19: March | M19: Florida - Phillips WI | N19: =SUMIF(Data!$A:$A,Summary!A19,Data!$M:$M) -> 0 | O19: =SUMIF(Data!$A:$A,Summary!B19,Data!$M:$M) -> 0 | P19: =SUMIF(Data!$A:$A,Summary!C19,Data!$M:$M) -> 0 | Q19: =SUMIF(Data!$A:$A,Summary!D19,Data!$M:$M) -> 0 | R19: =SUMIF(Data!$A:$A,Summary!E19,Data!$M:$M) -> 0 | S19: =SUMIF(Data!$A:$A,Summary!F19,Data!$M:$M) -> 0 | T19: =SUMIF(Data!$A:$A,Summary!G19,Data!$M:$M) -> 0 | U19: =SUMIF(Data!$A:$A,Summary!H19,Data!$M:$M) -> 0 | ... X19: =SUMIF(Data!$A:$A,Summary!K19,Data!$M:$M) -> 0 | AB19: User: | AC19: alejandro | AE19: Fin. Period: | AF19: 07-2018
A20: =$L20&N$1&$M20 -> MarchFebruaryHong Kong - AFG NC | B20: =$L20&O$1&$M20 -> MarchMarchHong Kong - AFG NC | C20: =$L20&P$1&$M20 -> MarchAprilHong Kong - AFG NC | D20: =$L20&Q$1&$M20 -> MarchMayHong Kong - AFG NC | E20: =$L20&R$1&$M20 -> MarchJuneHong Kong - AFG NC | F20: =$L20&S$1&$M20 -> MarchJulyHong Kong - AFG NC | G20: =$L20&T$1&$M20 -> MarchAugustHong Kong - AFG NC | H20: =$L20&U$1&$M20 -> MarchSeptemberHong Kong - AFG NC | ... K20: =$L20&X$1&$M20 -> MarchDecemberHong Kong - AFG NC | L20: March | M20: Hong Kong - AFG NC | N20: =SUMIF(Data!$A:$A,Summary!A20,Data!$M:$M) -> 72 | O20: =SUMIF(Data!$A:$A,Summary!B20,Data!$M:$M) -> 0 | P20: =SUMIF(Data!$A:$A,Summary!C20,Data!$M:$M) -> 4398.85 | Q20: =SUMIF(Data!$A:$A,Summary!D20,Data!$M:$M) -> 0 | R20: =SUMIF(Data!$A:$A,Summary!E20,Data!$M:$M) -> 0 | S20: =SUMIF(Data!$A:$A,Summary!F20,Data!$M:$M) -> 0 | T20: =SUMIF(Data!$A:$A,Summary!G20,Data!$M:$M) -> 0 | U20: =SUMIF(Data!$A:$A,Summary!H20,Data!$M:$M) -> 0 | ... X20: =SUMIF(Data!$A:$A,Summary!K20,Data!$M:$M) -> 0 | AB20: Account | AC20: Type | AD20: Description | AE20: Beginning Balance | AF20: Debit | AG20: Credit | AH20: Ending Balance
A21: =$L21&N$1&$M21 -> MarchFebruaryHong Kong - DCL KY | B21: =$L21&O$1&$M21 -> MarchMarchHong Kong - DCL KY | C21: =$L21&P$1&$M21 -> MarchAprilHong Kong - DCL KY | D21: =$L21&Q$1&$M21 -> MarchMayHong Kong - DCL KY | E21: =$L21&R$1&$M21 -> MarchJuneHong Kong - DCL KY | F21: =$L21&S$1&$M21 -> MarchJulyHong Kong - DCL KY | G21: =$L21&T$1&$M21 -> MarchAugustHong Kong - DCL KY | H21: =$L21&U$1&$M21 -> MarchSeptemberHong Kong - DCL KY | ... K21: =$L21&X$1&$M21 -> MarchDecemberHong Kong - DCL KY | L21: March | M21: Hong Kong - DCL KY | N21: =SUMIF(Data!$A:$A,Summary!A21,Data!$M:$M) -> 0 | O21: =SUMIF(Data!$A:$A,Summary!B21,Data!$M:$M) -> 55750.41 | P21: =SUMIF(Data!$A:$A,Summary!C21,Data!$M:$M) -> 0 | Q21: =SUMIF(Data!$A:$A,Summary!D21,Data!$M:$M) -> 0 | R21: =SUMIF(Data!$A:$A,Summary!E21,Data!$M:$M) -> 0 | S21: =SUMIF(Data!$A:$A,Summary!F21,Data!$M:$M) -> 0 | T21: =SUMIF(Data!$A:$A,Summary!G21,Data!$M:$M) -> 0 | U21: =SUMIF(Data!$A:$A,Summary!H21,Data!$M:$M) -> 0 | ... X21: =SUMIF(Data!$A:$A,Summary!K21,Data!$M:$M) -> 0 | AB21: 513000 | AC21: E | AD21: Cost of Goods - Landed Cost Variance | AE21: 3662165.3 | AF21: 100021.68 | AG21: 100021.68 | AH21: 3662165.3
A22: =$L22&N$1&$M22 -> MarchFebruaryHong Kong - DECI NC | B22: =$L22&O$1&$M22 -> MarchMarchHong Kong - DECI NC | C22: =$L22&P$1&$M22 -> MarchAprilHong Kong - DECI NC | D22: =$L22&Q$1&$M22 -> MarchMayHong Kong - DECI NC | E22: =$L22&R$1&$M22 -> MarchJuneHong Kong - DECI NC | F22: =$L22&S$1&$M22 -> MarchJulyHong Kong - DECI NC | G22: =$L22&T$1&$M22 -> MarchAugustHong Kong - DECI NC | H22: =$L22&U$1&$M22 -> MarchSeptemberHong Kong - DECI NC | ... K22: =$L22&X$1&$M22 -> MarchDecemberHong Kong - DECI NC | L22: March | M22: Hong Kong - DECI NC | N22: =SUMIF(Data!$A:$A,Summary!A22,Data!$M:$M) -> 0 | O22: =SUMIF(Data!$A:$A,Summary!B22,Data!$M:$M) -> 58913.29 | P22: =SUMIF(Data!$A:$A,Summary!C22,Data!$M:$M) -> 0 | Q22: =SUMIF(Data!$A:$A,Summary!D22,Data!$M:$M) -> 0 | R22: =SUMIF(Data!$A:$A,Summary!E22,Data!$M:$M) -> 0 | S22: =SUMIF(Data!$A:$A,Summary!F22,Data!$M:$M) -> 0 | T22: =SUMIF(Data!$A:$A,Summary!G22,Data!$M:$M) -> 0 | U22: =SUMIF(Data!$A:$A,Summary!H22,Data!$M:$M) -> 0 | ... X22: =SUMIF(Data!$A:$A,Summary!K22,Data!$M:$M) -> 0 | AB22: 515000 | AC22: E | AD22: Freight Inbound | AE22: 1497842.6 | AF22: 1388272.6 | AG22: 197141.27 | AH22: 2688974
A23: =$L23&N$1&$M23 -> MarchFebruaryHong Kong - Flex IL | B23: =$L23&O$1&$M23 -> MarchMarchHong Kong - Flex IL | C23: =$L23&P$1&$M23 -> MarchAprilHong Kong - Flex IL | D23: =$L23&Q$1&$M23 -> MarchMayHong Kong - Flex IL | E23: =$L23&R$1&$M23 -> MarchJuneHong Kong - Flex IL | F23: =$L23&S$1&$M23 -> MarchJulyHong Kong - Flex IL | G23: =$L23&T$1&$M23 -> MarchAugustHong Kong - Flex IL | H23: =$L23&U$1&$M23 -> MarchSeptemberHong Kong - Flex IL | ... K23: =$L23&X$1&$M23 -> MarchDecemberHong Kong - Flex IL | L23: March | M23: Hong Kong - Flex IL | N23: =SUMIF(Data!$A:$A,Summary!A23,Data!$M:$M) -> 0 | O23: =SUMIF(Data!$A:$A,Summary!B23,Data!$M:$M) -> 0 | P23: =SUMIF(Data!$A:$A,Summary!C23,Data!$M:$M) -> 0 | Q23: =SUMIF(Data!$A:$A,Summary!D23,Data!$M:$M) -> 0 | R23: =SUMIF(Data!$A:$A,Summary!E23,Data!$M:$M) -> 0 | S23: =SUMIF(Data!$A:$A,Summary!F23,Data!$M:$M) -> 0 | T23: =SUMIF(Data!$A:$A,Summary!G23,Data!$M:$M) -> 0 | U23: =SUMIF(Data!$A:$A,Summary!H23,Data!$M:$M) -> 0 | ... X23: =SUMIF(Data!$A:$A,Summary!K23,Data!$M:$M) -> 0 | AD23: Total: | AE23: =SUM(AE21:AE22) -> 5160007.9 | AF23: =SUM(AF21:AF22) -> 1488294.3 | AG23: =SUM(AG21:AG22) -> 297162.95 | AH23: =SUM(AH21:AH22) -> 6351139.3
A24: =$L24&N$1&$M24 -> MarchFebruaryHong Kong - Phillips WI | B24: =$L24&O$1&$M24 -> MarchMarchHong Kong - Phillips WI | C24: =$L24&P$1&$M24 -> MarchAprilHong Kong - Phillips WI | D24: =$L24&Q$1&$M24 -> MarchMayHong Kong - Phillips WI | E24: =$L24&R$1&$M24 -> MarchJuneHong Kong - Phillips WI | F24: =$L24&S$1&$M24 -> MarchJulyHong Kong - Phillips WI | G24: =$L24&T$1&$M24 -> MarchAugustHong Kong - Phillips WI | H24: =$L24&U$1&$M24 -> MarchSeptemberHong Kong - Phillips WI | ... K24: =$L24&X$1&$M24 -> MarchDecemberHong Kong - Phillips WI | L24: March | M24: Hong Kong - Phillips WI | N24: =SUMIF(Data!$A:$A,Summary!A24,Data!$M:$M) -> 0 | O24: =SUMIF(Data!$A:$A,Summary!B24,Data!$M:$M) -> 0 | P24: =SUMIF(Data!$A:$A,Summary!C24,Data!$M:$M) -> 0 | Q24: =SUMIF(Data!$A:$A,Summary!D24,Data!$M:$M) -> 0 | R24: =SUMIF(Data!$A:$A,Summary!E24,Data!$M:$M) -> 0 | S24: =SUMIF(Data!$A:$A,Summary!F24,Data!$M:$M) -> 0 | T24: =SUMIF(Data!$A:$A,Summary!G24,Data!$M:$M) -> 0 | U24: =SUMIF(Data!$A:$A,Summary!H24,Data!$M:$M) -> 0 | ... X24: =SUMIF(Data!$A:$A,Summary!K24,Data!$M:$M) -> 0 | AF24: =AF23-AG23 -> 1191131.4
A25: =$L25&N$1&$M25 -> MarchFebruaryPhillips WI - DCL KY | B25: =$L25&O$1&$M25 -> MarchMarchPhillips WI - DCL KY | C25: =$L25&P$1&$M25 -> MarchAprilPhillips WI - DCL KY | D25: =$L25&Q$1&$M25 -> MarchMayPhillips WI - DCL KY | E25: =$L25&R$1&$M25 -> MarchJunePhillips WI - DCL KY | F25: =$L25&S$1&$M25 -> MarchJulyPhillips WI - DCL KY | G25: =$L25&T$1&$M25 -> MarchAugustPhillips WI - DCL KY | H25: =$L25&U$1&$M25 -> MarchSeptemberPhillips WI - DCL KY | ... K25: =$L25&X$1&$M25 -> MarchDecemberPhillips WI - DCL KY | L25: March | M25: Phillips WI - DCL KY | N25: =SUMIF(Data!$A:$A,Summary!A25,Data!$M:$M) -> 0 | O25: =SUMIF(Data!$A:$A,Summary!B25,Data!$M:$M) -> 0 | P25: =SUMIF(Data!$A:$A,Summary!C25,Data!$M:$M) -> 0 | Q25: =SUMIF(Data!$A:$A,Summary!D25,Data!$M:$M) -> 0 | R25: =SUMIF(Data!$A:$A,Summary!E25,Data!$M:$M) -> 0 | S25: =SUMIF(Data!$A:$A,Summary!F25,Data!$M:$M) -> 0 | T25: =SUMIF(Data!$A:$A,Summary!G25,Data!$M:$M) -> 0 | U25: =SUMIF(Data!$A:$A,Summary!H25,Data!$M:$M) -> 0 | ... X25: =SUMIF(Data!$A:$A,Summary!K25,Data!$M:$M) -> 0 | AB25: Trial Balance Summary | AE25: Ledger: | AF25: ACTUAL | AG25: Page: | AH25: 1 of 1
A26: =$L26&N$1&$M26 -> MarchFebruarySan Francisco - Canada | B26: =$L26&O$1&$M26 -> MarchMarchSan Francisco - Canada | C26: =$L26&P$1&$M26 -> MarchAprilSan Francisco - Canada | D26: =$L26&Q$1&$M26 -> MarchMaySan Francisco - Canada | E26: =$L26&R$1&$M26 -> MarchJuneSan Francisco - Canada | F26: =$L26&S$1&$M26 -> MarchJulySan Francisco - Canada | G26: =$L26&T$1&$M26 -> MarchAugustSan Francisco - Canada | H26: =$L26&U$1&$M26 -> MarchSeptemberSan Francisco - Canada | ... K26: =$L26&X$1&$M26 -> MarchDecemberSan Francisco - Canada | L26: March | M26: San Francisco - Canada | N26: =SUMIF(Data!$A:$A,Summary!A26,Data!$M:$M) -> 0 | O26: =SUMIF(Data!$A:$A,Summary!B26,Data!$M:$M) -> 0 | P26: =SUMIF(Data!$A:$A,Summary!C26,Data!$M:$M) -> 0 | Q26: =SUMIF(Data!$A:$A,Summary!D26,Data!$M:$M) -> 0 | R26: =SUMIF(Data!$A:$A,Summary!E26,Data!$M:$M) -> 0 | S26: =SUMIF(Data!$A:$A,Summary!F26,Data!$M:$M) -> 0 | T26: =SUMIF(Data!$A:$A,Summary!G26,Data!$M:$M) -> 0 | U26: =SUMIF(Data!$A:$A,Summary!H26,Data!$M:$M) -> 0 | ... X26: =SUMIF(Data!$A:$A,Summary!K26,Data!$M:$M) -> 0 | AB26: Company: | AC26: Juul | AE26: Branch: | AF26: PLOOM | AG26: Date: | AH26: 43367.421
A27: =$L27&N$1&$M27 -> MarchFebruaryShanghai - DCL KY | B27: =$L27&O$1&$M27 -> MarchMarchShanghai - DCL KY | C27: =$L27&P$1&$M27 -> MarchAprilShanghai - DCL KY | D27: =$L27&Q$1&$M27 -> MarchMayShanghai - DCL KY | E27: =$L27&R$1&$M27 -> MarchJuneShanghai - DCL KY | F27: =$L27&S$1&$M27 -> MarchJulyShanghai - DCL KY | G27: =$L27&T$1&$M27 -> MarchAugustShanghai - DCL KY | H27: =$L27&U$1&$M27 -> MarchSeptemberShanghai - DCL KY | ... K27: =$L27&X$1&$M27 -> MarchDecemberShanghai - DCL KY | L27: March | M27: Shanghai - DCL KY | N27: =SUMIF(Data!$A:$A,Summary!A27,Data!$M:$M) -> 0 | O27: =SUMIF(Data!$A:$A,Summary!B27,Data!$M:$M) -> 0 | P27: =SUMIF(Data!$A:$A,Summary!C27,Data!$M:$M) -> 0 | Q27: =SUMIF(Data!$A:$A,Summary!D27,Data!$M:$M) -> 0 | R27: =SUMIF(Data!$A:$A,Summary!E27,Data!$M:$M) -> 0 | S27: =SUMIF(Data!$A:$A,Summary!F27,Data!$M:$M) -> 0 | T27: =SUMIF(Data!$A:$A,Summary!G27,Data!$M:$M) -> 0 | U27: =SUMIF(Data!$A:$A,Summary!H27,Data!$M:$M) -> 0 | ... X27: =SUMIF(Data!$A:$A,Summary!K27,Data!$M:$M) -> 0 | AB27: User: | AC27: Barajas, Alejandro | AE27: Fin. Period: | AF27: 08-2018
A28: =$L28&N$1&$M28 -> MarchFebruaryShanghai - DECI NC | B28: =$L28&O$1&$M28 -> MarchMarchShanghai - DECI NC | C28: =$L28&P$1&$M28 -> MarchAprilShanghai - DECI NC | D28: =$L28&Q$1&$M28 -> MarchMayShanghai - DECI NC | E28: =$L28&R$1&$M28 -> MarchJuneShanghai - DECI NC | F28: =$L28&S$1&$M28 -> MarchJulyShanghai - DECI NC | G28: =$L28&T$1&$M28 -> MarchAugustShanghai - DECI NC | H28: =$L28&U$1&$M28 -> MarchSeptemberShanghai - DECI NC | ... K28: =$L28&X$1&$M28 -> MarchDecemberShanghai - DECI NC | L28: March | M28: Shanghai - DECI NC | N28: =SUMIF(Data!$A:$A,Summary!A28,Data!$M:$M) -> 0 | O28: =SUMIF(Data!$A:$A,Summary!B28,Data!$M:$M) -> 0 | P28: =SUMIF(Data!$A:$A,Summary!C28,Data!$M:$M) -> 0 | Q28: =SUMIF(Data!$A:$A,Summary!D28,Data!$M:$M) -> 0 | R28: =SUMIF(Data!$A:$A,Summary!E28,Data!$M:$M) -> 0 | S28: =SUMIF(Data!$A:$A,Summary!F28,Data!$M:$M) -> 0 | T28: =SUMIF(Data!$A:$A,Summary!G28,Data!$M:$M) -> 0 | U28: =SUMIF(Data!$A:$A,Summary!H28,Data!$M:$M) -> 0 | ... X28: =SUMIF(Data!$A:$A,Summary!K28,Data!$M:$M) -> 0
A29: =$L29&N$1&$M29 -> MarchFebruaryTaiwan - DCL KY | B29: =$L29&O$1&$M29 -> MarchMarchTaiwan - DCL KY | C29: =$L29&P$1&$M29 -> MarchAprilTaiwan - DCL KY | D29: =$L29&Q$1&$M29 -> MarchMayTaiwan - DCL KY | E29: =$L29&R$1&$M29 -> MarchJuneTaiwan - DCL KY | F29: =$L29&S$1&$M29 -> MarchJulyTaiwan - DCL KY | G29: =$L29&T$1&$M29 -> MarchAugustTaiwan - DCL KY | H29: =$L29&U$1&$M29 -> MarchSeptemberTaiwan - DCL KY | ... K29: =$L29&X$1&$M29 -> MarchDecemberTaiwan - DCL KY | L29: March | M29: Taiwan - DCL KY | N29: =SUMIF(Data!$A:$A,Summary!A29,Data!$M:$M) -> 0 | O29: =SUMIF(Data!$A:$A,Summary!B29,Data!$M:$M) -> 0 | P29: =SUMIF(Data!$A:$A,Summary!C29,Data!$M:$M) -> 0 | Q29: =SUMIF(Data!$A:$A,Summary!D29,Data!$M:$M) -> 0 | R29: =SUMIF(Data!$A:$A,Summary!E29,Data!$M:$M) -> 0 | S29: =SUMIF(Data!$A:$A,Summary!F29,Data!$M:$M) -> 0 | T29: =SUMIF(Data!$A:$A,Summary!G29,Data!$M:$M) -> 0 | U29: =SUMIF(Data!$A:$A,Summary!H29,Data!$M:$M) -> 0 | ... X29: =SUMIF(Data!$A:$A,Summary!K29,Data!$M:$M) -> 0 | AB29: Account | AC29: Type | AD29: Description | AE29: Beginning Balance | AF29: Debit | AG29: Credit | AH29: Ending Balance
A30: =$L30&N$1&$M30 -> AprilFebruaryAFG NC - DCL KY | B30: =$L30&O$1&$M30 -> AprilMarchAFG NC - DCL KY | C30: =$L30&P$1&$M30 -> AprilAprilAFG NC - DCL KY | D30: =$L30&Q$1&$M30 -> AprilMayAFG NC - DCL KY | E30: =$L30&R$1&$M30 -> AprilJuneAFG NC - DCL KY | F30: =$L30&S$1&$M30 -> AprilJulyAFG NC - DCL KY | G30: =$L30&T$1&$M30 -> AprilAugustAFG NC - DCL KY | H30: =$L30&U$1&$M30 -> AprilSeptemberAFG NC - DCL KY | ... K30: =$L30&X$1&$M30 -> AprilDecemberAFG NC - DCL KY | L30: April | M30: AFG NC - DCL KY | N30: =SUMIF(Data!$A:$A,Summary!A30,Data!$M:$M) -> 0 | O30: =SUMIF(Data!$A:$A,Summary!B30,Data!$M:$M) -> 0 | P30: =SUMIF(Data!$A:$A,Summary!C30,Data!$M:$M) -> 33300 | Q30: =SUMIF(Data!$A:$A,Summary!D30,Data!$M:$M) -> 0 | R30: =SUMIF(Data!$A:$A,Summary!E30,Data!$M:$M) -> 0 | S30: =SUMIF(Data!$A:$A,Summary!F30,Data!$M:$M) -> 0 | T30: =SUMIF(Data!$A:$A,Summary!G30,Data!$M:$M) -> 0 | U30: =SUMIF(Data!$A:$A,Summary!H30,Data!$M:$M) -> 0 | ... X30: =SUMIF(Data!$A:$A,Summary!K30,Data!$M:$M) -> 0 | AB30: 513000 | AC30: E | AD30: Cost of Goods - Landed Cost Variance | AE30: 3662165.3 | AF30: 0 | AG30: 0 | AH30: 3662165.3
A31: =$L31&N$1&$M31 -> AprilFebruaryAFG NC - Canada | B31: =$L31&O$1&$M31 -> AprilMarchAFG NC - Canada | C31: =$L31&P$1&$M31 -> AprilAprilAFG NC - Canada | D31: =$L31&Q$1&$M31 -> AprilMayAFG NC - Canada | E31: =$L31&R$1&$M31 -> AprilJuneAFG NC - Canada | F31: =$L31&S$1&$M31 -> AprilJulyAFG NC - Canada | G31: =$L31&T$1&$M31 -> AprilAugustAFG NC - Canada | H31: =$L31&U$1&$M31 -> AprilSeptemberAFG NC - Canada | ... K31: =$L31&X$1&$M31 -> AprilDecemberAFG NC - Canada | L31: April | M31: AFG NC - Canada | N31: =SUMIF(Data!$A:$A,Summary!A31,Data!$M:$M) -> 0 | O31: =SUMIF(Data!$A:$A,Summary!B31,Data!$M:$M) -> 0 | P31: =SUMIF(Data!$A:$A,Summary!C31,Data!$M:$M) -> 0 | Q31: =SUMIF(Data!$A:$A,Summary!D31,Data!$M:$M) -> 0 | R31: =SUMIF(Data!$A:$A,Summary!E31,Data!$M:$M) -> 0 | S31: =SUMIF(Data!$A:$A,Summary!F31,Data!$M:$M) -> 0 | T31: =SUMIF(Data!$A:$A,Summary!G31,Data!$M:$M) -> 0 | U31: =SUMIF(Data!$A:$A,Summary!H31,Data!$M:$M) -> 0 | ... X31: =SUMIF(Data!$A:$A,Summary!K31,Data!$M:$M) -> 0 | AB31: 515000 | AC31: E | AD31: Freight Inbound | AE31: 2688974 | AF31: 1105646 | AG31: 0 | AH31: 3794620
A32: =$L32&N$1&$M32 -> AprilFebruaryAFG NC - Phillips WI | B32: =$L32&O$1&$M32 -> AprilMarchAFG NC - Phillips WI | C32: =$L32&P$1&$M32 -> AprilAprilAFG NC - Phillips WI | D32: =$L32&Q$1&$M32 -> AprilMayAFG NC - Phillips WI | E32: =$L32&R$1&$M32 -> AprilJuneAFG NC - Phillips WI | F32: =$L32&S$1&$M32 -> AprilJulyAFG NC - Phillips WI | G32: =$L32&T$1&$M32 -> AprilAugustAFG NC - Phillips WI | H32: =$L32&U$1&$M32 -> AprilSeptemberAFG NC - Phillips WI | ... K32: =$L32&X$1&$M32 -> AprilDecemberAFG NC - Phillips WI | L32: April | M32: AFG NC - Phillips WI | N32: =SUMIF(Data!$A:$A,Summary!A32,Data!$M:$M) -> 0 | O32: =SUMIF(Data!$A:$A,Summary!B32,Data!$M:$M) -> 0 | P32: =SUMIF(Data!$A:$A,Summary!C32,Data!$M:$M) -> 0 | Q32: =SUMIF(Data!$A:$A,Summary!D32,Data!$M:$M) -> 0 | R32: =SUMIF(Data!$A:$A,Summary!E32,Data!$M:$M) -> 0 | S32: =SUMIF(Data!$A:$A,Summary!F32,Data!$M:$M) -> 0 | T32: =SUMIF(Data!$A:$A,Summary!G32,Data!$M:$M) -> 0 | U32: =SUMIF(Data!$A:$A,Summary!H32,Data!$M:$M) -> 0 | ... X32: =SUMIF(Data!$A:$A,Summary!K32,Data!$M:$M) -> 0 | AD32: Total: | AE32: =SUM(AE30:AE31) -> 6351139.3 | AF32: =SUM(AF30:AF31) -> 1105646 | AG32: =SUM(AG30:AG31) -> 0 | AH32: =SUM(AH30:AH31) -> 7456785.3
A33: =$L33&N$1&$M33 -> AprilFebruaryAFG Suzho - DCL KY | B33: =$L33&O$1&$M33 -> AprilMarchAFG Suzho - DCL KY | C33: =$L33&P$1&$M33 -> AprilAprilAFG Suzho - DCL KY | D33: =$L33&Q$1&$M33 -> AprilMayAFG Suzho - DCL KY | E33: =$L33&R$1&$M33 -> AprilJuneAFG Suzho - DCL KY | F33: =$L33&S$1&$M33 -> AprilJulyAFG Suzho - DCL KY | G33: =$L33&T$1&$M33 -> AprilAugustAFG Suzho - DCL KY | H33: =$L33&U$1&$M33 -> AprilSeptemberAFG Suzho - DCL KY | ... K33: =$L33&X$1&$M33 -> AprilDecemberAFG Suzho - DCL KY | L33: April | M33: AFG Suzho - DCL KY | N33: =SUMIF(Data!$A:$A,Summary!A33,Data!$M:$M) -> 0 | O33: =SUMIF(Data!$A:$A,Summary!B33,Data!$M:$M) -> 0 | P33: =SUMIF(Data!$A:$A,Summary!C33,Data!$M:$M) -> 0 | Q33: =SUMIF(Data!$A:$A,Summary!D33,Data!$M:$M) -> 0 | R33: =SUMIF(Data!$A:$A,Summary!E33,Data!$M:$M) -> 0 | S33: =SUMIF(Data!$A:$A,Summary!F33,Data!$M:$M) -> 0 | T33: =SUMIF(Data!$A:$A,Summary!G33,Data!$M:$M) -> 0 | U33: =SUMIF(Data!$A:$A,Summary!H33,Data!$M:$M) -> 0 | ... X33: =SUMIF(Data!$A:$A,Summary!K33,Data!$M:$M) -> 0 | AF33: =AF32-AG32 -> 1105646
A34: =$L34&N$1&$M34 -> AprilFebruaryAFG Suzho - DECI NC | B34: =$L34&O$1&$M34 -> AprilMarchAFG Suzho - DECI NC | C34: =$L34&P$1&$M34 -> AprilAprilAFG Suzho - DECI NC | D34: =$L34&Q$1&$M34 -> AprilMayAFG Suzho - DECI NC | E34: =$L34&R$1&$M34 -> AprilJuneAFG Suzho - DECI NC | F34: =$L34&S$1&$M34 -> AprilJulyAFG Suzho - DECI NC | G34: =$L34&T$1&$M34 -> AprilAugustAFG Suzho - DECI NC | H34: =$L34&U$1&$M34 -> AprilSeptemberAFG Suzho - DECI NC | ... K34: =$L34&X$1&$M34 -> AprilDecemberAFG Suzho - DECI NC | L34: April | M34: AFG Suzho - DECI NC | N34: =SUMIF(Data!$A:$A,Summary!A34,Data!$M:$M) -> 0 | O34: =SUMIF(Data!$A:$A,Summary!B34,Data!$M:$M) -> 0 | P34: =SUMIF(Data!$A:$A,Summary!C34,Data!$M:$M) -> 0 | Q34: =SUMIF(Data!$A:$A,Summary!D34,Data!$M:$M) -> 0 | R34: =SUMIF(Data!$A:$A,Summary!E34,Data!$M:$M) -> 0 | S34: =SUMIF(Data!$A:$A,Summary!F34,Data!$M:$M) -> 0 | T34: =SUMIF(Data!$A:$A,Summary!G34,Data!$M:$M) -> 0 | U34: =SUMIF(Data!$A:$A,Summary!H34,Data!$M:$M) -> 0 | ... X34: =SUMIF(Data!$A:$A,Summary!K34,Data!$M:$M) -> 0 | AE34: Total May to Aug | AF34: =SUM(AF24,AF16,AF8,AF33) -> 4632579.4
A35: =$L35&N$1&$M35 -> AprilFebruaryAFG Suzho - Flex IL | B35: =$L35&O$1&$M35 -> AprilMarchAFG Suzho - Flex IL | C35: =$L35&P$1&$M35 -> AprilAprilAFG Suzho - Flex IL | D35: =$L35&Q$1&$M35 -> AprilMayAFG Suzho - Flex IL | E35: =$L35&R$1&$M35 -> AprilJuneAFG Suzho - Flex IL | F35: =$L35&S$1&$M35 -> AprilJulyAFG Suzho - Flex IL | G35: =$L35&T$1&$M35 -> AprilAugustAFG Suzho - Flex IL | H35: =$L35&U$1&$M35 -> AprilSeptemberAFG Suzho - Flex IL | ... K35: =$L35&X$1&$M35 -> AprilDecemberAFG Suzho - Flex IL | L35: April | M35: AFG Suzho - Flex IL | N35: =SUMIF(Data!$A:$A,Summary!A35,Data!$M:$M) -> 0 | O35: =SUMIF(Data!$A:$A,Summary!B35,Data!$M:$M) -> 0 | P35: =SUMIF(Data!$A:$A,Summary!C35,Data!$M:$M) -> 0 | Q35: =SUMIF(Data!$A:$A,Summary!D35,Data!$M:$M) -> 0 | R35: =SUMIF(Data!$A:$A,Summary!E35,Data!$M:$M) -> 0 | S35: =SUMIF(Data!$A:$A,Summary!F35,Data!$M:$M) -> 0 | T35: =SUMIF(Data!$A:$A,Summary!G35,Data!$M:$M) -> 0 | U35: =SUMIF(Data!$A:$A,Summary!H35,Data!$M:$M) -> 0 | ... X35: =SUMIF(Data!$A:$A,Summary!K35,Data!$M:$M) -> 0
A36: =$L36&N$1&$M36 -> AprilFebruaryChicago IL - Phillips WI | B36: =$L36&O$1&$M36 -> AprilMarchChicago IL - Phillips WI | C36: =$L36&P$1&$M36 -> AprilAprilChicago IL - Phillips WI | D36: =$L36&Q$1&$M36 -> AprilMayChicago IL - Phillips WI | E36: =$L36&R$1&$M36 -> AprilJuneChicago IL - Phillips WI | F36: =$L36&S$1&$M36 -> AprilJulyChicago IL - Phillips WI | G36: =$L36&T$1&$M36 -> AprilAugustChicago IL - Phillips WI | H36: =$L36&U$1&$M36 -> AprilSeptemberChicago IL - Phillips WI | ... K36: =$L36&X$1&$M36 -> AprilDecemberChicago IL - Phillips WI | L36: April | M36: Chicago IL - Phillips WI | N36: =SUMIF(Data!$A:$A,Summary!A36,Data!$M:$M) -> 0 | O36: =SUMIF(Data!$A:$A,Summary!B36,Data!$M:$M) -> 0 | P36: =SUMIF(Data!$A:$A,Summary!C36,Data!$M:$M) -> 0 | Q36: =SUMIF(Data!$A:$A,Summary!D36,Data!$M:$M) -> 0 | R36: =SUMIF(Data!$A:$A,Summary!E36,Data!$M:$M) -> 0 | S36: =SUMIF(Data!$A:$A,Summary!F36,Data!$M:$M) -> 0 | T36: =SUMIF(Data!$A:$A,Summary!G36,Data!$M:$M) -> 0 | U36: =SUMIF(Data!$A:$A,Summary!H36,Data!$M:$M) -> 0 | ... X36: =SUMIF(Data!$A:$A,Summary!K36,Data!$M:$M) -> 0
A37: =$L37&N$1&$M37 -> AprilFebruaryChina - DCL KY | B37: =$L37&O$1&$M37 -> AprilMarchChina - DCL KY | C37: =$L37&P$1&$M37 -> AprilAprilChina - DCL KY | D37: =$L37&Q$1&$M37 -> AprilMayChina - DCL KY | E37: =$L37&R$1&$M37 -> AprilJuneChina - DCL KY | F37: =$L37&S$1&$M37 -> AprilJulyChina - DCL KY | G37: =$L37&T$1&$M37 -> AprilAugustChina - DCL KY | H37: =$L37&U$1&$M37 -> AprilSeptemberChina - DCL KY | ... K37: =$L37&X$1&$M37 -> AprilDecemberChina - DCL KY | L37: April | M37: China - DCL KY | N37: =SUMIF(Data!$A:$A,Summary!A37,Data!$M:$M) -> 0 | O37: =SUMIF(Data!$A:$A,Summary!B37,Data!$M:$M) -> 0 | P37: =SUMIF(Data!$A:$A,Summary!C37,Data!$M:$M) -> 215526.2 | Q37: =SUMIF(Data!$A:$A,Summary!D37,Data!$M:$M) -> 0 | R37: =SUMIF(Data!$A:$A,Summary!E37,Data!$M:$M) -> 0 | S37: =SUMIF(Data!$A:$A,Summary!F37,Data!$M:$M) -> 0 | T37: =SUMIF(Data!$A:$A,Summary!G37,Data!$M:$M) -> 0 | U37: =SUMIF(Data!$A:$A,Summary!H37,Data!$M:$M) -> 0 | ... X37: =SUMIF(Data!$A:$A,Summary!K37,Data!$M:$M) -> 0
A38: =$L38&N$1&$M38 -> AprilFebruaryChina - DECI NC | B38: =$L38&O$1&$M38 -> AprilMarchChina - DECI NC | C38: =$L38&P$1&$M38 -> AprilAprilChina - DECI NC | D38: =$L38&Q$1&$M38 -> AprilMayChina - DECI NC | E38: =$L38&R$1&$M38 -> AprilJuneChina - DECI NC | F38: =$L38&S$1&$M38 -> AprilJulyChina - DECI NC | G38: =$L38&T$1&$M38 -> AprilAugustChina - DECI NC | H38: =$L38&U$1&$M38 -> AprilSeptemberChina - DECI NC | ... K38: =$L38&X$1&$M38 -> AprilDecemberChina - DECI NC | L38: April | M38: China - DECI NC | N38: =SUMIF(Data!$A:$A,Summary!A38,Data!$M:$M) -> 0 | O38: =SUMIF(Data!$A:$A,Summary!B38,Data!$M:$M) -> 0 | P38: =SUMIF(Data!$A:$A,Summary!C38,Data!$M:$M) -> 301176.02 | Q38: =SUMIF(Data!$A:$A,Summary!D38,Data!$M:$M) -> 0 | R38: =SUMIF(Data!$A:$A,Summary!E38,Data!$M:$M) -> 0 | S38: =SUMIF(Data!$A:$A,Summary!F38,Data!$M:$M) -> 0 | T38: =SUMIF(Data!$A:$A,Summary!G38,Data!$M:$M) -> 0 | U38: =SUMIF(Data!$A:$A,Summary!H38,Data!$M:$M) -> 0 | ... X38: =SUMIF(Data!$A:$A,Summary!K38,Data!$M:$M) -> 0
A39: =$L39&N$1&$M39 -> AprilFebruaryChina - Flex IL | B39: =$L39&O$1&$M39 -> AprilMarchChina - Flex IL | C39: =$L39&P$1&$M39 -> AprilAprilChina - Flex IL | D39: =$L39&Q$1&$M39 -> AprilMayChina - Flex IL | E39: =$L39&R$1&$M39 -> AprilJuneChina - Flex IL | F39: =$L39&S$1&$M39 -> AprilJulyChina - Flex IL | G39: =$L39&T$1&$M39 -> AprilAugustChina - Flex IL | H39: =$L39&U$1&$M39 -> AprilSeptemberChina - Flex IL | ... K39: =$L39&X$1&$M39 -> AprilDecemberChina - Flex IL | L39: April | M39: China - Flex IL | N39: =SUMIF(Data!$A:$A,Summary!A39,Data!$M:$M) -> 0 | O39: =SUMIF(Data!$A:$A,Summary!B39,Data!$M:$M) -> 0 | P39: =SUMIF(Data!$A:$A,Summary!C39,Data!$M:$M) -> 0 | Q39: =SUMIF(Data!$A:$A,Summary!D39,Data!$M:$M) -> 0 | R39: =SUMIF(Data!$A:$A,Summary!E39,Data!$M:$M) -> 0 | S39: =SUMIF(Data!$A:$A,Summary!F39,Data!$M:$M) -> 0 | T39: =SUMIF(Data!$A:$A,Summary!G39,Data!$M:$M) -> 0 | U39: =SUMIF(Data!$A:$A,Summary!H39,Data!$M:$M) -> 0 | ... X39: =SUMIF(Data!$A:$A,Summary!K39,Data!$M:$M) -> 0
A40: =$L40&N$1&$M40 -> AprilFebruaryChina - Phillips WI | B40: =$L40&O$1&$M40 -> AprilMarchChina - Phillips WI | C40: =$L40&P$1&$M40 -> AprilAprilChina - Phillips WI | D40: =$L40&Q$1&$M40 -> AprilMayChina - Phillips WI | E40: =$L40&R$1&$M40 -> AprilJuneChina - Phillips WI | F40: =$L40&S$1&$M40 -> AprilJulyChina - Phillips WI | G40: =$L40&T$1&$M40 -> AprilAugustChina - Phillips WI | H40: =$L40&U$1&$M40 -> AprilSeptemberChina - Phillips WI | ... K40: =$L40&X$1&$M40 -> AprilDecemberChina - Phillips WI | L40: April | M40: China - Phillips WI | N40: =SUMIF(Data!$A:$A,Summary!A40,Data!$M:$M) -> 0 | O40: =SUMIF(Data!$A:$A,Summary!B40,Data!$M:$M) -> 0 | P40: =SUMIF(Data!$A:$A,Summary!C40,Data!$M:$M) -> 0 | Q40: =SUMIF(Data!$A:$A,Summary!D40,Data!$M:$M) -> 0 | R40: =SUMIF(Data!$A:$A,Summary!E40,Data!$M:$M) -> 0 | S40: =SUMIF(Data!$A:$A,Summary!F40,Data!$M:$M) -> 0 | T40: =SUMIF(Data!$A:$A,Summary!G40,Data!$M:$M) -> 0 | U40: =SUMIF(Data!$A:$A,Summary!H40,Data!$M:$M) -> 0 | ... X40: =SUMIF(Data!$A:$A,Summary!K40,Data!$M:$M) -> 0
...

Sheet Data
A1: Code | B1: Type | C1: Module | D1: Batch Number | E1: Tran. Date | F1: Period | G1: Description | H1: Ref. Number | I1: Account | J1: Subaccount | K1: Debit Amount | L1: Credit Amount | M1: Net Activity | N1: Reclass. Batch | O1: Freight Full Comments | P1: Freight Code | Q1: Invoice | R1: Ship Month | S1: Rec Month | T1: Invoiced | U1: Month
A2: =U2&W2&P2 -> MarchMarchGreensboro NC - Phillips WI | B2: Freight Inbound | C2: AP | D2: 3395916 | E2: 43164 | F2: 06-2018 | G2: Shipping and Handling | H2: 1011158 | I2: 515000 | J2: HCORP-CRP-4600-JUL | K2: 1700 | L2: 0 | M2: 1700 | O2: Shipping and Handling | P2: Greensboro NC - Phillips WI | Q2: 0001445 | R2: 43160 | S2: 43160 | T2: 3 | U2: =IF(T2=6,"June",IF(T2=5,"May",IF(T2=4,"April",IF(T2=3,"March",0)))) -> March | V2: =MONTH(S2) -> 3 | W2: =IF(V2=6,"June",IF(V2=5,"May",IF(V2=4,"April",IF(V2=3,"March",IF(V2=7,"July",IF(V2=2,"February",0)))))) -> March
A3: =U3&W3&P3 -> MarchMarchGreensboro NC - Phillips WI | B3: Freight Inbound | C3: AP | D3: 3386028 | E3: 43186 | F3: 06-2018 | G3: Freight Charges | H3: 1010838 | I3: 515000 | J3: HCORP-CRP-4600-JUL | K3: 1422.8 | L3: 0 | M3: 1422.8 | O3: Shipping and Handling | P3: Greensboro NC - Phillips WI | Q3: 0001512 | R3: 43160 | S3: 43160 | T3: 3 | U3: =IF(T3=6,"June",IF(T3=5,"May",IF(T3=4,"April",IF(T3=3,"March",0)))) -> March | V3: =MONTH(S3) -> 3 | W3: =IF(V3=6,"June",IF(V3=5,"May",IF(V3=4,"April",IF(V3=3,"March",IF(V3=7,"July",IF(V3=2,"February",0)))))) -> March
A4: =U4&W4&P4 -> MarchFebruaryHong Kong - AFG NC | B4: Freight Inbound | C4: AP | D4: 3353216 | E4: 43160 | F4: 05-2018 | G4: Freight Inbound | H4: 1006462 | I4: 515000 | J4: HCORP-CRP-4600-JUL | K4: 72 | L4: 0 | M4: 72 | O4: Freight Inbound | P4: Hong Kong - AFG NC | Q4: W2B18DN0100 | R4: 43132 | S4: 43132 | T4: 3 | U4: =IF(T4=6,"June",IF(T4=5,"May",IF(T4=4,"April",IF(T4=3,"March",0)))) -> March | V4: =MONTH(S4) -> 2 | W4: =IF(V4=6,"June",IF(V4=5,"May",IF(V4=4,"April",IF(V4=3,"March",IF(V4=7,"July",IF(V4=2,"February",0)))))) -> February
A5: =U5&W5&P5 -> MarchMarchHong Kong - DCL KY | B5: Freight Inbound | C5: AP | D5: 3346582 | E5: 43161 | F5: 05-2018 | G5: Pallet Charges | H5: 1009610 | I5: 515000 | J5: HCORP-CRP-4600-JUL | K5: 48 | L5: 0 | M5: 48 | O5: Pallet Charges | P5: Hong Kong - DCL KY | Q5: W2C18DN0019 | R5: 43160 | S5: 43160 | T5: 3 | U5: =IF(T5=6,"June",IF(T5=5,"May",IF(T5=4,"April",IF(T5=3,"March",0)))) -> March | V5: =MONTH(S5) -> 3 | W5: =IF(V5=6,"June",IF(V5=5,"May",IF(V5=4,"April",IF(V5=3,"March",IF(V5=7,"July",IF(V5=2,"February",0)))))) -> March
A6: =U6&W6&P6 -> MarchMarchHong Kong - DCL KY | B6: Freight Inbound | C6: AP | D6: 3342417 | E6: 43168 | F6: 05-2018 | G6: Freight Charge | H6: 1009360 | I6: 515000 | J6: HCORP-CRP-4600-JUL | K6: 741.66 | L6: 0 | M6: 741.66 | O6: Freight Charge | P6: Hong Kong - DCL KY | R6: 43160 | S6: 43160 | T6: 3 | U6: =IF(T6=6,"June",IF(T6=5,"May",IF(T6=4,"April",IF(T6=3,"March",0)))) -> March | V6: =MONTH(S6) -> 3 | W6: =IF(V6=6,"June",IF(V6=5,"May",IF(V6=4,"April",IF(V6=3,"March",IF(V6=7,"July",IF(V6=2,"February",0)))))) -> March
A7: =U7&W7&P7 -> MarchMarchHong Kong - DCL KY | B7: Freight Inbound | C7: AP | D7: 3346584 | E7: 43168 | F7: 05-2018 | G7: Pallet Charges | H7: 1009614 | I7: 515000 | J7: HCORP-CRP-4600-JUL | K7: 24 | L7: 0 | M7: 24 | O7: Pallet Charges | P7: Hong Kong - DCL KY | R7: 43160 | S7: 43160 | T7: 3 | U7: =IF(T7=6,"June",IF(T7=5,"May",IF(T7=4,"April",IF(T7=3,"March",0)))) -> March | V7: =MONTH(S7) -> 3 | W7: =IF(V7=6,"June",IF(V7=5,"May",IF(V7=4,"April",IF(V7=3,"March",IF(V7=7,"July",IF(V7=2,"February",0)))))) -> March
A8: =U8&W8&P8 -> MarchMarchAFG NC - DCL KY | B8: Freight Inbound | C8: AP | D8: 3346472 | E8: 43185 | F8: 05-2018 | G8: Freight Inbound-Rec 03/21/18 Morrisville,NC to Louisville,KY | H8: 1009618 | I8: 515000 | J8: NAUSA-CRP-4600-JUL | K8: 1725 | L8: 0 | M8: 1725 | O8: Freight Inbound-Rec 03/21/18 Morrisville,NC to Louisville,KY | P8: AFG NC - DCL KY | R8: 43160 | S8: 43160 | T8: 3 | U8: =IF(T8=6,"June",IF(T8=5,"May",IF(T8=4,"April",IF(T8=3,"March",0)))) -> March | V8: =MONTH(S8) -> 3 | W8: =IF(V8=6,"June",IF(V8=5,"May",IF(V8=4,"April",IF(V8=3,"March",IF(V8=7,"July",IF(V8=2,"February",0)))))) -> March
A9: =U9&W9&P9 -> MarchMarchHong Kong - DECI NC | B9: Freight Inbound | C9: GL | D9: 3274637 | E9: 43189 | F9: 05-2018 | G9: Freight Inbound Delivered 03/29/18 Hong Kong - Durham, NC | H9: 1007676 | I9: 223100 | J9: HCORP-CRP-4600-JUL | K9: 11426.21 | L9: 0 | M9: 11426.21 | O9: Freight Inbound Delivered 03/29/18 Hong Kong - Durham, NC | P9: Hong Kong - DECI NC | Q9: FLEX-232032-1 | R9: 43160 | S9: 43160 | T9: 3 | U9: =IF(T9=6,"June",IF(T9=5,"May",IF(T9=4,"April",IF(T9=3,"March",0)))) -> March | V9: =MONTH(S9) -> 3 | W9: =IF(V9=6,"June",IF(V9=5,"May",IF(V9=4,"April",IF(V9=3,"March",IF(V9=7,"July",IF(V9=2,"February",0)))))) -> March
A10: =U10&W10&P10 -> MarchMarchHong Kong - DECI NC | B10: Freight Inbound | C10: GL | D10: 3274639 | E10: 43189 | F10: 05-2018 | G10: Freight Inbound Delivered 03/29/18 Hong Kong - Durham, NC | H10: 1007677 | I10: 223100 | J10: HCORP-CRP-4600-JUL | K10: 13267.81 | L10: 0 | M10: 13267.81 | O10: Freight Inbound Delivered 03/29/18 Hong Kong - Durham, NC | P10: Hong Kong - DECI NC | R10: 43160 | S10: 43160 | T10: 3 | U10: =IF(T10=6,"June",IF(T10=5,"May",IF(T10=4,"April",IF(T10=3,"March",0)))) -> March | V10: =MONTH(S10) -> 3 | W10: =IF(V10=6,"June",IF(V10=5,"May",IF(V10=4,"April",IF(V10=3,"March",IF(V10=7,"July",IF(V10=2,"February",0)))))) -> March
A11: =U11&W11&P11 -> MarchMarchHong Kong - DECI NC | B11: Freight Inbound | C11: GL | D11: 3274641 | E11: 43189 | F11: 05-2018 | G11: Freight Inbound Delivered 03/30/18 Hong Kong - Durham, NC | H11: 1007678 | I11: 223100 | J11: HCORP-CRP-4600-JUL | K11: 8290.41 | L11: 0 | M11: 8290.41 | O11: Freight Inbound Delivered 03/30/18 Hong Kong - Durham, NC | P11: Hong Kong - DECI NC | R11: 43160 | S11: 43160 | T11: 3 | U11: =IF(T11=6,"June",IF(T11=5,"May",IF(T11=4,"April",IF(T11=3,"March",0)))) -> March | V11: =MONTH(S11) -> 3 | W11: =IF(V11=6,"June",IF(V11=5,"May",IF(V11=4,"April",IF(V11=3,"March",IF(V11=7,"July",IF(V11=2,"February",0)))))) -> March
A12: =U12&W12&P12 -> MarchMarchChina - DCL KY | B12: Freight Inbound | C12: GL | D12: 3274643 | E12: 43189 | F12: 05-2018 | G12: Freight Inbound Delivered 03/28/18 China-Louisville,KY | H12: 1007679 | I12: 223100 | J12: HCORP-CRP-4600-JUL | K12: 30091.58 | L12: 0 | M12: 30091.58 | O12: Freight Inbound Delivered 03/28/18 China-Louisville,KY | P12: China - DCL KY | R12: 43160 | S12: 43160 | T12: 3 | U12: =IF(T12=6,"June",IF(T12=5,"May",IF(T12=4,"April",IF(T12=3,"March",0)))) -> March | V12: =MONTH(S12) -> 3 | W12: =IF(V12=6,"June",IF(V12=5,"May",IF(V12=4,"April",IF(V12=3,"March",IF(V12=7,"July",IF(V12=2,"February",0)))))) -> March
A13: =U13&W13&P13 -> MarchMarchHong Kong - DECI NC | B13: Freight Inbound | C13: GL | D13: 3274645 | E13: 43189 | F13: 05-2018 | G13: Freight Inbound Delivered 03/29/18 Hong Kong - Durham, NC | H13: 1007681 | I13: 223100 | J13: HCORP-CRP-4600-JUL | K13: 9881.8 | L13: 0 | M13: 9881.8 | O13: Freight Inbound Delivered 03/29/18 Hong Kong - Durham, NC | P13: Hong Kong - DECI NC | R13: 43160 | S13: 43160 | T13: 3 | U13: =IF(T13=6,"June",IF(T13=5,"May",IF(T13=4,"April",IF(T13=3,"March",0)))) -> March | V13: =MONTH(S13) -> 3 | W13: =IF(V13=6,"June",IF(V13=5,"May",IF(V13=4,"April",IF(V13=3,"March",IF(V13=7,"July",IF(V13=2,"February",0)))))) -> March
A14: =U14&W14&P14 -> MarchMarchHong Kong - DCL KY | B14: Freight Inbound | C14: GL | D14: 3274662 | E14: 43189 | F14: 05-2018 | G14: Freight Inbound Delivered 03/28/18 Hong Kong-Louisville,KY | H14: 1007695 | I14: 223100 | J14: HCORP-CRP-4600-JUL | K14: 12626.39 | L14: 0 | M14: 12626.39 | O14: Freight Inbound Delivered 03/28/18 Hong Kong-Louisville,KY | P14: Hong Kong - DCL KY | R14: 43160 | S14: 43160 | T14: 3 | U14: =IF(T14=6,"June",IF(T14=5,"May",IF(T14=4,"April",IF(T14=3,"March",0)))) -> March | V14: =MONTH(S14) -> 3 | W14: =IF(V14=6,"June",IF(V14=5,"May",IF(V14=4,"April",IF(V14=3,"March",IF(V14=7,"July",IF(V14=2,"February",0)))))) -> March
A15: =U15&W15&P15 -> MarchMarchHong Kong - DCL KY | B15: Freight Inbound | C15: GL | D15: 3274664 | E15: 43189 | F15: 05-2018 | G15: Freight Inbound Delivered 03/26/18 Hong Kong-Louisville,KY | H15: 1007697 | I15: 223100 | J15: HCORP-CRP-4600-JUL | K15: 20178.6 | L15: 0 | M15: 20178.6 | O15: Freight Inbound Delivered 03/26/18 Hong Kong-Louisville,KY | P15: Hong Kong - DCL KY | R15: 43160 | S15: 43160 | T15: 3 | U15: =IF(T15=6,"June",IF(T15=5,"May",IF(T15=4,"April",IF(T15=3,"March",0)))) -> March | V15: =MONTH(S15) -> 3 | W15: =IF(V15=6,"June",IF(V15=5,"May",IF(V15=4,"April",IF(V15=3,"March",IF(V15=7,"July",IF(V15=2,"February",0)))))) -> March
A16: =U16&W16&P16 -> MarchMarchChina - DCL KY | B16: Freight Inbound | C16: GL | D16: 3274666 | E16: 43189 | F16: 05-2018 | G16: Freight Inbound Delivered 03/26/18 China-Louisville,KY | H16: 1007698 | I16: 223100 | J16: HCORP-CRP-4600-JUL | K16: 566.25 | L16: 0 | M16: 566.25 | O16: Freight Inbound Delivered 03/26/18 China-Louisville,KY | P16: China - DCL KY | R16: 43160 | S16: 43160 | T16: 3 | U16: =IF(T16=6,"June",IF(T16=5,"May",IF(T16=4,"April",IF(T16=3,"March",0)))) -> March | V16: =MONTH(S16) -> 3 | W16: =IF(V16=6,"June",IF(V16=5,"May",IF(V16=4,"April",IF(V16=3,"March",IF(V16=7,"July",IF(V16=2,"February",0)))))) -> March
A17: =U17&W17&P17 -> MarchMarchHong Kong - DCL KY | B17: Freight Inbound | C17: GL | D17: 3274668 | E17: 43189 | F17: 05-2018 | G17: Freight Inbound Delivered 03/28/18 Hong Kong-Louisville,KY | H17: 1007699 | I17: 223100 | J17: HCORP-CRP-4600-JUL | K17: 22131.76 | L17: 0 | M17: 22131.76 | O17: Freight Inbound Delivered 03/28/18 Hong Kong-Louisville,KY | P17: Hong Kong - DCL KY | R17: 43160 | S17: 43160 | T17: 3 | U17: =IF(T17=6,"June",IF(T17=5,"May",IF(T17=4,"April",IF(T17=3,"March",0)))) -> March | V17: =MONTH(S17) -> 3 | W17: =IF(V17=6,"June",IF(V17=5,"May",IF(V17=4,"April",IF(V17=3,"March",IF(V17=7,"July",IF(V17=2,"February",0)))))) -> March
A18: =U18&W18&P18 -> MarchMarchChina - DCL KY | B18: Freight Inbound | C18: GL | D18: 3274670 | E18: 43189 | F18: 05-2018 | G18: Freight Inbound Delivered 03/26/18 China-Louisville,KY | H18: 1007700 | I18: 223100 | J18: HCORP-CRP-4600-JUL | K18: 29986.6 | L18: 0 | M18: 29986.6 | O18: Freight Inbound Delivered 03/26/18 China-Louisville,KY | P18: China - DCL KY | R18: 43160 | S18: 43160 | T18: 3 | U18: =IF(T18=6,"June",IF(T18=5,"May",IF(T18=4,"April",IF(T18=3,"March",0)))) -> March | V18: =MONTH(S18) -> 3 | W18: =IF(V18=6,"June",IF(V18=5,"May",IF(V18=4,"April",IF(V18=3,"March",IF(V18=7,"July",IF(V18=2,"February",0)))))) -> March
A19: =U19&W19&P19 -> MarchMarchChina - DCL KY | B19: Freight Inbound | C19: GL | D19: 3274672 | E19: 43189 | F19: 05-2018 | G19: Freight Inbound Delivered 03/28/18 China-Louisville,KY | H19: 1007701 | I19: 223100 | J19: HCORP-CRP-4600-JUL | K19: 570.3 | L19: 0 | M19: 570.3 | O19: Freight Inbound Delivered 03/28/18 China-Louisville,KY | P19: China - DCL KY | R19: 43160 | S19: 43160 | T19: 3 | U19: =IF(T19=6,"June",IF(T19=5,"May",IF(T19=4,"April",IF(T19=3,"March",0)))) -> March | V19: =MONTH(S19) -> 3 | W19: =IF(V19=6,"June",IF(V19=5,"May",IF(V19=4,"April",IF(V19=3,"March",IF(V19=7,"July",IF(V19=2,"February",0)))))) -> March
A20: =U20&W20&P20 -> MarchMarchHong Kong - DECI NC | B20: Freight Inbound | C20: GL | D20: 3274678 | E20: 43189 | F20: 05-2018 | G20: Freight Inbound Delivered 03/26/18 Hong Kong - Durham, NC | H20: 1007705 | I20: 223100 | J20: HCORP-CRP-4600-JUL | K20: 5275.15 | L20: 0 | M20: 5275.15 | O20: Freight Inbound Delivered 03/26/18 Hong Kong - Durham, NC | P20: Hong Kong - DECI NC | R20: 43160 | S20: 43160 | T20: 3 | U20: =IF(T20=6,"June",IF(T20=5,"May",IF(T20=4,"April",IF(T20=3,"March",0)))) -> March | V20: =MONTH(S20) -> 3 | W20: =IF(V20=6,"June",IF(V20=5,"May",IF(V20=4,"April",IF(V20=3,"March",IF(V20=7,"July",IF(V20=2,"February",0)))))) -> March
A21: =U21&W21&P21 -> MarchMarchHong Kong - DECI NC | B21: Freight Inbound | C21: GL | D21: 3274681 | E21: 43189 | F21: 05-2018 | G21: Freight Inbound Delivered 03/30/18 Hong Kong - Durham, NC | H21: 1007710 | I21: 223100 | J21: HCORP-CRP-4600-JUL | K21: 10771.91 | L21: 0 | M21: 10771.91 | O21: Freight Inbound Delivered 03/30/18 Hong Kong - Durham, NC | P21: Hong Kong - DECI NC | R21: 43160 | S21: 43160 | T21: 3 | U21: =IF(T21=6,"June",IF(T21=5,"May",IF(T21=4,"April",IF(T21=3,"March",0)))) -> March | V21: =MONTH(S21) -> 3 | W21: =IF(V21=6,"June",IF(V21=5,"May",IF(V21=4,"April",IF(V21=3,"March",IF(V21=7,"July",IF(V21=2,"February",0)))))) -> March
A22: =U22&W22&P22 -> MarchMarchChina - DCL KY | B22: Freight Inbound | C22: GL | D22: 3274683 | E22: 43189 | F22: 05-2018 | G22: Freight Inbound Delivered 03/23/18 China-Louisville,KY | H22: 1007711 | I22: 223100 | J22: HCORP-CRP-4600-JUL | K22: 849.45 | L22: 0 | M22: 849.45 | O22: Freight Inbound Delivered 03/23/18 China-Louisville,KY | P22: China - DCL KY | R22: 43160 | S22: 43160 | T22: 3 | U22: =IF(T22=6,"June",IF(T22=5,"May",IF(T22=4,"April",IF(T22=3,"March",0)))) -> March | V22: =MONTH(S22) -> 3 | W22: =IF(V22=6,"June",IF(V22=5,"May",IF(V22=4,"April",IF(V22=3,"March",IF(V22=7,"July",IF(V22=2,"February",0)))))) -> March
A23: =U23&W23&P23 -> AprilAprilHong Kong - DECI NC | B23: Freight Inbound | C23: AP | D23: 3368458 | E23: 43194 | F23: 06-2018 | G23: Pallet Charges | H23: 1010008 | I23: 515000 | J23: HCORP-CRP-4600-JUL | K23: 30 | L23: 0 | M23: 30 | O23: Pallet Charges | P23: Hong Kong - DECI NC | Q23: W2D18DN0011 | R23: 43191 | S23: 43191 | T23: 4 | U23: =IF(T23=6,"June",IF(T23=5,"May",IF(T23=4,"April",IF(T23=3,"March",0)))) -> April | V23: =MONTH(S23) -> 4 | W23: =IF(V23=6,"June",IF(V23=5,"May",IF(V23=4,"April",IF(V23=3,"March",IF(V23=7,"July",IF(V23=2,"February",0)))))) -> April
A24: =U24&W24&P24 -> AprilAprilHong Kong - DCL KY | B24: Freight Inbound | C24: AP | D24: 3358408 | E24: 43196 | F24: 06-2018 | G24: Freight Inbound | H24: 1010011 | I24: 515000 | J24: HCORP-CRP-4600-JUL | K24: 132 | L24: 0 | M24: 132 | O24: Pallet Charges | P24: Hong Kong - DCL KY | Q24: W2D18DN0022 | R24: 43191 | S24: 43191 | T24: 4 | U24: =IF(T24=6,"June",IF(T24=5,"May",IF(T24=4,"April",IF(T24=3,"March",0)))) -> April | V24: =MONTH(S24) -> 4 | W24: =IF(V24=6,"June",IF(V24=5,"May",IF(V24=4,"April",IF(V24=3,"March",IF(V24=7,"July",IF(V24=2,"February",0)))))) -> April
A25: =U25&W25&P25 -> AprilAprilHong Kong - DCL KY | B25: Freight Inbound | C25: AP | D25: 3372874 | E25: 43196 | F25: 06-2018 | G25: Pallet Charges | H25: 1010305 | I25: 515000 | J25: HCORP-CRP-4600-JUL | K25: 48 | L25: 0 | M25: 48 | O25: Pallet Charges | P25: Hong Kong - DCL KY | Q25: A2D18DN0004 | R25: 43191 | S25: 43191 | T25: 4 | U25: =IF(T25=6,"June",IF(T25=5,"May",IF(T25=4,"April",IF(T25=3,"March",0)))) -> April | V25: =MONTH(S25) -> 4 | W25: =IF(V25=6,"June",IF(V25=5,"May",IF(V25=4,"April",IF(V25=3,"March",IF(V25=7,"July",IF(V25=2,"February",0)))))) -> April
A26: =U26&W26&P26 -> AprilAprilAFG NC - DCL KY | B26: Freight Inbound | C26: AP | D26: 3371286 | E26: 43199 | F26: 06-2018 | G26: Freight Inbound-Rec 04/06/18 Morrisville,NC to Louisville,KY | H26: 1008448 | I26: 515000 | J26: NAUSA-CRP-4600-JUL | K26: 1675 | L26: 0 | M26: 1675 | O26: Freight Inbound-Rec 04/06/18 Morrisville,NC to Louisville,KY | P26: AFG NC - DCL KY | Q26: S01178205 | R26: 43191 | S26: 43191 | T26: 4 | U26: =IF(T26=6,"June",IF(T26=5,"May",IF(T26=4,"April",IF(T26=3,"March",0)))) -> April | V26: =MONTH(S26) -> 4 | W26: =IF(V26=6,"June",IF(V26=5,"May",IF(V26=4,"April",IF(V26=3,"March",IF(V26=7,"July",IF(V26=2,"February",0)))))) -> April
A27: =U27&W27&P27 -> AprilAprilDECI NC - DCL KY | B27: Freight Inbound | C27: AP | D27: 3386039 | E27: 43202 | F27: 06-2018 | G27: Freight Inbound - Rec 04/19/18 Durham, NC to Louisville, KY | H27: 1010612 | I27: 515000 | J27: NAUSA-CRP-4600-JUL | K27: 1450 | L27: 0 | M27: 1450 | O27: Freight Inbound - Rec 04/19/18 Durham, NC to Louisville, KY | P27: DECI NC - DCL KY | Q27: S01181251 | R27: 43191 | S27: 43191 | T27: 4 | U27: =IF(T27=6,"June",IF(T27=5,"May",IF(T27=4,"April",IF(T27=3,"March",0)))) -> April | V27: =MONTH(S27) -> 4 | W27: =IF(V27=6,"June",IF(V27=5,"May",IF(V27=4,"April",IF(V27=3,"March",IF(V27=7,"July",IF(V27=2,"February",0)))))) -> April
A28: =U28&W28&P28 -> AprilAprilHong Kong - DECI NC | B28: Freight Inbound | C28: AP | D28: 3368437 | E28: 43204 | F28: 06-2018 | G28: Pallet Charges | H28: 1010274 | I28: 515000 | J28: HCORP-CRP-4600-JUL | K28: 45 | L28: 0 | M28: 45 | O28: Pallet Charges | P28: Hong Kong - DECI NC | Q28: W2D18DN0037 | R28: 43191 | S28: 43191 | T28: 4 | U28: =IF(T28=6,"June",IF(T28=5,"May",IF(T28=4,"April",IF(T28=3,"March",0)))) -> April | V28: =MONTH(S28) -> 4 | W28: =IF(V28=6,"June",IF(V28=5,"May",IF(V28=4,"April",IF(V28=3,"March",IF(V28=7,"July",IF(V28=2,"February",0)))))) -> April
