Workbook

Sheet Spread
A1: Dosage Pharmaceuticals
A2: FY15 Allocations
A3: =CELL("Filename") -> N:\Hazelwood01\Shared Services\Finance\Commercial\PSG_Finance\GRPFINCE\Forecast - FY15\Freight\[Freight Reclass - FY15.xlsx]Spread
A4: =NOW() -> 42276.327
C5: Oct | D5: Nov | E5: Dec | F5: Jan | G5: Feb | H5: Mar | I5: Apr | J5: May | K5: Jun | L5: Jul | M5: Aug | N5: Sep | O5: Total
A6: Modified Sales Dollars
A7: 157001000211.4010 | B7: HB | C7: 35670717 | D7: 27274218 | E7: 32977110 | F7: 16352796 | G7: 33240657 | H7: 42521965 | I7: 30244788 | J7: 47092927 | K7: 40039096 | L7: 39983533 | M7: 38126195 | N7: 30298025 | O7: =SUM(C7:N7) -> 4.1382203e+08
A8: 157001000210.4010 | B8: Oxy | C8: 7621643.4 | D8: 3308516.8 | E8: 5928628.5 | F8: 1212476.7 | G8: 4899436.8 | H8: 4212735.1 | I8: 5567003.1 | J8: 7675156.8 | K8: 6463722.3 | L8: 5898623.2 | M8: 8016856.1 | N8: 7260037.1 | O8: =SUM(C8:N8) -> 68064836
A9: 157001000244.4010 | B9: Oxy APAP | C9: 19121416 | D9: 16113145 | E9: 13411791 | F9: 11724419 | G9: 18099637 | H9: 12909862 | I9: 9290990.7 | J9: 16902889 | K9: 9747493.5 | L9: 8780236.3 | M9: 12040034 | N9: 9487105.6 | O9: =SUM(C9:N9) -> 1.5762902e+08
A10: 157001000222.4010 | B10: Methylphenidate | C10: 9535951.2 | D10: 6155238.8 | E10: 10113896 | F10: 3720419.2 | G10: 8516287.9 | H10: 12187975 | I10: 8556016.9 | J10: 15151613 | K10: 11223948 | L10: 9934298.8 | M10: 10059469 | N10: 8778105.1 | O10: =SUM(C10:N10) -> 1.1393322e+08
A11: 157001000263.4010 | B11: Dextroamphetamine | C11: 1425523.5 | D11: 915588 | E11: 595101.35 | F11: 88271.688 | G11: 628893.13 | H11: 2405639.7 | I11: 700033.23 | J11: 1287902.5 | K11: 2362943.8 | L11: 1061580 | M11: 2640617.3 | N11: 1877223 | O11: =SUM(C11:N11) -> 15989317
A12: 157001000238.4010 | B12: Methylphenidate ER | C12: 34286246 | D12: 22204260 | E12: 19733595 | F12: 10346581 | G12: 13699294 | H12: 19124998 | I12: 13316076 | J12: 22493306 | K12: 16223057 | L12: 11759838 | M12: 18657286 | N12: 15329734 | O12: =SUM(C12:N12) -> 2.1717427e+08
A13: 157001000248.4010 | B13: Oxymorphone IR | C13: 214076.7 | D13: 257702.58 | E13: 442441.01 | F13: 192799.88 | G13: 214006.09 | H13: 169219.79 | I13: 145679.83 | J13: 270047.85 | K13: 278811.18 | L13: 130390.37 | M13: 204352.98 | N13: 164760.61 | O13: =SUM(C13:N13) -> 2684288.9
A14: 157001000229.4010 | B14: Morphine ER | C14: 9800849.7 | D14: 13910648 | E14: 10209906 | F14: 5151083.7 | G14: 9917848.9 | H14: 10538565 | I14: 6856681.6 | J14: 12850673 | K14: 11691409 | L14: 9724833 | M14: 10774067 | N14: 9982130.4 | O14: =SUM(C14:N14) -> 1.214087e+08
A15: 157001000230.4010 | B15: Hydromorphone | C15: 1275488.7 | D15: 812438.41 | E15: 1102035.4 | F15: 218002.52 | G15: 1060287.1 | H15: 1609309.3 | I15: 1012396.3 | J15: 1522762.7 | K15: 1315560.9 | L15: 1201940.5 | M15: 1773659.6 | N15: 922605.85 | O15: =SUM(C15:N15) -> 13826487
A16: 157001000231.4010 | B16: Methadone | C16: 2919527.1 | D16: 664326.9 | E16: 1761710.8 | F16: 1347293.8 | G16: 1135968.4 | H16: 3752755.8 | I16: 1780792 | J16: 3225879.6 | K16: 3213602.1 | L16: 3000633.2 | M16: 2902817.1 | N16: 2283073.4 | O16: =SUM(C16:N16) -> 27988380
A17: 157001000232.4010 | B17: APAP/Codeine | C17: 915527.73 | D17: 459241.38 | E17: 747723.65 | F17: 614707.68 | G17: 49809.604 | H17: 0 | I17: 344614.01 | J17: 1335002.6 | K17: 528012.38 | L17: 573344.56 | M17: 724722.23 | N17: 3191357.4 | O17: =SUM(C17:N17) -> 9484063.2
A18: 157001000234.4010 | B18: Fentanyl Lozenge | C18: 1419678.4 | D18: 866855.42 | E18: 1979555.2 | F18: 628127.92 | G18: 854604.74 | H18: 1311545.3 | I18: 1261304.7 | J18: 1655665.8 | K18: 1425268.9 | L18: 1422092.5 | M18: 1771198.5 | N18: 1942741 | O18: =SUM(C18:N18) -> 16538638
... A33: 157001000221.4010 | B33: AT | C33: 90980.74 | D33: 93069.33 | E33: 1964001.1 | F33: 1589199 | G33: 2066911.5 | H33: 1792502.3 | I33: 1830806.6 | J33: 2271169.8 | K33: 1792529.4 | L33: 1951356.1 | M33: 2319191.9 | N33: 1833699 | O33: =SUM(C33:N33) -> 19595417
C34: =SUM(C7:C33) -> 1.5830737e+08 | D34: =SUM(D7:D33) -> 1.1637831e+08 | E34: =SUM(E7:E33) -> 1.3059981e+08 | F34: =SUM(F7:F33) -> 68678374 | G34: =SUM(G7:G33) -> 1.141009e+08 | H34: =SUM(H7:H33) -> 1.3785672e+08 | I34: =SUM(I7:I33) -> 1.0337446e+08 | J34: =SUM(J7:J33) -> 1.6651313e+08 | ... O34: =SUM(O7:O33) -> 1.4955411e+09
A35: Auto Write/off
A36: 157001000209.4313 | C36: -883.64 | D36: -145944.01 | E36: -3118.35 | F36: 27037.76 | G36: -89613.24 | H36: 35594.07 | I36: -1319.94 | J36: -1836.04 | K36: 42534.94 | L36: -58624.26 | M36: -66330.23 | N36: -81844.45 | O36: =SUM(C36:N36) -> -344347.39
A37: 157001000209.4313.0100 | C37: 3058.15 | D37: 3689.19 | E37: 1862.7 | F37: 41569.65 | G37: 4850.05 | H37: 3423.03 | I37: 1249.54 | J37: 3367.07 | K37: 1825.85 | L37: 4598.88 | M37: 7922.61 | N37: 14316.7 | O37: =SUM(C37:N37) -> 91733.42
A38: Subtotal | C38: =SUM(C36:C37) -> 2174.51 | D38: =SUM(D36:D37) -> -142254.82 | E38: =SUM(E36:E37) -> -1255.65 | F38: =SUM(F36:F37) -> 68607.41 | G38: =SUM(G36:G37) -> -84763.19 | H38: =SUM(H36:H37) -> 39017.1 | I38: =SUM(I36:I37) -> -70.4 | J38: =SUM(J36:J37) -> 1531.03 | ... O38: =SUM(O36:O37) -> -252613.97
A40: 157001000211.4313 | B40: HB | C40: =IFERROR(ROUND(C7/(C$34-C$33-C$26-C$28-C$29-C$31)*(C$38),0),0) -> 524 | D40: =IFERROR(ROUND(D7/(D$34-D$33-D$26-D$28-D$29-D$31)*(D$38),0),0) -> -34950 | E40: =IFERROR(ROUND(E7/(E$34-E$33-E$26-E$28-E$29-E$31)*(E$38),0),0) -> -345 | F40: =IFERROR(ROUND(F7/(F$34-F$33-F$26-F$28-F$29-F$31)*(F$38),0),0) -> 17900 | G40: =IFERROR(ROUND(G7/(G$34-G$33-G$26-G$28-G$29-G$31)*(G$38),0),0) -> -26386 | H40: =IFERROR(ROUND(H7/(H$34-H$33-H$26-H$28-H$29-H$31)*(H$38),0),0) -> 12839 | I40: =IFERROR(ROUND(I7/(I$34-I$33-I$26-I$28-I$29-I$31)*(I$38),0),0) -> -23 | J40: =IFERROR(ROUND(J7/(J$34-J$33-J$26-J$28-J$29-J$31)*(J$38),0),0) -> 463 | ... N40: =IFERROR(ROUND(N7/(N$34-N$33-N$26-N$28-N$29-N$31)*(N$38),0),0) -> -19040 | O40: =SUM(C40:N40) -> -72605
A41: 157001000210.4313 | B41: Oxy | C41: =IFERROR(ROUND(C8/(C$34-C$33-C$26-C$28-C$29-C$31)*(C$38),0),0) -> 112 | D41: =IFERROR(ROUND(D8/(D$34-D$33-D$26-D$28-D$29-D$31)*(D$38),0),0) -> -4240 | E41: =IFERROR(ROUND(E8/(E$34-E$33-E$26-E$28-E$29-E$31)*(E$38),0),0) -> -62 | F41: =IFERROR(ROUND(F8/(F$34-F$33-F$26-F$28-F$29-F$31)*(F$38),0),0) -> 1327 | G41: =IFERROR(ROUND(G8/(G$34-G$33-G$26-G$28-G$29-G$31)*(G$38),0),0) -> -3889 | H41: =IFERROR(ROUND(H8/(H$34-H$33-H$26-H$28-H$29-H$31)*(H$38),0),0) -> 1272 | I41: =IFERROR(ROUND(I8/(I$34-I$33-I$26-I$28-I$29-I$31)*(I$38),0),0) -> -4 | J41: =IFERROR(ROUND(J8/(J$34-J$33-J$26-J$28-J$29-J$31)*(J$38),0),0) -> 76 | ... N41: =IFERROR(ROUND(N8/(N$34-N$33-N$26-N$28-N$29-N$31)*(N$38),0),0) -> -4562 | O41: =SUM(C41:N41) -> -14360
A42: 157001000244.4313 | B42: Oxy APAP | C42: =IFERROR(ROUND(C9/(C$34-C$33-C$26-C$28-C$29-C$31)*(C$38),0),0) -> 281 | D42: =IFERROR(ROUND(D9/(D$34-D$33-D$26-D$28-D$29-D$31)*(D$38),0),0) -> -20648 | E42: =IFERROR(ROUND(E9/(E$34-E$33-E$26-E$28-E$29-E$31)*(E$38),0),0) -> -141 | F42: =IFERROR(ROUND(F9/(F$34-F$33-F$26-F$28-F$29-F$31)*(F$38),0),0) -> 12834 | G42: =IFERROR(ROUND(G9/(G$34-G$33-G$26-G$28-G$29-G$31)*(G$38),0),0) -> -14367 | H42: =IFERROR(ROUND(H9/(H$34-H$33-H$26-H$28-H$29-H$31)*(H$38),0),0) -> 3898 | I42: =IFERROR(ROUND(I9/(I$34-I$33-I$26-I$28-I$29-I$31)*(I$38),0),0) -> -7 | J42: =IFERROR(ROUND(J9/(J$34-J$33-J$26-J$28-J$29-J$31)*(J$38),0),0) -> 166 | ... N42: =IFERROR(ROUND(N9/(N$34-N$33-N$26-N$28-N$29-N$31)*(N$38),0),0) -> -5962 | O42: =SUM(C42:N42) -> -30487
A43: 157001000222.4313 | B43: ADHD | C43: =IFERROR(ROUND(C10/(C$34-C$33-C$26-C$28-C$29-C$31)*(C$38),0),0) -> 140 | D43: =IFERROR(ROUND(D10/(D$34-D$33-D$26-D$28-D$29-D$31)*(D$38),0),0) -> -7888 | E43: =IFERROR(ROUND(E10/(E$34-E$33-E$26-E$28-E$29-E$31)*(E$38),0),0) -> -106 | F43: =IFERROR(ROUND(F10/(F$34-F$33-F$26-F$28-F$29-F$31)*(F$38),0),0) -> 4073 | G43: =IFERROR(ROUND(G10/(G$34-G$33-G$26-G$28-G$29-G$31)*(G$38),0),0) -> -6760 | H43: =IFERROR(ROUND(H10/(H$34-H$33-H$26-H$28-H$29-H$31)*(H$38),0),0) -> 3680 | I43: =IFERROR(ROUND(I10/(I$34-I$33-I$26-I$28-I$29-I$31)*(I$38),0),0) -> -6 | J43: =IFERROR(ROUND(J10/(J$34-J$33-J$26-J$28-J$29-J$31)*(J$38),0),0) -> 149 | ... N43: =IFERROR(ROUND(N10/(N$34-N$33-N$26-N$28-N$29-N$31)*(N$38),0),0) -> -5516 | O43: =SUM(C43:N43) -> -17915
A44: 157001000263.4313 | B44: Dextroamphetamine | C44: =IFERROR(ROUND(C11/(C$34-C$33-C$26-C$28-C$29-C$31)*(C$38),0),0) -> 21 | D44: =IFERROR(ROUND(D11/(D$34-D$33-D$26-D$28-D$29-D$31)*(D$38),0),0) -> -1173 | E44: =IFERROR(ROUND(E11/(E$34-E$33-E$26-E$28-E$29-E$31)*(E$38),0),0) -> -6 | F44: =IFERROR(ROUND(F11/(F$34-F$33-F$26-F$28-F$29-F$31)*(F$38),0),0) -> 97 | G44: =IFERROR(ROUND(G11/(G$34-G$33-G$26-G$28-G$29-G$31)*(G$38),0),0) -> -499 | H44: =IFERROR(ROUND(H11/(H$34-H$33-H$26-H$28-H$29-H$31)*(H$38),0),0) -> 726 | I44: =IFERROR(ROUND(I11/(I$34-I$33-I$26-I$28-I$29-I$31)*(I$38),0),0) -> -1 | J44: =IFERROR(ROUND(J11/(J$34-J$33-J$26-J$28-J$29-J$31)*(J$38),0),0) -> 13 | ... N44: =IFERROR(ROUND(N11/(N$34-N$33-N$26-N$28-N$29-N$31)*(N$38),0),0) -> -1180 | O44: =SUM(C44:N44) -> -2923
A45: 157001000238.4313 | B45: =+B12 -> Methylphenidate ER | C45: =IFERROR(ROUND(C12/(C$34-C$33-C$26-C$28-C$29-C$31)*(C$38),0),0) -> 504 | D45: =IFERROR(ROUND(D12/(D$34-D$33-D$26-D$28-D$29-D$31)*(D$38),0),0) -> -28454 | E45: =IFERROR(ROUND(E12/(E$34-E$33-E$26-E$28-E$29-E$31)*(E$38),0),0) -> -207 | F45: =IFERROR(ROUND(F12/(F$34-F$33-F$26-F$28-F$29-F$31)*(F$38),0),0) -> 11326 | G45: =IFERROR(ROUND(G12/(G$34-G$33-G$26-G$28-G$29-G$31)*(G$38),0),0) -> -10874 | H45: =IFERROR(ROUND(H12/(H$34-H$33-H$26-H$28-H$29-H$31)*(H$38),0),0) -> 5774 | I45: =IFERROR(ROUND(I12/(I$34-I$33-I$26-I$28-I$29-I$31)*(I$38),0),0) -> -10 | J45: =IFERROR(ROUND(J12/(J$34-J$33-J$26-J$28-J$29-J$31)*(J$38),0),0) -> 221 | ... N45: =IFERROR(ROUND(N12/(N$34-N$33-N$26-N$28-N$29-N$31)*(N$38),0),0) -> -9633 | O45: =SUM(C45:N45) -> -40167
A46: 157001000248.4313 | B46: Oxymorphone IR | C46: =IFERROR(ROUND(C13/(C$34-C$33-C$26-C$28-C$29-C$31)*(C$38),0),0) -> 3 | D46: =IFERROR(ROUND(D13/(D$34-D$33-D$26-D$28-D$29-D$31)*(D$38),0),0) -> -330 | E46: =IFERROR(ROUND(E13/(E$34-E$33-E$26-E$28-E$29-E$31)*(E$38),0),0) -> -5 | F46: =IFERROR(ROUND(F13/(F$34-F$33-F$26-F$28-F$29-F$31)*(F$38),0),0) -> 211 | G46: =IFERROR(ROUND(G13/(G$34-G$33-G$26-G$28-G$29-G$31)*(G$38),0),0) -> -170 | H46: =IFERROR(ROUND(H13/(H$34-H$33-H$26-H$28-H$29-H$31)*(H$38),0),0) -> 51 | I46: =IFERROR(ROUND(I13/(I$34-I$33-I$26-I$28-I$29-I$31)*(I$38),0),0) -> 0 | J46: =IFERROR(ROUND(J13/(J$34-J$33-J$26-J$28-J$29-J$31)*(J$38),0),0) -> 3 | ... N46: =IFERROR(ROUND(N13/(N$34-N$33-N$26-N$28-N$29-N$31)*(N$38),0),0) -> -104 | O46: =SUM(C46:N46) -> -403
A47: 157001000229.4313 | B47: Morphine ER | C47: =IFERROR(ROUND(C14/(C$34-C$33-C$26-C$28-C$29-C$31)*(C$38),0),0) -> 144 | D47: =IFERROR(ROUND(D14/(D$34-D$33-D$26-D$28-D$29-D$31)*(D$38),0),0) -> -17826 | E47: =IFERROR(ROUND(E14/(E$34-E$33-E$26-E$28-E$29-E$31)*(E$38),0),0) -> -107 | F47: =IFERROR(ROUND(F14/(F$34-F$33-F$26-F$28-F$29-F$31)*(F$38),0),0) -> 5639 | G47: =IFERROR(ROUND(G14/(G$34-G$33-G$26-G$28-G$29-G$31)*(G$38),0),0) -> -7873 | H47: =IFERROR(ROUND(H14/(H$34-H$33-H$26-H$28-H$29-H$31)*(H$38),0),0) -> 3182 | I47: =IFERROR(ROUND(I14/(I$34-I$33-I$26-I$28-I$29-I$31)*(I$38),0),0) -> -5 | J47: =IFERROR(ROUND(J14/(J$34-J$33-J$26-J$28-J$29-J$31)*(J$38),0),0) -> 126 | ... N47: =IFERROR(ROUND(N14/(N$34-N$33-N$26-N$28-N$29-N$31)*(N$38),0),0) -> -6273 | O47: =SUM(C47:N47) -> -28735
A48: 157001000230.4313 | B48: Hydromorphone | C48: =IFERROR(ROUND(C15/(C$34-C$33-C$26-C$28-C$29-C$31)*(C$38),0),0) -> 19 | D48: =IFERROR(ROUND(D15/(D$34-D$33-D$26-D$28-D$29-D$31)*(D$38),0),0) -> -1041 | E48: =IFERROR(ROUND(E15/(E$34-E$33-E$26-E$28-E$29-E$31)*(E$38),0),0) -> -12 | F48: =IFERROR(ROUND(F15/(F$34-F$33-F$26-F$28-F$29-F$31)*(F$38),0),0) -> 239 | G48: =IFERROR(ROUND(G15/(G$34-G$33-G$26-G$28-G$29-G$31)*(G$38),0),0) -> -842 | H48: =IFERROR(ROUND(H15/(H$34-H$33-H$26-H$28-H$29-H$31)*(H$38),0),0) -> 486 | I48: =IFERROR(ROUND(I15/(I$34-I$33-I$26-I$28-I$29-I$31)*(I$38),0),0) -> -1 | J48: =IFERROR(ROUND(J15/(J$34-J$33-J$26-J$28-J$29-J$31)*(J$38),0),0) -> 15 | ... N48: =IFERROR(ROUND(N15/(N$34-N$33-N$26-N$28-N$29-N$31)*(N$38),0),0) -> -580 | O48: =SUM(C48:N48) -> -2676
A49: 157001000231.4313 | B49: Methadone | C49: =IFERROR(ROUND(C16/(C$34-C$33-C$26-C$28-C$29-C$31)*(C$38),0),0) -> 43 | D49: =IFERROR(ROUND(D16/(D$34-D$33-D$26-D$28-D$29-D$31)*(D$38),0),0) -> -851 | E49: =IFERROR(ROUND(E16/(E$34-E$33-E$26-E$28-E$29-E$31)*(E$38),0),0) -> -18 | F49: =IFERROR(ROUND(F16/(F$34-F$33-F$26-F$28-F$29-F$31)*(F$38),0),0) -> 1475 | G49: =IFERROR(ROUND(G16/(G$34-G$33-G$26-G$28-G$29-G$31)*(G$38),0),0) -> -902 | H49: =IFERROR(ROUND(H16/(H$34-H$33-H$26-H$28-H$29-H$31)*(H$38),0),0) -> 1133 | I49: =IFERROR(ROUND(I16/(I$34-I$33-I$26-I$28-I$29-I$31)*(I$38),0),0) -> -1 | J49: =IFERROR(ROUND(J16/(J$34-J$33-J$26-J$28-J$29-J$31)*(J$38),0),0) -> 32 | ... N49: =IFERROR(ROUND(N16/(N$34-N$33-N$26-N$28-N$29-N$31)*(N$38),0),0) -> -1435 | O49: =SUM(C49:N49) -> -2239
A50: 157001000232.4313 | B50: APAP/Codeine | C50: =IFERROR(ROUND(C17/(C$34-C$33-C$26-C$28-C$29-C$31)*(C$38),0),0) -> 13 | D50: =IFERROR(ROUND(D17/(D$34-D$33-D$26-D$28-D$29-D$31)*(D$38),0),0) -> -588 | E50: =IFERROR(ROUND(E17/(E$34-E$33-E$26-E$28-E$29-E$31)*(E$38),0),0) -> -8 | F50: =IFERROR(ROUND(F17/(F$34-F$33-F$26-F$28-F$29-F$31)*(F$38),0),0) -> 673 | G50: =IFERROR(ROUND(G17/(G$34-G$33-G$26-G$28-G$29-G$31)*(G$38),0),0) -> -40 | H50: =IFERROR(ROUND(H17/(H$34-H$33-H$26-H$28-H$29-H$31)*(H$38),0),0) -> 0 | I50: =IFERROR(ROUND(I17/(I$34-I$33-I$26-I$28-I$29-I$31)*(I$38),0),0) -> 0 | J50: =IFERROR(ROUND(J17/(J$34-J$33-J$26-J$28-J$29-J$31)*(J$38),0),0) -> 13 | ... N50: =IFERROR(ROUND(N17/(N$34-N$33-N$26-N$28-N$29-N$31)*(N$38),0),0) -> -2005 | O50: =SUM(C50:N50) -> -2380
A51: 157001000234.4313 | B51: Fentanyl Lozenge | C51: =IFERROR(ROUND(C18/(C$34-C$33-C$26-C$28-C$29-C$31)*(C$38),0),0) -> 21 | D51: =IFERROR(ROUND(D18/(D$34-D$33-D$26-D$28-D$29-D$31)*(D$38),0),0) -> -1111 | E51: =IFERROR(ROUND(E18/(E$34-E$33-E$26-E$28-E$29-E$31)*(E$38),0),0) -> -21 | F51: =IFERROR(ROUND(F18/(F$34-F$33-F$26-F$28-F$29-F$31)*(F$38),0),0) -> 688 | G51: =IFERROR(ROUND(G18/(G$34-G$33-G$26-G$28-G$29-G$31)*(G$38),0),0) -> -678 | H51: =IFERROR(ROUND(H18/(H$34-H$33-H$26-H$28-H$29-H$31)*(H$38),0),0) -> 396 | I51: =IFERROR(ROUND(I18/(I$34-I$33-I$26-I$28-I$29-I$31)*(I$38),0),0) -> -1 | J51: =IFERROR(ROUND(J18/(J$34-J$33-J$26-J$28-J$29-J$31)*(J$38),0),0) -> 16 | ... N51: =IFERROR(ROUND(N18/(N$34-N$33-N$26-N$28-N$29-N$31)*(N$38),0),0) -> -1221 | O51: =SUM(C51:N51) -> -2942
A52: 157001000236.4313 | B52: Fentanyl Patch | C52: =IFERROR(ROUND(C19/(C$34-C$33-C$26-C$28-C$29-C$31)*(C$38),0),0) -> 121 | D52: =IFERROR(ROUND(D19/(D$34-D$33-D$26-D$28-D$29-D$31)*(D$38),0),0) -> -6321 | E52: =IFERROR(ROUND(E19/(E$34-E$33-E$26-E$28-E$29-E$31)*(E$38),0),0) -> -85 | F52: =IFERROR(ROUND(F19/(F$34-F$33-F$26-F$28-F$29-F$31)*(F$38),0),0) -> 4086 | G52: =IFERROR(ROUND(G19/(G$34-G$33-G$26-G$28-G$29-G$31)*(G$38),0),0) -> -4061 | H52: =IFERROR(ROUND(H19/(H$34-H$33-H$26-H$28-H$29-H$31)*(H$38),0),0) -> 2205 | I52: =IFERROR(ROUND(I19/(I$34-I$33-I$26-I$28-I$29-I$31)*(I$38),0),0) -> -4 | J52: =IFERROR(ROUND(J19/(J$34-J$33-J$26-J$28-J$29-J$31)*(J$38),0),0) -> 88 | ... N52: =IFERROR(ROUND(N19/(N$34-N$33-N$26-N$28-N$29-N$31)*(N$38),0),0) -> -4875 | O52: =SUM(C52:N52) -> -13429
A53: 157001000253.4313 | B53: Temazepam | C53: =IFERROR(ROUND(C20/(C$34-C$33-C$26-C$28-C$29-C$31)*(C$38),0),0) -> 15 | D53: =IFERROR(ROUND(D20/(D$34-D$33-D$26-D$28-D$29-D$31)*(D$38),0),0) -> -1012 | E53: =IFERROR(ROUND(E20/(E$34-E$33-E$26-E$28-E$29-E$31)*(E$38),0),0) -> -10 | F53: =IFERROR(ROUND(F20/(F$34-F$33-F$26-F$28-F$29-F$31)*(F$38),0),0) -> 912 | G53: =IFERROR(ROUND(G20/(G$34-G$33-G$26-G$28-G$29-G$31)*(G$38),0),0) -> -410 | H53: =IFERROR(ROUND(H20/(H$34-H$33-H$26-H$28-H$29-H$31)*(H$38),0),0) -> 295 | I53: =IFERROR(ROUND(I20/(I$34-I$33-I$26-I$28-I$29-I$31)*(I$38),0),0) -> -1 | J53: =IFERROR(ROUND(J20/(J$34-J$33-J$26-J$28-J$29-J$31)*(J$38),0),0) -> 21 | ... N53: =IFERROR(ROUND(N20/(N$34-N$33-N$26-N$28-N$29-N$31)*(N$38),0),0) -> -742 | O53: =SUM(C53:N53) -> -1424
A54: 157001000254.4313 | B54: Imipramine Pamoate | C54: =IFERROR(ROUND(C21/(C$34-C$33-C$26-C$28-C$29-C$31)*(C$38),0),0) -> 5 | D54: =IFERROR(ROUND(D21/(D$34-D$33-D$26-D$28-D$29-D$31)*(D$38),0),0) -> -196 | E54: =IFERROR(ROUND(E21/(E$34-E$33-E$26-E$28-E$29-E$31)*(E$38),0),0) -> -3 | F54: =IFERROR(ROUND(F21/(F$34-F$33-F$26-F$28-F$29-F$31)*(F$38),0),0) -> 53 | G54: =IFERROR(ROUND(G21/(G$34-G$33-G$26-G$28-G$29-G$31)*(G$38),0),0) -> -40 | H54: =IFERROR(ROUND(H21/(H$34-H$33-H$26-H$28-H$29-H$31)*(H$38),0),0) -> 42 | I54: =IFERROR(ROUND(I21/(I$34-I$33-I$26-I$28-I$29-I$31)*(I$38),0),0) -> 0 | J54: =IFERROR(ROUND(J21/(J$34-J$33-J$26-J$28-J$29-J$31)*(J$38),0),0) -> 1 | ... N54: =IFERROR(ROUND(N21/(N$34-N$33-N$26-N$28-N$29-N$31)*(N$38),0),0) -> -12 | O54: =SUM(C54:N54) -> -188
A55: 157001000264.4313 | B55: =+B23 -> Mixed Amphet Salts | C55: =IFERROR(ROUND(C22/(C$34-C$33-C$26-C$28-C$29-C$31)*(C$38),0),0) -> 103 | D55: =IFERROR(ROUND(D22/(D$34-D$33-D$26-D$28-D$29-D$31)*(D$38),0),0) -> -6926 | E55: =IFERROR(ROUND(E22/(E$34-E$33-E$26-E$28-E$29-E$31)*(E$38),0),0) -> -77 | F55: =IFERROR(ROUND(F22/(F$34-F$33-F$26-F$28-F$29-F$31)*(F$38),0),0) -> 4421 | G55: =IFERROR(ROUND(G22/(G$34-G$33-G$26-G$28-G$29-G$31)*(G$38),0),0) -> -4589 | H55: =IFERROR(ROUND(H22/(H$34-H$33-H$26-H$28-H$29-H$31)*(H$38),0),0) -> 2097 | I55: =IFERROR(ROUND(I22/(I$34-I$33-I$26-I$28-I$29-I$31)*(I$38),0),0) -> -4 | J55: =IFERROR(ROUND(J22/(J$34-J$33-J$26-J$28-J$29-J$31)*(J$38),0),0) -> 96 | ... N55: =IFERROR(ROUND(N22/(N$34-N$33-N$26-N$28-N$29-N$31)*(N$38),0),0) -> -2511 | O55: =SUM(C55:N55) -> -8906
...

Sheet JE
A2: Explanation | B2: Sum | C2: JE#
A3: September Dosage Reclass | B3: =SUM(B6:B88) -> 2.910383e-11 | C3: 894097
A5: Acct# | B5: Amount | C5: Explanation 2
A6: 157001000209.4313 | B6: =-Spread!N36 -> 81844.45 | C6: Allowances Reclass
A7: 157001000209.4313.0100 | B7: =-Spread!N37 -> -14316.7 | C7: Allowances Reclass
A8: 157001000211.4313 | B8: =Spread!N40 -> -19040 | C8: Allowances Reclass
A9: 157001000210.4313 | B9: =Spread!N41 -> -4562 | C9: Allowances Reclass
A10: 157001000244.4313 | B10: =Spread!N42 -> -5962 | C10: Allowances Reclass
A11: 157001000222.4313 | B11: =Spread!N43 -> -5516 | C11: Allowances Reclass
A12: 157001000263.4313 | B12: =Spread!N44 -> -1180 | C12: Allowances Reclass
A13: 157001000238.4313 | B13: =Spread!N45 -> -9633 | C13: Allowances Reclass
A14: 157001000248.4313 | B14: =Spread!N46 -> -104 | C14: Allowances Reclass
A15: 157001000229.4313 | B15: =Spread!N47 -> -6273 | C15: Allowances Reclass
A16: 157001000230.4313 | B16: =Spread!N48 -> -580 | C16: Allowances Reclass
A17: 157001000231.4313 | B17: =Spread!N49 -> -1435 | C17: Allowances Reclass
A19: 157001000232.4313 | B19: =Spread!N50 -> -2005 | C19: Allowances Reclass
A20: 157001000234.4313 | B20: =Spread!N51 -> -1221 | C20: Allowances Reclass
A21: 157001000236.4313 | B21: =Spread!N52 -> -4875 | C21: Allowances Reclass
A22: 157001000253.4313 | B22: =Spread!N53 -> -742 | C22: Allowances Reclass
A23: 157001000254.4313 | B23: =Spread!N54 -> -12 | C23: Allowances Reclass
A24: 157001000264.4313 | B24: =Spread!N55 -> -2511 | C24: Allowances Reclass
A25: 157001000270.4313 | B25: =Spread!N56 -> -370 | C25: Allowances Reclass
A26: 157001000212.4313 | B26: =Spread!N57 -> -238 | C26: Allowances Reclass
A27: 157001000209.4313 | B27: =Spread!N58 -> -1097 | C27: Allowances Reclass
A28: 157001150209.7165 | B28: =-Spread!N62 -> -213 | C28: Freight Reclass
A29: 157001150209.7171 | B29: =-Spread!N63 -> -364220.85 | C29: Freight Reclass
A30: 157001150211.7165 | B30: =Spread!N67 -> 56 | C30: Freight Reclass
A32: 157001150210.7165 | B32: =Spread!N68 -> 13 | C32: Freight Reclass
A33: 157001150244.7165 | B33: =Spread!N69 -> 18 | C33: Freight Reclass
A34: 157001150222.7165 | B34: =Spread!N70 -> 16 | C34: Freight Reclass
A35: 157001150263.7165 | B35: =Spread!N71 -> 3 | C35: Freight Reclass
A36: 157001150238.7165 | B36: =Spread!N72 -> 28 | C36: Freight Reclass
A37: 157001150248.7165 | B37: =Spread!N73 -> 0 | C37: Freight Reclass
A38: 157001150229.7165 | B38: =Spread!N74 -> 19 | C38: Freight Reclass
A39: 157001150230.7165 | B39: =Spread!N75 -> 2 | C39: Freight Reclass
A40: 157001150231.7165 | B40: =Spread!N76 -> 4 | C40: Freight Reclass
A41: 157001150232.7165 | B41: =Spread!N77 -> 6 | C41: Freight Reclass
A42: 157001150234.7165 | B42: =Spread!N78 -> 4 | C42: Freight Reclass
A43: 157001150236.7165 | B43: =Spread!N79 -> 14 | C43: Freight Reclass
A45: 157001150253.7165 | B45: =Spread!N80 -> 2 | C45: Freight Reclass
...
