Workbook
Name EssAliasTable: "Default"
Name EssAliasTable: "Default"
Name EssAliasTable: "Default"
Name EssAliasTable: "Default"
Name EssfHasNonUnique: FALSE
Name EssfHasNonUnique: FALSE
Name EssfHasNonUnique: FALSE
Name EssfHasNonUnique: FALSE
Name EssLatest: "Beg Bal"
Name EssLatest: "Beg Bal"
Name EssLatest: "Beg Bal"
Name EssLatest: "Beg Bal"
Name EssOptions: "A3100000000111000000001100020_020 00"
Name EssOptions: "A3100000000111000000001100020_020 00"
Name EssOptions: "A1100000000111000000001100020_020 00"
Name EssOptions: "A1100000000111000000001100020_020 00"
Name EssSamplingValue: 100
Name EssSamplingValue: 100
Name EssSamplingValue: 100
Name EssSamplingValue: 100

Sheet Report
A1: Pharma Freight Actual VS Budget
B2: FY15 | C2: September | H2: Full Year
A3: This report is NOT total Mallinckrodt, OUS regions not converted to E1 are not included | C3: Budget | D3: Current Forecast | E3: Actual | H3: Budget | I3: Current Forecast | J3: Actual
A5: In Freight
A6: API | B6: STL StearPhos/Gateway
B7: Japan | D7: =+'FY15 Current Forecast'!N59+'FY15 Current Forecast'!N61+'FY15 Current Forecast'!N68+'FY15 Current Forecast'!N62+'FY15 Current Forecast'!N63+'FY15 Current Forecast'!N66+'FY15 Current Forecast'!N67+'FY15 Current Forecast'!N60 -> 0 | E7: =+'FY15 Working Forecast'!N59+'FY15 Working Forecast'!N61+'FY15 Working Forecast'!N68+'FY15 Working Forecast'!N62+'FY15 Working Forecast'!N63+'FY15 Working Forecast'!N66+'FY15 Working Forecast'!N67+'FY15 Working Forecast'!N60 -> -28487.97 | I7: =+'FY15 Current Forecast'!O59+'FY15 Current Forecast'!O61+'FY15 Current Forecast'!O68+'FY15 Current Forecast'!O62+'FY15 Current Forecast'!O63+'FY15 Current Forecast'!O66+'FY15 Current Forecast'!O67+'FY15 Current Forecast'!O60 -> 0 | J7: =+'FY15 Working Forecast'!O59+'FY15 Working Forecast'!O61+'FY15 Working Forecast'!O68+'FY15 Working Forecast'!O62+'FY15 Working Forecast'!O63+'FY15 Working Forecast'!O66+'FY15 Working Forecast'!O67+'FY15 Working Forecast'!O60 -> 65508.17
B8: UK PAP/APAP | C8: =+'FY15 Budget'!N51+'FY15 Budget'!N52+'FY15 Budget'!N55+'FY15 Budget'!N57 -> 111832.17 | D8: =+'FY15 Current Forecast'!N52+'FY15 Current Forecast'!N53+'FY15 Current Forecast'!N55+'FY15 Current Forecast'!N57+'FY15 Current Forecast'!N58 -> 0 | E8: =+'FY15 Working Forecast'!N52+'FY15 Working Forecast'!N53+'FY15 Working Forecast'!N55+'FY15 Working Forecast'!N57+'FY15 Working Forecast'!N58 -> 117207.46 | H8: =+'FY15 Budget'!O51+'FY15 Budget'!O52+'FY15 Budget'!O55+'FY15 Budget'!O57 -> 1453818.2 | I8: =+'FY15 Current Forecast'!O52+'FY15 Current Forecast'!O53+'FY15 Current Forecast'!O55+'FY15 Current Forecast'!O57+'FY15 Current Forecast'!O58 -> 0 | J8: =+'FY15 Working Forecast'!O52+'FY15 Working Forecast'!O53+'FY15 Working Forecast'!O55+'FY15 Working Forecast'!O57+'FY15 Working Forecast'!O58 -> 1222339.2
B9: UK Bulk Narcotics | C9: =+'FY15 Budget'!N50 -> 0 | D9: =+'FY15 Current Forecast'!N51 -> 0 | E9: =+'FY15 Working Forecast'!N51 -> 0 | H9: =+'FY15 Budget'!O50 -> 0 | I9: =+'FY15 Current Forecast'!O51 -> 0 | J9: =+'FY15 Working Forecast'!O51 -> 42.97
B10: UK Stear/Phos | C10: =+'FY15 Budget'!N53 -> 5425.1694 | D10: =+'FY15 Current Forecast'!N54 -> 0 | E10: =+'FY15 Working Forecast'!N54 -> 10916.78 | H10: =+'FY15 Budget'!O53 -> 70527.202 | I10: =+'FY15 Current Forecast'!O54 -> 0 | J10: =+'FY15 Working Forecast'!O54 -> 148747.95
B11: Canada PHM | C11: =+'FY15 Budget'!N59 -> 0 | D11: =+'FY15 Current Forecast'!N69+'FY15 Current Forecast'!N64+'FY15 Current Forecast'!N65 -> 0 | E11: =+'FY15 Working Forecast'!N69+'FY15 Working Forecast'!N64+'FY15 Working Forecast'!N65 -> 0 | H11: =+'FY15 Budget'!O59 -> 0 | I11: =+'FY15 Current Forecast'!O69+'FY15 Current Forecast'!O64+'FY15 Current Forecast'!O65 -> 0 | J11: =+'FY15 Working Forecast'!O69+'FY15 Working Forecast'!O64+'FY15 Working Forecast'!O65 -> 0
B12: Sub-Total API In Freight | C12: =SUM(C6:C11) -> 117257.34 | D12: =SUM(D6:D11) -> 0 | E12: =SUM(E6:E11) -> 99636.27 | H12: =SUM(H6:H11) -> 1524345.4 | I12: =SUM(I6:I11) -> 0 | J12: =SUM(J6:J11) -> 1436638.2
A14: Dosage | B14: Hobart | C14: =+SUM('FY15 Budget'!N8:N49)+'FY15 Budget'!N56 -> 25593.521 | D14: =+SUM('FY15 Current Forecast'!N8:N50)+'FY15 Current Forecast'!N56 -> 0 | E14: =+SUM('FY15 Working Forecast'!N8:N50)+'FY15 Working Forecast'!N56 -> -3 | H14: =+SUM('FY15 Budget'!O8:O49) -> 299030.65 | I14: =+SUM('FY15 Current Forecast'!O8:O50)+'FY15 Current Forecast'!O56 -> 0 | J14: =+SUM('FY15 Working Forecast'!O8:O50)+'FY15 Working Forecast'!O56 -> 76286
B15: External Manufacturing | C15: =+'FY15 Budget'!N66+'FY15 Budget'!N67+'FY15 Budget'!N60 -> 4323.0783 | D15: =+'FY15 Current Forecast'!N76+'FY15 Current Forecast'!N77+'FY15 Current Forecast'!N70 -> 0 | E15: =+'FY15 Working Forecast'!N76+'FY15 Working Forecast'!N77+'FY15 Working Forecast'!N70 -> 9357.36 | H15: =+'FY15 Budget'!O66+'FY15 Budget'!O67+'FY15 Budget'!O60 -> 51876.94 | I15: =+'FY15 Current Forecast'!O76+'FY15 Current Forecast'!O77+'FY15 Current Forecast'!O70 -> 0 | J15: =+'FY15 Working Forecast'!O76+'FY15 Working Forecast'!O77+'FY15 Working Forecast'!O70 -> 98812.31
B16: Sub-Total Dosage In Freight | C16: =SUM(C14:C15) -> 29916.599 | D16: =SUM(D14:D15) -> 0 | E16: =SUM(E14:E15) -> 9354.36 | H16: =SUM(H14:H15) -> 350907.59 | I16: =SUM(I14:I15) -> 0 | J16: =SUM(J14:J15) -> 175098.31
A18: Questcor | B18: Autoimmune | C18: =+'FY15 Budget'!N64+'FY15 Budget'!N65+'FY15 Budget'!N63+'FY15 Budget'!N62+'FY15 Budget'!N61 -> 0 | D18: =+'FY15 Current Forecast'!N74+'FY15 Current Forecast'!N75+'FY15 Current Forecast'!N71+'FY15 Current Forecast'!N72+'FY15 Current Forecast'!N73 -> 0 | E18: =+'FY15 Working Forecast'!N74+'FY15 Working Forecast'!N75+'FY15 Working Forecast'!N71+'FY15 Working Forecast'!N72+'FY15 Working Forecast'!N73 -> 25626.73 | H18: =+'FY15 Budget'!O64+'FY15 Budget'!O65+'FY15 Budget'!O63+'FY15 Budget'!O62+'FY15 Budget'!O61 -> 0 | I18: =+'FY15 Current Forecast'!O74+'FY15 Current Forecast'!O75+'FY15 Current Forecast'!O71+'FY15 Current Forecast'!O72+'FY15 Current Forecast'!O73 -> 0 | J18: =+'FY15 Working Forecast'!O74+'FY15 Working Forecast'!O75+'FY15 Working Forecast'!O71+'FY15 Working Forecast'!O72+'FY15 Working Forecast'!O73 -> 473068.11
B19: Sub-Total Autoimmune | C19: =SUM(C17:C18) -> 0 | D19: =SUM(D17:D18) -> 0 | E19: =SUM(E17:E18) -> 25626.73 | H19: =SUM(H17:H18) -> 0 | I19: =SUM(I17:I18) -> 0 | J19: =SUM(J17:J18) -> 473068.11
A21: Imaging | B21: KN/Cincinnati | C21: =+SUM('FY15 Budget'!N191:N196) -> 0 | D21: =+SUM('FY15 Current Forecast'!N222:N227) -> 0 | E21: =+SUM('FY15 Working Forecast'!N222:N227) -> 4494.95 | H21: =+SUM('FY15 Budget'!O191:O196) -> 0 | I21: =+SUM('FY15 Current Forecast'!O222:O227) -> 0 | J21: =+SUM('FY15 Working Forecast'!O222:O227) -> 122224.95
B22: Canada | C22: =+'FY15 Budget'!N279 -> 9328.358 | D22: =+'FY15 Current Forecast'!N310+'FY15 Current Forecast'!N312 -> 0 | E22: =+'FY15 Working Forecast'!N310+'FY15 Working Forecast'!N312 -> 6520.23 | H22: =+'FY15 Budget'!O279 -> 111940.3 | I22: =+'FY15 Current Forecast'!O310+'FY15 Current Forecast'!O312 -> 0 | J22: =+'FY15 Working Forecast'!O310+'FY15 Working Forecast'!O312 -> 105793.68
B23: Sub-Total Imaging In Freight | C23: =SUM(C21:C22) -> 9328.358 | D23: =SUM(D21:D22) -> 0 | E23: =SUM(E21:E22) -> 11015.18 | H23: =SUM(H21:H22) -> 111940.3 | I23: =SUM(I21:I22) -> 0 | J23: =SUM(J21:J22) -> 228018.63
B25: Total JDE and E1 In Freight | C25: =SUM(C12,C16,C23,C19) -> 156502.29 | D25: =SUM(D12,D16,D23,D19) -> 0 | E25: =SUM(E12,E16,E23,E19) -> 145632.54 | H25: =SUM(H12,H16,H23,H19) -> 1987193.3 | I25: =SUM(I12,I16,I23,I19) -> 0 | J25: =SUM(J12,J16,J23,J19) -> 2312823.3
A27: Out Freight
A28: API | B28: STL StearPhos/Gateway | C28: =+'FY15 Budget'!N105+'FY15 Budget'!N129+'FY15 Budget'!N131+'FY15 Budget'!N124+'FY15 Budget'!N110+'FY15 Budget'!N130+'FY15 Budget'!N132 -> 24240 | D28: =+'FY15 Current Forecast'!N160+'FY15 Current Forecast'!N161+'FY15 Current Forecast'!N162+'FY15 Current Forecast'!N142+'FY15 Current Forecast'!N113+'FY15 Current Forecast'!N125+'FY15 Current Forecast'!N163 -> 0 | E28: =+'FY15 Working Forecast'!N160+'FY15 Working Forecast'!N161+'FY15 Working Forecast'!N162+'FY15 Working Forecast'!N142+'FY15 Working Forecast'!N113+'FY15 Working Forecast'!N125+'FY15 Working Forecast'!N163 -> 62374.76 | H28: =+'FY15 Budget'!O105+'FY15 Budget'!O130+'FY15 Budget'!O129+'FY15 Budget'!O131+'FY15 Budget'!O124+'FY15 Budget'!O110+'FY15 Budget'!O129 -> 315120 | I28: =+'FY15 Current Forecast'!O160+'FY15 Current Forecast'!O161+'FY15 Current Forecast'!O162+'FY15 Current Forecast'!O142+'FY15 Current Forecast'!O113+'FY15 Current Forecast'!O125+'FY15 Current Forecast'!O163 -> 0 | J28: =+'FY15 Working Forecast'!O160+'FY15 Working Forecast'!O161+'FY15 Working Forecast'!O162+'FY15 Working Forecast'!O142+'FY15 Working Forecast'!O113+'FY15 Working Forecast'!O125+'FY15 Working Forecast'!O163 -> 193863.56
B29: STL Plant Narcotics | C29: =+'FY15 Budget'!N127+'FY15 Budget'!N123+'FY15 Budget'!N128 -> 44560 | D29: =+'FY15 Current Forecast'!N158+'FY15 Current Forecast'!N159+'FY15 Current Forecast'!N138+'FY15 Current Forecast'!N139+'FY15 Current Forecast'!N140+'FY15 Current Forecast'!N141+'FY15 Current Forecast'!N109+'FY15 Current Forecast'!N114+'FY15 Current Forecast'!N129+'FY15 Current Forecast'!N130+'FY15 Current Forecast'!N131+'FY15 Current Forecast'!N132+'FY15 Current Forecast'!N119+'FY15 Current Forecast'!N99+'FY15 Current Forecast'!N112+'FY15 Current Forecast'!N117+'FY15 Current Forecast'!N128 -> 0 | E29: =+'FY15 Working Forecast'!N158+'FY15 Working Forecast'!N159+'FY15 Working Forecast'!N138+'FY15 Working Forecast'!N139+'FY15 Working Forecast'!N140+'FY15 Working Forecast'!N141+'FY15 Working Forecast'!N109+'FY15 Working Forecast'!N114+'FY15 Working Forecast'!N129+'FY15 Working Forecast'!N130+'FY15 Working Forecast'!N131+'FY15 Working Forecast'!N132+'FY15 Working Forecast'!N119+'FY15 Working Forecast'!N99+'FY15 Working Forecast'!N112+'FY15 Working Forecast'!N117+'FY15 Working Forecast'!N128 -> 72243.14 | H29: =+'FY15 Budget'!O127+'FY15 Budget'!O123+'FY15 Budget'!O128 -> 579280 | I29: =+'FY15 Current Forecast'!O158+'FY15 Current Forecast'!O159+'FY15 Current Forecast'!O138+'FY15 Current Forecast'!O139+'FY15 Current Forecast'!O140+'FY15 Current Forecast'!O141+'FY15 Current Forecast'!O109+'FY15 Current Forecast'!O114+'FY15 Current Forecast'!O129+'FY15 Current Forecast'!O130+'FY15 Current Forecast'!O131+'FY15 Current Forecast'!O132+'FY15 Current Forecast'!O119+'FY15 Current Forecast'!O99+'FY15 Current Forecast'!O112+'FY15 Current Forecast'!O117+'FY15 Current Forecast'!O128 -> 0 | J29: =+'FY15 Working Forecast'!O158+'FY15 Working Forecast'!O159+'FY15 Working Forecast'!O138+'FY15 Working Forecast'!O139+'FY15 Working Forecast'!O140+'FY15 Working Forecast'!O141+'FY15 Working Forecast'!O109+'FY15 Working Forecast'!O114+'FY15 Working Forecast'!O129+'FY15 Working Forecast'!O130+'FY15 Working Forecast'!O131+'FY15 Working Forecast'!O132+'FY15 Working Forecast'!O119+'FY15 Working Forecast'!O99+'FY15 Working Forecast'!O112+'FY15 Working Forecast'!O117+'FY15 Working Forecast'!O128 -> 619274.9
B30: Peptides
B31: APAP/COMPAP | C31: =+'FY15 Budget'!N126+'FY15 Budget'!N109+'FY15 Budget'!N184+'FY15 Budget'!N102+'FY15 Budget'!N119+'FY15 Budget'!N183+'FY15 Budget'!N99+'FY15 Budget'!N124 -> 126920 | D31: =+'FY15 Current Forecast'!N157+'FY15 Current Forecast'!N215+'FY15 Current Forecast'!N133+'FY15 Current Forecast'!N123+'FY15 Current Forecast'!N126+'FY15 Current Forecast'!N97+'FY15 Current Forecast'!N127+'FY15 Current Forecast'!N116+'FY15 Current Forecast'!N120+'FY15 Current Forecast'!N164+'FY15 Current Forecast'!N122+'FY15 Current Forecast'!N124+'FY15 Current Forecast'!N121+'FY15 Current Forecast'!N115+'FY15 Current Forecast'!N137+'FY15 Current Forecast'!N134+'FY15 Current Forecast'!N98+'FY15 Current Forecast'!N118+'FY15 Current Forecast'!N108+'FY15 Current Forecast'!N106+'FY15 Current Forecast'!N107+'FY15 Current Forecast'!N110+'FY15 Current Forecast'!N111+'FY15 Current Forecast'!N144+'FY15 Current Forecast'!N145+'FY15 Current Forecast'!N146+'FY15 Current Forecast'!N147+'FY15 Current Forecast'!N148+'FY15 Current Forecast'!N149+'FY15 Current Forecast'!N150+'FY15 Current Forecast'!N151+'FY15 Current Forecast'!N152+'FY15 Current Forecast'!N153+'FY15 Current Forecast'!N154+'FY15 Current Forecast'!N155+'FY15 Current Forecast'!N143 -> 0 | E31: =+'FY15 Working Forecast'!N157+'FY15 Working Forecast'!N215+'FY15 Working Forecast'!N133+'FY15 Working Forecast'!N123+'FY15 Working Forecast'!N126+'FY15 Working Forecast'!N97+'FY15 Working Forecast'!N127+'FY15 Working Forecast'!N116+'FY15 Working Forecast'!N120+'FY15 Working Forecast'!N164+'FY15 Working Forecast'!N122+'FY15 Working Forecast'!N124+'FY15 Working Forecast'!N121+'FY15 Working Forecast'!N115+'FY15 Working Forecast'!N137+'FY15 Working Forecast'!N134+'FY15 Working Forecast'!N98+'FY15 Working Forecast'!N118+'FY15 Working Forecast'!N108+'FY15 Working Forecast'!N106+'FY15 Working Forecast'!N107+'FY15 Working Forecast'!N110+'FY15 Working Forecast'!N111+'FY15 Working Forecast'!N144+'FY15 Working Forecast'!N145+'FY15 Working Forecast'!N146+'FY15 Working Forecast'!N147+'FY15 Working Forecast'!N148+'FY15 Working Forecast'!N149+'FY15 Working Forecast'!N150+'FY15 Working Forecast'!N151+'FY15 Working Forecast'!N152+'FY15 Working Forecast'!N153+'FY15 Working Forecast'!N154+'FY15 Working Forecast'!N155+'FY15 Working Forecast'!N143 -> 235017.58 | H31: =+'FY15 Budget'!O126+'FY15 Budget'!O109+'FY15 Budget'!O184+'FY15 Budget'!O102+'FY15 Budget'!O119+'FY15 Budget'!O183+'FY15 Budget'!O99+'FY15 Budget'!O124 -> 1649960 | I31: =+'FY15 Current Forecast'!O157+'FY15 Current Forecast'!O215+'FY15 Current Forecast'!O133+'FY15 Current Forecast'!O123+'FY15 Current Forecast'!O126+'FY15 Current Forecast'!O97+'FY15 Current Forecast'!O127+'FY15 Current Forecast'!O116+'FY15 Current Forecast'!O120+'FY15 Current Forecast'!O164+'FY15 Current Forecast'!O122+'FY15 Current Forecast'!O124+'FY15 Current Forecast'!O121+'FY15 Current Forecast'!O115+'FY15 Current Forecast'!O137+'FY15 Current Forecast'!O134+'FY15 Current Forecast'!O98+'FY15 Current Forecast'!O118+'FY15 Current Forecast'!O108+'FY15 Current Forecast'!O106+'FY15 Current Forecast'!O107+'FY15 Current Forecast'!O110+'FY15 Current Forecast'!O111+'FY15 Current Forecast'!O144+'FY15 Current Forecast'!O145+'FY15 Current Forecast'!O146+'FY15 Current Forecast'!O147+'FY15 Current Forecast'!O148+'FY15 Current Forecast'!O149+'FY15 Current Forecast'!O150+'FY15 Current Forecast'!O151+'FY15 Current Forecast'!O152+'FY15 Current Forecast'!O153+'FY15 Current Forecast'!O154+'FY15 Current Forecast'!O155+'FY15 Current Forecast'!O143 -> 0 | J31: =+'FY15 Working Forecast'!O157+'FY15 Working Forecast'!O215+'FY15 Working Forecast'!O133+'FY15 Working Forecast'!O123+'FY15 Working Forecast'!O126+'FY15 Working Forecast'!O97+'FY15 Working Forecast'!O127+'FY15 Working Forecast'!O116+'FY15 Working Forecast'!O120+'FY15 Working Forecast'!O164+'FY15 Working Forecast'!O122+'FY15 Working Forecast'!O124+'FY15 Working Forecast'!O121+'FY15 Working Forecast'!O115+'FY15 Working Forecast'!O137+'FY15 Working Forecast'!O134+'FY15 Working Forecast'!O98+'FY15 Working Forecast'!O118+'FY15 Working Forecast'!O108+'FY15 Working Forecast'!O106+'FY15 Working Forecast'!O107+'FY15 Working Forecast'!O110+'FY15 Working Forecast'!O111+'FY15 Working Forecast'!O144+'FY15 Working Forecast'!O145+'FY15 Working Forecast'!O146+'FY15 Working Forecast'!O147+'FY15 Working Forecast'!O148+'FY15 Working Forecast'!O149+'FY15 Working Forecast'!O150+'FY15 Working Forecast'!O151+'FY15 Working Forecast'!O152+'FY15 Working Forecast'!O153+'FY15 Working Forecast'!O154+'FY15 Working Forecast'!O155+'FY15 Working Forecast'!O143 -> 2089495.9
B32: UK PAP/APAP | C32: =+'FY15 Budget'!N180 -> 124391.43 | D32: =+'FY15 Current Forecast'!N212+'FY15 Current Forecast'!N208+'FY15 Current Forecast'!N211 -> 0 | E32: =+'FY15 Working Forecast'!N212+'FY15 Working Forecast'!N208+'FY15 Working Forecast'!N211 -> 93276.07 | H32: =+'FY15 Budget'!O180 -> 1617088.6 | I32: =+'FY15 Current Forecast'!O212+'FY15 Current Forecast'!O208+'FY15 Current Forecast'!O211 -> 0 | J32: =+'FY15 Working Forecast'!O212+'FY15 Working Forecast'!O208+'FY15 Working Forecast'!O211 -> 1556832.6
B33: UK Bulk Narcotics | C33: =+'FY15 Budget'!N181 -> 13635.088 | D33: =+'FY15 Current Forecast'!N213+'FY15 Current Forecast'!N209 -> 0 | E33: =+'FY15 Working Forecast'!N213+'FY15 Working Forecast'!N209 -> 3459.34 | H33: =+'FY15 Budget'!O181 -> 177256.15 | I33: =+'FY15 Current Forecast'!O213+'FY15 Current Forecast'!O209 -> 0 | J33: =+'FY15 Working Forecast'!O213+'FY15 Working Forecast'!O209 -> 113669.54
B34: UK Stear/Phos | C34: =+'FY15 Budget'!N182 -> 5907.7515 | D34: =+'FY15 Current Forecast'!N214+'FY15 Current Forecast'!N210 -> 0 | E34: =+'FY15 Working Forecast'!N214+'FY15 Working Forecast'!N210 -> 6122.43 | H34: =+'FY15 Budget'!O182 -> 76800.769 | I34: =+'FY15 Current Forecast'!O214+'FY15 Current Forecast'!O210 -> 0 | J34: =+'FY15 Working Forecast'!O214+'FY15 Working Forecast'!O210 -> 185197.04
B35: Goaling | C35: =+'FY15 Budget'!N116 -> 0 | D35: =+'FY15 Current Forecast'!N135 -> 0 | E35: =+'FY15 Working Forecast'!N135 -> 0 | H35: =+'FY15 Budget'!O116 -> 0 | I35: =+'FY15 Current Forecast'!O135 -> 0 | J35: =+'FY15 Working Forecast'!O135 -> 0
B36: Sub-Total API Out Freight | C36: =SUM(C28:C35) -> 339654.27 | D36: =SUM(D28:D35) -> 0 | E36: =SUM(E28:E35) -> 472493.32 | H36: =SUM(H28:H35) -> 4415505.5 | I36: =SUM(I28:I35) -> 0 | J36: =SUM(J28:J35) -> 4758333.5
A38: Dosage | B38: Hobart | C38: =+SUM('FY15 Budget'!N134:N175)+'FY15 Budget'!N90+'FY15 Budget'!N91+'FY15 Budget'!N92+'FY15 Budget'!N93+'FY15 Budget'!N94 -> 432448.89 | D38: =+SUM('FY15 Current Forecast'!N165:N207)+'FY15 Current Forecast'!N100+'FY15 Current Forecast'!N101+'FY15 Current Forecast'!N102+'FY15 Current Forecast'!N103+'FY15 Current Forecast'!N104+'FY15 Current Forecast'!N156 -> 0 | E38: =+SUM('FY15 Working Forecast'!N165:N207)+'FY15 Working Forecast'!N100+'FY15 Working Forecast'!N101+'FY15 Working Forecast'!N102+'FY15 Working Forecast'!N103+'FY15 Working Forecast'!N104+'FY15 Working Forecast'!N156 -> 338194.03 | H38: =+SUM('FY15 Budget'!O134:O175)+'FY15 Budget'!O90+'FY15 Budget'!O91+'FY15 Budget'!O92+'FY15 Budget'!O93+'FY15 Budget'!O94 -> 5658751.8 | I38: =+SUM('FY15 Current Forecast'!O165:O207)+'FY15 Current Forecast'!O100+'FY15 Current Forecast'!O101+'FY15 Current Forecast'!O102+'FY15 Current Forecast'!O103+'FY15 Current Forecast'!O104+'FY15 Current Forecast'!O156 -> 0 | J38: =+SUM('FY15 Working Forecast'!O165:O207)+'FY15 Working Forecast'!O100+'FY15 Working Forecast'!O101+'FY15 Working Forecast'!O102+'FY15 Working Forecast'!O103+'FY15 Working Forecast'!O104+'FY15 Working Forecast'!O156 -> 4884686.8
B39: Canada | C39: =+'FY15 Budget'!N285+'FY15 Budget'!N95+'FY15 Budget'!N287 -> 0 | D39: =+'FY15 Current Forecast'!N318+'FY15 Current Forecast'!N105+'FY15 Current Forecast'!N320 -> 0 | E39: =+'FY15 Working Forecast'!N318+'FY15 Working Forecast'!N105+'FY15 Working Forecast'!N320 -> 14665.54 | H39: =+'FY15 Budget'!O285+'FY15 Budget'!O95+'FY15 Budget'!O287 -> 0 | I39: =+'FY15 Current Forecast'!O318+'FY15 Current Forecast'!O105+'FY15 Current Forecast'!O320 -> 0 | J39: =+'FY15 Working Forecast'!O318+'FY15 Working Forecast'!O105+'FY15 Working Forecast'!O320 -> 142597.77
B40: External Manufactuing | C40: =+'FY15 Budget'!N70+'FY15 Budget'!N71+'FY15 Budget'!N77+'FY15 Budget'!N78 -> 472831.58 | D40: =+'FY15 Current Forecast'!N80+'FY15 Current Forecast'!N81+'FY15 Current Forecast'!N87+'FY15 Current Forecast'!N88 -> 0 | E40: =+'FY15 Working Forecast'!N80+'FY15 Working Forecast'!N81+'FY15 Working Forecast'!N87+'FY15 Working Forecast'!N88 -> 59795.61 | H40: =+'FY15 Budget'!O70+'FY15 Budget'!O71+'FY15 Budget'!O77+'FY15 Budget'!O78 -> 3595668.5 | I40: =+'FY15 Current Forecast'!O80+'FY15 Current Forecast'!O81+'FY15 Current Forecast'!O87+'FY15 Current Forecast'!O88 -> 0 | J40: =+'FY15 Working Forecast'!O80+'FY15 Working Forecast'!O81+'FY15 Working Forecast'!O87+'FY15 Working Forecast'!O88 -> 1185220.3
B41: Sub-Total Dosage Out Freight | C41: =SUM(C38:C40) -> 905280.47 | D41: =SUM(D38:D40) -> 0 | E41: =SUM(E38:E40) -> 412655.18 | H41: =SUM(H38:H40) -> 9254420.3 | I41: =SUM(I38:I40) -> 0 | J41: =SUM(J38:J40) -> 6212504.9
A43: Ikeria | B43: INO Therapeutics | C43: =SUM('FY15 Budget'!N299:N315)+'FY15 Budget'!N318 -> 0 | D43: =SUM('FY15 Current Forecast'!N335:N351)+'FY15 Current Forecast'!N354 -> 0 | E43: =SUM('FY15 Working Forecast'!N335:N351)+'FY15 Working Forecast'!N354 -> 406649.98 | H43: =SUM('FY15 Budget'!O299:O315)+'FY15 Budget'!O318 -> 0 | I43: =SUM('FY15 Current Forecast'!O335:O351)+'FY15 Current Forecast'!O354 -> 0 | J43: =SUM('FY15 Working Forecast'!O335:O351)+'FY15 Working Forecast'!O354 -> 1620738
B44: Sub-Total Autoimmune | C44: =SUM(C43:C43) -> 0 | D44: =SUM(D43:D43) -> 0 | E44: =SUM(E43:E43) -> 406649.98 | H44: =SUM(H43:H43) -> 0 | I44: =SUM(I43:I43) -> 0 | J44: =SUM(J43:J43) -> 1620738
A46: Questcor | B46: Autoimmune | C46: =+'FY15 Budget'!N72+'FY15 Budget'!N73+'FY15 Budget'!N74+'FY15 Budget'!N75+'FY15 Budget'!N76 -> 2000 | D46: =+'FY15 Current Forecast'!N82+'FY15 Current Forecast'!N83+'FY15 Current Forecast'!N84+'FY15 Current Forecast'!N85+'FY15 Current Forecast'!N86+'FY15 Current Forecast'!N89 -> 0 | E46: =+'FY15 Working Forecast'!N82+'FY15 Working Forecast'!N83+'FY15 Working Forecast'!N84+'FY15 Working Forecast'!N85+'FY15 Working Forecast'!N86+'FY15 Working Forecast'!N89 -> 21853.26 | H46: =+'FY15 Budget'!O72+'FY15 Budget'!O73+'FY15 Budget'!O74+'FY15 Budget'!O75+'FY15 Budget'!O76 -> 24000 | I46: =+'FY15 Current Forecast'!O82+'FY15 Current Forecast'!O83+'FY15 Current Forecast'!O84+'FY15 Current Forecast'!O85+'FY15 Current Forecast'!O86+'FY15 Current Forecast'!O89 -> 0 | J46: =+'FY15 Working Forecast'!O82+'FY15 Working Forecast'!O83+'FY15 Working Forecast'!O84+'FY15 Working Forecast'!O85+'FY15 Working Forecast'!O86+'FY15 Working Forecast'!O89 -> 319100.91
B47: Sub-Total Autoimmune | C47: =SUM(C46:C46) -> 2000 | D47: =SUM(D46:D46) -> 0 | E47: =SUM(E46:E46) -> 21853.26 | H47: =SUM(H46:H46) -> 24000 | I47: =SUM(I46:I46) -> 0 | J47: =SUM(J46:J46) -> 319100.91
A49: Imaging | B49: Cincinnati | C49: =+SUM('FY15 Budget'!N202:N203) -> 37838 | D49: =+SUM('FY15 Current Forecast'!N234:N235) -> 0 | E49: =+SUM('FY15 Working Forecast'!N234:N235) -> 62108.37 | H49: =+SUM('FY15 Budget'!O202:O203) -> 491896 | I49: =+SUM('FY15 Current Forecast'!O234:O235) -> 0 | J49: =+SUM('FY15 Working Forecast'!O234:O235) -> 778207.05
B50: KN | C50: =+SUM('FY15 Budget'!N198:N201)+'FY15 Budget'!N86+'FY15 Budget'!N87+'FY15 Budget'!N88+'FY15 Budget'!N89 -> 109441 | D50: =+SUM('FY15 Current Forecast'!N229:N232)+'FY15 Current Forecast'!N96 -> 0 | E50: =+SUM('FY15 Working Forecast'!N229:N232)+'FY15 Working Forecast'!N96 -> 109236.66 | H50: =+SUM('FY15 Budget'!O198:O201)+'FY15 Budget'!O86+'FY15 Budget'!O87+'FY15 Budget'!O88+'FY15 Budget'!O89 -> 1422737 | I50: =+SUM('FY15 Current Forecast'!O229:O232)+'FY15 Current Forecast'!O96 -> 0 | J50: =+SUM('FY15 Working Forecast'!O229:O232)+'FY15 Working Forecast'!O96 -> 1448006.1
...

Sheet Freight report
A1: Pharma Freight Actual VS Budget
B2: FY13 | C2: March | G2: YTD | K2: Full Year
C3: Actual | D3: Budget | E3: B/(W) | G3: Actual | H3: Budget | I3: B/(W) | K3: Budget | L3: Current Forecast | M3: B/(W)
A5: In Freight
A6: API | B6: STL StearPhos/Gateway | C6: =#REF! -> #REF! | E6: =+D6-C6 -> #REF! | G6: =#REF! -> #REF! | I6: =+H6-G6 -> #REF! | M6: =+L6-K6 -> 0
B7: Japan | C7: =+#REF!+#REF!+#REF!+#REF! -> #REF! | G7: =+#REF!+#REF!+#REF!+#REF! -> #REF! | L7: =+'FY15 Current Forecast'!O59+'FY15 Current Forecast'!O61 -> 0
B8: UK PAP/APAP | C8: =#REF! -> #REF! | D8: =+'FY15 Budget'!H51+'FY15 Budget'!H52+'FY15 Budget'!H55+'FY15 Budget'!H57 -> 111832.17 | E8: =+D8-C8 -> #REF! | G8: =#REF! -> #REF! | H8: =+'FY15 Budget'!C51+'FY15 Budget'!C52+'FY15 Budget'!C55+'FY15 Budget'!C57+'FY15 Budget'!D51+'FY15 Budget'!D52+'FY15 Budget'!D55+'FY15 Budget'!D57+'FY15 Budget'!E51+'FY15 Budget'!E52+'FY15 Budget'!E55+'FY15 Budget'!E57+'FY15 Budget'!F51+'FY15 Budget'!F52+'FY15 Budget'!F55+'FY15 Budget'!F57+'FY15 Budget'!G51+'FY15 Budget'!G52+'FY15 Budget'!G55+'FY15 Budget'!G57+'FY15 Budget'!H51+'FY15 Budget'!H52+'FY15 Budget'!H55+'FY15 Budget'!H57 -> 726909.09 | I8: =+H8-G8 -> #REF! | K8: =+'FY15 Budget'!O51+'FY15 Budget'!O52+'FY15 Budget'!O55+'FY15 Budget'!O57 -> 1453818.2 | L8: =+'FY15 Current Forecast'!O52+'FY15 Current Forecast'!O53+'FY15 Current Forecast'!O55+'FY15 Current Forecast'!O57 -> 0 | M8: =+L8-K8 -> -1453818.2
B9: UK Bulk Narcotics | C9: =+#REF! -> #REF! | D9: =+'FY15 Budget'!H50 -> 0 | E9: =+D9-C9 -> #REF! | G9: =#REF! -> #REF! | H9: =+'FY15 Budget'!C50+'FY15 Budget'!D50+'FY15 Budget'!E50+'FY15 Budget'!F50+'FY15 Budget'!G50+'FY15 Budget'!H50 -> 0 | I9: =+H9-G9 -> #REF! | K9: =+'FY15 Budget'!O50 -> 0 | L9: =+'FY15 Current Forecast'!O51 -> 0 | M9: =+L9-K9 -> 0
B10: UK Stear/Phos | C10: =#REF! -> #REF! | D10: =+'FY15 Budget'!H53 -> 5425.1694 | E10: =+D10-C10 -> #REF! | G10: =#REF! -> #REF! | H10: =+'FY15 Budget'!C53+'FY15 Budget'!D53+'FY15 Budget'!E53+'FY15 Budget'!F53+'FY15 Budget'!G53+'FY15 Budget'!H53 -> 35263.601 | I10: =+H10-G10 -> #REF! | K10: =+'FY15 Budget'!O53 -> 70527.202 | L10: =+'FY15 Current Forecast'!O54 -> 0 | M10: =+L10-K10 -> -70527.202
B11: Canada PHM | C11: =+#REF! -> #REF! | D11: =+'FY15 Budget'!H59 -> 0 | E11: =+D11-C11 -> #REF! | G11: =+#REF! -> #REF! | H11: =+'FY15 Budget'!C59+'FY15 Budget'!D59+'FY15 Budget'!E59+'FY15 Budget'!F59+'FY15 Budget'!G59+'FY15 Budget'!H59 -> 0 | I11: =+H11-G11 -> #REF! | K11: =+'FY15 Budget'!O59 -> 0 | L11: =+'FY15 Current Forecast'!O69 -> 0 | M11: =+L11-K11 -> 0
B12: Sub-Total API In Freight | C12: =SUM(C6:C11) -> #REF! | D12: =SUM(D6:D11) -> 117257.34 | E12: =SUM(E6:E11) -> #REF! | G12: =SUM(G6:G11) -> #REF! | H12: =SUM(H6:H11) -> 762172.69 | I12: =SUM(I6:I11) -> #REF! | K12: =SUM(K6:K11) -> 1524345.4 | L12: =SUM(L6:L11) -> 0 | M12: =SUM(M6:M11) -> -1524345.4
A14: Dosage | B14: Hobart | C14: =SUM(#REF!,#REF!) -> #REF! | D14: =+SUM('FY15 Budget'!H8:H49)+'FY15 Budget'!H56 -> 24803.452 | E14: =+D14-C14 -> #REF! | G14: =SUM(#REF!,#REF!) -> #REF! | H14: =+SUM('FY15 Budget'!C8:C49)+SUM('FY15 Budget'!D8:D49)+SUM('FY15 Budget'!E8:E49)+SUM('FY15 Budget'!F8:F49)+SUM('FY15 Budget'!G8:G49)+SUM('FY15 Budget'!H8:H49) -> 147671.62 | I14: =+H14-G14 -> #REF! | K14: =+SUM('FY15 Budget'!O8:O49) -> 299030.65 | L14: =+SUM('FY15 Current Forecast'!O8:O50)+'FY15 Current Forecast'!O56 -> 0 | M14: =+L14-K14 -> -299030.65
B15: CNS/Intrathecal | C15: =+#REF!+#REF! -> #REF! | D15: =+'FY15 Budget'!H66+'FY15 Budget'!H67 -> 4323.0783 | E15: =+D15-C15 -> #REF! | G15: =+#REF!+#REF! -> #REF! | H15: =+'FY15 Budget'!C66+'FY15 Budget'!C67+'FY15 Budget'!D66+'FY15 Budget'!D67+'FY15 Budget'!E66+'FY15 Budget'!E67+'FY15 Budget'!F66+'FY15 Budget'!F67+'FY15 Budget'!G66+'FY15 Budget'!G67+'FY15 Budget'!H66+'FY15 Budget'!H67 -> 25938.47 | I15: =+H15-G15 -> #REF! | K15: =+'FY15 Budget'!O66+'FY15 Budget'!O67 -> 51876.94 | L15: =+'FY15 Current Forecast'!O76+'FY15 Current Forecast'!O77 -> 0 | M15: =+L15-K15 -> -51876.94
B16: Sub-Total Dosage In Freight | C16: =SUM(C14:C15) -> #REF! | D16: =SUM(D14:D15) -> 29126.53 | E16: =SUM(E14:E15) -> #REF! | G16: =SUM(G14:G15) -> #REF! | H16: =SUM(H14:H15) -> 173610.09 | I16: =SUM(I14:I15) -> #REF! | K16: =SUM(K14:K15) -> 350907.59 | L16: =SUM(L14:L15) -> 0 | M16: =SUM(M14:M15) -> -350907.59
A18: Imaging | B18: Joliet/Cincinnati/KN | C18: =+#REF!+#REF!+#REF!+#REF!+#REF!+#REF! -> #REF! | D18: =+SUM('FY15 Budget'!H191:H196) -> 0 | E18: =+D18-C18 -> #REF! | G18: =+#REF!+#REF!+#REF!+#REF!+#REF!++#REF! -> #REF! | H18: =+SUM('FY15 Budget'!C191:C196)+SUM('FY15 Budget'!D191:D196)+SUM('FY15 Budget'!E191:E196)+SUM('FY15 Budget'!F191:F196)+SUM('FY15 Budget'!G191:G196)+SUM('FY15 Budget'!H191:H196) -> 0 | I18: =+H18-G18 -> #REF! | K18: =+SUM('FY15 Budget'!O191:O196) -> 0 | L18: =+SUM('FY15 Current Forecast'!O214:O218) -> 0 | M18: =+L18-K18 -> 0
B19: Canada | C19: =+#REF!-#REF! -> #REF! | D19: =+'FY15 Budget'!H277 -> 0 | E19: =+D19-C19 -> #REF! | G19: =+#REF!-#REF! -> #REF! | H19: =+'FY15 Budget'!C277+'FY15 Budget'!D277+'FY15 Budget'!E277+'FY15 Budget'!F277+'FY15 Budget'!G277+'FY15 Budget'!H277 -> 0 | I19: =+H19-G19 -> #REF! | K19: =+'FY15 Budget'!O277 -> 0 | L19: =+'FY15 Current Forecast'!O301 -> 0 | M19: =+L19-K19 -> 0
B20: Sub-Total Imaging In Freight | C20: =SUM(C18:C19) -> #REF! | D20: =SUM(D18:D19) -> 0 | E20: =SUM(E18:E19) -> #REF! | G20: =SUM(G18:G19) -> #REF! | H20: =SUM(H18:H19) -> 0 | I20: =SUM(I18:I19) -> #REF! | K20: =SUM(K18:K19) -> 0 | L20: =SUM(L18:L19) -> 0 | M20: =SUM(M18:M19) -> 0
B22: Total InFreight | C22: =SUM(C12,C16,C20) -> #REF! | D22: =SUM(D12,D16,D20) -> 146383.87 | E22: =SUM(E12,E16,E20) -> #REF! | G22: =SUM(G12,G16,G20) -> #REF! | H22: =SUM(H12,H16,H20) -> 935782.78 | I22: =SUM(I12,I16,I20) -> #REF! | K22: =SUM(K12,K16,K20) -> 1875253 | L22: =SUM(L12,L16,L20) -> 0 | M22: =SUM(M12,M16,M20) -> -1875253
A24: Out Freight
A25: API | B25: STL StearPhos/Gateway | C25: =+#REF!+#REF!+#REF!+#REF!+#REF!+#REF!+#REF!+#REF!+#REF!+#REF!+#REF!+#REF!+#REF! -> #REF! | D25: =+'FY15 Budget'!H105+'FY15 Budget'!H129+'FY15 Budget'!H131+'FY15 Budget'!H124+'FY15 Budget'!H110 -> 0 | E25: =+D25-C25 -> #REF! | G25: =+#REF!+#REF!+#REF!+#REF!+#REF!+#REF!+#REF!+#REF!+#REF!+#REF!+#REF!+#REF!+#REF! -> #REF! | H25: =+'FY15 Budget'!C105+'FY15 Budget'!C129+'FY15 Budget'!C131+'FY15 Budget'!C124+'FY15 Budget'!C110+'FY15 Budget'!D105+'FY15 Budget'!D129+'FY15 Budget'!D131+'FY15 Budget'!D124+'FY15 Budget'!D110+'FY15 Budget'!E105+'FY15 Budget'!E129+'FY15 Budget'!E131+'FY15 Budget'!E124+'FY15 Budget'!E110+'FY15 Budget'!F105+'FY15 Budget'!F129+'FY15 Budget'!F131+'FY15 Budget'!F124+'FY15 Budget'!F110+'FY15 Budget'!G105+'FY15 Budget'!G129+'FY15 Budget'!G131+'FY15 Budget'!G124+'FY15 Budget'!G110+'FY15 Budget'!H105+'FY15 Budget'!H129+'FY15 Budget'!H131+'FY15 Budget'!H124+'FY15 Budget'!H110 -> 0 | I25: =+H25-G25 -> #REF! | K25: =+'FY15 Budget'!O105+'FY15 Budget'!O129+'FY15 Budget'!O131+'FY15 Budget'!O124+'FY15 Budget'!O110 -> 0 | L25: =+'FY15 Current Forecast'!O152+'FY15 Current Forecast'!O154+'FY15 Current Forecast'!O148+'FY15 Current Forecast'!O60+'FY15 Current Forecast'!O116+'FY15 Current Forecast'!O128+'FY15 Current Forecast'!O147+'FY15 Current Forecast'!O132 -> 0 | M25: =+L25-K25 -> 0
B26: STL Plant Narcotics | C26: =+#REF!+#REF!+SUM(#REF!)+#REF!+#REF!+#REF!+#REF! -> #REF! | D26: =+'FY15 Budget'!H127+'FY15 Budget'!H123 -> 0 | E26: =+D26-C26 -> #REF! | G26: =+#REF!+#REF!+SUM(#REF!)+#REF!+#REF!+#REF!+#REF! -> #REF! | H26: =+'FY15 Budget'!C127+'FY15 Budget'!C123+'FY15 Budget'!D127+'FY15 Budget'!D123+'FY15 Budget'!E127+'FY15 Budget'!E123+'FY15 Budget'!F127+'FY15 Budget'!F123+'FY15 Budget'!G127+'FY15 Budget'!G123+'FY15 Budget'!H127+'FY15 Budget'!H123 -> 0 | I26: =+H26-G26 -> #REF! | K26: =+'FY15 Budget'!O127+'FY15 Budget'!O123 -> 0 | L26: =+'FY15 Current Forecast'!O150+'FY15 Current Forecast'!O142+'FY15 Current Forecast'!O144+'FY15 Current Forecast'!O145+'FY15 Current Forecast'!O146+'FY15 Current Forecast'!O111+'FY15 Current Forecast'!O117+'FY15 Current Forecast'!O133+'FY15 Current Forecast'!O134+'FY15 Current Forecast'!O135+'FY15 Current Forecast'!O136+'FY15 Current Forecast'!O122 -> 0 | M26: =+L26-K26 -> 0
B27: Peptides | C27: =+#REF!+#REF! -> #REF! | E27: =+D27-C27 -> #REF! | G27: =+#REF!+#REF! -> #REF! | I27: =+H27-G27 -> #REF! | M27: =+L27-K27 -> 0
B28: APAP/COMPAP | C28: =+#REF!+#REF!+#REF!+#REF!+#REF!+#REF!+#REF!+#REF!+#REF!+#REF!+#REF!+#REF!+#REF!+#REF!+#REF!+#REF!+#REF!+#REF!+#REF!+#REF!+#REF!+#REF!+#REF! -> #REF! | D28: =+'FY15 Budget'!H126+'FY15 Budget'!H109+'FY15 Budget'!H184+'FY15 Budget'!H102+'FY15 Budget'!H119+'FY15 Budget'!H183 -> 126920 | E28: =+D28-C28 -> #REF! | G28: =+#REF!+#REF!+#REF!+#REF!+#REF!+#REF!+#REF!+#REF!+#REF!+#REF!+#REF!+#REF!+#REF!+#REF!+#REF!+#REF!+#REF!+#REF!+#REF!+#REF!+#REF!+#REF!+#REF! -> #REF! | H28: =+'FY15 Budget'!C126+'FY15 Budget'!C109+'FY15 Budget'!C184+'FY15 Budget'!C102+'FY15 Budget'!C119+'FY15 Budget'!C183+'FY15 Budget'!D126+'FY15 Budget'!D109+'FY15 Budget'!D184+'FY15 Budget'!D102+'FY15 Budget'!D119+'FY15 Budget'!D183+'FY15 Budget'!E126+'FY15 Budget'!E109+'FY15 Budget'!E184+'FY15 Budget'!E102+'FY15 Budget'!E119+'FY15 Budget'!E183+'FY15 Budget'!F126+'FY15 Budget'!F109+'FY15 Budget'!F184+'FY15 Budget'!F102+'FY15 Budget'!F119+'FY15 Budget'!F183+'FY15 Budget'!G126+'FY15 Budget'!G109+'FY15 Budget'!G184+'FY15 Budget'!G102+'FY15 Budget'!G119+'FY15 Budget'!G183+'FY15 Budget'!H126+'FY15 Budget'!H109+'FY15 Budget'!H184+'FY15 Budget'!H102+'FY15 Budget'!H119+'FY15 Budget'!H183 -> 824980 | I28: =+H28-G28 -> #REF! | K28: =+'FY15 Budget'!O126+'FY15 Budget'!O109+'FY15 Budget'!O184+'FY15 Budget'!O102+'FY15 Budget'!O119+'FY15 Budget'!O183 -> 1649960 | L28: =+'FY15 Current Forecast'!O149+'FY15 Current Forecast'!#REF!+'FY15 Current Forecast'!O124+'FY15 Current Forecast'!O137+'FY15 Current Forecast'!O126+'FY15 Current Forecast'!O129+'FY15 Current Forecast'!O107+'FY15 Current Forecast'!O130+'FY15 Current Forecast'!O119+'FY15 Current Forecast'!#REF!+'FY15 Current Forecast'!O155+'FY15 Current Forecast'!O125+'FY15 Current Forecast'!O127+'FY15 Current Forecast'!O123+'FY15 Current Forecast'!O118+'FY15 Current Forecast'!O141+'FY15 Current Forecast'!O138 -> #REF! | M28: =+L28-K28 -> #REF!
B29: UK PAP/APAP | C29: =+#REF! -> #REF! | D29: =+'FY15 Budget'!H180 -> 124391.43 | E29: =+D29-C29 -> #REF! | G29: =+#REF! -> #REF! | H29: =+'FY15 Budget'!C180+'FY15 Budget'!D180+'FY15 Budget'!E180+'FY15 Budget'!F180+'FY15 Budget'!G180+'FY15 Budget'!H180 -> 808544.3 | I29: =+H29-G29 -> #REF! | K29: =+'FY15 Budget'!O180 -> 1617088.6 | L29: =+'FY15 Current Forecast'!O205 -> 0 | M29: =+L29-K29 -> -1617088.6
B30: UK Bulk Narcotics | C30: =+#REF! -> #REF! | D30: =+'FY15 Budget'!H181 -> 13635.088 | E30: =+D30-C30 -> #REF! | G30: =+#REF! -> #REF! | H30: =+'FY15 Budget'!C181+'FY15 Budget'!D181+'FY15 Budget'!E181+'FY15 Budget'!F181+'FY15 Budget'!G181+'FY15 Budget'!H181 -> 88628.073 | I30: =+H30-G30 -> #REF! | K30: =+'FY15 Budget'!O181 -> 177256.15 | L30: =+'FY15 Current Forecast'!O206 -> 0 | M30: =+L30-K30 -> -177256.15
B31: UK Stear/Phos | C31: =+#REF! -> #REF! | D31: =+'FY15 Budget'!H182 -> 5907.7515 | E31: =+D31-C31 -> #REF! | G31: =+#REF! -> #REF! | H31: =+'FY15 Budget'!C182+'FY15 Budget'!D182+'FY15 Budget'!E182+'FY15 Budget'!F182+'FY15 Budget'!G182+'FY15 Budget'!H182 -> 38400.385 | I31: =+H31-G31 -> #REF! | K31: =+'FY15 Budget'!O182 -> 76800.769 | L31: =+'FY15 Current Forecast'!O207 -> 0 | M31: =+L31-K31 -> -76800.769
B32: Goaling | D32: =+'FY15 Budget'!H116 -> 0 | E32: =+D32-C32 -> 0 | H32: =+'FY15 Budget'!C116+'FY15 Budget'!D116+'FY15 Budget'!E116+'FY15 Budget'!F116+'FY15 Budget'!G116+'FY15 Budget'!H116 -> 0 | I32: =+H32-G32 -> 0 | K32: =+'FY15 Budget'!O116 -> 0 | L32: =+'FY15 Current Forecast'!O139 -> 0 | M32: =+L32-K32 -> 0
B33: Sub-Total API Out Freight | C33: =SUM(C25:C32) -> #REF! | D33: =SUM(D25:D32) -> 270854.27 | E33: =SUM(E25:E32) -> #REF! | G33: =SUM(G25:G32) -> #REF! | H33: =SUM(H25:H32) -> 1760552.8 | I33: =SUM(I25:I32) -> #REF! | K33: =SUM(K25:K32) -> 3521105.5 | L33: =SUM(L25:L32) -> #REF! | M33: =SUM(M25:M32) -> #REF!
A35: Dosage | B35: Hobart | C35: =SUM(#REF!,#REF!)+#REF! -> #REF! | D35: =+SUM('FY15 Budget'!H134:H175) -> 438290.42 | E35: =+D35-C35 -> #REF! | G35: =SUM(#REF!,#REF!)+#REF! -> #REF! | H35: =+SUM('FY15 Budget'!C134:C175)+SUM('FY15 Budget'!D134:D175)+SUM('FY15 Budget'!E134:E175)+SUM('FY15 Budget'!F134:F175)+SUM('FY15 Budget'!G134:G175)+SUM('FY15 Budget'!H134:H175) -> 2856059.5 | I35: =+H35-G35 -> #REF! | K35: =+SUM('FY15 Budget'!O134:O175) -> 5658751.8 | L35: =+SUM('FY15 Current Forecast'!O156:O200) -> 0 | M35: =+L35-K35 -> -5658751.8
B36: CNS/Intrathecal | C36: =+#REF!+#REF! -> #REF! | D36: =+'FY15 Budget'!H70+'FY15 Budget'!H71 -> 25000 | E36: =+D36-C36 -> #REF! | G36: =+#REF!+#REF! -> #REF! | H36: =+'FY15 Budget'!C70+'FY15 Budget'!C71+'FY15 Budget'!D70+'FY15 Budget'!D71+'FY15 Budget'!E70+'FY15 Budget'!E71+'FY15 Budget'!F70+'FY15 Budget'!F71+'FY15 Budget'!G70+'FY15 Budget'!G71+'FY15 Budget'!H70+'FY15 Budget'!H71 -> 150000 | I36: =+H36-G36 -> #REF! | K36: =+'FY15 Budget'!O70+'FY15 Budget'!O71 -> 300000 | L36: =+'FY15 Current Forecast'!O80+'FY15 Current Forecast'!O81 -> 0 | M36: =+L36-K36 -> -300000
B37: Sub-Total Dosage Out Freight | C37: =SUM(C35:C36) -> #REF! | D37: =SUM(D35:D36) -> 463290.42 | E37: =SUM(E35:E36) -> #REF! | G37: =SUM(G35:G36) -> #REF! | H37: =SUM(H35:H36) -> 3006059.5 | I37: =SUM(I35:I36) -> #REF! | K37: =SUM(K35:K36) -> 5958751.8 | L37: =SUM(L35:L36) -> 0 | M37: =SUM(M35:M36) -> -5958751.8
A39: Imaging | B39: Cincinnati | C39: =+#REF!+#REF!+#REF!+#REF! -> #REF! | D39: =+SUM('FY15 Budget'!H202:H203) -> 37838 | E39: =+D39-C39 -> #REF! | G39: =+#REF!+#REF!+#REF! -> #REF! | H39: =+SUM('FY15 Budget'!C202:C203)+SUM('FY15 Budget'!D202:D203)+SUM('FY15 Budget'!E202:E203)+SUM('FY15 Budget'!F202:F203)+SUM('FY15 Budget'!G202:G203)+SUM('FY15 Budget'!H202:H203) -> 245948 | I39: =+H39-G39 -> #REF! | K39: =+SUM('FY15 Budget'!O202:O203) -> 491896 | L39: =+SUM('FY15 Current Forecast'!O224:O226) -> 0 | M39: =+L39-K39 -> -491896
B40: Contrast | C40: =+#REF!+#REF!+#REF!+#REF! -> #REF! | D40: =+SUM('FY15 Budget'!H200:H201) -> 109441 | E40: =+D40-C40 -> #REF! | G40: =+#REF!+#REF!+#REF!+#REF!+#REF! -> #REF! | H40: =+SUM('FY15 Budget'!C200:C201)+SUM('FY15 Budget'!D200:D201)+SUM('FY15 Budget'!E200:E201)+SUM('FY15 Budget'!F200:F201)+SUM('FY15 Budget'!G200:G201)+SUM('FY15 Budget'!H200:H201) -> 711368 | I40: =+H40-G40 -> #REF! | K40: =+SUM('FY15 Budget'!O200:O201) -> 1422737 | L40: =+SUM('FY15 Current Forecast'!O222:O223) -> 0 | M40: =+L40-K40 -> -1422737
B41: Canada | C41: =+#REF! -> #REF! | E41: =+D41-C41 -> #REF! | G41: =+#REF! -> #REF! | I41: =+H41-G41 -> #REF! | L41: =+'FY15 Current Forecast'!O306 -> 0 | M41: =+L41-K41 -> 0
B42: Sub-Total Contrast | C42: =SUM(C39:C41) -> #REF! | D42: =SUM(D39:D41) -> 147279 | E42: =SUM(E39:E41) -> #REF! | G42: =SUM(G39:G41) -> #REF! | H42: =SUM(H39:H41) -> 957316 | I42: =SUM(I39:I41) -> #REF! | K42: =SUM(K39:K41) -> 1914633 | L42: =SUM(L39:L41) -> 0 | M42: =SUM(M39:M41) -> -1914633
A44: Nuc Med | B44: Nuc Med Direct | C44: =SUM(#REF!)-C46 -> #REF! | D44: =+'FY15 Budget'!H292 -> 0 | E44: =+D44-C44 -> #REF! | G44: =SUM(#REF!)-G46 -> #REF! | H44: =+'FY15 Budget'!C292+'FY15 Budget'!D292+'FY15 Budget'!E292+'FY15 Budget'!F292+'FY15 Budget'!G292+'FY15 Budget'!H292 -> 0 | I44: =+H44-G44 -> #REF! | K44: =+'FY15 Budget'!O292 -> 0 | L44: =+'FY15 Current Forecast'!O312+'FY15 Current Forecast'!O227+'FY15 Current Forecast'!O313+'FY15 Current Forecast'!O315 -> 0 | M44: =+L44-K44 -> 0
B45: Canada | C45: =+#REF!+#REF!-#REF!+#REF!+#REF! -> #REF! | D45: =+'FY15 Budget'!H281 -> 229621.26 | E45: =+D45-C45 -> #REF! | G45: =+#REF!+#REF!-#REF!+#REF!+#REF! -> #REF! | H45: =+'FY15 Budget'!C281+'FY15 Budget'!D281+'FY15 Budget'!E281+'FY15 Budget'!F281+'FY15 Budget'!G281+'FY15 Budget'!H281 -> 1492537.3 | I45: =+H45-G45 -> #REF! | K45: =+'FY15 Budget'!O281 -> 2985074.6 | L45: =+'FY15 Current Forecast'!O305-'FY15 Current Forecast'!O306 -> 0 | M45: =+L45-K45 -> -2985074.6
B46: Freight Accrual | C46: 0 | E46: =+D46-C46 -> 0 | G46: =+C46 -> 0 | I46: =+H46-G46 -> 0 | M46: =+L46-K46 -> 0
B47: Sub-Total Maryland Heights | C47: =SUM(C44:C46) -> #REF! | D47: =SUM(D44:D46) -> 229621.26 | E47: =SUM(E44:E46) -> #REF! | G47: =SUM(G44:G46) -> #REF! | H47: =SUM(H44:H46) -> 1492537.3 | I47: =SUM(I44:I46) -> #REF! | K47: =SUM(K44:K46) -> 2985074.6 | L47: =SUM(L44:L46) -> 0 | M47: =SUM(M44:M46) -> -2985074.6
B49: Total Out Freight | C49: =SUM(C47,C42,C37,C33) -> #REF! | D49: =SUM(D47,D42,D37,D33) -> 1111045 | E49: =SUM(E47,E42,E37,E33) -> #REF! | G49: =SUM(G47,G42,G37,G33) -> #REF! | H49: =SUM(H47,H42,H37,H33) -> 7216465.6 | I49: =SUM(I47,I42,I37,I33) -> #REF! | K49: =SUM(K47,K42,K37,K33) -> 14379565 | L49: =SUM(L47,L42,L37,L33) -> #REF! | M49: =SUM(M47,M42,M37,M33) -> #REF!
...

Sheet Act vs Budget - revised format
A1: Pharma Freight Actual VS Budget
B2: FY12 | C2: Jan | G2: YTD | K2: Full Year
C3: Actual | D3: Budget | E3: B/(W) | G3: Actual | H3: Budget | I3: B/(W) | K3: Budget | L3: Current Forecast | M3: B/(W)
A5: PHARMA
B6: Net Sales | C6: 1.0957036e+08 | D6: 1.1892978e+08 | E6: =+D6-C6 -> 9359423.2 | G6: 4.6322965e+08 | H6: 4.6889988e+08 | I6: =+H6-G6 -> 5670226.1 | M6: =+L6-K6 -> 0
A7: In Freight
A8: API | B8: STL Plant Stear/Phos | C8: =#REF! -> #REF! | E8: =+D8-C8 -> #REF! | G8: =#REF! -> #REF! | I8: =+H8-G8 -> #REF! | K8: 0 | M8: =+L8-K8 -> 0
B9: STL Plant Narcotics | E9: =+D9-C9 -> 0 | I9: =+H9-G9 -> 0 | M9: =+L9-K9 -> 0
B10: Gateway | E10: =+D10-C10 -> 0 | I10: =+H10-G10 -> 0 | M10: =+L10-K10 -> 0
B11: Japan | C11: =+#REF!+#REF!+#REF!+#REF! -> #REF! | G11: =+#REF!+#REF!+#REF!+#REF! -> #REF! | K11: 0 | L11: =+'FY15 Current Forecast'!O56+'FY15 Current Forecast'!O59 -> 0
B12: UK PAP/APAP | C12: =#REF! -> #REF! | D12: =+'FY15 Budget'!F51+'FY15 Budget'!F52+'FY15 Budget'!F55+'FY15 Budget'!F57 -> 111832.17 | E12: =+D12-C12 -> #REF! | G12: =#REF! -> #REF! | H12: =+'FY15 Budget'!C51+'FY15 Budget'!C52+'FY15 Budget'!C55+'FY15 Budget'!C57+'FY15 Budget'!D51+'FY15 Budget'!D52+'FY15 Budget'!D55+'FY15 Budget'!D57+'FY15 Budget'!E51+'FY15 Budget'!E52+'FY15 Budget'!E55+'FY15 Budget'!E57+'FY15 Budget'!F51+'FY15 Budget'!F52+'FY15 Budget'!F55+'FY15 Budget'!F57 -> 475286.71 | I12: =+H12-G12 -> #REF! | K12: =+'FY15 Budget'!O51+'FY15 Budget'!O52+'FY15 Budget'!O55+'FY15 Budget'!O57 -> 1453818.2 | L12: =+'FY15 Current Forecast'!O50+'FY15 Current Forecast'!O51+'FY15 Current Forecast'!O53+'FY15 Current Forecast'!O55 -> 0 | M12: =+L12-K12 -> -1453818.2
B13: UK Bulk Narcotics | C13: =+#REF! -> #REF! | D13: =+'FY15 Budget'!F50 -> 0 | E13: =+D13-C13 -> #REF! | G13: =#REF! -> #REF! | H13: =+'FY15 Budget'!C50+'FY15 Budget'!D50+'FY15 Budget'!E50+'FY15 Budget'!F50 -> 0 | I13: =+H13-G13 -> #REF! | K13: =+'FY15 Budget'!O50 -> 0 | L13: =+'FY15 Current Forecast'!O49 -> 0 | M13: =+L13-K13 -> 0
B14: UK Stear/Phos | C14: =#REF! -> #REF! | D14: =+'FY15 Budget'!F53 -> 5425.1694 | E14: =+D14-C14 -> #REF! | G14: =#REF! -> #REF! | H14: =+'FY15 Budget'!C53+'FY15 Budget'!D53+'FY15 Budget'!E53+'FY15 Budget'!F53 -> 23056.97 | I14: =+H14-G14 -> #REF! | K14: =+'FY15 Budget'!O53 -> 70527.202 | L14: =+'FY15 Current Forecast'!O52 -> 0 | M14: =+L14-K14 -> -70527.202
B15: Canada PHM | C15: =+#REF! -> #REF! | D15: =+'FY15 Budget'!F59 -> 0 | E15: =+D15-C15 -> #REF! | G15: =+#REF! -> #REF! | H15: =+'FY15 Budget'!C59+'FY15 Budget'!D59+'FY15 Budget'!E59+'FY15 Budget'!F59 -> 0 | I15: =+H15-G15 -> #REF! | K15: =+'FY15 Budget'!O59 -> 0 | L15: =+'FY15 Current Forecast'!O67 -> 0 | M15: =+L15-K15 -> 0
B16: Sub-Total API In Freight | C16: =SUM(C8:C15) -> #REF! | D16: =SUM(D8:D15) -> 117257.34 | E16: =SUM(E8:E15) -> #REF! | G16: =SUM(G8:G15) -> #REF! | H16: =SUM(H8:H15) -> 498343.68 | I16: =SUM(I8:I15) -> #REF! | K16: =SUM(K8:K15) -> 1524345.4 | L16: =SUM(L8:L15) -> 0 | M16: =SUM(M8:M15) -> -1524345.4
A18: Dosage | B18: Hobart | C18: =SUM(#REF!,#REF!) -> #REF! | D18: =+SUM('FY15 Budget'!F8:F49)+'FY15 Budget'!F56 -> 24662.776 | E18: =+D18-C18 -> #REF! | G18: =SUM(#REF!,#REF!) -> #REF! | H18: =+SUM('FY15 Budget'!C8:C49)+'FY15 Budget'!C56+SUM('FY15 Budget'!D8:D49)+'FY15 Budget'!D56+SUM('FY15 Budget'!E8:E49)+'FY15 Budget'!E56+SUM('FY15 Budget'!F8:F49)+'FY15 Budget'!F56 -> 98138.307 | I18: =+H18-G18 -> #REF! | K18: =+SUM('FY15 Budget'!O8:O49)+'FY15 Budget'!O56 -> 299030.65 | L18: =+SUM('FY15 Current Forecast'!O7:O47)+'FY15 Current Forecast'!O54 -> 0 | M18: =+L18-K18 -> -299030.65
B19: Sub-Total Dosage In Freight | C19: =SUM(C18:C18) -> #REF! | D19: =SUM(D18:D18) -> 24662.776 | E19: =SUM(E18:E18) -> #REF! | G19: =SUM(G18:G18) -> #REF! | H19: =SUM(H18:H18) -> 98138.307 | I19: =SUM(I18:I18) -> #REF! | K19: =SUM(K18:K18) -> 299030.65 | L19: =SUM(L18:L18) -> 0 | M19: =SUM(M18:M18) -> -299030.65
A21: Imaging | B21: Joliet | C21: =+#REF!+#REF!+#REF!+#REF!+#REF!+#REF! -> #REF! | D21: =+SUM('FY15 Budget'!F191:F196) -> 0 | E21: =+D21-C21 -> #REF! | G21: =+#REF!+#REF!+#REF!+#REF!+#REF!++#REF! -> #REF! | H21: =+SUM('FY15 Budget'!C191:C196)+SUM('FY15 Budget'!D191:D196)+SUM('FY15 Budget'!E191:E196)+SUM('FY15 Budget'!F191:F196) -> 0 | I21: =+H21-G21 -> #REF! | K21: =+SUM('FY15 Budget'!O191:O196) -> 0 | L21: =+SUM('FY15 Current Forecast'!O209:O213) -> 0 | M21: =+L21-K21 -> 0
B22: Sub-Total Imaging In Freight | C22: =SUM(C21:C21) -> #REF! | D22: =SUM(D21:D21) -> 0 | E22: =SUM(E21:E21) -> #REF! | G22: =SUM(G21:G21) -> #REF! | H22: =SUM(H21:H21) -> 0 | I22: =SUM(I21:I21) -> #REF! | K22: =SUM(K21:K21) -> 0 | L22: =SUM(L21:L21) -> 0 | M22: =SUM(M21:M21) -> 0
B24: Total InFreight | C24: =SUM(C16,C19,C22) -> #REF! | D24: =SUM(D16,D19,D22) -> 141920.11 | E24: =SUM(E16,E19,E22) -> #REF! | G24: =SUM(G16,G19,G22) -> #REF! | H24: =SUM(H16,H19,H22) -> 596481.99 | I24: =SUM(I16,I19,I22) -> #REF! | K24: =SUM(K16,K19,K22) -> 1823376 | L24: =SUM(L16,L19,L22) -> 0 | M24: =SUM(M16,M19,M22) -> -1823376
C25: =C24/C6 -> #REF! | D25: =-D24/D6 -> -0.0011933101 | G25: =G24/G6 -> #REF! | H25: =-H24/H6 -> -0.0012720882 | K25: =-K24/K6 -> #DIV/0! | L25: =-L24/L6 -> #DIV/0!
A26: Out Freight
A27: API | B27: STL Plant Stear/Phos | C27: =+#REF!+#REF! -> #REF! | D27: =+'FY15 Budget'!F129+'FY15 Budget'!F131 -> 0 | E27: =+D27-C27 -> #REF! | G27: =+#REF!+#REF! -> #REF! | H27: =+'FY15 Budget'!C129+'FY15 Budget'!C131+'FY15 Budget'!D129+'FY15 Budget'!D131+'FY15 Budget'!E129+'FY15 Budget'!E131+'FY15 Budget'!F129+'FY15 Budget'!F131 -> 0 | I27: =+H27-G27 -> #REF! | K27: =+'FY15 Budget'!O129+'FY15 Budget'!O131 -> 0 | L27: =+'FY15 Current Forecast'!O149+'FY15 Current Forecast'!O150 -> 0 | M27: =+L27-K27 -> 0
B28: Canada | C28: =+#REF! -> #REF! | E28: =+D28-C28 -> #REF! | G28: =+#REF! -> #REF! | I28: =+H28-G28 -> #REF! | M28: =+L28-K28 -> 0
B29: LATAM | C29: =+#REF! -> #REF! | D29: =+'FY15 Budget'!F124 -> 0 | E29: =+D29-C29 -> #REF! | G29: =+#REF! -> #REF! | H29: =+'FY15 Budget'!C124+'FY15 Budget'!D124+'FY15 Budget'!E124+'FY15 Budget'!F124 -> 0 | I29: =+H29-G29 -> #REF! | K29: =+'FY15 Budget'!O124 -> 0 | L29: =+'FY15 Current Forecast'!O145 -> 0 | M29: =+L29-K29 -> 0
B30: EMEA | C30: =+#REF!+#REF!+#REF! -> #REF! | E30: =+D30-C30 -> #REF! | G30: =+#REF!+#REF!+#REF! -> #REF! | I30: =+H30-G30 -> #REF! | M30: =+L30-K30 -> 0
B31: Japan | C31: =+#REF!+#REF!+#REF!+#REF! -> #REF! | E31: =+D31-C31 -> #REF! | G31: =+#REF!+#REF!+#REF!+#REF! -> #REF! | I31: =+H31-G31 -> #REF! | L31: =+'FY15 Current Forecast'!O57 -> 0 | M31: =+L31-K31 -> 0
B32: APAC | C32: =+#REF! -> #REF! | E32: =+D32-C32 -> #REF! | G32: =+#REF! -> #REF! | I32: =+H32-G32 -> #REF! | L32: =+'FY15 Current Forecast'!O114 -> 0 | M32: =+L32-K32 -> 0
B33: STL Plant Narcotics | C33: =+#REF! -> #REF! | D33: =+'FY15 Budget'!F127 -> 0 | E33: =+D33-C33 -> #REF! | G33: =+#REF! -> #REF! | H33: =+'FY15 Budget'!C127+'FY15 Budget'!D127+'FY15 Budget'!E127+'FY15 Budget'!F127 -> 0 | I33: =+H33-G33 -> #REF! | K33: =+'FY15 Budget'!O127 -> 0 | L33: =+'FY15 Current Forecast'!O148 -> 0 | M33: =+L33-K33 -> 0
B34: Canada | C34: =+#REF! -> #REF! | D34: 0 | E34: =+D34-C34 -> #REF! | G34: =+#REF! -> #REF! | H34: 0 | I34: =+H34-G34 -> #REF! | K34: 0 | L34: 0 | M34: =+L34-K34 -> 0
B35: LATAM | C35: =SUM(#REF!) -> #REF! | E35: =+D35-C35 -> #REF! | G35: =SUM(#REF!) -> #REF! | I35: =+H35-G35 -> #REF! | L35: =+'FY15 Current Forecast'!O140+'FY15 Current Forecast'!O141+'FY15 Current Forecast'!O142+'FY15 Current Forecast'!O144 -> 0 | M35: =+L35-K35 -> 0
B36: EMEA | C36: =+#REF!+#REF! -> #REF! | E36: =+D36-C36 -> #REF! | G36: =+#REF!+#REF! -> #REF! | I36: =+H36-G36 -> #REF! | L36: =+'FY15 Current Forecast'!O107 -> 0 | M36: =+L36-K36 -> 0
B37: Japan | C37: =+#REF! -> #REF! | E37: =+D37-C37 -> #REF! | G37: =+#REF! -> #REF! | I37: =+H37-G37 -> #REF! | L37: =+'FY15 Current Forecast'!O129 -> 0 | M37: =+L37-K37 -> 0
B38: APAC | C38: =+#REF! -> #REF! | E38: =+D38-C38 -> #REF! | G38: =+#REF! -> #REF! | I38: =+H38-G38 -> #REF! | L38: =+'FY15 Current Forecast'!O115 -> 0 | M38: =+L38-K38 -> 0
B39: Peptides | C39: =+#REF!+#REF! -> #REF! | E39: =+D39-C39 -> #REF! | G39: =+#REF!+#REF! -> #REF! | I39: =+H39-G39 -> #REF! | M39: =+L39-K39 -> 0
B40: Gateway | C40: =+#REF!-(C57*0.04)-(C57*0.2) -> #REF! | E40: =+D40-C40 -> #REF! | G40: =+#REF! -> #REF! | I40: =+H40-G40 -> #REF! | L40: =+'FY15 Current Forecast'!O126 -> 0 | M40: =+L40-K40 -> 0
B41: Raleigh APAP | C41: =+#REF!-(C57*0.14) -> #REF! | D41: =+'FY15 Budget'!F126 -> 126920 | E41: =+D41-C41 -> #REF! | G41: =+#REF!-G57 -> #REF! | H41: =+'FY15 Budget'!C126+'FY15 Budget'!D126+'FY15 Budget'!E126+'FY15 Budget'!F126 -> 539410 | I41: =+H41-G41 -> #REF! | K41: =+'FY15 Budget'!O126 -> 1649960 | L41: =+'FY15 Current Forecast'!O146 -> 0 | M41: =+L41-K41 -> -1649960
B42: Canada | C42: =+#REF!+#REF!-(C57*0.06) -> #REF! | D42: =+'FY15 Budget'!F184 -> 0 | E42: =+D42-C42 -> #REF! | G42: =+#REF!+#REF! -> #REF! | H42: =+'FY15 Budget'!C184+'FY15 Budget'!D184+'FY15 Budget'!E184+'FY15 Budget'!F184 -> 0 | I42: =+H42-G42 -> #REF! | K42: =+'FY15 Budget'!O184 -> 0 | L42: =+'FY15 Current Forecast'!O206+'FY15 Current Forecast'!#REF! -> #REF! | M42: =+L42-K42 -> #REF!
B43: LATAM | C43: =+#REF!+#REF!+#REF!+#REF!+#REF!+#REF!-(C57*0.15) -> #REF! | E43: =+D43-C43 -> #REF! | G43: =+#REF!+#REF!+#REF!+#REF!+#REF!+#REF! -> #REF! | I43: =+H43-G43 -> #REF! | L43: =+'FY15 Current Forecast'!O135+'FY15 Current Forecast'!O124 -> 0 | M43: =+L43-K43 -> 0
B44: EMEA | C44: =+#REF!+#REF!+#REF!+#REF!+#REF! -> #REF! | E44: =+D44-C44 -> #REF! | G44: =+#REF!+#REF!+#REF!+#REF!+#REF! -> #REF! | I44: =+H44-G44 -> #REF! | L44: =+'FY15 Current Forecast'!O127+'FY15 Current Forecast'!O79 -> 0 | M44: =+L44-K44 -> 0
...

Sheet Net Sales Actual
C2: Net Sales | D2: Net Sales | E2: Net Sales | F2: Net Sales | G2: Net Sales | H2: Net Sales | I2: Net Sales | J2: Net Sales | K2: Net Sales | L2: Net Sales | M2: Net Sales | N2: Net Sales | O2: Net Sales
C3: 2010 Actuals | D3: 2010 Actuals | E3: 2010 Actuals | F3: 2011 Actuals | G3: 2011 Actuals | H3: 2011 Actuals | I3: 2011 Actuals | J3: 2011 Actuals | K3: 2011 Actuals | L3: 2011 Actuals | M3: 2011 Actuals | N3: 2011 Actuals | O3: 2011 Actuals
C4: Oct | D4: Nov | E4: Dec | F4: Jan | G4: Feb | H4: Mar | I4: Apr | J4: May | K4: Jun | L4: Jul | M4: Aug | N4: Sep | O4: Annual
A6: Disisional Pharmaceuticals - CYR
A13: Nuclear Direct w/Grp Alloc - CYR | C13: 16691751 | D13: 18245665 | E13: 16257951 | F13: 0 | G13: 0 | H13: 0 | I13: 0 | J13: 0 | K13: 0 | L13: 0 | M13: 0 | N13: 0 | O13: 25560512
A15: Nuclear Pharmacies w/Grp Alloc - CYR | C15: 14855177 | D15: 17523774 | E15: 12800017 | F15: 0 | G15: 0 | H15: 0 | I15: 0 | J15: 0 | K15: 0 | L15: 0 | M15: 0 | N15: 0 | O15: -168.3
A16: Virtual Network w/Grp Alloc - CYR | C16: 4683542.8 | D16: 5714064 | E16: -10702907 | F16: 0 | G16: 0 | H16: 0 | I16: 0 | J16: 0 | K16: 0 | L16: 0 | M16: 0 | N16: 0 | O16: -366473.37

Sheet Net Sales Budget
C2: Net Sales | D2: Net Sales | E2: Net Sales | F2: Net Sales | G2: Net Sales | H2: Net Sales | I2: Net Sales | J2: Net Sales | K2: Net Sales | L2: Net Sales | M2: Net Sales | N2: Net Sales | O2: Net Sales
C3: 2010 Budget | D3: 2010 Budget | E3: 2010 Budget | F3: 2010 Budget | G3: 2010 Budget | H3: 2010 Budget | I3: 2010 Budget | J3: 2010 Budget | K3: 2010 Budget | L3: 2010 Budget | M3: 2010 Budget | N3: 2010 Budget | O3: 2010 Budget
C4: Oct | D4: Nov | E4: Dec | F4: Jan | G4: Feb | H4: Mar | I4: Apr | J4: May | K4: Jun | L4: Jul | M4: Aug | N4: Sep | O4: Annual
A6: WW Pharm (Excl L&M, Incl SS Alloc) - CYR | C6: 73513713 | D6: 78159268 | E6: 68800829 | F6: 86283804 | G6: 87038405 | H6: 81281779 | I6: 93553846 | J6: 88113337 | K6: 84918299 | L6: 80880852 | M6: 84118740 | N6: 1.130358e+08 | O6: 1.0196987e+09
A7: Total US Imaging Incl SS Alloc - CYR | C7: 54967378 | D7: 67446826 | E7: 52691264 | F7: 48628019 | G7: 66894936 | H7: 47213514 | I7: 47214790 | J7: 59485682 | K7: 49432716 | L7: 47634908 | M7: 61890011 | N7: 60462081 | O7: 6.6396212e+08
A12: Total US CM&DS (incl SS Alloc) - CYR | C12: 18821056 | D12: 24880983 | E12: 18310376 | F12: 15866627 | G12: 25772272 | H12: 16589457 | I12: 18120585 | J12: 22759272 | K12: 18746675 | L12: 18188737 | M12: 22989029 | N12: 18829509 | O12: =SUM(C12:N12) -> 2.3987458e+08
O13: =SUM(C13:N13) -> 0
O14: =SUM(C14:N14) -> 0
A15: Nuclear Direct w/Grp Alloc - CYR | C15: 36238322 | D15: 42674843 | E15: 34066025 | F15: 32822392 | G15: 41278664 | H15: 30056932 | I15: 29168205 | J15: 36819410 | K15: 27677916 | L15: 29520171 | M15: 38993982 | N15: 32574447 | O15: =SUM(C15:N15) -> 4.1189131e+08
O16: =SUM(C16:N16) -> 0

Sheet FY15 Budget
C2: FY 2015 | D2: FY 2015 | E2: FY 2015 | F2: FY 2015 | G2: FY 2015 | H2: FY 2015 | I2: FY 2015 | J2: FY 2015 | K2: FY 2015 | L2: FY 2015 | M2: FY 2015 | N2: FY 2015
C3: Budget Rate | D3: Budget Rate | E3: Budget Rate | F3: Budget Rate | G3: Budget Rate | H3: Budget Rate | I3: Budget Rate | J3: Budget Rate | K3: Budget Rate | L3: Budget Rate | M3: Budget Rate | N3: Budget Rate
C4: USD | D4: USD | E4: USD | F4: USD | G4: USD | H4: USD | I4: USD | J4: USD | K4: USD | L4: USD | M4: USD | N4: USD
C5: Budget | D5: Budget | E5: Budget | F5: Budget | G5: Budget | H5: Budget | I5: Budget | J5: Budget | K5: Budget | L5: Budget | M5: Budget | N5: Budget
C6: FDC 015 Out-Freight Expense | D6: FDC 015 Out-Freight Expense | E6: FDC 015 Out-Freight Expense | F6: FDC 015 Out-Freight Expense | G6: FDC 015 Out-Freight Expense | H6: FDC 015 Out-Freight Expense | I6: FDC 015 Out-Freight Expense | J6: FDC 015 Out-Freight Expense | K6: FDC 015 Out-Freight Expense | L6: FDC 015 Out-Freight Expense | M6: FDC 015 Out-Freight Expense | N6: FDC 015 Out-Freight Expense | O6: FDC 015 Out-Freight Expense
C7: Oct | D7: Nov | E7: Dec | F7: Jan | G7: Feb | H7: Mar | I7: Apr | J7: May | K7: Jun | L7: Jul | M7: Aug | N7: Sep | O7: Annual
A8: 157001150209 FREIGHT | B8: 7165i In-freight Expense | C8: 750 | D8: 750 | E8: 750 | F8: 750 | G8: 750 | H8: 750 | I8: 750 | J8: 750 | K8: 750 | L8: 750 | M8: 750 | N8: 750 | O8: =SUM(C8:N8) -> 9000
A9: 157001150210 Frt Exp-Oxycodone Products | B9: 7165i In-freight Expense | C9: 3000 | D9: 3000 | E9: 3000 | F9: 3000 | G9: 3000 | H9: 3000 | I9: 3000 | J9: 3000 | K9: 3000 | L9: 3000 | M9: 3000 | N9: 3000 | O9: =SUM(C9:N9) -> 36000
A10: 157001150211 Frt Exp-Hydrocodone Products | B10: 7165i In-freight Expense | C10: 6000 | D10: 6000 | E10: 6000 | F10: 6000 | G10: 6000 | H10: 6000 | I10: 6000 | J10: 6000 | K10: 6000 | L10: 6000 | M10: 6000 | N10: 6000 | O10: =SUM(C10:N10) -> 72000
A11: 157001150212 Frt Exp-Methylin Oral Solution | B11: 7165i In-freight Expense | C11: 150 | D11: 150 | E11: 150 | F11: 150 | G11: 150 | H11: 150 | I11: 150 | J11: 150 | K11: 150 | L11: 150 | M11: 150 | N11: 150 | O11: =SUM(C11:N11) -> 1800
A12: 157001150219 FREIGHT | B12: 7165i In-freight Expense | C12: 0 | D12: 0 | E12: 0 | F12: 0 | G12: 0 | H12: 0 | I12: 0 | J12: 0 | K12: 0 | L12: 0 | M12: 0 | N12: 0 | O12: =SUM(C12:N12) -> 0
A13: 157001150221 Frt Exp-ADDICTION TREATMENT | B13: 7165i In-freight Expense | C13: 3000 | D13: 3000 | E13: 3000 | F13: 3000 | G13: 3000 | H13: 3000 | I13: 3000 | J13: 3000 | K13: 3000 | L13: 3000 | M13: 3000 | N13: 3000 | O13: =SUM(C13:N13) -> 36000
A14: 157001150222 Frt Exp-Methylphenidate | B14: 7165i In-freight Expense | C14: 750 | D14: 750 | E14: 750 | F14: 750 | G14: 750 | H14: 750 | I14: 750 | J14: 750 | K14: 750 | L14: 750 | M14: 750 | N14: 750 | O14: =SUM(C14:N14) -> 9000
A15: 157001150224 Frt Exp-Other Brand Products | B15: 7165i In-freight Expense | C15: 0 | D15: 0 | E15: 0 | F15: 0 | G15: 0 | H15: 0 | I15: 0 | J15: 0 | K15: 0 | L15: 0 | M15: 0 | N15: 0 | O15: =SUM(C15:N15) -> 0
A16: 157001150225 Frt Exp-CNS Non-Promoted Prod | B16: 7165i In-freight Expense | C16: 216.86225 | D16: 191.03066 | E16: 200.98427 | F16: 200.48238 | G16: 196.76671 | H16: 203.08308 | I16: 202.44431 | J16: 199.05069 | K16: 201.80554 | L16: 201.34928 | M16: 197.95419 | N16: 197.74479 | O16: =SUM(C16:N16) -> 2409.5582
A17: 157001150226 Zydus Freight Expense | B17: 7165i In-freight Expense | C17: 0 | D17: 0 | E17: 0 | F17: 0 | G17: 0 | H17: 0 | I17: 0 | J17: 0 | K17: 0 | L17: 0 | M17: 0 | N17: 0 | O17: =SUM(C17:N17) -> 0
A18: 157001150227 Oxycodone ER Products Freight | B18: 7165i In-freight Expense | C18: 0 | D18: 0 | E18: 0 | F18: 0 | G18: 0 | H18: 0 | I18: 0 | J18: 0 | K18: 0 | L18: 0 | M18: 0 | N18: 0 | O18: =SUM(C18:N18) -> 0
A19: 157001150229 Morphine ER-Frt Exp | B19: 7165i In-freight Expense | C19: 1500 | D19: 1500 | E19: 1500 | F19: 1500 | G19: 1500 | H19: 1500 | I19: 1500 | J19: 1500 | K19: 1500 | L19: 1500 | M19: 1500 | N19: 1500 | O19: =SUM(C19:N19) -> 18000
A20: 157001150230 Hydromorphone-Frt Exp | B20: 7165i In-freight Expense | C20: 750 | D20: 750 | E20: 750 | F20: 750 | G20: 750 | H20: 750 | I20: 750 | J20: 750 | K20: 750 | L20: 750 | M20: 750 | N20: 750 | O20: =SUM(C20:N20) -> 9000
A21: 157001150231 Methadone Generics-Frt Exp | B21: 7165i In-freight Expense | C21: 1500 | D21: 1500 | E21: 1500 | F21: 1500 | G21: 1500 | H21: 1500 | I21: 1500 | J21: 1500 | K21: 1500 | L21: 1500 | M21: 1500 | N21: 1500 | O21: =SUM(C21:N21) -> 18000
A22: 157001150232 APAP Codeine-Frt Exp | B22: 7165i In-freight Expense | C22: 300 | D22: 300 | E22: 300 | F22: 300 | G22: 300 | H22: 300 | I22: 300 | J22: 300 | K22: 300 | L22: 300 | M22: 300 | N22: 300 | O22: =SUM(C22:N22) -> 3600
A23: 157001150233 APAP Propoxyphene-Frt Exp | B23: 7165i In-freight Expense | C23: 0 | D23: 0 | E23: 0 | F23: 0 | G23: 0 | H23: 0 | I23: 0 | J23: 0 | K23: 0 | L23: 0 | M23: 0 | N23: 0 | O23: =SUM(C23:N23) -> 0
A24: 157001150234 Fentanyl Lozenge-Frt Exp | B24: 7165i In-freight Expense | C24: 100 | D24: 100 | E24: 100 | F24: 100 | G24: 100 | H24: 100 | I24: 100 | J24: 100 | K24: 100 | L24: 100 | M24: 100 | N24: 100 | O24: =SUM(C24:N24) -> 1200
A25: 157001150235 Tussicaps-Frt Exp | B25: 7165i In-freight Expense | C25: 0 | D25: 0 | E25: 0 | F25: 0 | G25: 0 | H25: 0 | I25: 0 | J25: 0 | K25: 0 | L25: 0 | M25: 0 | N25: 0 | O25: =SUM(C25:N25) -> 0
A26: 157001150236 Fentanyl Patch-Frt Exp | B26: 7165i In-freight Expense | C26: 1500 | D26: 1500 | E26: 1500 | F26: 1500 | G26: 1500 | H26: 1500 | I26: 1500 | J26: 1500 | K26: 1500 | L26: 1500 | M26: 1500 | N26: 1500 | O26: =SUM(C26:N26) -> 18000
A27: 157001150237 Methylphenidate ER(MedadateCD) | B27: 7165i In-freight Expense | C27: 0 | D27: 150 | E27: 150 | F27: 150 | G27: 150 | H27: 150 | I27: 150 | J27: 150 | K27: 150 | L27: 150 | M27: 150 | N27: 150 | O27: =SUM(C27:N27) -> 1650
A28: 157001150238 Methylphenidate ER (Concerta) | B28: 7165i In-freight Expense | C28: 150 | D28: 150 | E28: 150 | F28: 150 | G28: 150 | H28: 150 | I28: 150 | J28: 150 | K28: 150 | L28: 150 | M28: 150 | N28: 150 | O28: =SUM(C28:N28) -> 1800
A29: 157001150240 Tussi Suspension-Frt Exp | B29: 7165i In-freight Expense | C29: 0 | D29: 0 | E29: 0 | F29: 0 | G29: 0 | H29: 0 | I29: 0 | J29: 0 | K29: 0 | L29: 0 | M29: 0 | N29: 0 | O29: =SUM(C29:N29) -> 0
A30: 157001150241 OxymorphoneER(OpanaER) Frt Exp | B30: 7165i In-freight Expense | C30: 0 | D30: 0 | E30: 0 | F30: 0 | G30: 0 | H30: 0 | I30: 0 | J30: 0 | K30: 0 | L30: 0 | M30: 0 | N30: 0 | O30: =SUM(C30:N30) -> 0
A31: 157001150242 New Brands (External)-Frt Exp | B31: 7165i In-freight Expense | C31: 0 | D31: 0 | E31: 0 | F31: 0 | G31: 0 | H31: 0 | I31: 0 | J31: 0 | K31: 0 | L31: 0 | M31: 0 | N31: 0 | O31: =SUM(C31:N31) -> 0
A32: 157001150244 Oxycodone APAP-Frt Exp | B32: 7165i In-freight Expense | C32: 3000 | D32: 3000 | E32: 3000 | F32: 3000 | G32: 3000 | H32: 3000 | I32: 3000 | J32: 3000 | K32: 3000 | L32: 3000 | M32: 3000 | N32: 3000 | O32: =SUM(C32:N32) -> 36000
A33: 157001150245 Tofranil-PM/ImipraPam Frt Exp | B33: 7165i In-freight Expense | C33: 0 | D33: 0 | E33: 0 | F33: 0 | G33: 0 | H33: 0 | I33: 0 | J33: 0 | K33: 0 | L33: 0 | M33: 0 | N33: 0 | O33: =SUM(C33:N33) -> 0
A34: 157001150247 Morphine Sulfate ER (Kadian) | B34: 7165i In-freight Expense | C34: 0 | D34: 0 | E34: 0 | F34: 0 | G34: 0 | H34: 0 | I34: 0 | J34: 0 | K34: 0 | L34: 0 | M34: 0 | N34: 0 | O34: =SUM(C34:N34) -> 0
